2018-05-25 16:17:34,251,5960,django.request,ERROR,exception.py:118,Internal Server Error: /api/automation/test_time
Traceback (most recent call last):
  File "D:\Users\SIMO\AppData\Local\Programs\Python\Python36\lib\site-packages\django\core\handlers\exception.py", line 35, in inner
    response = get_response(request)
  File "D:\Users\SIMO\AppData\Local\Programs\Python\Python36\lib\site-packages\django\core\handlers\base.py", line 158, in _get_response
    response = self.process_exception_by_middleware(e, request)
  File "D:\Users\SIMO\AppData\Local\Programs\Python\Python36\lib\site-packages\django\core\handlers\base.py", line 156, in _get_response
    response = response.render()
  File "D:\Users\SIMO\AppData\Local\Programs\Python\Python36\lib\site-packages\django\template\response.py", line 106, in render
    self.content = self.rendered_content
  File "D:\Users\SIMO\AppData\Local\Programs\Python\Python36\lib\site-packages\rest_framework\response.py", line 72, in rendered_content
    ret = renderer.render(self.data, accepted_media_type, context)
  File "D:\Users\SIMO\AppData\Local\Programs\Python\Python36\lib\site-packages\rest_framework\renderers.py", line 105, in render
    allow_nan=not self.strict, separators=separators
  File "D:\Users\SIMO\AppData\Local\Programs\Python\Python36\lib\site-packages\rest_framework\utils\json.py", line 28, in dumps
    return json.dumps(*args, **kwargs)
  File "D:\Users\SIMO\AppData\Local\Programs\Python\Python36\lib\json\__init__.py", line 238, in dumps
    **kw).encode(obj)
  File "D:\Users\SIMO\AppData\Local\Programs\Python\Python36\lib\json\encoder.py", line 199, in encode
    chunks = self.iterencode(o, _one_shot=True)
  File "D:\Users\SIMO\AppData\Local\Programs\Python\Python36\lib\json\encoder.py", line 257, in iterencode
    return _iterencode(o, 0)
  File "D:\Users\SIMO\AppData\Local\Programs\Python\Python36\lib\site-packages\rest_framework\utils\encoders.py", line 68, in default
    return super(JSONEncoder, self).default(obj)
  File "D:\Users\SIMO\AppData\Local\Programs\Python\Python36\lib\json\encoder.py", line 180, in default
    o.__class__.__name__)
TypeError: Object of type 'ListSerializer' is not JSON serializable
2018-05-25 16:17:34,387,5960,django.server,ERROR,basehttp.py:124,"GET /api/automation/test_time?project_id=1 HTTP/1.1" 500 117915
2018-05-25 16:25:05,295,2736,django.request,ERROR,exception.py:118,Internal Server Error: /api/automation/test_time
Traceback (most recent call last):
  File "D:\Users\SIMO\AppData\Local\Programs\Python\Python36\lib\site-packages\django\core\handlers\exception.py", line 35, in inner
    response = get_response(request)
  File "D:\Users\SIMO\AppData\Local\Programs\Python\Python36\lib\site-packages\django\core\handlers\base.py", line 128, in _get_response
    response = self.process_exception_by_middleware(e, request)
  File "D:\Users\SIMO\AppData\Local\Programs\Python\Python36\lib\site-packages\django\core\handlers\base.py", line 126, in _get_response
    response = wrapped_callback(request, *callback_args, **callback_kwargs)
  File "D:\Users\SIMO\AppData\Local\Programs\Python\Python36\lib\site-packages\django\views\decorators\csrf.py", line 54, in wrapped_view
    return view_func(*args, **kwargs)
  File "D:\Users\SIMO\AppData\Local\Programs\Python\Python36\lib\site-packages\django\views\generic\base.py", line 69, in view
    return self.dispatch(request, *args, **kwargs)
  File "D:\Users\SIMO\AppData\Local\Programs\Python\Python36\lib\site-packages\rest_framework\views.py", line 494, in dispatch
    response = self.handle_exception(exc)
  File "D:\Users\SIMO\AppData\Local\Programs\Python\Python36\lib\site-packages\rest_framework\views.py", line 454, in handle_exception
    self.raise_uncaught_exception(exc)
  File "D:\Users\SIMO\AppData\Local\Programs\Python\Python36\lib\site-packages\rest_framework\views.py", line 491, in dispatch
    response = handler(request, *args, **kwargs)
  File "D:\Users\SIMO\AppData\Local\Programs\Python\Python36\lib\site-packages\rest_framework\decorators.py", line 53, in handler
    return func(*args, **kwargs)
  File "H:\project\api_automation_test\api_test\common\common.py", line 79, in verify
    return func(reality_parameter)
  File "H:\project\api_automation_test\api_test\api\automationCase.py", line 1116, in test_time
    serialize = serialize[0, 10]
  File "D:\Users\SIMO\AppData\Local\Programs\Python\Python36\lib\site-packages\django\db\models\query.py", line 282, in __getitem__
    raise TypeError
TypeError
2018-05-25 16:25:05,409,2736,django.server,ERROR,basehttp.py:124,"GET /api/automation/test_time?project_id=1 HTTP/1.1" 500 18902
2018-05-25 16:29:02,931,5656,django.request,ERROR,exception.py:118,Internal Server Error: /api/automation/test_time
Traceback (most recent call last):
  File "D:\Users\SIMO\AppData\Local\Programs\Python\Python36\lib\site-packages\django\core\handlers\exception.py", line 35, in inner
    response = get_response(request)
  File "D:\Users\SIMO\AppData\Local\Programs\Python\Python36\lib\site-packages\django\core\handlers\base.py", line 128, in _get_response
    response = self.process_exception_by_middleware(e, request)
  File "D:\Users\SIMO\AppData\Local\Programs\Python\Python36\lib\site-packages\django\core\handlers\base.py", line 126, in _get_response
    response = wrapped_callback(request, *callback_args, **callback_kwargs)
  File "D:\Users\SIMO\AppData\Local\Programs\Python\Python36\lib\site-packages\django\views\decorators\csrf.py", line 54, in wrapped_view
    return view_func(*args, **kwargs)
  File "D:\Users\SIMO\AppData\Local\Programs\Python\Python36\lib\site-packages\django\views\generic\base.py", line 69, in view
    return self.dispatch(request, *args, **kwargs)
  File "D:\Users\SIMO\AppData\Local\Programs\Python\Python36\lib\site-packages\rest_framework\views.py", line 494, in dispatch
    response = self.handle_exception(exc)
  File "D:\Users\SIMO\AppData\Local\Programs\Python\Python36\lib\site-packages\rest_framework\views.py", line 454, in handle_exception
    self.raise_uncaught_exception(exc)
  File "D:\Users\SIMO\AppData\Local\Programs\Python\Python36\lib\site-packages\rest_framework\views.py", line 491, in dispatch
    response = handler(request, *args, **kwargs)
  File "D:\Users\SIMO\AppData\Local\Programs\Python\Python36\lib\site-packages\rest_framework\decorators.py", line 53, in handler
    return func(*args, **kwargs)
  File "H:\project\api_automation_test\api_test\common\common.py", line 79, in verify
    return func(reality_parameter)
  File "H:\project\api_automation_test\api_test\api\automationCase.py", line 1114, in test_time
    print(AutomationTaskRunTime.objects.filter(project=project_id).order_by("-startTime")[0,10])
  File "D:\Users\SIMO\AppData\Local\Programs\Python\Python36\lib\site-packages\django\db\models\query.py", line 282, in __getitem__
    raise TypeError
TypeError
2018-05-25 16:29:02,947,5656,django.server,ERROR,basehttp.py:124,"GET /api/automation/test_time?project_id=1 HTTP/1.1" 500 18966
2018-05-25 16:34:51,802,7324,django.request,ERROR,exception.py:118,Internal Server Error: /api/automation/test_time
Traceback (most recent call last):
  File "D:\Users\SIMO\AppData\Local\Programs\Python\Python36\lib\site-packages\django\db\backends\utils.py", line 85, in _execute
    return self.cursor.execute(sql, params)
  File "D:\Users\SIMO\AppData\Local\Programs\Python\Python36\lib\site-packages\django\db\backends\mysql\base.py", line 71, in execute
    return self.cursor.execute(query, args)
  File "D:\Users\SIMO\AppData\Local\Programs\Python\Python36\lib\site-packages\MySQLdb\cursors.py", line 250, in execute
    self.errorhandler(self, exc, value)
  File "D:\Users\SIMO\AppData\Local\Programs\Python\Python36\lib\site-packages\MySQLdb\connections.py", line 50, in defaulterrorhandler
    raise errorvalue
  File "D:\Users\SIMO\AppData\Local\Programs\Python\Python36\lib\site-packages\MySQLdb\cursors.py", line 247, in execute
    res = self._query(query)
  File "D:\Users\SIMO\AppData\Local\Programs\Python\Python36\lib\site-packages\MySQLdb\cursors.py", line 411, in _query
    rowcount = self._do_query(q)
  File "D:\Users\SIMO\AppData\Local\Programs\Python\Python36\lib\site-packages\MySQLdb\cursors.py", line 374, in _do_query
    db.query(q)
  File "D:\Users\SIMO\AppData\Local\Programs\Python\Python36\lib\site-packages\MySQLdb\connections.py", line 277, in query
    _mysql.connection.query(self, query)
_mysql_exceptions.OperationalError: (1054, "Unknown column 'api_test_automationtaskruntime.elapsedTime' in 'field list'")

The above exception was the direct cause of the following exception:

Traceback (most recent call last):
  File "D:\Users\SIMO\AppData\Local\Programs\Python\Python36\lib\site-packages\django\core\handlers\exception.py", line 35, in inner
    response = get_response(request)
  File "D:\Users\SIMO\AppData\Local\Programs\Python\Python36\lib\site-packages\django\core\handlers\base.py", line 128, in _get_response
    response = self.process_exception_by_middleware(e, request)
  File "D:\Users\SIMO\AppData\Local\Programs\Python\Python36\lib\site-packages\django\core\handlers\base.py", line 126, in _get_response
    response = wrapped_callback(request, *callback_args, **callback_kwargs)
  File "D:\Users\SIMO\AppData\Local\Programs\Python\Python36\lib\site-packages\django\views\decorators\csrf.py", line 54, in wrapped_view
    return view_func(*args, **kwargs)
  File "D:\Users\SIMO\AppData\Local\Programs\Python\Python36\lib\site-packages\django\views\generic\base.py", line 69, in view
    return self.dispatch(request, *args, **kwargs)
  File "D:\Users\SIMO\AppData\Local\Programs\Python\Python36\lib\site-packages\rest_framework\views.py", line 494, in dispatch
    response = self.handle_exception(exc)
  File "D:\Users\SIMO\AppData\Local\Programs\Python\Python36\lib\site-packages\rest_framework\views.py", line 454, in handle_exception
    self.raise_uncaught_exception(exc)
  File "D:\Users\SIMO\AppData\Local\Programs\Python\Python36\lib\site-packages\rest_framework\views.py", line 491, in dispatch
    response = handler(request, *args, **kwargs)
  File "D:\Users\SIMO\AppData\Local\Programs\Python\Python36\lib\site-packages\rest_framework\decorators.py", line 53, in handler
    return func(*args, **kwargs)
  File "H:\project\api_automation_test\api_test\common\common.py", line 79, in verify
    return func(reality_parameter)
  File "H:\project\api_automation_test\api_test\api\automationCase.py", line 1114, in test_time
    print(AutomationTaskRunTime.objects.filter(project=project_id).order_by("-startTime")[:10])
  File "D:\Users\SIMO\AppData\Local\Programs\Python\Python36\lib\site-packages\django\db\models\query.py", line 248, in __repr__
    data = list(self[:REPR_OUTPUT_SIZE + 1])
  File "D:\Users\SIMO\AppData\Local\Programs\Python\Python36\lib\site-packages\django\db\models\query.py", line 272, in __iter__
    self._fetch_all()
  File "D:\Users\SIMO\AppData\Local\Programs\Python\Python36\lib\site-packages\django\db\models\query.py", line 1179, in _fetch_all
    self._result_cache = list(self._iterable_class(self))
  File "D:\Users\SIMO\AppData\Local\Programs\Python\Python36\lib\site-packages\django\db\models\query.py", line 53, in __iter__
    results = compiler.execute_sql(chunked_fetch=self.chunked_fetch, chunk_size=self.chunk_size)
  File "D:\Users\SIMO\AppData\Local\Programs\Python\Python36\lib\site-packages\django\db\models\sql\compiler.py", line 1064, in execute_sql
    cursor.execute(sql, params)
  File "D:\Users\SIMO\AppData\Local\Programs\Python\Python36\lib\site-packages\django\db\backends\utils.py", line 100, in execute
    return super().execute(sql, params)
  File "D:\Users\SIMO\AppData\Local\Programs\Python\Python36\lib\site-packages\django\db\backends\utils.py", line 68, in execute
    return self._execute_with_wrappers(sql, params, many=False, executor=self._execute)
  File "D:\Users\SIMO\AppData\Local\Programs\Python\Python36\lib\site-packages\django\db\backends\utils.py", line 77, in _execute_with_wrappers
    return executor(sql, params, many, context)
  File "D:\Users\SIMO\AppData\Local\Programs\Python\Python36\lib\site-packages\django\db\backends\utils.py", line 85, in _execute
    return self.cursor.execute(sql, params)
  File "D:\Users\SIMO\AppData\Local\Programs\Python\Python36\lib\site-packages\django\db\utils.py", line 89, in __exit__
    raise dj_exc_value.with_traceback(traceback) from exc_value
  File "D:\Users\SIMO\AppData\Local\Programs\Python\Python36\lib\site-packages\django\db\backends\utils.py", line 85, in _execute
    return self.cursor.execute(sql, params)
  File "D:\Users\SIMO\AppData\Local\Programs\Python\Python36\lib\site-packages\django\db\backends\mysql\base.py", line 71, in execute
    return self.cursor.execute(query, args)
  File "D:\Users\SIMO\AppData\Local\Programs\Python\Python36\lib\site-packages\MySQLdb\cursors.py", line 250, in execute
    self.errorhandler(self, exc, value)
  File "D:\Users\SIMO\AppData\Local\Programs\Python\Python36\lib\site-packages\MySQLdb\connections.py", line 50, in defaulterrorhandler
    raise errorvalue
  File "D:\Users\SIMO\AppData\Local\Programs\Python\Python36\lib\site-packages\MySQLdb\cursors.py", line 247, in execute
    res = self._query(query)
  File "D:\Users\SIMO\AppData\Local\Programs\Python\Python36\lib\site-packages\MySQLdb\cursors.py", line 411, in _query
    rowcount = self._do_query(q)
  File "D:\Users\SIMO\AppData\Local\Programs\Python\Python36\lib\site-packages\MySQLdb\cursors.py", line 374, in _do_query
    db.query(q)
  File "D:\Users\SIMO\AppData\Local\Programs\Python\Python36\lib\site-packages\MySQLdb\connections.py", line 277, in query
    _mysql.connection.query(self, query)
django.db.utils.OperationalError: (1054, "Unknown column 'api_test_automationtaskruntime.elapsedTime' in 'field list'")
2018-05-25 16:34:51,876,7324,django.server,ERROR,basehttp.py:124,"GET /api/automation/test_time?project_id=1 HTTP/1.1" 500 23592
2018-05-28 10:15:15,505,16216,django.request,ERROR,exception.py:118,Internal Server Error: /api/automation/add_time_task
Traceback (most recent call last):
  File "D:\Users\SIMO\AppData\Local\Programs\Python\Python36\lib\site-packages\django\core\handlers\exception.py", line 35, in inner
    response = get_response(request)
  File "D:\Users\SIMO\AppData\Local\Programs\Python\Python36\lib\site-packages\django\core\handlers\base.py", line 128, in _get_response
    response = self.process_exception_by_middleware(e, request)
  File "D:\Users\SIMO\AppData\Local\Programs\Python\Python36\lib\site-packages\django\core\handlers\base.py", line 126, in _get_response
    response = wrapped_callback(request, *callback_args, **callback_kwargs)
  File "D:\Users\SIMO\AppData\Local\Programs\Python\Python36\lib\site-packages\django\views\decorators\csrf.py", line 54, in wrapped_view
    return view_func(*args, **kwargs)
  File "D:\Users\SIMO\AppData\Local\Programs\Python\Python36\lib\site-packages\django\views\generic\base.py", line 69, in view
    return self.dispatch(request, *args, **kwargs)
  File "D:\Users\SIMO\AppData\Local\Programs\Python\Python36\lib\site-packages\rest_framework\views.py", line 494, in dispatch
    response = self.handle_exception(exc)
  File "D:\Users\SIMO\AppData\Local\Programs\Python\Python36\lib\site-packages\rest_framework\views.py", line 454, in handle_exception
    self.raise_uncaught_exception(exc)
  File "D:\Users\SIMO\AppData\Local\Programs\Python\Python36\lib\site-packages\rest_framework\views.py", line 491, in dispatch
    response = handler(request, *args, **kwargs)
  File "D:\Users\SIMO\AppData\Local\Programs\Python\Python36\lib\site-packages\rest_framework\decorators.py", line 53, in handler
    return func(*args, **kwargs)
  File "H:\project\api_automation_test\api_test\common\common.py", line 79, in verify
    return func(reality_parameter)
  File "H:\project\api_automation_test\api_test\api\automationCase.py", line 956, in add_time_task
    start_time=request.POST.get("startTime"), end_time=request.POST.get("endTime"))
  File "H:\project\api_automation_test\api_test\common\addTask.py", line 54, in add
    my_user_cron.write()
  File "D:\Users\SIMO\AppData\Local\Programs\Python\Python36\lib\site-packages\crontab.py", line 344, in write
    raise IOError("Please specify user or filename to write.")
OSError: Please specify user or filename to write.
2018-05-28 10:15:15,697,16216,django.server,ERROR,basehttp.py:124,"POST /api/automation/add_time_task HTTP/1.1" 500 19465
2018-05-28 10:16:11,512,16216,django.request,ERROR,exception.py:118,Internal Server Error: /api/automation/add_time_task
Traceback (most recent call last):
  File "D:\Users\SIMO\AppData\Local\Programs\Python\Python36\lib\site-packages\django\core\handlers\exception.py", line 35, in inner
    response = get_response(request)
  File "D:\Users\SIMO\AppData\Local\Programs\Python\Python36\lib\site-packages\django\core\handlers\base.py", line 128, in _get_response
    response = self.process_exception_by_middleware(e, request)
  File "D:\Users\SIMO\AppData\Local\Programs\Python\Python36\lib\site-packages\django\core\handlers\base.py", line 126, in _get_response
    response = wrapped_callback(request, *callback_args, **callback_kwargs)
  File "D:\Users\SIMO\AppData\Local\Programs\Python\Python36\lib\site-packages\django\views\decorators\csrf.py", line 54, in wrapped_view
    return view_func(*args, **kwargs)
  File "D:\Users\SIMO\AppData\Local\Programs\Python\Python36\lib\site-packages\django\views\generic\base.py", line 69, in view
    return self.dispatch(request, *args, **kwargs)
  File "D:\Users\SIMO\AppData\Local\Programs\Python\Python36\lib\site-packages\rest_framework\views.py", line 494, in dispatch
    response = self.handle_exception(exc)
  File "D:\Users\SIMO\AppData\Local\Programs\Python\Python36\lib\site-packages\rest_framework\views.py", line 454, in handle_exception
    self.raise_uncaught_exception(exc)
  File "D:\Users\SIMO\AppData\Local\Programs\Python\Python36\lib\site-packages\rest_framework\views.py", line 491, in dispatch
    response = handler(request, *args, **kwargs)
  File "D:\Users\SIMO\AppData\Local\Programs\Python\Python36\lib\site-packages\rest_framework\decorators.py", line 53, in handler
    return func(*args, **kwargs)
  File "H:\project\api_automation_test\api_test\common\common.py", line 79, in verify
    return func(reality_parameter)
  File "H:\project\api_automation_test\api_test\api\automationCase.py", line 956, in add_time_task
    start_time=request.POST.get("startTime"), end_time=request.POST.get("endTime"))
  File "H:\project\api_automation_test\api_test\common\addTask.py", line 54, in add
    my_user_cron.write()
  File "D:\Users\SIMO\AppData\Local\Programs\Python\Python36\lib\site-packages\crontab.py", line 344, in write
    raise IOError("Please specify user or filename to write.")
OSError: Please specify user or filename to write.
2018-05-28 10:16:11,525,16216,django.server,ERROR,basehttp.py:124,"POST /api/automation/add_time_task HTTP/1.1" 500 19464
2018-05-28 10:35:06,054,16216,django.request,ERROR,exception.py:118,Internal Server Error: /api/automation/add_time_task
Traceback (most recent call last):
  File "D:\Users\SIMO\AppData\Local\Programs\Python\Python36\lib\site-packages\django\core\handlers\exception.py", line 35, in inner
    response = get_response(request)
  File "D:\Users\SIMO\AppData\Local\Programs\Python\Python36\lib\site-packages\django\core\handlers\base.py", line 128, in _get_response
    response = self.process_exception_by_middleware(e, request)
  File "D:\Users\SIMO\AppData\Local\Programs\Python\Python36\lib\site-packages\django\core\handlers\base.py", line 126, in _get_response
    response = wrapped_callback(request, *callback_args, **callback_kwargs)
  File "D:\Users\SIMO\AppData\Local\Programs\Python\Python36\lib\site-packages\django\views\decorators\csrf.py", line 54, in wrapped_view
    return view_func(*args, **kwargs)
  File "D:\Users\SIMO\AppData\Local\Programs\Python\Python36\lib\site-packages\django\views\generic\base.py", line 69, in view
    return self.dispatch(request, *args, **kwargs)
  File "D:\Users\SIMO\AppData\Local\Programs\Python\Python36\lib\site-packages\rest_framework\views.py", line 494, in dispatch
    response = self.handle_exception(exc)
  File "D:\Users\SIMO\AppData\Local\Programs\Python\Python36\lib\site-packages\rest_framework\views.py", line 454, in handle_exception
    self.raise_uncaught_exception(exc)
  File "D:\Users\SIMO\AppData\Local\Programs\Python\Python36\lib\site-packages\rest_framework\views.py", line 491, in dispatch
    response = handler(request, *args, **kwargs)
  File "D:\Users\SIMO\AppData\Local\Programs\Python\Python36\lib\site-packages\rest_framework\decorators.py", line 53, in handler
    return func(*args, **kwargs)
  File "H:\project\api_automation_test\api_test\common\common.py", line 79, in verify
    return func(reality_parameter)
  File "H:\project\api_automation_test\api_test\api\automationCase.py", line 956, in add_time_task
    start_time=request.POST.get("startTime"), end_time=request.POST.get("endTime"))
  File "H:\project\api_automation_test\api_test\common\addTask.py", line 54, in add
    my_user_cron.write()
  File "D:\Users\SIMO\AppData\Local\Programs\Python\Python36\lib\site-packages\crontab.py", line 344, in write
    raise IOError("Please specify user or filename to write.")
OSError: Please specify user or filename to write.
2018-05-28 10:35:06,066,16216,django.server,ERROR,basehttp.py:124,"POST /api/automation/add_time_task HTTP/1.1" 500 19483
2018-05-28 10:38:44,412,16216,django.request,ERROR,exception.py:118,Internal Server Error: /api/automation/add_time_task
Traceback (most recent call last):
  File "D:\Users\SIMO\AppData\Local\Programs\Python\Python36\lib\site-packages\django\core\handlers\exception.py", line 35, in inner
    response = get_response(request)
  File "D:\Users\SIMO\AppData\Local\Programs\Python\Python36\lib\site-packages\django\core\handlers\base.py", line 128, in _get_response
    response = self.process_exception_by_middleware(e, request)
  File "D:\Users\SIMO\AppData\Local\Programs\Python\Python36\lib\site-packages\django\core\handlers\base.py", line 126, in _get_response
    response = wrapped_callback(request, *callback_args, **callback_kwargs)
  File "D:\Users\SIMO\AppData\Local\Programs\Python\Python36\lib\site-packages\django\views\decorators\csrf.py", line 54, in wrapped_view
    return view_func(*args, **kwargs)
  File "D:\Users\SIMO\AppData\Local\Programs\Python\Python36\lib\site-packages\django\views\generic\base.py", line 69, in view
    return self.dispatch(request, *args, **kwargs)
  File "D:\Users\SIMO\AppData\Local\Programs\Python\Python36\lib\site-packages\rest_framework\views.py", line 494, in dispatch
    response = self.handle_exception(exc)
  File "D:\Users\SIMO\AppData\Local\Programs\Python\Python36\lib\site-packages\rest_framework\views.py", line 454, in handle_exception
    self.raise_uncaught_exception(exc)
  File "D:\Users\SIMO\AppData\Local\Programs\Python\Python36\lib\site-packages\rest_framework\views.py", line 491, in dispatch
    response = handler(request, *args, **kwargs)
  File "D:\Users\SIMO\AppData\Local\Programs\Python\Python36\lib\site-packages\rest_framework\decorators.py", line 53, in handler
    return func(*args, **kwargs)
  File "H:\project\api_automation_test\api_test\common\common.py", line 79, in verify
    return func(reality_parameter)
  File "H:\project\api_automation_test\api_test\api\automationCase.py", line 956, in add_time_task
    start_time=request.POST.get("startTime"), end_time=request.POST.get("endTime"))
  File "H:\project\api_automation_test\api_test\common\addTask.py", line 54, in add
    my_user_cron.write()
  File "D:\Users\SIMO\AppData\Local\Programs\Python\Python36\lib\site-packages\crontab.py", line 344, in write
    raise IOError("Please specify user or filename to write.")
OSError: Please specify user or filename to write.
2018-05-28 10:38:44,425,16216,django.server,ERROR,basehttp.py:124,"POST /api/automation/add_time_task HTTP/1.1" 500 19482
2018-05-28 10:40:48,065,16216,django.request,ERROR,exception.py:118,Internal Server Error: /api/automation/add_time_task
Traceback (most recent call last):
  File "D:\Users\SIMO\AppData\Local\Programs\Python\Python36\lib\site-packages\django\core\handlers\exception.py", line 35, in inner
    response = get_response(request)
  File "D:\Users\SIMO\AppData\Local\Programs\Python\Python36\lib\site-packages\django\core\handlers\base.py", line 128, in _get_response
    response = self.process_exception_by_middleware(e, request)
  File "D:\Users\SIMO\AppData\Local\Programs\Python\Python36\lib\site-packages\django\core\handlers\base.py", line 126, in _get_response
    response = wrapped_callback(request, *callback_args, **callback_kwargs)
  File "D:\Users\SIMO\AppData\Local\Programs\Python\Python36\lib\site-packages\django\views\decorators\csrf.py", line 54, in wrapped_view
    return view_func(*args, **kwargs)
  File "D:\Users\SIMO\AppData\Local\Programs\Python\Python36\lib\site-packages\django\views\generic\base.py", line 69, in view
    return self.dispatch(request, *args, **kwargs)
  File "D:\Users\SIMO\AppData\Local\Programs\Python\Python36\lib\site-packages\rest_framework\views.py", line 494, in dispatch
    response = self.handle_exception(exc)
  File "D:\Users\SIMO\AppData\Local\Programs\Python\Python36\lib\site-packages\rest_framework\views.py", line 454, in handle_exception
    self.raise_uncaught_exception(exc)
  File "D:\Users\SIMO\AppData\Local\Programs\Python\Python36\lib\site-packages\rest_framework\views.py", line 491, in dispatch
    response = handler(request, *args, **kwargs)
  File "D:\Users\SIMO\AppData\Local\Programs\Python\Python36\lib\site-packages\rest_framework\decorators.py", line 53, in handler
    return func(*args, **kwargs)
  File "H:\project\api_automation_test\api_test\common\common.py", line 79, in verify
    return func(reality_parameter)
  File "H:\project\api_automation_test\api_test\api\automationCase.py", line 956, in add_time_task
    start_time=request.POST.get("startTime"), end_time=request.POST.get("endTime"))
  File "H:\project\api_automation_test\api_test\common\addTask.py", line 54, in add
    my_user_cron.write()
  File "D:\Users\SIMO\AppData\Local\Programs\Python\Python36\lib\site-packages\crontab.py", line 344, in write
    raise IOError("Please specify user or filename to write.")
OSError: Please specify user or filename to write.
2018-05-28 10:40:48,077,16216,django.server,ERROR,basehttp.py:124,"POST /api/automation/add_time_task HTTP/1.1" 500 19474
2018-05-28 10:41:13,731,16216,django.request,ERROR,exception.py:118,Internal Server Error: /api/automation/add_time_task
Traceback (most recent call last):
  File "D:\Users\SIMO\AppData\Local\Programs\Python\Python36\lib\site-packages\django\core\handlers\exception.py", line 35, in inner
    response = get_response(request)
  File "D:\Users\SIMO\AppData\Local\Programs\Python\Python36\lib\site-packages\django\core\handlers\base.py", line 128, in _get_response
    response = self.process_exception_by_middleware(e, request)
  File "D:\Users\SIMO\AppData\Local\Programs\Python\Python36\lib\site-packages\django\core\handlers\base.py", line 126, in _get_response
    response = wrapped_callback(request, *callback_args, **callback_kwargs)
  File "D:\Users\SIMO\AppData\Local\Programs\Python\Python36\lib\site-packages\django\views\decorators\csrf.py", line 54, in wrapped_view
    return view_func(*args, **kwargs)
  File "D:\Users\SIMO\AppData\Local\Programs\Python\Python36\lib\site-packages\django\views\generic\base.py", line 69, in view
    return self.dispatch(request, *args, **kwargs)
  File "D:\Users\SIMO\AppData\Local\Programs\Python\Python36\lib\site-packages\rest_framework\views.py", line 494, in dispatch
    response = self.handle_exception(exc)
  File "D:\Users\SIMO\AppData\Local\Programs\Python\Python36\lib\site-packages\rest_framework\views.py", line 454, in handle_exception
    self.raise_uncaught_exception(exc)
  File "D:\Users\SIMO\AppData\Local\Programs\Python\Python36\lib\site-packages\rest_framework\views.py", line 491, in dispatch
    response = handler(request, *args, **kwargs)
  File "D:\Users\SIMO\AppData\Local\Programs\Python\Python36\lib\site-packages\rest_framework\decorators.py", line 53, in handler
    return func(*args, **kwargs)
  File "H:\project\api_automation_test\api_test\common\common.py", line 79, in verify
    return func(reality_parameter)
  File "H:\project\api_automation_test\api_test\api\automationCase.py", line 956, in add_time_task
    start_time=request.POST.get("startTime"), end_time=request.POST.get("endTime"))
  File "H:\project\api_automation_test\api_test\common\addTask.py", line 54, in add
    my_user_cron.write()
  File "D:\Users\SIMO\AppData\Local\Programs\Python\Python36\lib\site-packages\crontab.py", line 344, in write
    raise IOError("Please specify user or filename to write.")
OSError: Please specify user or filename to write.
2018-05-28 10:41:13,743,16216,django.server,ERROR,basehttp.py:124,"POST /api/automation/add_time_task HTTP/1.1" 500 19475
2018-05-28 10:41:41,408,16216,django.request,ERROR,exception.py:118,Internal Server Error: /api/automation/add_time_task
Traceback (most recent call last):
  File "D:\Users\SIMO\AppData\Local\Programs\Python\Python36\lib\site-packages\django\core\handlers\exception.py", line 35, in inner
    response = get_response(request)
  File "D:\Users\SIMO\AppData\Local\Programs\Python\Python36\lib\site-packages\django\core\handlers\base.py", line 128, in _get_response
    response = self.process_exception_by_middleware(e, request)
  File "D:\Users\SIMO\AppData\Local\Programs\Python\Python36\lib\site-packages\django\core\handlers\base.py", line 126, in _get_response
    response = wrapped_callback(request, *callback_args, **callback_kwargs)
  File "D:\Users\SIMO\AppData\Local\Programs\Python\Python36\lib\site-packages\django\views\decorators\csrf.py", line 54, in wrapped_view
    return view_func(*args, **kwargs)
  File "D:\Users\SIMO\AppData\Local\Programs\Python\Python36\lib\site-packages\django\views\generic\base.py", line 69, in view
    return self.dispatch(request, *args, **kwargs)
  File "D:\Users\SIMO\AppData\Local\Programs\Python\Python36\lib\site-packages\rest_framework\views.py", line 494, in dispatch
    response = self.handle_exception(exc)
  File "D:\Users\SIMO\AppData\Local\Programs\Python\Python36\lib\site-packages\rest_framework\views.py", line 454, in handle_exception
    self.raise_uncaught_exception(exc)
  File "D:\Users\SIMO\AppData\Local\Programs\Python\Python36\lib\site-packages\rest_framework\views.py", line 491, in dispatch
    response = handler(request, *args, **kwargs)
  File "D:\Users\SIMO\AppData\Local\Programs\Python\Python36\lib\site-packages\rest_framework\decorators.py", line 53, in handler
    return func(*args, **kwargs)
  File "H:\project\api_automation_test\api_test\common\common.py", line 79, in verify
    return func(reality_parameter)
  File "H:\project\api_automation_test\api_test\api\automationCase.py", line 956, in add_time_task
    start_time=request.POST.get("startTime"), end_time=request.POST.get("endTime"))
  File "H:\project\api_automation_test\api_test\common\addTask.py", line 54, in add
    my_user_cron.write()
  File "D:\Users\SIMO\AppData\Local\Programs\Python\Python36\lib\site-packages\crontab.py", line 344, in write
    raise IOError("Please specify user or filename to write.")
OSError: Please specify user or filename to write.
2018-05-28 10:41:41,421,16216,django.server,ERROR,basehttp.py:124,"POST /api/automation/add_time_task HTTP/1.1" 500 19475
2018-05-28 10:43:55,203,16216,django.request,ERROR,exception.py:118,Internal Server Error: /api/automation/add_time_task
Traceback (most recent call last):
  File "D:\Users\SIMO\AppData\Local\Programs\Python\Python36\lib\site-packages\django\core\handlers\exception.py", line 35, in inner
    response = get_response(request)
  File "D:\Users\SIMO\AppData\Local\Programs\Python\Python36\lib\site-packages\django\core\handlers\base.py", line 128, in _get_response
    response = self.process_exception_by_middleware(e, request)
  File "D:\Users\SIMO\AppData\Local\Programs\Python\Python36\lib\site-packages\django\core\handlers\base.py", line 126, in _get_response
    response = wrapped_callback(request, *callback_args, **callback_kwargs)
  File "D:\Users\SIMO\AppData\Local\Programs\Python\Python36\lib\site-packages\django\views\decorators\csrf.py", line 54, in wrapped_view
    return view_func(*args, **kwargs)
  File "D:\Users\SIMO\AppData\Local\Programs\Python\Python36\lib\site-packages\django\views\generic\base.py", line 69, in view
    return self.dispatch(request, *args, **kwargs)
  File "D:\Users\SIMO\AppData\Local\Programs\Python\Python36\lib\site-packages\rest_framework\views.py", line 494, in dispatch
    response = self.handle_exception(exc)
  File "D:\Users\SIMO\AppData\Local\Programs\Python\Python36\lib\site-packages\rest_framework\views.py", line 454, in handle_exception
    self.raise_uncaught_exception(exc)
  File "D:\Users\SIMO\AppData\Local\Programs\Python\Python36\lib\site-packages\rest_framework\views.py", line 491, in dispatch
    response = handler(request, *args, **kwargs)
  File "D:\Users\SIMO\AppData\Local\Programs\Python\Python36\lib\site-packages\rest_framework\decorators.py", line 53, in handler
    return func(*args, **kwargs)
  File "H:\project\api_automation_test\api_test\common\common.py", line 79, in verify
    return func(reality_parameter)
  File "H:\project\api_automation_test\api_test\api\automationCase.py", line 956, in add_time_task
    start_time=request.POST.get("startTime"), end_time=request.POST.get("endTime"))
  File "H:\project\api_automation_test\api_test\common\addTask.py", line 54, in add
    my_user_cron.write()
  File "D:\Users\SIMO\AppData\Local\Programs\Python\Python36\lib\site-packages\crontab.py", line 344, in write
    raise IOError("Please specify user or filename to write.")
OSError: Please specify user or filename to write.
2018-05-28 10:43:55,216,16216,django.server,ERROR,basehttp.py:124,"POST /api/automation/add_time_task HTTP/1.1" 500 19475
2018-05-28 10:46:28,475,6360,django.request,ERROR,exception.py:118,Internal Server Error: /api/automation/add_time_task
Traceback (most recent call last):
  File "D:\Users\SIMO\AppData\Local\Programs\Python\Python36\lib\site-packages\django\core\handlers\exception.py", line 35, in inner
    response = get_response(request)
  File "D:\Users\SIMO\AppData\Local\Programs\Python\Python36\lib\site-packages\django\core\handlers\base.py", line 128, in _get_response
    response = self.process_exception_by_middleware(e, request)
  File "D:\Users\SIMO\AppData\Local\Programs\Python\Python36\lib\site-packages\django\core\handlers\base.py", line 126, in _get_response
    response = wrapped_callback(request, *callback_args, **callback_kwargs)
  File "D:\Users\SIMO\AppData\Local\Programs\Python\Python36\lib\site-packages\django\views\decorators\csrf.py", line 54, in wrapped_view
    return view_func(*args, **kwargs)
  File "D:\Users\SIMO\AppData\Local\Programs\Python\Python36\lib\site-packages\django\views\generic\base.py", line 69, in view
    return self.dispatch(request, *args, **kwargs)
  File "D:\Users\SIMO\AppData\Local\Programs\Python\Python36\lib\site-packages\rest_framework\views.py", line 494, in dispatch
    response = self.handle_exception(exc)
  File "D:\Users\SIMO\AppData\Local\Programs\Python\Python36\lib\site-packages\rest_framework\views.py", line 454, in handle_exception
    self.raise_uncaught_exception(exc)
  File "D:\Users\SIMO\AppData\Local\Programs\Python\Python36\lib\site-packages\rest_framework\views.py", line 491, in dispatch
    response = handler(request, *args, **kwargs)
  File "D:\Users\SIMO\AppData\Local\Programs\Python\Python36\lib\site-packages\rest_framework\decorators.py", line 53, in handler
    return func(*args, **kwargs)
  File "H:\project\api_automation_test\api_test\common\common.py", line 79, in verify
    return func(reality_parameter)
  File "H:\project\api_automation_test\api_test\api\automationCase.py", line 956, in add_time_task
    start_time=request.POST.get("startTime"), end_time=request.POST.get("endTime"))
  File "H:\project\api_automation_test\api_test\common\addTask.py", line 54, in add
    my_user_cron.write()
  File "D:\Users\SIMO\AppData\Local\Programs\Python\Python36\lib\site-packages\crontab.py", line 344, in write
    raise IOError("Please specify user or filename to write.")
OSError: Please specify user or filename to write.
2018-05-28 10:46:28,492,6360,django.server,ERROR,basehttp.py:124,"POST /api/automation/add_time_task HTTP/1.1" 500 19465
2018-05-28 10:48:56,100,6360,django.request,ERROR,exception.py:118,Internal Server Error: /api/automation/add_time_task
Traceback (most recent call last):
  File "D:\Users\SIMO\AppData\Local\Programs\Python\Python36\lib\site-packages\django\core\handlers\exception.py", line 35, in inner
    response = get_response(request)
  File "D:\Users\SIMO\AppData\Local\Programs\Python\Python36\lib\site-packages\django\core\handlers\base.py", line 128, in _get_response
    response = self.process_exception_by_middleware(e, request)
  File "D:\Users\SIMO\AppData\Local\Programs\Python\Python36\lib\site-packages\django\core\handlers\base.py", line 126, in _get_response
    response = wrapped_callback(request, *callback_args, **callback_kwargs)
  File "D:\Users\SIMO\AppData\Local\Programs\Python\Python36\lib\site-packages\django\views\decorators\csrf.py", line 54, in wrapped_view
    return view_func(*args, **kwargs)
  File "D:\Users\SIMO\AppData\Local\Programs\Python\Python36\lib\site-packages\django\views\generic\base.py", line 69, in view
    return self.dispatch(request, *args, **kwargs)
  File "D:\Users\SIMO\AppData\Local\Programs\Python\Python36\lib\site-packages\rest_framework\views.py", line 494, in dispatch
    response = self.handle_exception(exc)
  File "D:\Users\SIMO\AppData\Local\Programs\Python\Python36\lib\site-packages\rest_framework\views.py", line 454, in handle_exception
    self.raise_uncaught_exception(exc)
  File "D:\Users\SIMO\AppData\Local\Programs\Python\Python36\lib\site-packages\rest_framework\views.py", line 491, in dispatch
    response = handler(request, *args, **kwargs)
  File "D:\Users\SIMO\AppData\Local\Programs\Python\Python36\lib\site-packages\rest_framework\decorators.py", line 53, in handler
    return func(*args, **kwargs)
  File "H:\project\api_automation_test\api_test\common\common.py", line 79, in verify
    return func(reality_parameter)
  File "H:\project\api_automation_test\api_test\api\automationCase.py", line 956, in add_time_task
    start_time=request.POST.get("startTime"), end_time=request.POST.get("endTime"))
  File "H:\project\api_automation_test\api_test\common\addTask.py", line 54, in add
    my_user_cron.write()
  File "D:\Users\SIMO\AppData\Local\Programs\Python\Python36\lib\site-packages\crontab.py", line 344, in write
    raise IOError("Please specify user or filename to write.")
OSError: Please specify user or filename to write.
2018-05-28 10:48:56,114,6360,django.server,ERROR,basehttp.py:124,"POST /api/automation/add_time_task HTTP/1.1" 500 19475
2018-05-28 10:51:01,981,6360,django.request,ERROR,exception.py:118,Internal Server Error: /api/automation/add_time_task
Traceback (most recent call last):
  File "D:\Users\SIMO\AppData\Local\Programs\Python\Python36\lib\site-packages\django\core\handlers\exception.py", line 35, in inner
    response = get_response(request)
  File "D:\Users\SIMO\AppData\Local\Programs\Python\Python36\lib\site-packages\django\core\handlers\base.py", line 128, in _get_response
    response = self.process_exception_by_middleware(e, request)
  File "D:\Users\SIMO\AppData\Local\Programs\Python\Python36\lib\site-packages\django\core\handlers\base.py", line 126, in _get_response
    response = wrapped_callback(request, *callback_args, **callback_kwargs)
  File "D:\Users\SIMO\AppData\Local\Programs\Python\Python36\lib\site-packages\django\views\decorators\csrf.py", line 54, in wrapped_view
    return view_func(*args, **kwargs)
  File "D:\Users\SIMO\AppData\Local\Programs\Python\Python36\lib\site-packages\django\views\generic\base.py", line 69, in view
    return self.dispatch(request, *args, **kwargs)
  File "D:\Users\SIMO\AppData\Local\Programs\Python\Python36\lib\site-packages\rest_framework\views.py", line 494, in dispatch
    response = self.handle_exception(exc)
  File "D:\Users\SIMO\AppData\Local\Programs\Python\Python36\lib\site-packages\rest_framework\views.py", line 454, in handle_exception
    self.raise_uncaught_exception(exc)
  File "D:\Users\SIMO\AppData\Local\Programs\Python\Python36\lib\site-packages\rest_framework\views.py", line 491, in dispatch
    response = handler(request, *args, **kwargs)
  File "D:\Users\SIMO\AppData\Local\Programs\Python\Python36\lib\site-packages\rest_framework\decorators.py", line 53, in handler
    return func(*args, **kwargs)
  File "H:\project\api_automation_test\api_test\common\common.py", line 79, in verify
    return func(reality_parameter)
  File "H:\project\api_automation_test\api_test\api\automationCase.py", line 956, in add_time_task
    start_time=request.POST.get("startTime"), end_time=request.POST.get("endTime"))
  File "H:\project\api_automation_test\api_test\common\addTask.py", line 54, in add
    my_user_cron.write()
  File "D:\Users\SIMO\AppData\Local\Programs\Python\Python36\lib\site-packages\crontab.py", line 344, in write
    raise IOError("Please specify user or filename to write.")
OSError: Please specify user or filename to write.
2018-05-28 10:51:01,996,6360,django.server,ERROR,basehttp.py:124,"POST /api/automation/add_time_task HTTP/1.1" 500 19475
2018-05-28 10:55:55,361,6360,django.request,ERROR,exception.py:118,Internal Server Error: /api/automation/add_time_task
Traceback (most recent call last):
  File "D:\Users\SIMO\AppData\Local\Programs\Python\Python36\lib\site-packages\django\core\handlers\exception.py", line 35, in inner
    response = get_response(request)
  File "D:\Users\SIMO\AppData\Local\Programs\Python\Python36\lib\site-packages\django\core\handlers\base.py", line 128, in _get_response
    response = self.process_exception_by_middleware(e, request)
  File "D:\Users\SIMO\AppData\Local\Programs\Python\Python36\lib\site-packages\django\core\handlers\base.py", line 126, in _get_response
    response = wrapped_callback(request, *callback_args, **callback_kwargs)
  File "D:\Users\SIMO\AppData\Local\Programs\Python\Python36\lib\site-packages\django\views\decorators\csrf.py", line 54, in wrapped_view
    return view_func(*args, **kwargs)
  File "D:\Users\SIMO\AppData\Local\Programs\Python\Python36\lib\site-packages\django\views\generic\base.py", line 69, in view
    return self.dispatch(request, *args, **kwargs)
  File "D:\Users\SIMO\AppData\Local\Programs\Python\Python36\lib\site-packages\rest_framework\views.py", line 494, in dispatch
    response = self.handle_exception(exc)
  File "D:\Users\SIMO\AppData\Local\Programs\Python\Python36\lib\site-packages\rest_framework\views.py", line 454, in handle_exception
    self.raise_uncaught_exception(exc)
  File "D:\Users\SIMO\AppData\Local\Programs\Python\Python36\lib\site-packages\rest_framework\views.py", line 491, in dispatch
    response = handler(request, *args, **kwargs)
  File "D:\Users\SIMO\AppData\Local\Programs\Python\Python36\lib\site-packages\rest_framework\decorators.py", line 53, in handler
    return func(*args, **kwargs)
  File "H:\project\api_automation_test\api_test\common\common.py", line 79, in verify
    return func(reality_parameter)
  File "H:\project\api_automation_test\api_test\api\automationCase.py", line 956, in add_time_task
    start_time=request.POST.get("startTime"), end_time=request.POST.get("endTime"))
  File "H:\project\api_automation_test\api_test\common\addTask.py", line 54, in add
    my_user_cron.write()
  File "D:\Users\SIMO\AppData\Local\Programs\Python\Python36\lib\site-packages\crontab.py", line 344, in write
    raise IOError("Please specify user or filename to write.")
OSError: Please specify user or filename to write.
2018-05-28 10:55:55,374,6360,django.server,ERROR,basehttp.py:124,"POST /api/automation/add_time_task HTTP/1.1" 500 19475
2018-05-28 10:57:20,238,6360,django.request,ERROR,exception.py:118,Internal Server Error: /api/automation/add_time_task
Traceback (most recent call last):
  File "D:\Users\SIMO\AppData\Local\Programs\Python\Python36\lib\site-packages\django\core\handlers\exception.py", line 35, in inner
    response = get_response(request)
  File "D:\Users\SIMO\AppData\Local\Programs\Python\Python36\lib\site-packages\django\core\handlers\base.py", line 128, in _get_response
    response = self.process_exception_by_middleware(e, request)
  File "D:\Users\SIMO\AppData\Local\Programs\Python\Python36\lib\site-packages\django\core\handlers\base.py", line 126, in _get_response
    response = wrapped_callback(request, *callback_args, **callback_kwargs)
  File "D:\Users\SIMO\AppData\Local\Programs\Python\Python36\lib\site-packages\django\views\decorators\csrf.py", line 54, in wrapped_view
    return view_func(*args, **kwargs)
  File "D:\Users\SIMO\AppData\Local\Programs\Python\Python36\lib\site-packages\django\views\generic\base.py", line 69, in view
    return self.dispatch(request, *args, **kwargs)
  File "D:\Users\SIMO\AppData\Local\Programs\Python\Python36\lib\site-packages\rest_framework\views.py", line 494, in dispatch
    response = self.handle_exception(exc)
  File "D:\Users\SIMO\AppData\Local\Programs\Python\Python36\lib\site-packages\rest_framework\views.py", line 454, in handle_exception
    self.raise_uncaught_exception(exc)
  File "D:\Users\SIMO\AppData\Local\Programs\Python\Python36\lib\site-packages\rest_framework\views.py", line 491, in dispatch
    response = handler(request, *args, **kwargs)
  File "D:\Users\SIMO\AppData\Local\Programs\Python\Python36\lib\site-packages\rest_framework\decorators.py", line 53, in handler
    return func(*args, **kwargs)
  File "H:\project\api_automation_test\api_test\common\common.py", line 79, in verify
    return func(reality_parameter)
  File "H:\project\api_automation_test\api_test\api\automationCase.py", line 956, in add_time_task
    start_time=request.POST.get("startTime"), end_time=request.POST.get("endTime"))
  File "H:\project\api_automation_test\api_test\common\addTask.py", line 54, in add
    my_user_cron.write()
  File "D:\Users\SIMO\AppData\Local\Programs\Python\Python36\lib\site-packages\crontab.py", line 344, in write
    raise IOError("Please specify user or filename to write.")
OSError: Please specify user or filename to write.
2018-05-28 10:57:20,251,6360,django.server,ERROR,basehttp.py:124,"POST /api/automation/add_time_task HTTP/1.1" 500 19475
2018-05-28 10:59:12,281,6360,django.request,ERROR,exception.py:118,Internal Server Error: /api/automation/add_time_task
Traceback (most recent call last):
  File "D:\Users\SIMO\AppData\Local\Programs\Python\Python36\lib\site-packages\django\core\handlers\exception.py", line 35, in inner
    response = get_response(request)
  File "D:\Users\SIMO\AppData\Local\Programs\Python\Python36\lib\site-packages\django\core\handlers\base.py", line 128, in _get_response
    response = self.process_exception_by_middleware(e, request)
  File "D:\Users\SIMO\AppData\Local\Programs\Python\Python36\lib\site-packages\django\core\handlers\base.py", line 126, in _get_response
    response = wrapped_callback(request, *callback_args, **callback_kwargs)
  File "D:\Users\SIMO\AppData\Local\Programs\Python\Python36\lib\site-packages\django\views\decorators\csrf.py", line 54, in wrapped_view
    return view_func(*args, **kwargs)
  File "D:\Users\SIMO\AppData\Local\Programs\Python\Python36\lib\site-packages\django\views\generic\base.py", line 69, in view
    return self.dispatch(request, *args, **kwargs)
  File "D:\Users\SIMO\AppData\Local\Programs\Python\Python36\lib\site-packages\rest_framework\views.py", line 494, in dispatch
    response = self.handle_exception(exc)
  File "D:\Users\SIMO\AppData\Local\Programs\Python\Python36\lib\site-packages\rest_framework\views.py", line 454, in handle_exception
    self.raise_uncaught_exception(exc)
  File "D:\Users\SIMO\AppData\Local\Programs\Python\Python36\lib\site-packages\rest_framework\views.py", line 491, in dispatch
    response = handler(request, *args, **kwargs)
  File "D:\Users\SIMO\AppData\Local\Programs\Python\Python36\lib\site-packages\rest_framework\decorators.py", line 53, in handler
    return func(*args, **kwargs)
  File "H:\project\api_automation_test\api_test\common\common.py", line 79, in verify
    return func(reality_parameter)
  File "H:\project\api_automation_test\api_test\api\automationCase.py", line 956, in add_time_task
    start_time=request.POST.get("startTime"), end_time=request.POST.get("endTime"))
  File "H:\project\api_automation_test\api_test\common\addTask.py", line 54, in add
    my_user_cron.write()
  File "D:\Users\SIMO\AppData\Local\Programs\Python\Python36\lib\site-packages\crontab.py", line 344, in write
    raise IOError("Please specify user or filename to write.")
OSError: Please specify user or filename to write.
2018-05-28 10:59:12,295,6360,django.server,ERROR,basehttp.py:124,"POST /api/automation/add_time_task HTTP/1.1" 500 19475
2018-05-28 11:00:02,099,6360,django.request,ERROR,exception.py:118,Internal Server Error: /api/automation/add_time_task
Traceback (most recent call last):
  File "D:\Users\SIMO\AppData\Local\Programs\Python\Python36\lib\site-packages\django\core\handlers\exception.py", line 35, in inner
    response = get_response(request)
  File "D:\Users\SIMO\AppData\Local\Programs\Python\Python36\lib\site-packages\django\core\handlers\base.py", line 128, in _get_response
    response = self.process_exception_by_middleware(e, request)
  File "D:\Users\SIMO\AppData\Local\Programs\Python\Python36\lib\site-packages\django\core\handlers\base.py", line 126, in _get_response
    response = wrapped_callback(request, *callback_args, **callback_kwargs)
  File "D:\Users\SIMO\AppData\Local\Programs\Python\Python36\lib\site-packages\django\views\decorators\csrf.py", line 54, in wrapped_view
    return view_func(*args, **kwargs)
  File "D:\Users\SIMO\AppData\Local\Programs\Python\Python36\lib\site-packages\django\views\generic\base.py", line 69, in view
    return self.dispatch(request, *args, **kwargs)
  File "D:\Users\SIMO\AppData\Local\Programs\Python\Python36\lib\site-packages\rest_framework\views.py", line 494, in dispatch
    response = self.handle_exception(exc)
  File "D:\Users\SIMO\AppData\Local\Programs\Python\Python36\lib\site-packages\rest_framework\views.py", line 454, in handle_exception
    self.raise_uncaught_exception(exc)
  File "D:\Users\SIMO\AppData\Local\Programs\Python\Python36\lib\site-packages\rest_framework\views.py", line 491, in dispatch
    response = handler(request, *args, **kwargs)
  File "D:\Users\SIMO\AppData\Local\Programs\Python\Python36\lib\site-packages\rest_framework\decorators.py", line 53, in handler
    return func(*args, **kwargs)
  File "H:\project\api_automation_test\api_test\common\common.py", line 79, in verify
    return func(reality_parameter)
  File "H:\project\api_automation_test\api_test\api\automationCase.py", line 934, in add_time_task
    frequency=frequency, unit=unit, project=project_id)
  File "H:\project\api_automation_test\api_test\common\addTask.py", line 54, in add
    my_user_cron.write()
  File "D:\Users\SIMO\AppData\Local\Programs\Python\Python36\lib\site-packages\crontab.py", line 344, in write
    raise IOError("Please specify user or filename to write.")
OSError: Please specify user or filename to write.
2018-05-28 11:00:02,114,6360,django.server,ERROR,basehttp.py:124,"POST /api/automation/add_time_task HTTP/1.1" 500 19453
2018-05-28 11:00:53,966,6360,django.request,ERROR,exception.py:118,Internal Server Error: /api/automation/add_time_task
Traceback (most recent call last):
  File "D:\Users\SIMO\AppData\Local\Programs\Python\Python36\lib\site-packages\django\core\handlers\exception.py", line 35, in inner
    response = get_response(request)
  File "D:\Users\SIMO\AppData\Local\Programs\Python\Python36\lib\site-packages\django\core\handlers\base.py", line 128, in _get_response
    response = self.process_exception_by_middleware(e, request)
  File "D:\Users\SIMO\AppData\Local\Programs\Python\Python36\lib\site-packages\django\core\handlers\base.py", line 126, in _get_response
    response = wrapped_callback(request, *callback_args, **callback_kwargs)
  File "D:\Users\SIMO\AppData\Local\Programs\Python\Python36\lib\site-packages\django\views\decorators\csrf.py", line 54, in wrapped_view
    return view_func(*args, **kwargs)
  File "D:\Users\SIMO\AppData\Local\Programs\Python\Python36\lib\site-packages\django\views\generic\base.py", line 69, in view
    return self.dispatch(request, *args, **kwargs)
  File "D:\Users\SIMO\AppData\Local\Programs\Python\Python36\lib\site-packages\rest_framework\views.py", line 494, in dispatch
    response = self.handle_exception(exc)
  File "D:\Users\SIMO\AppData\Local\Programs\Python\Python36\lib\site-packages\rest_framework\views.py", line 454, in handle_exception
    self.raise_uncaught_exception(exc)
  File "D:\Users\SIMO\AppData\Local\Programs\Python\Python36\lib\site-packages\rest_framework\views.py", line 491, in dispatch
    response = handler(request, *args, **kwargs)
  File "D:\Users\SIMO\AppData\Local\Programs\Python\Python36\lib\site-packages\rest_framework\decorators.py", line 53, in handler
    return func(*args, **kwargs)
  File "H:\project\api_automation_test\api_test\common\common.py", line 79, in verify
    return func(reality_parameter)
  File "H:\project\api_automation_test\api_test\api\automationCase.py", line 934, in add_time_task
    frequency=frequency, unit=unit, project=project_id)
  File "H:\project\api_automation_test\api_test\common\addTask.py", line 54, in add
    my_user_cron.write()
  File "D:\Users\SIMO\AppData\Local\Programs\Python\Python36\lib\site-packages\crontab.py", line 344, in write
    raise IOError("Please specify user or filename to write.")
OSError: Please specify user or filename to write.
2018-05-28 11:00:53,998,6360,django.server,ERROR,basehttp.py:124,"POST /api/automation/add_time_task HTTP/1.1" 500 19453
2018-05-28 11:00:56,310,6360,django.request,ERROR,exception.py:118,Internal Server Error: /api/automation/add_time_task
Traceback (most recent call last):
  File "D:\Users\SIMO\AppData\Local\Programs\Python\Python36\lib\site-packages\django\core\handlers\exception.py", line 35, in inner
    response = get_response(request)
  File "D:\Users\SIMO\AppData\Local\Programs\Python\Python36\lib\site-packages\django\core\handlers\base.py", line 128, in _get_response
    response = self.process_exception_by_middleware(e, request)
  File "D:\Users\SIMO\AppData\Local\Programs\Python\Python36\lib\site-packages\django\core\handlers\base.py", line 126, in _get_response
    response = wrapped_callback(request, *callback_args, **callback_kwargs)
  File "D:\Users\SIMO\AppData\Local\Programs\Python\Python36\lib\site-packages\django\views\decorators\csrf.py", line 54, in wrapped_view
    return view_func(*args, **kwargs)
  File "D:\Users\SIMO\AppData\Local\Programs\Python\Python36\lib\site-packages\django\views\generic\base.py", line 69, in view
    return self.dispatch(request, *args, **kwargs)
  File "D:\Users\SIMO\AppData\Local\Programs\Python\Python36\lib\site-packages\rest_framework\views.py", line 494, in dispatch
    response = self.handle_exception(exc)
  File "D:\Users\SIMO\AppData\Local\Programs\Python\Python36\lib\site-packages\rest_framework\views.py", line 454, in handle_exception
    self.raise_uncaught_exception(exc)
  File "D:\Users\SIMO\AppData\Local\Programs\Python\Python36\lib\site-packages\rest_framework\views.py", line 491, in dispatch
    response = handler(request, *args, **kwargs)
  File "D:\Users\SIMO\AppData\Local\Programs\Python\Python36\lib\site-packages\rest_framework\decorators.py", line 53, in handler
    return func(*args, **kwargs)
  File "H:\project\api_automation_test\api_test\common\common.py", line 79, in verify
    return func(reality_parameter)
  File "H:\project\api_automation_test\api_test\api\automationCase.py", line 956, in add_time_task
    start_time=request.POST.get("startTime"), end_time=request.POST.get("endTime"))
  File "H:\project\api_automation_test\api_test\common\addTask.py", line 54, in add
    my_user_cron.write()
  File "D:\Users\SIMO\AppData\Local\Programs\Python\Python36\lib\site-packages\crontab.py", line 344, in write
    raise IOError("Please specify user or filename to write.")
OSError: Please specify user or filename to write.
2018-05-28 11:00:56,322,6360,django.server,ERROR,basehttp.py:124,"POST /api/automation/add_time_task HTTP/1.1" 500 19465
2018-05-28 11:01:02,295,6360,django.request,ERROR,exception.py:118,Internal Server Error: /api/automation/add_time_task
Traceback (most recent call last):
  File "D:\Users\SIMO\AppData\Local\Programs\Python\Python36\lib\site-packages\django\core\handlers\exception.py", line 35, in inner
    response = get_response(request)
  File "D:\Users\SIMO\AppData\Local\Programs\Python\Python36\lib\site-packages\django\core\handlers\base.py", line 128, in _get_response
    response = self.process_exception_by_middleware(e, request)
  File "D:\Users\SIMO\AppData\Local\Programs\Python\Python36\lib\site-packages\django\core\handlers\base.py", line 126, in _get_response
    response = wrapped_callback(request, *callback_args, **callback_kwargs)
  File "D:\Users\SIMO\AppData\Local\Programs\Python\Python36\lib\site-packages\django\views\decorators\csrf.py", line 54, in wrapped_view
    return view_func(*args, **kwargs)
  File "D:\Users\SIMO\AppData\Local\Programs\Python\Python36\lib\site-packages\django\views\generic\base.py", line 69, in view
    return self.dispatch(request, *args, **kwargs)
  File "D:\Users\SIMO\AppData\Local\Programs\Python\Python36\lib\site-packages\rest_framework\views.py", line 494, in dispatch
    response = self.handle_exception(exc)
  File "D:\Users\SIMO\AppData\Local\Programs\Python\Python36\lib\site-packages\rest_framework\views.py", line 454, in handle_exception
    self.raise_uncaught_exception(exc)
  File "D:\Users\SIMO\AppData\Local\Programs\Python\Python36\lib\site-packages\rest_framework\views.py", line 491, in dispatch
    response = handler(request, *args, **kwargs)
  File "D:\Users\SIMO\AppData\Local\Programs\Python\Python36\lib\site-packages\rest_framework\decorators.py", line 53, in handler
    return func(*args, **kwargs)
  File "H:\project\api_automation_test\api_test\common\common.py", line 79, in verify
    return func(reality_parameter)
  File "H:\project\api_automation_test\api_test\api\automationCase.py", line 956, in add_time_task
    start_time=request.POST.get("startTime"), end_time=request.POST.get("endTime"))
  File "H:\project\api_automation_test\api_test\common\addTask.py", line 54, in add
    my_user_cron.write()
  File "D:\Users\SIMO\AppData\Local\Programs\Python\Python36\lib\site-packages\crontab.py", line 344, in write
    raise IOError("Please specify user or filename to write.")
OSError: Please specify user or filename to write.
2018-05-28 11:01:02,308,6360,django.server,ERROR,basehttp.py:124,"POST /api/automation/add_time_task HTTP/1.1" 500 19465
2018-05-28 11:02:20,404,6360,django.request,ERROR,exception.py:118,Internal Server Error: /api/automation/add_time_task
Traceback (most recent call last):
  File "D:\Users\SIMO\AppData\Local\Programs\Python\Python36\lib\site-packages\django\core\handlers\exception.py", line 35, in inner
    response = get_response(request)
  File "D:\Users\SIMO\AppData\Local\Programs\Python\Python36\lib\site-packages\django\core\handlers\base.py", line 128, in _get_response
    response = self.process_exception_by_middleware(e, request)
  File "D:\Users\SIMO\AppData\Local\Programs\Python\Python36\lib\site-packages\django\core\handlers\base.py", line 126, in _get_response
    response = wrapped_callback(request, *callback_args, **callback_kwargs)
  File "D:\Users\SIMO\AppData\Local\Programs\Python\Python36\lib\site-packages\django\views\decorators\csrf.py", line 54, in wrapped_view
    return view_func(*args, **kwargs)
  File "D:\Users\SIMO\AppData\Local\Programs\Python\Python36\lib\site-packages\django\views\generic\base.py", line 69, in view
    return self.dispatch(request, *args, **kwargs)
  File "D:\Users\SIMO\AppData\Local\Programs\Python\Python36\lib\site-packages\rest_framework\views.py", line 494, in dispatch
    response = self.handle_exception(exc)
  File "D:\Users\SIMO\AppData\Local\Programs\Python\Python36\lib\site-packages\rest_framework\views.py", line 454, in handle_exception
    self.raise_uncaught_exception(exc)
  File "D:\Users\SIMO\AppData\Local\Programs\Python\Python36\lib\site-packages\rest_framework\views.py", line 491, in dispatch
    response = handler(request, *args, **kwargs)
  File "D:\Users\SIMO\AppData\Local\Programs\Python\Python36\lib\site-packages\rest_framework\decorators.py", line 53, in handler
    return func(*args, **kwargs)
  File "H:\project\api_automation_test\api_test\common\common.py", line 79, in verify
    return func(reality_parameter)
  File "H:\project\api_automation_test\api_test\api\automationCase.py", line 956, in add_time_task
    start_time=request.POST.get("startTime"), end_time=request.POST.get("endTime"))
  File "H:\project\api_automation_test\api_test\common\addTask.py", line 54, in add
    my_user_cron.write()
  File "D:\Users\SIMO\AppData\Local\Programs\Python\Python36\lib\site-packages\crontab.py", line 344, in write
    raise IOError("Please specify user or filename to write.")
OSError: Please specify user or filename to write.
2018-05-28 11:02:20,418,6360,django.server,ERROR,basehttp.py:124,"POST /api/automation/add_time_task HTTP/1.1" 500 19465
2018-05-28 11:02:46,983,6360,django.request,ERROR,exception.py:118,Internal Server Error: /api/automation/add_time_task
Traceback (most recent call last):
  File "D:\Users\SIMO\AppData\Local\Programs\Python\Python36\lib\site-packages\django\core\handlers\exception.py", line 35, in inner
    response = get_response(request)
  File "D:\Users\SIMO\AppData\Local\Programs\Python\Python36\lib\site-packages\django\core\handlers\base.py", line 128, in _get_response
    response = self.process_exception_by_middleware(e, request)
  File "D:\Users\SIMO\AppData\Local\Programs\Python\Python36\lib\site-packages\django\core\handlers\base.py", line 126, in _get_response
    response = wrapped_callback(request, *callback_args, **callback_kwargs)
  File "D:\Users\SIMO\AppData\Local\Programs\Python\Python36\lib\site-packages\django\views\decorators\csrf.py", line 54, in wrapped_view
    return view_func(*args, **kwargs)
  File "D:\Users\SIMO\AppData\Local\Programs\Python\Python36\lib\site-packages\django\views\generic\base.py", line 69, in view
    return self.dispatch(request, *args, **kwargs)
  File "D:\Users\SIMO\AppData\Local\Programs\Python\Python36\lib\site-packages\rest_framework\views.py", line 494, in dispatch
    response = self.handle_exception(exc)
  File "D:\Users\SIMO\AppData\Local\Programs\Python\Python36\lib\site-packages\rest_framework\views.py", line 454, in handle_exception
    self.raise_uncaught_exception(exc)
  File "D:\Users\SIMO\AppData\Local\Programs\Python\Python36\lib\site-packages\rest_framework\views.py", line 491, in dispatch
    response = handler(request, *args, **kwargs)
  File "D:\Users\SIMO\AppData\Local\Programs\Python\Python36\lib\site-packages\rest_framework\decorators.py", line 53, in handler
    return func(*args, **kwargs)
  File "H:\project\api_automation_test\api_test\common\common.py", line 79, in verify
    return func(reality_parameter)
  File "H:\project\api_automation_test\api_test\api\automationCase.py", line 956, in add_time_task
    start_time=request.POST.get("startTime"), end_time=request.POST.get("endTime"))
  File "H:\project\api_automation_test\api_test\common\addTask.py", line 54, in add
    my_user_cron.write()
  File "D:\Users\SIMO\AppData\Local\Programs\Python\Python36\lib\site-packages\crontab.py", line 344, in write
    raise IOError("Please specify user or filename to write.")
OSError: Please specify user or filename to write.
2018-05-28 11:02:46,995,6360,django.server,ERROR,basehttp.py:124,"POST /api/automation/add_time_task HTTP/1.1" 500 19465
2018-05-28 11:02:54,237,6360,django.request,ERROR,exception.py:118,Internal Server Error: /api/automation/add_time_task
Traceback (most recent call last):
  File "D:\Users\SIMO\AppData\Local\Programs\Python\Python36\lib\site-packages\django\core\handlers\exception.py", line 35, in inner
    response = get_response(request)
  File "D:\Users\SIMO\AppData\Local\Programs\Python\Python36\lib\site-packages\django\core\handlers\base.py", line 128, in _get_response
    response = self.process_exception_by_middleware(e, request)
  File "D:\Users\SIMO\AppData\Local\Programs\Python\Python36\lib\site-packages\django\core\handlers\base.py", line 126, in _get_response
    response = wrapped_callback(request, *callback_args, **callback_kwargs)
  File "D:\Users\SIMO\AppData\Local\Programs\Python\Python36\lib\site-packages\django\views\decorators\csrf.py", line 54, in wrapped_view
    return view_func(*args, **kwargs)
  File "D:\Users\SIMO\AppData\Local\Programs\Python\Python36\lib\site-packages\django\views\generic\base.py", line 69, in view
    return self.dispatch(request, *args, **kwargs)
  File "D:\Users\SIMO\AppData\Local\Programs\Python\Python36\lib\site-packages\rest_framework\views.py", line 494, in dispatch
    response = self.handle_exception(exc)
  File "D:\Users\SIMO\AppData\Local\Programs\Python\Python36\lib\site-packages\rest_framework\views.py", line 454, in handle_exception
    self.raise_uncaught_exception(exc)
  File "D:\Users\SIMO\AppData\Local\Programs\Python\Python36\lib\site-packages\rest_framework\views.py", line 491, in dispatch
    response = handler(request, *args, **kwargs)
  File "D:\Users\SIMO\AppData\Local\Programs\Python\Python36\lib\site-packages\rest_framework\decorators.py", line 53, in handler
    return func(*args, **kwargs)
  File "H:\project\api_automation_test\api_test\common\common.py", line 79, in verify
    return func(reality_parameter)
  File "H:\project\api_automation_test\api_test\api\automationCase.py", line 934, in add_time_task
    frequency=frequency, unit=unit, project=project_id)
  File "H:\project\api_automation_test\api_test\common\addTask.py", line 54, in add
    my_user_cron.write()
  File "D:\Users\SIMO\AppData\Local\Programs\Python\Python36\lib\site-packages\crontab.py", line 344, in write
    raise IOError("Please specify user or filename to write.")
OSError: Please specify user or filename to write.
2018-05-28 11:02:54,251,6360,django.server,ERROR,basehttp.py:124,"POST /api/automation/add_time_task HTTP/1.1" 500 19453
2018-05-28 11:03:49,880,6360,django.request,ERROR,exception.py:118,Internal Server Error: /api/automation/add_time_task
Traceback (most recent call last):
  File "D:\Users\SIMO\AppData\Local\Programs\Python\Python36\lib\site-packages\django\core\handlers\exception.py", line 35, in inner
    response = get_response(request)
  File "D:\Users\SIMO\AppData\Local\Programs\Python\Python36\lib\site-packages\django\core\handlers\base.py", line 128, in _get_response
    response = self.process_exception_by_middleware(e, request)
  File "D:\Users\SIMO\AppData\Local\Programs\Python\Python36\lib\site-packages\django\core\handlers\base.py", line 126, in _get_response
    response = wrapped_callback(request, *callback_args, **callback_kwargs)
  File "D:\Users\SIMO\AppData\Local\Programs\Python\Python36\lib\site-packages\django\views\decorators\csrf.py", line 54, in wrapped_view
    return view_func(*args, **kwargs)
  File "D:\Users\SIMO\AppData\Local\Programs\Python\Python36\lib\site-packages\django\views\generic\base.py", line 69, in view
    return self.dispatch(request, *args, **kwargs)
  File "D:\Users\SIMO\AppData\Local\Programs\Python\Python36\lib\site-packages\rest_framework\views.py", line 494, in dispatch
    response = self.handle_exception(exc)
  File "D:\Users\SIMO\AppData\Local\Programs\Python\Python36\lib\site-packages\rest_framework\views.py", line 454, in handle_exception
    self.raise_uncaught_exception(exc)
  File "D:\Users\SIMO\AppData\Local\Programs\Python\Python36\lib\site-packages\rest_framework\views.py", line 491, in dispatch
    response = handler(request, *args, **kwargs)
  File "D:\Users\SIMO\AppData\Local\Programs\Python\Python36\lib\site-packages\rest_framework\decorators.py", line 53, in handler
    return func(*args, **kwargs)
  File "H:\project\api_automation_test\api_test\common\common.py", line 79, in verify
    return func(reality_parameter)
  File "H:\project\api_automation_test\api_test\api\automationCase.py", line 934, in add_time_task
    frequency=frequency, unit=unit, project=project_id)
  File "H:\project\api_automation_test\api_test\common\addTask.py", line 54, in add
    my_user_cron.write()
  File "D:\Users\SIMO\AppData\Local\Programs\Python\Python36\lib\site-packages\crontab.py", line 344, in write
    raise IOError("Please specify user or filename to write.")
OSError: Please specify user or filename to write.
2018-05-28 11:03:49,892,6360,django.server,ERROR,basehttp.py:124,"POST /api/automation/add_time_task HTTP/1.1" 500 19454
2018-05-28 11:06:02,638,6360,django.request,ERROR,exception.py:118,Internal Server Error: /api/automation/add_time_task
Traceback (most recent call last):
  File "D:\Users\SIMO\AppData\Local\Programs\Python\Python36\lib\site-packages\django\core\handlers\exception.py", line 35, in inner
    response = get_response(request)
  File "D:\Users\SIMO\AppData\Local\Programs\Python\Python36\lib\site-packages\django\core\handlers\base.py", line 128, in _get_response
    response = self.process_exception_by_middleware(e, request)
  File "D:\Users\SIMO\AppData\Local\Programs\Python\Python36\lib\site-packages\django\core\handlers\base.py", line 126, in _get_response
    response = wrapped_callback(request, *callback_args, **callback_kwargs)
  File "D:\Users\SIMO\AppData\Local\Programs\Python\Python36\lib\site-packages\django\views\decorators\csrf.py", line 54, in wrapped_view
    return view_func(*args, **kwargs)
  File "D:\Users\SIMO\AppData\Local\Programs\Python\Python36\lib\site-packages\django\views\generic\base.py", line 69, in view
    return self.dispatch(request, *args, **kwargs)
  File "D:\Users\SIMO\AppData\Local\Programs\Python\Python36\lib\site-packages\rest_framework\views.py", line 494, in dispatch
    response = self.handle_exception(exc)
  File "D:\Users\SIMO\AppData\Local\Programs\Python\Python36\lib\site-packages\rest_framework\views.py", line 454, in handle_exception
    self.raise_uncaught_exception(exc)
  File "D:\Users\SIMO\AppData\Local\Programs\Python\Python36\lib\site-packages\rest_framework\views.py", line 491, in dispatch
    response = handler(request, *args, **kwargs)
  File "D:\Users\SIMO\AppData\Local\Programs\Python\Python36\lib\site-packages\rest_framework\decorators.py", line 53, in handler
    return func(*args, **kwargs)
  File "H:\project\api_automation_test\api_test\common\common.py", line 79, in verify
    return func(reality_parameter)
  File "H:\project\api_automation_test\api_test\api\automationCase.py", line 934, in add_time_task
    frequency=frequency, unit=unit, project=project_id)
  File "H:\project\api_automation_test\api_test\common\addTask.py", line 54, in add
    my_user_cron.write()
  File "D:\Users\SIMO\AppData\Local\Programs\Python\Python36\lib\site-packages\crontab.py", line 344, in write
    raise IOError("Please specify user or filename to write.")
OSError: Please specify user or filename to write.
2018-05-28 11:06:02,651,6360,django.server,ERROR,basehttp.py:124,"POST /api/automation/add_time_task HTTP/1.1" 500 19454
2018-05-28 11:06:57,226,6360,django.request,ERROR,exception.py:118,Internal Server Error: /api/automation/add_time_task
Traceback (most recent call last):
  File "D:\Users\SIMO\AppData\Local\Programs\Python\Python36\lib\site-packages\django\core\handlers\exception.py", line 35, in inner
    response = get_response(request)
  File "D:\Users\SIMO\AppData\Local\Programs\Python\Python36\lib\site-packages\django\core\handlers\base.py", line 128, in _get_response
    response = self.process_exception_by_middleware(e, request)
  File "D:\Users\SIMO\AppData\Local\Programs\Python\Python36\lib\site-packages\django\core\handlers\base.py", line 126, in _get_response
    response = wrapped_callback(request, *callback_args, **callback_kwargs)
  File "D:\Users\SIMO\AppData\Local\Programs\Python\Python36\lib\site-packages\django\views\decorators\csrf.py", line 54, in wrapped_view
    return view_func(*args, **kwargs)
  File "D:\Users\SIMO\AppData\Local\Programs\Python\Python36\lib\site-packages\django\views\generic\base.py", line 69, in view
    return self.dispatch(request, *args, **kwargs)
  File "D:\Users\SIMO\AppData\Local\Programs\Python\Python36\lib\site-packages\rest_framework\views.py", line 494, in dispatch
    response = self.handle_exception(exc)
  File "D:\Users\SIMO\AppData\Local\Programs\Python\Python36\lib\site-packages\rest_framework\views.py", line 454, in handle_exception
    self.raise_uncaught_exception(exc)
  File "D:\Users\SIMO\AppData\Local\Programs\Python\Python36\lib\site-packages\rest_framework\views.py", line 491, in dispatch
    response = handler(request, *args, **kwargs)
  File "D:\Users\SIMO\AppData\Local\Programs\Python\Python36\lib\site-packages\rest_framework\decorators.py", line 53, in handler
    return func(*args, **kwargs)
  File "H:\project\api_automation_test\api_test\common\common.py", line 79, in verify
    return func(reality_parameter)
  File "H:\project\api_automation_test\api_test\api\automationCase.py", line 934, in add_time_task
    frequency=frequency, unit=unit, project=project_id)
  File "H:\project\api_automation_test\api_test\common\addTask.py", line 54, in add
    my_user_cron.write()
  File "D:\Users\SIMO\AppData\Local\Programs\Python\Python36\lib\site-packages\crontab.py", line 344, in write
    raise IOError("Please specify user or filename to write.")
OSError: Please specify user or filename to write.
2018-05-28 11:06:57,239,6360,django.server,ERROR,basehttp.py:124,"POST /api/automation/add_time_task HTTP/1.1" 500 19454
2018-05-28 11:09:58,957,6360,django.request,ERROR,exception.py:118,Internal Server Error: /api/automation/add_time_task
Traceback (most recent call last):
  File "D:\Users\SIMO\AppData\Local\Programs\Python\Python36\lib\site-packages\django\core\handlers\exception.py", line 35, in inner
    response = get_response(request)
  File "D:\Users\SIMO\AppData\Local\Programs\Python\Python36\lib\site-packages\django\core\handlers\base.py", line 128, in _get_response
    response = self.process_exception_by_middleware(e, request)
  File "D:\Users\SIMO\AppData\Local\Programs\Python\Python36\lib\site-packages\django\core\handlers\base.py", line 126, in _get_response
    response = wrapped_callback(request, *callback_args, **callback_kwargs)
  File "D:\Users\SIMO\AppData\Local\Programs\Python\Python36\lib\site-packages\django\views\decorators\csrf.py", line 54, in wrapped_view
    return view_func(*args, **kwargs)
  File "D:\Users\SIMO\AppData\Local\Programs\Python\Python36\lib\site-packages\django\views\generic\base.py", line 69, in view
    return self.dispatch(request, *args, **kwargs)
  File "D:\Users\SIMO\AppData\Local\Programs\Python\Python36\lib\site-packages\rest_framework\views.py", line 494, in dispatch
    response = self.handle_exception(exc)
  File "D:\Users\SIMO\AppData\Local\Programs\Python\Python36\lib\site-packages\rest_framework\views.py", line 454, in handle_exception
    self.raise_uncaught_exception(exc)
  File "D:\Users\SIMO\AppData\Local\Programs\Python\Python36\lib\site-packages\rest_framework\views.py", line 491, in dispatch
    response = handler(request, *args, **kwargs)
  File "D:\Users\SIMO\AppData\Local\Programs\Python\Python36\lib\site-packages\rest_framework\decorators.py", line 53, in handler
    return func(*args, **kwargs)
  File "H:\project\api_automation_test\api_test\common\common.py", line 79, in verify
    return func(reality_parameter)
  File "H:\project\api_automation_test\api_test\api\automationCase.py", line 956, in add_time_task
    start_time=request.POST.get("startTime"), end_time=request.POST.get("endTime"))
  File "H:\project\api_automation_test\api_test\common\addTask.py", line 54, in add
    my_user_cron.write()
  File "D:\Users\SIMO\AppData\Local\Programs\Python\Python36\lib\site-packages\crontab.py", line 344, in write
    raise IOError("Please specify user or filename to write.")
OSError: Please specify user or filename to write.
2018-05-28 11:09:58,969,6360,django.server,ERROR,basehttp.py:124,"POST /api/automation/add_time_task HTTP/1.1" 500 19465
2018-05-28 11:10:10,728,6360,django.request,ERROR,exception.py:118,Internal Server Error: /api/automation/del_task
Traceback (most recent call last):
  File "D:\Users\SIMO\AppData\Local\Programs\Python\Python36\lib\site-packages\django\core\handlers\exception.py", line 35, in inner
    response = get_response(request)
  File "D:\Users\SIMO\AppData\Local\Programs\Python\Python36\lib\site-packages\django\core\handlers\base.py", line 128, in _get_response
    response = self.process_exception_by_middleware(e, request)
  File "D:\Users\SIMO\AppData\Local\Programs\Python\Python36\lib\site-packages\django\core\handlers\base.py", line 126, in _get_response
    response = wrapped_callback(request, *callback_args, **callback_kwargs)
  File "D:\Users\SIMO\AppData\Local\Programs\Python\Python36\lib\site-packages\django\views\decorators\csrf.py", line 54, in wrapped_view
    return view_func(*args, **kwargs)
  File "D:\Users\SIMO\AppData\Local\Programs\Python\Python36\lib\site-packages\django\views\generic\base.py", line 69, in view
    return self.dispatch(request, *args, **kwargs)
  File "D:\Users\SIMO\AppData\Local\Programs\Python\Python36\lib\site-packages\rest_framework\views.py", line 494, in dispatch
    response = self.handle_exception(exc)
  File "D:\Users\SIMO\AppData\Local\Programs\Python\Python36\lib\site-packages\rest_framework\views.py", line 454, in handle_exception
    self.raise_uncaught_exception(exc)
  File "D:\Users\SIMO\AppData\Local\Programs\Python\Python36\lib\site-packages\rest_framework\views.py", line 491, in dispatch
    response = handler(request, *args, **kwargs)
  File "D:\Users\SIMO\AppData\Local\Programs\Python\Python36\lib\site-packages\rest_framework\decorators.py", line 53, in handler
    return func(*args, **kwargs)
  File "H:\project\api_automation_test\api_test\common\common.py", line 79, in verify
    return func(reality_parameter)
  File "H:\project\api_automation_test\api_test\api\automationCase.py", line 1008, in del_task
    del_task_crontab(project_id)
  File "H:\project\api_automation_test\api_test\common\common.py", line 203, in del_task_crontab
    my_user_cron.write()
  File "D:\Users\SIMO\AppData\Local\Programs\Python\Python36\lib\site-packages\crontab.py", line 344, in write
    raise IOError("Please specify user or filename to write.")
OSError: Please specify user or filename to write.
2018-05-28 11:10:10,741,6360,django.server,ERROR,basehttp.py:124,"POST /api/automation/del_task HTTP/1.1" 500 19260
2018-05-28 11:10:48,936,6360,django.request,ERROR,exception.py:118,Internal Server Error: /api/automation/add_time_task
Traceback (most recent call last):
  File "D:\Users\SIMO\AppData\Local\Programs\Python\Python36\lib\site-packages\django\core\handlers\exception.py", line 35, in inner
    response = get_response(request)
  File "D:\Users\SIMO\AppData\Local\Programs\Python\Python36\lib\site-packages\django\core\handlers\base.py", line 128, in _get_response
    response = self.process_exception_by_middleware(e, request)
  File "D:\Users\SIMO\AppData\Local\Programs\Python\Python36\lib\site-packages\django\core\handlers\base.py", line 126, in _get_response
    response = wrapped_callback(request, *callback_args, **callback_kwargs)
  File "D:\Users\SIMO\AppData\Local\Programs\Python\Python36\lib\site-packages\django\views\decorators\csrf.py", line 54, in wrapped_view
    return view_func(*args, **kwargs)
  File "D:\Users\SIMO\AppData\Local\Programs\Python\Python36\lib\site-packages\django\views\generic\base.py", line 69, in view
    return self.dispatch(request, *args, **kwargs)
  File "D:\Users\SIMO\AppData\Local\Programs\Python\Python36\lib\site-packages\rest_framework\views.py", line 494, in dispatch
    response = self.handle_exception(exc)
  File "D:\Users\SIMO\AppData\Local\Programs\Python\Python36\lib\site-packages\rest_framework\views.py", line 454, in handle_exception
    self.raise_uncaught_exception(exc)
  File "D:\Users\SIMO\AppData\Local\Programs\Python\Python36\lib\site-packages\rest_framework\views.py", line 491, in dispatch
    response = handler(request, *args, **kwargs)
  File "D:\Users\SIMO\AppData\Local\Programs\Python\Python36\lib\site-packages\rest_framework\decorators.py", line 53, in handler
    return func(*args, **kwargs)
  File "H:\project\api_automation_test\api_test\common\common.py", line 79, in verify
    return func(reality_parameter)
  File "H:\project\api_automation_test\api_test\api\automationCase.py", line 956, in add_time_task
    start_time=request.POST.get("startTime"), end_time=request.POST.get("endTime"))
  File "H:\project\api_automation_test\api_test\common\addTask.py", line 54, in add
    my_user_cron.write()
  File "D:\Users\SIMO\AppData\Local\Programs\Python\Python36\lib\site-packages\crontab.py", line 344, in write
    raise IOError("Please specify user or filename to write.")
OSError: Please specify user or filename to write.
2018-05-28 11:10:48,947,6360,django.server,ERROR,basehttp.py:124,"POST /api/automation/add_time_task HTTP/1.1" 500 19466
2018-05-28 11:11:04,650,6360,django.request,ERROR,exception.py:118,Internal Server Error: /api/automation/add_time_task
Traceback (most recent call last):
  File "D:\Users\SIMO\AppData\Local\Programs\Python\Python36\lib\site-packages\django\core\handlers\exception.py", line 35, in inner
    response = get_response(request)
  File "D:\Users\SIMO\AppData\Local\Programs\Python\Python36\lib\site-packages\django\core\handlers\base.py", line 128, in _get_response
    response = self.process_exception_by_middleware(e, request)
  File "D:\Users\SIMO\AppData\Local\Programs\Python\Python36\lib\site-packages\django\core\handlers\base.py", line 126, in _get_response
    response = wrapped_callback(request, *callback_args, **callback_kwargs)
  File "D:\Users\SIMO\AppData\Local\Programs\Python\Python36\lib\site-packages\django\views\decorators\csrf.py", line 54, in wrapped_view
    return view_func(*args, **kwargs)
  File "D:\Users\SIMO\AppData\Local\Programs\Python\Python36\lib\site-packages\django\views\generic\base.py", line 69, in view
    return self.dispatch(request, *args, **kwargs)
  File "D:\Users\SIMO\AppData\Local\Programs\Python\Python36\lib\site-packages\rest_framework\views.py", line 494, in dispatch
    response = self.handle_exception(exc)
  File "D:\Users\SIMO\AppData\Local\Programs\Python\Python36\lib\site-packages\rest_framework\views.py", line 454, in handle_exception
    self.raise_uncaught_exception(exc)
  File "D:\Users\SIMO\AppData\Local\Programs\Python\Python36\lib\site-packages\rest_framework\views.py", line 491, in dispatch
    response = handler(request, *args, **kwargs)
  File "D:\Users\SIMO\AppData\Local\Programs\Python\Python36\lib\site-packages\rest_framework\decorators.py", line 53, in handler
    return func(*args, **kwargs)
  File "H:\project\api_automation_test\api_test\common\common.py", line 79, in verify
    return func(reality_parameter)
  File "H:\project\api_automation_test\api_test\api\automationCase.py", line 956, in add_time_task
    start_time=request.POST.get("startTime"), end_time=request.POST.get("endTime"))
  File "H:\project\api_automation_test\api_test\common\addTask.py", line 54, in add
    my_user_cron.write()
  File "D:\Users\SIMO\AppData\Local\Programs\Python\Python36\lib\site-packages\crontab.py", line 344, in write
    raise IOError("Please specify user or filename to write.")
OSError: Please specify user or filename to write.
2018-05-28 11:11:04,664,6360,django.server,ERROR,basehttp.py:124,"POST /api/automation/add_time_task HTTP/1.1" 500 19475
2018-05-28 14:27:01,129,2380,django.request,ERROR,exception.py:118,Internal Server Error: /api/report/auto_test_report
Traceback (most recent call last):
  File "D:\Users\SIMO\AppData\Local\Programs\Python\Python36\lib\site-packages\django\core\handlers\exception.py", line 35, in inner
    response = get_response(request)
  File "D:\Users\SIMO\AppData\Local\Programs\Python\Python36\lib\site-packages\django\core\handlers\base.py", line 128, in _get_response
    response = self.process_exception_by_middleware(e, request)
  File "D:\Users\SIMO\AppData\Local\Programs\Python\Python36\lib\site-packages\django\core\handlers\base.py", line 126, in _get_response
    response = wrapped_callback(request, *callback_args, **callback_kwargs)
  File "D:\Users\SIMO\AppData\Local\Programs\Python\Python36\lib\site-packages\django\views\decorators\csrf.py", line 54, in wrapped_view
    return view_func(*args, **kwargs)
  File "D:\Users\SIMO\AppData\Local\Programs\Python\Python36\lib\site-packages\django\views\generic\base.py", line 69, in view
    return self.dispatch(request, *args, **kwargs)
  File "D:\Users\SIMO\AppData\Local\Programs\Python\Python36\lib\site-packages\rest_framework\views.py", line 494, in dispatch
    response = self.handle_exception(exc)
  File "D:\Users\SIMO\AppData\Local\Programs\Python\Python36\lib\site-packages\rest_framework\views.py", line 454, in handle_exception
    self.raise_uncaught_exception(exc)
  File "D:\Users\SIMO\AppData\Local\Programs\Python\Python36\lib\site-packages\rest_framework\views.py", line 491, in dispatch
    response = handler(request, *args, **kwargs)
  File "D:\Users\SIMO\AppData\Local\Programs\Python\Python36\lib\site-packages\rest_framework\decorators.py", line 53, in handler
    return func(*args, **kwargs)
  File "H:\project\api_automation_test\api_test\common\common.py", line 79, in verify
    return func(reality_parameter)
  File "H:\project\api_automation_test\api_test\api\automationReport.py", line 50, in auto_test_report
    case = Q()
NameError: name 'Q' is not defined
2018-05-28 14:27:01,144,2380,django.server,ERROR,basehttp.py:124,"GET /api/report/auto_test_report?project_id=1&time=2018-05-28%2014%3A15%3A55 HTTP/1.1" 500 19007
2018-05-28 14:27:01,187,2380,django.request,ERROR,exception.py:118,Internal Server Error: /api/report/auto_test_report
Traceback (most recent call last):
  File "D:\Users\SIMO\AppData\Local\Programs\Python\Python36\lib\site-packages\django\core\handlers\exception.py", line 35, in inner
    response = get_response(request)
  File "D:\Users\SIMO\AppData\Local\Programs\Python\Python36\lib\site-packages\django\core\handlers\base.py", line 128, in _get_response
    response = self.process_exception_by_middleware(e, request)
  File "D:\Users\SIMO\AppData\Local\Programs\Python\Python36\lib\site-packages\django\core\handlers\base.py", line 126, in _get_response
    response = wrapped_callback(request, *callback_args, **callback_kwargs)
  File "D:\Users\SIMO\AppData\Local\Programs\Python\Python36\lib\site-packages\django\views\decorators\csrf.py", line 54, in wrapped_view
    return view_func(*args, **kwargs)
  File "D:\Users\SIMO\AppData\Local\Programs\Python\Python36\lib\site-packages\django\views\generic\base.py", line 69, in view
    return self.dispatch(request, *args, **kwargs)
  File "D:\Users\SIMO\AppData\Local\Programs\Python\Python36\lib\site-packages\rest_framework\views.py", line 494, in dispatch
    response = self.handle_exception(exc)
  File "D:\Users\SIMO\AppData\Local\Programs\Python\Python36\lib\site-packages\rest_framework\views.py", line 454, in handle_exception
    self.raise_uncaught_exception(exc)
  File "D:\Users\SIMO\AppData\Local\Programs\Python\Python36\lib\site-packages\rest_framework\views.py", line 491, in dispatch
    response = handler(request, *args, **kwargs)
  File "D:\Users\SIMO\AppData\Local\Programs\Python\Python36\lib\site-packages\rest_framework\decorators.py", line 53, in handler
    return func(*args, **kwargs)
  File "H:\project\api_automation_test\api_test\common\common.py", line 79, in verify
    return func(reality_parameter)
  File "H:\project\api_automation_test\api_test\api\automationReport.py", line 50, in auto_test_report
    case = Q()
NameError: name 'Q' is not defined
2018-05-28 14:27:01,197,2380,django.server,ERROR,basehttp.py:124,"GET /api/report/auto_test_report?project_id=1&time=2018-05-28%2014%3A15%3A55 HTTP/1.1" 500 19006
2018-05-28 14:27:03,931,2380,django.request,ERROR,exception.py:118,Internal Server Error: /api/report/auto_test_report
Traceback (most recent call last):
  File "D:\Users\SIMO\AppData\Local\Programs\Python\Python36\lib\site-packages\django\core\handlers\exception.py", line 35, in inner
    response = get_response(request)
  File "D:\Users\SIMO\AppData\Local\Programs\Python\Python36\lib\site-packages\django\core\handlers\base.py", line 128, in _get_response
    response = self.process_exception_by_middleware(e, request)
  File "D:\Users\SIMO\AppData\Local\Programs\Python\Python36\lib\site-packages\django\core\handlers\base.py", line 126, in _get_response
    response = wrapped_callback(request, *callback_args, **callback_kwargs)
  File "D:\Users\SIMO\AppData\Local\Programs\Python\Python36\lib\site-packages\django\views\decorators\csrf.py", line 54, in wrapped_view
    return view_func(*args, **kwargs)
  File "D:\Users\SIMO\AppData\Local\Programs\Python\Python36\lib\site-packages\django\views\generic\base.py", line 69, in view
    return self.dispatch(request, *args, **kwargs)
  File "D:\Users\SIMO\AppData\Local\Programs\Python\Python36\lib\site-packages\rest_framework\views.py", line 494, in dispatch
    response = self.handle_exception(exc)
  File "D:\Users\SIMO\AppData\Local\Programs\Python\Python36\lib\site-packages\rest_framework\views.py", line 454, in handle_exception
    self.raise_uncaught_exception(exc)
  File "D:\Users\SIMO\AppData\Local\Programs\Python\Python36\lib\site-packages\rest_framework\views.py", line 491, in dispatch
    response = handler(request, *args, **kwargs)
  File "D:\Users\SIMO\AppData\Local\Programs\Python\Python36\lib\site-packages\rest_framework\decorators.py", line 53, in handler
    return func(*args, **kwargs)
  File "H:\project\api_automation_test\api_test\common\common.py", line 79, in verify
    return func(reality_parameter)
  File "H:\project\api_automation_test\api_test\api\automationReport.py", line 50, in auto_test_report
    case = Q()
NameError: name 'Q' is not defined
2018-05-28 14:27:03,942,2380,django.server,ERROR,basehttp.py:124,"GET /api/report/auto_test_report?project_id=1&time=2018-05-28%2014%3A15%3A55 HTTP/1.1" 500 19007
2018-05-28 14:27:03,981,2380,django.request,ERROR,exception.py:118,Internal Server Error: /api/report/auto_test_report
Traceback (most recent call last):
  File "D:\Users\SIMO\AppData\Local\Programs\Python\Python36\lib\site-packages\django\core\handlers\exception.py", line 35, in inner
    response = get_response(request)
  File "D:\Users\SIMO\AppData\Local\Programs\Python\Python36\lib\site-packages\django\core\handlers\base.py", line 128, in _get_response
    response = self.process_exception_by_middleware(e, request)
  File "D:\Users\SIMO\AppData\Local\Programs\Python\Python36\lib\site-packages\django\core\handlers\base.py", line 126, in _get_response
    response = wrapped_callback(request, *callback_args, **callback_kwargs)
  File "D:\Users\SIMO\AppData\Local\Programs\Python\Python36\lib\site-packages\django\views\decorators\csrf.py", line 54, in wrapped_view
    return view_func(*args, **kwargs)
  File "D:\Users\SIMO\AppData\Local\Programs\Python\Python36\lib\site-packages\django\views\generic\base.py", line 69, in view
    return self.dispatch(request, *args, **kwargs)
  File "D:\Users\SIMO\AppData\Local\Programs\Python\Python36\lib\site-packages\rest_framework\views.py", line 494, in dispatch
    response = self.handle_exception(exc)
  File "D:\Users\SIMO\AppData\Local\Programs\Python\Python36\lib\site-packages\rest_framework\views.py", line 454, in handle_exception
    self.raise_uncaught_exception(exc)
  File "D:\Users\SIMO\AppData\Local\Programs\Python\Python36\lib\site-packages\rest_framework\views.py", line 491, in dispatch
    response = handler(request, *args, **kwargs)
  File "D:\Users\SIMO\AppData\Local\Programs\Python\Python36\lib\site-packages\rest_framework\decorators.py", line 53, in handler
    return func(*args, **kwargs)
  File "H:\project\api_automation_test\api_test\common\common.py", line 79, in verify
    return func(reality_parameter)
  File "H:\project\api_automation_test\api_test\api\automationReport.py", line 50, in auto_test_report
    case = Q()
NameError: name 'Q' is not defined
2018-05-28 14:27:03,991,2380,django.server,ERROR,basehttp.py:124,"GET /api/report/auto_test_report?project_id=1&time=2018-05-28%2014%3A15%3A55 HTTP/1.1" 500 19007
2018-05-28 14:27:22,198,2380,django.request,ERROR,exception.py:118,Internal Server Error: /api/report/auto_test_report
Traceback (most recent call last):
  File "D:\Users\SIMO\AppData\Local\Programs\Python\Python36\lib\site-packages\django\core\handlers\exception.py", line 35, in inner
    response = get_response(request)
  File "D:\Users\SIMO\AppData\Local\Programs\Python\Python36\lib\site-packages\django\core\handlers\base.py", line 128, in _get_response
    response = self.process_exception_by_middleware(e, request)
  File "D:\Users\SIMO\AppData\Local\Programs\Python\Python36\lib\site-packages\django\core\handlers\base.py", line 126, in _get_response
    response = wrapped_callback(request, *callback_args, **callback_kwargs)
  File "D:\Users\SIMO\AppData\Local\Programs\Python\Python36\lib\site-packages\django\views\decorators\csrf.py", line 54, in wrapped_view
    return view_func(*args, **kwargs)
  File "D:\Users\SIMO\AppData\Local\Programs\Python\Python36\lib\site-packages\django\views\generic\base.py", line 69, in view
    return self.dispatch(request, *args, **kwargs)
  File "D:\Users\SIMO\AppData\Local\Programs\Python\Python36\lib\site-packages\rest_framework\views.py", line 494, in dispatch
    response = self.handle_exception(exc)
  File "D:\Users\SIMO\AppData\Local\Programs\Python\Python36\lib\site-packages\rest_framework\views.py", line 454, in handle_exception
    self.raise_uncaught_exception(exc)
  File "D:\Users\SIMO\AppData\Local\Programs\Python\Python36\lib\site-packages\rest_framework\views.py", line 491, in dispatch
    response = handler(request, *args, **kwargs)
  File "D:\Users\SIMO\AppData\Local\Programs\Python\Python36\lib\site-packages\rest_framework\decorators.py", line 53, in handler
    return func(*args, **kwargs)
  File "H:\project\api_automation_test\api_test\common\common.py", line 79, in verify
    return func(reality_parameter)
  File "H:\project\api_automation_test\api_test\api\automationReport.py", line 50, in auto_test_report
    if obj:
NameError: name 'Q' is not defined
2018-05-28 14:27:22,211,2380,django.server,ERROR,basehttp.py:124,"GET /api/report/auto_test_report?project_id=1&time=2018-05-28%2014%3A15%3A55 HTTP/1.1" 500 19000
2018-05-28 14:27:22,250,2380,django.request,ERROR,exception.py:118,Internal Server Error: /api/report/auto_test_report
Traceback (most recent call last):
  File "D:\Users\SIMO\AppData\Local\Programs\Python\Python36\lib\site-packages\django\core\handlers\exception.py", line 35, in inner
    response = get_response(request)
  File "D:\Users\SIMO\AppData\Local\Programs\Python\Python36\lib\site-packages\django\core\handlers\base.py", line 128, in _get_response
    response = self.process_exception_by_middleware(e, request)
  File "D:\Users\SIMO\AppData\Local\Programs\Python\Python36\lib\site-packages\django\core\handlers\base.py", line 126, in _get_response
    response = wrapped_callback(request, *callback_args, **callback_kwargs)
  File "D:\Users\SIMO\AppData\Local\Programs\Python\Python36\lib\site-packages\django\views\decorators\csrf.py", line 54, in wrapped_view
    return view_func(*args, **kwargs)
  File "D:\Users\SIMO\AppData\Local\Programs\Python\Python36\lib\site-packages\django\views\generic\base.py", line 69, in view
    return self.dispatch(request, *args, **kwargs)
  File "D:\Users\SIMO\AppData\Local\Programs\Python\Python36\lib\site-packages\rest_framework\views.py", line 494, in dispatch
    response = self.handle_exception(exc)
  File "D:\Users\SIMO\AppData\Local\Programs\Python\Python36\lib\site-packages\rest_framework\views.py", line 454, in handle_exception
    self.raise_uncaught_exception(exc)
  File "D:\Users\SIMO\AppData\Local\Programs\Python\Python36\lib\site-packages\rest_framework\views.py", line 491, in dispatch
    response = handler(request, *args, **kwargs)
  File "D:\Users\SIMO\AppData\Local\Programs\Python\Python36\lib\site-packages\rest_framework\decorators.py", line 53, in handler
    return func(*args, **kwargs)
  File "H:\project\api_automation_test\api_test\common\common.py", line 79, in verify
    return func(reality_parameter)
  File "H:\project\api_automation_test\api_test\api\automationReport.py", line 50, in auto_test_report
    if obj:
NameError: name 'Q' is not defined
2018-05-28 14:27:22,261,2380,django.server,ERROR,basehttp.py:124,"GET /api/report/auto_test_report?project_id=1&time=2018-05-28%2014%3A15%3A55 HTTP/1.1" 500 19000
2018-05-28 14:42:53,643,10208,django.request,ERROR,exception.py:118,Internal Server Error: /api/report/lately_ten
Traceback (most recent call last):
  File "D:\Users\SIMO\AppData\Local\Programs\Python\Python36\lib\site-packages\django\core\handlers\exception.py", line 35, in inner
    response = get_response(request)
  File "D:\Users\SIMO\AppData\Local\Programs\Python\Python36\lib\site-packages\django\core\handlers\base.py", line 128, in _get_response
    response = self.process_exception_by_middleware(e, request)
  File "D:\Users\SIMO\AppData\Local\Programs\Python\Python36\lib\site-packages\django\core\handlers\base.py", line 126, in _get_response
    response = wrapped_callback(request, *callback_args, **callback_kwargs)
  File "D:\Users\SIMO\AppData\Local\Programs\Python\Python36\lib\site-packages\django\views\decorators\csrf.py", line 54, in wrapped_view
    return view_func(*args, **kwargs)
  File "D:\Users\SIMO\AppData\Local\Programs\Python\Python36\lib\site-packages\django\views\generic\base.py", line 69, in view
    return self.dispatch(request, *args, **kwargs)
  File "D:\Users\SIMO\AppData\Local\Programs\Python\Python36\lib\site-packages\rest_framework\views.py", line 494, in dispatch
    response = self.handle_exception(exc)
  File "D:\Users\SIMO\AppData\Local\Programs\Python\Python36\lib\site-packages\rest_framework\views.py", line 454, in handle_exception
    self.raise_uncaught_exception(exc)
  File "D:\Users\SIMO\AppData\Local\Programs\Python\Python36\lib\site-packages\rest_framework\views.py", line 491, in dispatch
    response = handler(request, *args, **kwargs)
  File "D:\Users\SIMO\AppData\Local\Programs\Python\Python36\lib\site-packages\rest_framework\decorators.py", line 53, in handler
    return func(*args, **kwargs)
  File "H:\project\api_automation_test\api_test\common\common.py", line 79, in verify
    return func(reality_parameter)
  File "H:\project\api_automation_test\api_test\api\automationReport.py", line 107, in auto_lately_ten_time
    AutomationTaskRunTime.objects.filter(project=project_id).order_by("startTime")[-10:], many=True).data
  File "D:\Users\SIMO\AppData\Local\Programs\Python\Python36\lib\site-packages\django\db\models\query.py", line 286, in __getitem__
    "Negative indexing is not supported."
AssertionError: Negative indexing is not supported.
2018-05-28 14:42:53,683,10208,django.server,ERROR,basehttp.py:124,"GET /api/report/lately_ten?project_id=1 HTTP/1.1" 500 19069
2018-05-28 14:43:35,962,4628,django.request,ERROR,exception.py:118,Internal Server Error: /api/report/lately_ten
Traceback (most recent call last):
  File "D:\Users\SIMO\AppData\Local\Programs\Python\Python36\lib\site-packages\django\core\handlers\exception.py", line 35, in inner
    response = get_response(request)
  File "D:\Users\SIMO\AppData\Local\Programs\Python\Python36\lib\site-packages\django\core\handlers\base.py", line 128, in _get_response
    response = self.process_exception_by_middleware(e, request)
  File "D:\Users\SIMO\AppData\Local\Programs\Python\Python36\lib\site-packages\django\core\handlers\base.py", line 126, in _get_response
    response = wrapped_callback(request, *callback_args, **callback_kwargs)
  File "D:\Users\SIMO\AppData\Local\Programs\Python\Python36\lib\site-packages\django\views\decorators\csrf.py", line 54, in wrapped_view
    return view_func(*args, **kwargs)
  File "D:\Users\SIMO\AppData\Local\Programs\Python\Python36\lib\site-packages\django\views\generic\base.py", line 69, in view
    return self.dispatch(request, *args, **kwargs)
  File "D:\Users\SIMO\AppData\Local\Programs\Python\Python36\lib\site-packages\rest_framework\views.py", line 494, in dispatch
    response = self.handle_exception(exc)
  File "D:\Users\SIMO\AppData\Local\Programs\Python\Python36\lib\site-packages\rest_framework\views.py", line 454, in handle_exception
    self.raise_uncaught_exception(exc)
  File "D:\Users\SIMO\AppData\Local\Programs\Python\Python36\lib\site-packages\rest_framework\views.py", line 491, in dispatch
    response = handler(request, *args, **kwargs)
  File "D:\Users\SIMO\AppData\Local\Programs\Python\Python36\lib\site-packages\rest_framework\decorators.py", line 53, in handler
    return func(*args, **kwargs)
  File "H:\project\api_automation_test\api_test\common\common.py", line 79, in verify
    return func(reality_parameter)
  File "H:\project\api_automation_test\api_test\api\automationReport.py", line 107, in auto_lately_ten_time
    AutomationTaskRunTime.objects.filter(project=project_id).order_by("-startTime")[-10:], many=True).data
  File "D:\Users\SIMO\AppData\Local\Programs\Python\Python36\lib\site-packages\django\db\models\query.py", line 286, in __getitem__
    "Negative indexing is not supported."
AssertionError: Negative indexing is not supported.
2018-05-28 14:43:35,978,4628,django.server,ERROR,basehttp.py:124,"GET /api/report/lately_ten?project_id=1 HTTP/1.1" 500 19070
2018-05-28 14:49:13,829,17232,django.request,ERROR,exception.py:118,Internal Server Error: /api/report/lately_ten
Traceback (most recent call last):
  File "D:\Users\SIMO\AppData\Local\Programs\Python\Python36\lib\site-packages\django\core\handlers\exception.py", line 35, in inner
    response = get_response(request)
  File "D:\Users\SIMO\AppData\Local\Programs\Python\Python36\lib\site-packages\django\core\handlers\base.py", line 128, in _get_response
    response = self.process_exception_by_middleware(e, request)
  File "D:\Users\SIMO\AppData\Local\Programs\Python\Python36\lib\site-packages\django\core\handlers\base.py", line 126, in _get_response
    response = wrapped_callback(request, *callback_args, **callback_kwargs)
  File "D:\Users\SIMO\AppData\Local\Programs\Python\Python36\lib\site-packages\django\views\decorators\csrf.py", line 54, in wrapped_view
    return view_func(*args, **kwargs)
  File "D:\Users\SIMO\AppData\Local\Programs\Python\Python36\lib\site-packages\django\views\generic\base.py", line 69, in view
    return self.dispatch(request, *args, **kwargs)
  File "D:\Users\SIMO\AppData\Local\Programs\Python\Python36\lib\site-packages\rest_framework\views.py", line 494, in dispatch
    response = self.handle_exception(exc)
  File "D:\Users\SIMO\AppData\Local\Programs\Python\Python36\lib\site-packages\rest_framework\views.py", line 454, in handle_exception
    self.raise_uncaught_exception(exc)
  File "D:\Users\SIMO\AppData\Local\Programs\Python\Python36\lib\site-packages\rest_framework\views.py", line 491, in dispatch
    response = handler(request, *args, **kwargs)
  File "D:\Users\SIMO\AppData\Local\Programs\Python\Python36\lib\site-packages\rest_framework\decorators.py", line 53, in handler
    return func(*args, **kwargs)
  File "H:\project\api_automation_test\api_test\common\common.py", line 79, in verify
    return func(reality_parameter)
  File "H:\project\api_automation_test\api_test\api\automationReport.py", line 109, in auto_lately_ten_time
    print(i.startTime)
AttributeError: 'collections.OrderedDict' object has no attribute 'startTime'
2018-05-28 14:49:13,841,17232,django.server,ERROR,basehttp.py:124,"GET /api/report/lately_ten?project_id=1 HTTP/1.1" 500 18861
2018-05-28 14:52:39,710,9344,django.request,ERROR,exception.py:118,Internal Server Error: /api/report/lately_ten
Traceback (most recent call last):
  File "D:\Users\SIMO\AppData\Local\Programs\Python\Python36\lib\site-packages\django\core\handlers\exception.py", line 35, in inner
    response = get_response(request)
  File "D:\Users\SIMO\AppData\Local\Programs\Python\Python36\lib\site-packages\django\core\handlers\base.py", line 128, in _get_response
    response = self.process_exception_by_middleware(e, request)
  File "D:\Users\SIMO\AppData\Local\Programs\Python\Python36\lib\site-packages\django\core\handlers\base.py", line 126, in _get_response
    response = wrapped_callback(request, *callback_args, **callback_kwargs)
  File "D:\Users\SIMO\AppData\Local\Programs\Python\Python36\lib\site-packages\django\views\decorators\csrf.py", line 54, in wrapped_view
    return view_func(*args, **kwargs)
  File "D:\Users\SIMO\AppData\Local\Programs\Python\Python36\lib\site-packages\django\views\generic\base.py", line 69, in view
    return self.dispatch(request, *args, **kwargs)
  File "D:\Users\SIMO\AppData\Local\Programs\Python\Python36\lib\site-packages\rest_framework\views.py", line 494, in dispatch
    response = self.handle_exception(exc)
  File "D:\Users\SIMO\AppData\Local\Programs\Python\Python36\lib\site-packages\rest_framework\views.py", line 454, in handle_exception
    self.raise_uncaught_exception(exc)
  File "D:\Users\SIMO\AppData\Local\Programs\Python\Python36\lib\site-packages\rest_framework\views.py", line 491, in dispatch
    response = handler(request, *args, **kwargs)
  File "D:\Users\SIMO\AppData\Local\Programs\Python\Python36\lib\site-packages\rest_framework\decorators.py", line 53, in handler
    return func(*args, **kwargs)
  File "H:\project\api_automation_test\api_test\common\common.py", line 79, in verify
    return func(reality_parameter)
  File "H:\project\api_automation_test\api_test\api\automationReport.py", line 112, in auto_lately_ten_time
    print(j["result"])
TypeError: 'AutomationCaseTestResult' object is not subscriptable
2018-05-28 14:52:39,724,9344,django.server,ERROR,basehttp.py:124,"GET /api/report/lately_ten?project_id=1 HTTP/1.1" 500 18841
2018-05-28 14:58:01,273,8596,django.request,ERROR,exception.py:118,Internal Server Error: /api/report/lately_ten
Traceback (most recent call last):
  File "D:\Users\SIMO\AppData\Local\Programs\Python\Python36\lib\site-packages\django\core\handlers\exception.py", line 35, in inner
    response = get_response(request)
  File "D:\Users\SIMO\AppData\Local\Programs\Python\Python36\lib\site-packages\django\core\handlers\base.py", line 128, in _get_response
    response = self.process_exception_by_middleware(e, request)
  File "D:\Users\SIMO\AppData\Local\Programs\Python\Python36\lib\site-packages\django\core\handlers\base.py", line 126, in _get_response
    response = wrapped_callback(request, *callback_args, **callback_kwargs)
  File "D:\Users\SIMO\AppData\Local\Programs\Python\Python36\lib\site-packages\django\views\decorators\csrf.py", line 54, in wrapped_view
    return view_func(*args, **kwargs)
  File "D:\Users\SIMO\AppData\Local\Programs\Python\Python36\lib\site-packages\django\views\generic\base.py", line 69, in view
    return self.dispatch(request, *args, **kwargs)
  File "D:\Users\SIMO\AppData\Local\Programs\Python\Python36\lib\site-packages\rest_framework\views.py", line 494, in dispatch
    response = self.handle_exception(exc)
  File "D:\Users\SIMO\AppData\Local\Programs\Python\Python36\lib\site-packages\rest_framework\views.py", line 454, in handle_exception
    self.raise_uncaught_exception(exc)
  File "D:\Users\SIMO\AppData\Local\Programs\Python\Python36\lib\site-packages\rest_framework\views.py", line 491, in dispatch
    response = handler(request, *args, **kwargs)
  File "D:\Users\SIMO\AppData\Local\Programs\Python\Python36\lib\site-packages\rest_framework\decorators.py", line 53, in handler
    return func(*args, **kwargs)
  File "H:\project\api_automation_test\api_test\common\common.py", line 79, in verify
    return func(reality_parameter)
  File "H:\project\api_automation_test\api_test\api\automationReport.py", line 109, in auto_lately_ten_time
    print(val["startTime"])
TypeError: tuple indices must be integers or slices, not str
2018-05-28 14:58:01,287,8596,django.server,ERROR,basehttp.py:124,"GET /api/report/lately_ten?project_id=1 HTTP/1.1" 500 18832
2018-05-28 14:58:42,737,11292,django.request,ERROR,exception.py:118,Internal Server Error: /api/report/lately_ten
Traceback (most recent call last):
  File "D:\Users\SIMO\AppData\Local\Programs\Python\Python36\lib\site-packages\django\core\handlers\exception.py", line 35, in inner
    response = get_response(request)
  File "D:\Users\SIMO\AppData\Local\Programs\Python\Python36\lib\site-packages\django\core\handlers\base.py", line 128, in _get_response
    response = self.process_exception_by_middleware(e, request)
  File "D:\Users\SIMO\AppData\Local\Programs\Python\Python36\lib\site-packages\django\core\handlers\base.py", line 126, in _get_response
    response = wrapped_callback(request, *callback_args, **callback_kwargs)
  File "D:\Users\SIMO\AppData\Local\Programs\Python\Python36\lib\site-packages\django\views\decorators\csrf.py", line 54, in wrapped_view
    return view_func(*args, **kwargs)
  File "D:\Users\SIMO\AppData\Local\Programs\Python\Python36\lib\site-packages\django\views\generic\base.py", line 69, in view
    return self.dispatch(request, *args, **kwargs)
  File "D:\Users\SIMO\AppData\Local\Programs\Python\Python36\lib\site-packages\rest_framework\views.py", line 494, in dispatch
    response = self.handle_exception(exc)
  File "D:\Users\SIMO\AppData\Local\Programs\Python\Python36\lib\site-packages\rest_framework\views.py", line 454, in handle_exception
    self.raise_uncaught_exception(exc)
  File "D:\Users\SIMO\AppData\Local\Programs\Python\Python36\lib\site-packages\rest_framework\views.py", line 491, in dispatch
    response = handler(request, *args, **kwargs)
  File "D:\Users\SIMO\AppData\Local\Programs\Python\Python36\lib\site-packages\rest_framework\decorators.py", line 53, in handler
    return func(*args, **kwargs)
  File "H:\project\api_automation_test\api_test\common\common.py", line 79, in verify
    return func(reality_parameter)
  File "H:\project\api_automation_test\api_test\api\automationReport.py", line 110, in auto_lately_ten_time
    print(i.index)
AttributeError: 'collections.OrderedDict' object has no attribute 'index'
2018-05-28 14:58:42,750,11292,django.server,ERROR,basehttp.py:124,"GET /api/report/lately_ten?project_id=1 HTTP/1.1" 500 18849
2018-05-28 15:01:39,976,13984,django.request,ERROR,exception.py:118,Internal Server Error: /api/report/lately_ten
Traceback (most recent call last):
  File "D:\Users\SIMO\AppData\Local\Programs\Python\Python36\lib\site-packages\django\core\handlers\exception.py", line 35, in inner
    response = get_response(request)
  File "D:\Users\SIMO\AppData\Local\Programs\Python\Python36\lib\site-packages\django\core\handlers\base.py", line 128, in _get_response
    response = self.process_exception_by_middleware(e, request)
  File "D:\Users\SIMO\AppData\Local\Programs\Python\Python36\lib\site-packages\django\core\handlers\base.py", line 126, in _get_response
    response = wrapped_callback(request, *callback_args, **callback_kwargs)
  File "D:\Users\SIMO\AppData\Local\Programs\Python\Python36\lib\site-packages\django\views\decorators\csrf.py", line 54, in wrapped_view
    return view_func(*args, **kwargs)
  File "D:\Users\SIMO\AppData\Local\Programs\Python\Python36\lib\site-packages\django\views\generic\base.py", line 69, in view
    return self.dispatch(request, *args, **kwargs)
  File "D:\Users\SIMO\AppData\Local\Programs\Python\Python36\lib\site-packages\rest_framework\views.py", line 494, in dispatch
    response = self.handle_exception(exc)
  File "D:\Users\SIMO\AppData\Local\Programs\Python\Python36\lib\site-packages\rest_framework\views.py", line 454, in handle_exception
    self.raise_uncaught_exception(exc)
  File "D:\Users\SIMO\AppData\Local\Programs\Python\Python36\lib\site-packages\rest_framework\views.py", line 491, in dispatch
    response = handler(request, *args, **kwargs)
  File "D:\Users\SIMO\AppData\Local\Programs\Python\Python36\lib\site-packages\rest_framework\decorators.py", line 53, in handler
    return func(*args, **kwargs)
  File "H:\project\api_automation_test\api_test\common\common.py", line 79, in verify
    return func(reality_parameter)
  File "H:\project\api_automation_test\api_test\api\automationReport.py", line 110, in auto_lately_ten_time
    a = data[data.index(i)].append("1")
AttributeError: 'collections.OrderedDict' object has no attribute 'append'
2018-05-28 15:01:39,989,13984,django.server,ERROR,basehttp.py:124,"GET /api/report/lately_ten?project_id=1 HTTP/1.1" 500 18873
2018-05-28 15:02:52,846,10556,django.request,ERROR,exception.py:118,Internal Server Error: /api/report/lately_ten
Traceback (most recent call last):
  File "D:\Users\SIMO\AppData\Local\Programs\Python\Python36\lib\site-packages\django\core\handlers\exception.py", line 35, in inner
    response = get_response(request)
  File "D:\Users\SIMO\AppData\Local\Programs\Python\Python36\lib\site-packages\django\core\handlers\base.py", line 128, in _get_response
    response = self.process_exception_by_middleware(e, request)
  File "D:\Users\SIMO\AppData\Local\Programs\Python\Python36\lib\site-packages\django\core\handlers\base.py", line 126, in _get_response
    response = wrapped_callback(request, *callback_args, **callback_kwargs)
  File "D:\Users\SIMO\AppData\Local\Programs\Python\Python36\lib\site-packages\django\views\decorators\csrf.py", line 54, in wrapped_view
    return view_func(*args, **kwargs)
  File "D:\Users\SIMO\AppData\Local\Programs\Python\Python36\lib\site-packages\django\views\generic\base.py", line 69, in view
    return self.dispatch(request, *args, **kwargs)
  File "D:\Users\SIMO\AppData\Local\Programs\Python\Python36\lib\site-packages\rest_framework\views.py", line 494, in dispatch
    response = self.handle_exception(exc)
  File "D:\Users\SIMO\AppData\Local\Programs\Python\Python36\lib\site-packages\rest_framework\views.py", line 454, in handle_exception
    self.raise_uncaught_exception(exc)
  File "D:\Users\SIMO\AppData\Local\Programs\Python\Python36\lib\site-packages\rest_framework\views.py", line 491, in dispatch
    response = handler(request, *args, **kwargs)
  File "D:\Users\SIMO\AppData\Local\Programs\Python\Python36\lib\site-packages\rest_framework\decorators.py", line 53, in handler
    return func(*args, **kwargs)
  File "H:\project\api_automation_test\api_test\common\common.py", line 79, in verify
    return func(reality_parameter)
  File "H:\project\api_automation_test\api_test\api\automationReport.py", line 111, in auto_lately_ten_time
    a = data[data.index(i)].append("1")
AttributeError: 'collections.OrderedDict' object has no attribute 'append'
2018-05-28 15:02:52,858,10556,django.server,ERROR,basehttp.py:124,"GET /api/report/lately_ten?project_id=1 HTTP/1.1" 500 18872
2018-05-28 15:03:09,210,6548,django.request,ERROR,exception.py:118,Internal Server Error: /api/report/lately_ten
Traceback (most recent call last):
  File "D:\Users\SIMO\AppData\Local\Programs\Python\Python36\lib\site-packages\django\core\handlers\exception.py", line 35, in inner
    response = get_response(request)
  File "D:\Users\SIMO\AppData\Local\Programs\Python\Python36\lib\site-packages\django\core\handlers\base.py", line 128, in _get_response
    response = self.process_exception_by_middleware(e, request)
  File "D:\Users\SIMO\AppData\Local\Programs\Python\Python36\lib\site-packages\django\core\handlers\base.py", line 126, in _get_response
    response = wrapped_callback(request, *callback_args, **callback_kwargs)
  File "D:\Users\SIMO\AppData\Local\Programs\Python\Python36\lib\site-packages\django\views\decorators\csrf.py", line 54, in wrapped_view
    return view_func(*args, **kwargs)
  File "D:\Users\SIMO\AppData\Local\Programs\Python\Python36\lib\site-packages\django\views\generic\base.py", line 69, in view
    return self.dispatch(request, *args, **kwargs)
  File "D:\Users\SIMO\AppData\Local\Programs\Python\Python36\lib\site-packages\rest_framework\views.py", line 494, in dispatch
    response = self.handle_exception(exc)
  File "D:\Users\SIMO\AppData\Local\Programs\Python\Python36\lib\site-packages\rest_framework\views.py", line 454, in handle_exception
    self.raise_uncaught_exception(exc)
  File "D:\Users\SIMO\AppData\Local\Programs\Python\Python36\lib\site-packages\rest_framework\views.py", line 491, in dispatch
    response = handler(request, *args, **kwargs)
  File "D:\Users\SIMO\AppData\Local\Programs\Python\Python36\lib\site-packages\rest_framework\decorators.py", line 53, in handler
    return func(*args, **kwargs)
  File "H:\project\api_automation_test\api_test\common\common.py", line 79, in verify
    return func(reality_parameter)
  File "H:\project\api_automation_test\api_test\api\automationReport.py", line 112, in auto_lately_ten_time
    a = data[data.index(i)].append("1")
AttributeError: 'collections.OrderedDict' object has no attribute 'append'
2018-05-28 15:03:09,222,6548,django.server,ERROR,basehttp.py:124,"GET /api/report/lately_ten?project_id=1 HTTP/1.1" 500 18872
2018-05-28 15:03:27,226,12440,django.request,ERROR,exception.py:118,Internal Server Error: /api/report/lately_ten
Traceback (most recent call last):
  File "D:\Users\SIMO\AppData\Local\Programs\Python\Python36\lib\site-packages\django\core\handlers\exception.py", line 35, in inner
    response = get_response(request)
  File "D:\Users\SIMO\AppData\Local\Programs\Python\Python36\lib\site-packages\django\core\handlers\base.py", line 128, in _get_response
    response = self.process_exception_by_middleware(e, request)
  File "D:\Users\SIMO\AppData\Local\Programs\Python\Python36\lib\site-packages\django\core\handlers\base.py", line 126, in _get_response
    response = wrapped_callback(request, *callback_args, **callback_kwargs)
  File "D:\Users\SIMO\AppData\Local\Programs\Python\Python36\lib\site-packages\django\views\decorators\csrf.py", line 54, in wrapped_view
    return view_func(*args, **kwargs)
  File "D:\Users\SIMO\AppData\Local\Programs\Python\Python36\lib\site-packages\django\views\generic\base.py", line 69, in view
    return self.dispatch(request, *args, **kwargs)
  File "D:\Users\SIMO\AppData\Local\Programs\Python\Python36\lib\site-packages\rest_framework\views.py", line 494, in dispatch
    response = self.handle_exception(exc)
  File "D:\Users\SIMO\AppData\Local\Programs\Python\Python36\lib\site-packages\rest_framework\views.py", line 454, in handle_exception
    self.raise_uncaught_exception(exc)
  File "D:\Users\SIMO\AppData\Local\Programs\Python\Python36\lib\site-packages\rest_framework\views.py", line 491, in dispatch
    response = handler(request, *args, **kwargs)
  File "D:\Users\SIMO\AppData\Local\Programs\Python\Python36\lib\site-packages\rest_framework\decorators.py", line 53, in handler
    return func(*args, **kwargs)
  File "H:\project\api_automation_test\api_test\common\common.py", line 79, in verify
    return func(reality_parameter)
  File "H:\project\api_automation_test\api_test\api\automationReport.py", line 112, in auto_lately_ten_time
    a = data[data.index(i)].append("1")
AttributeError: 'collections.OrderedDict' object has no attribute 'append'
2018-05-28 15:03:27,239,12440,django.server,ERROR,basehttp.py:124,"GET /api/report/lately_ten?project_id=1 HTTP/1.1" 500 18872
2018-05-28 15:18:27,783,14976,django.request,ERROR,exception.py:118,Internal Server Error: /api/report/lately_ten
Traceback (most recent call last):
  File "D:\Users\SIMO\AppData\Local\Programs\Python\Python36\lib\site-packages\django\core\handlers\exception.py", line 35, in inner
    response = get_response(request)
  File "D:\Users\SIMO\AppData\Local\Programs\Python\Python36\lib\site-packages\django\core\handlers\base.py", line 128, in _get_response
    response = self.process_exception_by_middleware(e, request)
  File "D:\Users\SIMO\AppData\Local\Programs\Python\Python36\lib\site-packages\django\core\handlers\base.py", line 126, in _get_response
    response = wrapped_callback(request, *callback_args, **callback_kwargs)
  File "D:\Users\SIMO\AppData\Local\Programs\Python\Python36\lib\site-packages\django\views\decorators\csrf.py", line 54, in wrapped_view
    return view_func(*args, **kwargs)
  File "D:\Users\SIMO\AppData\Local\Programs\Python\Python36\lib\site-packages\django\views\generic\base.py", line 69, in view
    return self.dispatch(request, *args, **kwargs)
  File "D:\Users\SIMO\AppData\Local\Programs\Python\Python36\lib\site-packages\rest_framework\views.py", line 494, in dispatch
    response = self.handle_exception(exc)
  File "D:\Users\SIMO\AppData\Local\Programs\Python\Python36\lib\site-packages\rest_framework\views.py", line 454, in handle_exception
    self.raise_uncaught_exception(exc)
  File "D:\Users\SIMO\AppData\Local\Programs\Python\Python36\lib\site-packages\rest_framework\views.py", line 491, in dispatch
    response = handler(request, *args, **kwargs)
  File "D:\Users\SIMO\AppData\Local\Programs\Python\Python36\lib\site-packages\rest_framework\decorators.py", line 53, in handler
    return func(*args, **kwargs)
  File "H:\project\api_automation_test\api_test\common\common.py", line 79, in verify
    return func(reality_parameter)
  File "H:\project\api_automation_test\api_test\api\automationReport.py", line 121, in auto_lately_ten_time
    data[data.index(i)]["fail"] = "%.4f" % fail/total
TypeError: unsupported operand type(s) for /: 'str' and 'int'
2018-05-28 15:18:27,798,14976,django.server,ERROR,basehttp.py:124,"GET /api/report/lately_ten?project_id=1 HTTP/1.1" 500 18860
2018-05-28 15:18:29,144,14976,django.request,ERROR,exception.py:118,Internal Server Error: /api/report/lately_ten
Traceback (most recent call last):
  File "D:\Users\SIMO\AppData\Local\Programs\Python\Python36\lib\site-packages\django\core\handlers\exception.py", line 35, in inner
    response = get_response(request)
  File "D:\Users\SIMO\AppData\Local\Programs\Python\Python36\lib\site-packages\django\core\handlers\base.py", line 128, in _get_response
    response = self.process_exception_by_middleware(e, request)
  File "D:\Users\SIMO\AppData\Local\Programs\Python\Python36\lib\site-packages\django\core\handlers\base.py", line 126, in _get_response
    response = wrapped_callback(request, *callback_args, **callback_kwargs)
  File "D:\Users\SIMO\AppData\Local\Programs\Python\Python36\lib\site-packages\django\views\decorators\csrf.py", line 54, in wrapped_view
    return view_func(*args, **kwargs)
  File "D:\Users\SIMO\AppData\Local\Programs\Python\Python36\lib\site-packages\django\views\generic\base.py", line 69, in view
    return self.dispatch(request, *args, **kwargs)
  File "D:\Users\SIMO\AppData\Local\Programs\Python\Python36\lib\site-packages\rest_framework\views.py", line 494, in dispatch
    response = self.handle_exception(exc)
  File "D:\Users\SIMO\AppData\Local\Programs\Python\Python36\lib\site-packages\rest_framework\views.py", line 454, in handle_exception
    self.raise_uncaught_exception(exc)
  File "D:\Users\SIMO\AppData\Local\Programs\Python\Python36\lib\site-packages\rest_framework\views.py", line 491, in dispatch
    response = handler(request, *args, **kwargs)
  File "D:\Users\SIMO\AppData\Local\Programs\Python\Python36\lib\site-packages\rest_framework\decorators.py", line 53, in handler
    return func(*args, **kwargs)
  File "H:\project\api_automation_test\api_test\common\common.py", line 79, in verify
    return func(reality_parameter)
  File "H:\project\api_automation_test\api_test\api\automationReport.py", line 121, in auto_lately_ten_time
    data[data.index(i)]["fail"] = "%.4f" % fail/total
TypeError: unsupported operand type(s) for /: 'str' and 'int'
2018-05-28 15:18:29,154,14976,django.server,ERROR,basehttp.py:124,"GET /api/report/lately_ten?project_id=1 HTTP/1.1" 500 18861
2018-05-28 18:35:45,372,13996,django.request,ERROR,exception.py:118,Internal Server Error: /
Traceback (most recent call last):
  File "D:\Users\SIMO\AppData\Local\Programs\Python\Python36\lib\site-packages\django\core\handlers\exception.py", line 35, in inner
    response = get_response(request)
  File "D:\Users\SIMO\AppData\Local\Programs\Python\Python36\lib\site-packages\django\core\handlers\base.py", line 158, in _get_response
    response = self.process_exception_by_middleware(e, request)
  File "D:\Users\SIMO\AppData\Local\Programs\Python\Python36\lib\site-packages\django\core\handlers\base.py", line 156, in _get_response
    response = response.render()
  File "D:\Users\SIMO\AppData\Local\Programs\Python\Python36\lib\site-packages\django\template\response.py", line 106, in render
    self.content = self.rendered_content
  File "D:\Users\SIMO\AppData\Local\Programs\Python\Python36\lib\site-packages\django\template\response.py", line 81, in rendered_content
    template = self.resolve_template(self.template_name)
  File "D:\Users\SIMO\AppData\Local\Programs\Python\Python36\lib\site-packages\django\template\response.py", line 63, in resolve_template
    return select_template(template, using=self.using)
  File "D:\Users\SIMO\AppData\Local\Programs\Python\Python36\lib\site-packages\django\template\loader.py", line 47, in select_template
    raise TemplateDoesNotExist(', '.join(template_name_list), chain=chain)
django.template.exceptions.TemplateDoesNotExist: index.html
2018-05-28 18:35:45,513,13996,django.server,ERROR,basehttp.py:124,"GET / HTTP/1.1" 500 86712
2018-05-28 18:35:46,831,13996,django.request,ERROR,exception.py:118,Internal Server Error: /
Traceback (most recent call last):
  File "D:\Users\SIMO\AppData\Local\Programs\Python\Python36\lib\site-packages\django\core\handlers\exception.py", line 35, in inner
    response = get_response(request)
  File "D:\Users\SIMO\AppData\Local\Programs\Python\Python36\lib\site-packages\django\core\handlers\base.py", line 158, in _get_response
    response = self.process_exception_by_middleware(e, request)
  File "D:\Users\SIMO\AppData\Local\Programs\Python\Python36\lib\site-packages\django\core\handlers\base.py", line 156, in _get_response
    response = response.render()
  File "D:\Users\SIMO\AppData\Local\Programs\Python\Python36\lib\site-packages\django\template\response.py", line 106, in render
    self.content = self.rendered_content
  File "D:\Users\SIMO\AppData\Local\Programs\Python\Python36\lib\site-packages\django\template\response.py", line 81, in rendered_content
    template = self.resolve_template(self.template_name)
  File "D:\Users\SIMO\AppData\Local\Programs\Python\Python36\lib\site-packages\django\template\response.py", line 63, in resolve_template
    return select_template(template, using=self.using)
  File "D:\Users\SIMO\AppData\Local\Programs\Python\Python36\lib\site-packages\django\template\loader.py", line 47, in select_template
    raise TemplateDoesNotExist(', '.join(template_name_list), chain=chain)
django.template.exceptions.TemplateDoesNotExist: index.html
2018-05-28 18:35:46,891,13996,django.server,ERROR,basehttp.py:124,"GET / HTTP/1.1" 500 86713
2018-05-28 18:35:47,535,13996,django.request,ERROR,exception.py:118,Internal Server Error: /
Traceback (most recent call last):
  File "D:\Users\SIMO\AppData\Local\Programs\Python\Python36\lib\site-packages\django\core\handlers\exception.py", line 35, in inner
    response = get_response(request)
  File "D:\Users\SIMO\AppData\Local\Programs\Python\Python36\lib\site-packages\django\core\handlers\base.py", line 158, in _get_response
    response = self.process_exception_by_middleware(e, request)
  File "D:\Users\SIMO\AppData\Local\Programs\Python\Python36\lib\site-packages\django\core\handlers\base.py", line 156, in _get_response
    response = response.render()
  File "D:\Users\SIMO\AppData\Local\Programs\Python\Python36\lib\site-packages\django\template\response.py", line 106, in render
    self.content = self.rendered_content
  File "D:\Users\SIMO\AppData\Local\Programs\Python\Python36\lib\site-packages\django\template\response.py", line 81, in rendered_content
    template = self.resolve_template(self.template_name)
  File "D:\Users\SIMO\AppData\Local\Programs\Python\Python36\lib\site-packages\django\template\response.py", line 63, in resolve_template
    return select_template(template, using=self.using)
  File "D:\Users\SIMO\AppData\Local\Programs\Python\Python36\lib\site-packages\django\template\loader.py", line 47, in select_template
    raise TemplateDoesNotExist(', '.join(template_name_list), chain=chain)
django.template.exceptions.TemplateDoesNotExist: index.html
2018-05-28 18:35:47,597,13996,django.server,ERROR,basehttp.py:124,"GET / HTTP/1.1" 500 86713
2018-05-29 18:00:01,792,9044,django.request,ERROR,exception.py:118,Internal Server Error: /api/robot/logout_wx
Traceback (most recent call last):
  File "D:\Users\SIMO\AppData\Local\Programs\Python\Python36\lib\site-packages\django\core\handlers\exception.py", line 35, in inner
    response = get_response(request)
  File "D:\Users\SIMO\AppData\Local\Programs\Python\Python36\lib\site-packages\django\core\handlers\base.py", line 128, in _get_response
    response = self.process_exception_by_middleware(e, request)
  File "D:\Users\SIMO\AppData\Local\Programs\Python\Python36\lib\site-packages\django\core\handlers\base.py", line 126, in _get_response
    response = wrapped_callback(request, *callback_args, **callback_kwargs)
  File "D:\Users\SIMO\AppData\Local\Programs\Python\Python36\lib\site-packages\django\views\decorators\csrf.py", line 54, in wrapped_view
    return view_func(*args, **kwargs)
  File "D:\Users\SIMO\AppData\Local\Programs\Python\Python36\lib\site-packages\django\views\generic\base.py", line 69, in view
    return self.dispatch(request, *args, **kwargs)
  File "D:\Users\SIMO\AppData\Local\Programs\Python\Python36\lib\site-packages\rest_framework\views.py", line 494, in dispatch
    response = self.handle_exception(exc)
  File "D:\Users\SIMO\AppData\Local\Programs\Python\Python36\lib\site-packages\rest_framework\views.py", line 454, in handle_exception
    self.raise_uncaught_exception(exc)
  File "D:\Users\SIMO\AppData\Local\Programs\Python\Python36\lib\site-packages\rest_framework\views.py", line 491, in dispatch
    response = handler(request, *args, **kwargs)
  File "D:\Users\SIMO\AppData\Local\Programs\Python\Python36\lib\site-packages\rest_framework\decorators.py", line 53, in handler
    return func(*args, **kwargs)
  File "H:\project\api_automation_test\api_test\common\common.py", line 79, in verify
    return func(reality_parameter)
  File "H:\project\api_automation_test\api_test\api\robot.py", line 49, in logout_wx_robot
    result = logout_wechat()
  File "H:\project\api_automation_test\api_test\common\logOutWx.py", line 9, in logout_wechat
    itchat.auto_login(hotReload=True)
  File "D:\Users\SIMO\AppData\Local\Programs\Python\Python36\lib\site-packages\itchat\components\register.py", line 29, in auto_login
    loginCallback=loginCallback, exitCallback=exitCallback):
  File "D:\Users\SIMO\AppData\Local\Programs\Python\Python36\lib\site-packages\itchat\components\hotreload.py", line 54, in load_login_status
    self.loginInfo['User'] = templates.User(self.loginInfo['User'])
KeyError: 'User'
2018-05-29 18:00:01,935,9044,django.server,ERROR,basehttp.py:124,"GET /api/robot/logout_wx HTTP/1.1" 500 19346
2018-05-29 18:00:05,281,9044,django.request,ERROR,exception.py:118,Internal Server Error: /api/robot/logout_wx
Traceback (most recent call last):
  File "D:\Users\SIMO\AppData\Local\Programs\Python\Python36\lib\site-packages\django\core\handlers\exception.py", line 35, in inner
    response = get_response(request)
  File "D:\Users\SIMO\AppData\Local\Programs\Python\Python36\lib\site-packages\django\core\handlers\base.py", line 128, in _get_response
    response = self.process_exception_by_middleware(e, request)
  File "D:\Users\SIMO\AppData\Local\Programs\Python\Python36\lib\site-packages\django\core\handlers\base.py", line 126, in _get_response
    response = wrapped_callback(request, *callback_args, **callback_kwargs)
  File "D:\Users\SIMO\AppData\Local\Programs\Python\Python36\lib\site-packages\django\views\decorators\csrf.py", line 54, in wrapped_view
    return view_func(*args, **kwargs)
  File "D:\Users\SIMO\AppData\Local\Programs\Python\Python36\lib\site-packages\django\views\generic\base.py", line 69, in view
    return self.dispatch(request, *args, **kwargs)
  File "D:\Users\SIMO\AppData\Local\Programs\Python\Python36\lib\site-packages\rest_framework\views.py", line 494, in dispatch
    response = self.handle_exception(exc)
  File "D:\Users\SIMO\AppData\Local\Programs\Python\Python36\lib\site-packages\rest_framework\views.py", line 454, in handle_exception
    self.raise_uncaught_exception(exc)
  File "D:\Users\SIMO\AppData\Local\Programs\Python\Python36\lib\site-packages\rest_framework\views.py", line 491, in dispatch
    response = handler(request, *args, **kwargs)
  File "D:\Users\SIMO\AppData\Local\Programs\Python\Python36\lib\site-packages\rest_framework\decorators.py", line 53, in handler
    return func(*args, **kwargs)
  File "H:\project\api_automation_test\api_test\common\common.py", line 79, in verify
    return func(reality_parameter)
  File "H:\project\api_automation_test\api_test\api\robot.py", line 49, in logout_wx_robot
    result = logout_wechat()
  File "H:\project\api_automation_test\api_test\common\logOutWx.py", line 9, in logout_wechat
    itchat.auto_login(hotReload=True)
  File "D:\Users\SIMO\AppData\Local\Programs\Python\Python36\lib\site-packages\itchat\components\register.py", line 29, in auto_login
    loginCallback=loginCallback, exitCallback=exitCallback):
  File "D:\Users\SIMO\AppData\Local\Programs\Python\Python36\lib\site-packages\itchat\components\hotreload.py", line 54, in load_login_status
    self.loginInfo['User'] = templates.User(self.loginInfo['User'])
KeyError: 'User'
2018-05-29 18:00:05,291,9044,django.server,ERROR,basehttp.py:124,"GET /api/robot/logout_wx HTTP/1.1" 500 19346
