2018-05-25 16:17:34,251,5960,django.request,ERROR,exception.py:118,Internal Server Error: /api/automation/test_time
Traceback (most recent call last):
  File "D:\Users\SIMO\AppData\Local\Programs\Python\Python36\lib\site-packages\django\core\handlers\exception.py", line 35, in inner
    response = get_response(request)
  File "D:\Users\SIMO\AppData\Local\Programs\Python\Python36\lib\site-packages\django\core\handlers\base.py", line 158, in _get_response
    response = self.process_exception_by_middleware(e, request)
  File "D:\Users\SIMO\AppData\Local\Programs\Python\Python36\lib\site-packages\django\core\handlers\base.py", line 156, in _get_response
    response = response.render()
  File "D:\Users\SIMO\AppData\Local\Programs\Python\Python36\lib\site-packages\django\template\response.py", line 106, in render
    self.content = self.rendered_content
  File "D:\Users\SIMO\AppData\Local\Programs\Python\Python36\lib\site-packages\rest_framework\response.py", line 72, in rendered_content
    ret = renderer.render(self.data, accepted_media_type, context)
  File "D:\Users\SIMO\AppData\Local\Programs\Python\Python36\lib\site-packages\rest_framework\renderers.py", line 105, in render
    allow_nan=not self.strict, separators=separators
  File "D:\Users\SIMO\AppData\Local\Programs\Python\Python36\lib\site-packages\rest_framework\utils\json.py", line 28, in dumps
    return json.dumps(*args, **kwargs)
  File "D:\Users\SIMO\AppData\Local\Programs\Python\Python36\lib\json\__init__.py", line 238, in dumps
    **kw).encode(obj)
  File "D:\Users\SIMO\AppData\Local\Programs\Python\Python36\lib\json\encoder.py", line 199, in encode
    chunks = self.iterencode(o, _one_shot=True)
  File "D:\Users\SIMO\AppData\Local\Programs\Python\Python36\lib\json\encoder.py", line 257, in iterencode
    return _iterencode(o, 0)
  File "D:\Users\SIMO\AppData\Local\Programs\Python\Python36\lib\site-packages\rest_framework\utils\encoders.py", line 68, in default
    return super(JSONEncoder, self).default(obj)
  File "D:\Users\SIMO\AppData\Local\Programs\Python\Python36\lib\json\encoder.py", line 180, in default
    o.__class__.__name__)
TypeError: Object of type 'ListSerializer' is not JSON serializable
2018-05-25 16:17:34,387,5960,django.server,ERROR,basehttp.py:124,"GET /api/automation/test_time?project_id=1 HTTP/1.1" 500 117915
2018-05-25 16:25:05,295,2736,django.request,ERROR,exception.py:118,Internal Server Error: /api/automation/test_time
Traceback (most recent call last):
  File "D:\Users\SIMO\AppData\Local\Programs\Python\Python36\lib\site-packages\django\core\handlers\exception.py", line 35, in inner
    response = get_response(request)
  File "D:\Users\SIMO\AppData\Local\Programs\Python\Python36\lib\site-packages\django\core\handlers\base.py", line 128, in _get_response
    response = self.process_exception_by_middleware(e, request)
  File "D:\Users\SIMO\AppData\Local\Programs\Python\Python36\lib\site-packages\django\core\handlers\base.py", line 126, in _get_response
    response = wrapped_callback(request, *callback_args, **callback_kwargs)
  File "D:\Users\SIMO\AppData\Local\Programs\Python\Python36\lib\site-packages\django\views\decorators\csrf.py", line 54, in wrapped_view
    return view_func(*args, **kwargs)
  File "D:\Users\SIMO\AppData\Local\Programs\Python\Python36\lib\site-packages\django\views\generic\base.py", line 69, in view
    return self.dispatch(request, *args, **kwargs)
  File "D:\Users\SIMO\AppData\Local\Programs\Python\Python36\lib\site-packages\rest_framework\views.py", line 494, in dispatch
    response = self.handle_exception(exc)
  File "D:\Users\SIMO\AppData\Local\Programs\Python\Python36\lib\site-packages\rest_framework\views.py", line 454, in handle_exception
    self.raise_uncaught_exception(exc)
  File "D:\Users\SIMO\AppData\Local\Programs\Python\Python36\lib\site-packages\rest_framework\views.py", line 491, in dispatch
    response = handler(request, *args, **kwargs)
  File "D:\Users\SIMO\AppData\Local\Programs\Python\Python36\lib\site-packages\rest_framework\decorators.py", line 53, in handler
    return func(*args, **kwargs)
  File "H:\project\api_automation_test\api_test\common\common.py", line 79, in verify
    return func(reality_parameter)
  File "H:\project\api_automation_test\api_test\api\automationCase.py", line 1116, in test_time
    serialize = serialize[0, 10]
  File "D:\Users\SIMO\AppData\Local\Programs\Python\Python36\lib\site-packages\django\db\models\query.py", line 282, in __getitem__
    raise TypeError
TypeError
2018-05-25 16:25:05,409,2736,django.server,ERROR,basehttp.py:124,"GET /api/automation/test_time?project_id=1 HTTP/1.1" 500 18902
2018-05-25 16:29:02,931,5656,django.request,ERROR,exception.py:118,Internal Server Error: /api/automation/test_time
Traceback (most recent call last):
  File "D:\Users\SIMO\AppData\Local\Programs\Python\Python36\lib\site-packages\django\core\handlers\exception.py", line 35, in inner
    response = get_response(request)
  File "D:\Users\SIMO\AppData\Local\Programs\Python\Python36\lib\site-packages\django\core\handlers\base.py", line 128, in _get_response
    response = self.process_exception_by_middleware(e, request)
  File "D:\Users\SIMO\AppData\Local\Programs\Python\Python36\lib\site-packages\django\core\handlers\base.py", line 126, in _get_response
    response = wrapped_callback(request, *callback_args, **callback_kwargs)
  File "D:\Users\SIMO\AppData\Local\Programs\Python\Python36\lib\site-packages\django\views\decorators\csrf.py", line 54, in wrapped_view
    return view_func(*args, **kwargs)
  File "D:\Users\SIMO\AppData\Local\Programs\Python\Python36\lib\site-packages\django\views\generic\base.py", line 69, in view
    return self.dispatch(request, *args, **kwargs)
  File "D:\Users\SIMO\AppData\Local\Programs\Python\Python36\lib\site-packages\rest_framework\views.py", line 494, in dispatch
    response = self.handle_exception(exc)
  File "D:\Users\SIMO\AppData\Local\Programs\Python\Python36\lib\site-packages\rest_framework\views.py", line 454, in handle_exception
    self.raise_uncaught_exception(exc)
  File "D:\Users\SIMO\AppData\Local\Programs\Python\Python36\lib\site-packages\rest_framework\views.py", line 491, in dispatch
    response = handler(request, *args, **kwargs)
  File "D:\Users\SIMO\AppData\Local\Programs\Python\Python36\lib\site-packages\rest_framework\decorators.py", line 53, in handler
    return func(*args, **kwargs)
  File "H:\project\api_automation_test\api_test\common\common.py", line 79, in verify
    return func(reality_parameter)
  File "H:\project\api_automation_test\api_test\api\automationCase.py", line 1114, in test_time
    print(AutomationTaskRunTime.objects.filter(project=project_id).order_by("-startTime")[0,10])
  File "D:\Users\SIMO\AppData\Local\Programs\Python\Python36\lib\site-packages\django\db\models\query.py", line 282, in __getitem__
    raise TypeError
TypeError
2018-05-25 16:29:02,947,5656,django.server,ERROR,basehttp.py:124,"GET /api/automation/test_time?project_id=1 HTTP/1.1" 500 18966
2018-05-25 16:34:51,802,7324,django.request,ERROR,exception.py:118,Internal Server Error: /api/automation/test_time
Traceback (most recent call last):
  File "D:\Users\SIMO\AppData\Local\Programs\Python\Python36\lib\site-packages\django\db\backends\utils.py", line 85, in _execute
    return self.cursor.execute(sql, params)
  File "D:\Users\SIMO\AppData\Local\Programs\Python\Python36\lib\site-packages\django\db\backends\mysql\base.py", line 71, in execute
    return self.cursor.execute(query, args)
  File "D:\Users\SIMO\AppData\Local\Programs\Python\Python36\lib\site-packages\MySQLdb\cursors.py", line 250, in execute
    self.errorhandler(self, exc, value)
  File "D:\Users\SIMO\AppData\Local\Programs\Python\Python36\lib\site-packages\MySQLdb\connections.py", line 50, in defaulterrorhandler
    raise errorvalue
  File "D:\Users\SIMO\AppData\Local\Programs\Python\Python36\lib\site-packages\MySQLdb\cursors.py", line 247, in execute
    res = self._query(query)
  File "D:\Users\SIMO\AppData\Local\Programs\Python\Python36\lib\site-packages\MySQLdb\cursors.py", line 411, in _query
    rowcount = self._do_query(q)
  File "D:\Users\SIMO\AppData\Local\Programs\Python\Python36\lib\site-packages\MySQLdb\cursors.py", line 374, in _do_query
    db.query(q)
  File "D:\Users\SIMO\AppData\Local\Programs\Python\Python36\lib\site-packages\MySQLdb\connections.py", line 277, in query
    _mysql.connection.query(self, query)
_mysql_exceptions.OperationalError: (1054, "Unknown column 'api_test_automationtaskruntime.elapsedTime' in 'field list'")

The above exception was the direct cause of the following exception:

Traceback (most recent call last):
  File "D:\Users\SIMO\AppData\Local\Programs\Python\Python36\lib\site-packages\django\core\handlers\exception.py", line 35, in inner
    response = get_response(request)
  File "D:\Users\SIMO\AppData\Local\Programs\Python\Python36\lib\site-packages\django\core\handlers\base.py", line 128, in _get_response
    response = self.process_exception_by_middleware(e, request)
  File "D:\Users\SIMO\AppData\Local\Programs\Python\Python36\lib\site-packages\django\core\handlers\base.py", line 126, in _get_response
    response = wrapped_callback(request, *callback_args, **callback_kwargs)
  File "D:\Users\SIMO\AppData\Local\Programs\Python\Python36\lib\site-packages\django\views\decorators\csrf.py", line 54, in wrapped_view
    return view_func(*args, **kwargs)
  File "D:\Users\SIMO\AppData\Local\Programs\Python\Python36\lib\site-packages\django\views\generic\base.py", line 69, in view
    return self.dispatch(request, *args, **kwargs)
  File "D:\Users\SIMO\AppData\Local\Programs\Python\Python36\lib\site-packages\rest_framework\views.py", line 494, in dispatch
    response = self.handle_exception(exc)
  File "D:\Users\SIMO\AppData\Local\Programs\Python\Python36\lib\site-packages\rest_framework\views.py", line 454, in handle_exception
    self.raise_uncaught_exception(exc)
  File "D:\Users\SIMO\AppData\Local\Programs\Python\Python36\lib\site-packages\rest_framework\views.py", line 491, in dispatch
    response = handler(request, *args, **kwargs)
  File "D:\Users\SIMO\AppData\Local\Programs\Python\Python36\lib\site-packages\rest_framework\decorators.py", line 53, in handler
    return func(*args, **kwargs)
  File "H:\project\api_automation_test\api_test\common\common.py", line 79, in verify
    return func(reality_parameter)
  File "H:\project\api_automation_test\api_test\api\automationCase.py", line 1114, in test_time
    print(AutomationTaskRunTime.objects.filter(project=project_id).order_by("-startTime")[:10])
  File "D:\Users\SIMO\AppData\Local\Programs\Python\Python36\lib\site-packages\django\db\models\query.py", line 248, in __repr__
    data = list(self[:REPR_OUTPUT_SIZE + 1])
  File "D:\Users\SIMO\AppData\Local\Programs\Python\Python36\lib\site-packages\django\db\models\query.py", line 272, in __iter__
    self._fetch_all()
  File "D:\Users\SIMO\AppData\Local\Programs\Python\Python36\lib\site-packages\django\db\models\query.py", line 1179, in _fetch_all
    self._result_cache = list(self._iterable_class(self))
  File "D:\Users\SIMO\AppData\Local\Programs\Python\Python36\lib\site-packages\django\db\models\query.py", line 53, in __iter__
    results = compiler.execute_sql(chunked_fetch=self.chunked_fetch, chunk_size=self.chunk_size)
  File "D:\Users\SIMO\AppData\Local\Programs\Python\Python36\lib\site-packages\django\db\models\sql\compiler.py", line 1064, in execute_sql
    cursor.execute(sql, params)
  File "D:\Users\SIMO\AppData\Local\Programs\Python\Python36\lib\site-packages\django\db\backends\utils.py", line 100, in execute
    return super().execute(sql, params)
  File "D:\Users\SIMO\AppData\Local\Programs\Python\Python36\lib\site-packages\django\db\backends\utils.py", line 68, in execute
    return self._execute_with_wrappers(sql, params, many=False, executor=self._execute)
  File "D:\Users\SIMO\AppData\Local\Programs\Python\Python36\lib\site-packages\django\db\backends\utils.py", line 77, in _execute_with_wrappers
    return executor(sql, params, many, context)
  File "D:\Users\SIMO\AppData\Local\Programs\Python\Python36\lib\site-packages\django\db\backends\utils.py", line 85, in _execute
    return self.cursor.execute(sql, params)
  File "D:\Users\SIMO\AppData\Local\Programs\Python\Python36\lib\site-packages\django\db\utils.py", line 89, in __exit__
    raise dj_exc_value.with_traceback(traceback) from exc_value
  File "D:\Users\SIMO\AppData\Local\Programs\Python\Python36\lib\site-packages\django\db\backends\utils.py", line 85, in _execute
    return self.cursor.execute(sql, params)
  File "D:\Users\SIMO\AppData\Local\Programs\Python\Python36\lib\site-packages\django\db\backends\mysql\base.py", line 71, in execute
    return self.cursor.execute(query, args)
  File "D:\Users\SIMO\AppData\Local\Programs\Python\Python36\lib\site-packages\MySQLdb\cursors.py", line 250, in execute
    self.errorhandler(self, exc, value)
  File "D:\Users\SIMO\AppData\Local\Programs\Python\Python36\lib\site-packages\MySQLdb\connections.py", line 50, in defaulterrorhandler
    raise errorvalue
  File "D:\Users\SIMO\AppData\Local\Programs\Python\Python36\lib\site-packages\MySQLdb\cursors.py", line 247, in execute
    res = self._query(query)
  File "D:\Users\SIMO\AppData\Local\Programs\Python\Python36\lib\site-packages\MySQLdb\cursors.py", line 411, in _query
    rowcount = self._do_query(q)
  File "D:\Users\SIMO\AppData\Local\Programs\Python\Python36\lib\site-packages\MySQLdb\cursors.py", line 374, in _do_query
    db.query(q)
  File "D:\Users\SIMO\AppData\Local\Programs\Python\Python36\lib\site-packages\MySQLdb\connections.py", line 277, in query
    _mysql.connection.query(self, query)
django.db.utils.OperationalError: (1054, "Unknown column 'api_test_automationtaskruntime.elapsedTime' in 'field list'")
2018-05-25 16:34:51,876,7324,django.server,ERROR,basehttp.py:124,"GET /api/automation/test_time?project_id=1 HTTP/1.1" 500 23592
