2018-02-18 14:27:20,595,5744,django.request,ERROR,exception.py:118,Internal Server Error: /
Traceback (most recent call last):
  File "D:\Program Files (x86)\Python36-32\lib\site-packages\django\core\handlers\exception.py", line 35, in inner
    response = get_response(request)
  File "D:\Program Files (x86)\Python36-32\lib\site-packages\django\core\handlers\base.py", line 158, in _get_response
    response = self.process_exception_by_middleware(e, request)
  File "D:\Program Files (x86)\Python36-32\lib\site-packages\django\core\handlers\base.py", line 156, in _get_response
    response = response.render()
  File "D:\Program Files (x86)\Python36-32\lib\site-packages\django\template\response.py", line 106, in render
    self.content = self.rendered_content
  File "D:\Program Files (x86)\Python36-32\lib\site-packages\django\template\response.py", line 81, in rendered_content
    template = self.resolve_template(self.template_name)
  File "D:\Program Files (x86)\Python36-32\lib\site-packages\django\template\response.py", line 63, in resolve_template
    return select_template(template, using=self.using)
  File "D:\Program Files (x86)\Python36-32\lib\site-packages\django\template\loader.py", line 47, in select_template
    raise TemplateDoesNotExist(', '.join(template_name_list), chain=chain)
django.template.exceptions.TemplateDoesNotExist: index.html
2018-02-18 14:27:20,941,5744,django.server,ERROR,basehttp.py:124,"GET / HTTP/1.1" 500 82910
2018-03-02 17:54:04,445,18936,django.security.DisallowedHost,ERROR,exception.py:74,Invalid HTTP_HOST header: '192.168.89.198:8001'. You may need to add '192.168.89.198' to ALLOWED_HOSTS.
2018-03-02 17:55:32,028,18936,django.security.DisallowedHost,ERROR,exception.py:74,Invalid HTTP_HOST header: '192.168.89.198:8001'. You may need to add '192.168.89.198' to ALLOWED_HOSTS.
2018-03-02 17:55:39,244,18936,django.security.DisallowedHost,ERROR,exception.py:74,Invalid HTTP_HOST header: '192.168.89.198:8001'. You may need to add '192.168.89.198' to ALLOWED_HOSTS.
2018-03-02 17:55:46,662,18936,django.security.DisallowedHost,ERROR,exception.py:74,Invalid HTTP_HOST header: '192.168.89.198:8001'. You may need to add '192.168.89.198' to ALLOWED_HOSTS.
2018-03-02 18:27:39,202,8244,django.security.DisallowedHost,ERROR,exception.py:74,Invalid HTTP_HOST header: '127.0.0.1:8001'. You may need to add '127.0.0.1' to ALLOWED_HOSTS.
2018-03-02 18:27:39,338,8244,django.security.DisallowedHost,ERROR,exception.py:74,Invalid HTTP_HOST header: '127.0.0.1:8001'. You may need to add '127.0.0.1' to ALLOWED_HOSTS.
2018-03-02 20:38:22,716,556,django.security.DisallowedHost,ERROR,exception.py:74,Invalid HTTP_HOST header: '127.0.0.1:8001'. You may need to add '127.0.0.1' to ALLOWED_HOSTS.
2018-03-02 20:38:41,721,556,django.security.DisallowedHost,ERROR,exception.py:74,Invalid HTTP_HOST header: '127.0.0.1:8001'. You may need to add '127.0.0.1' to ALLOWED_HOSTS.
2018-03-02 20:39:44,384,556,django.security.DisallowedHost,ERROR,exception.py:74,Invalid HTTP_HOST header: '127.0.0.1:8001'. You may need to add '127.0.0.1' to ALLOWED_HOSTS.
2018-03-02 20:40:58,749,556,django.security.DisallowedHost,ERROR,exception.py:74,Invalid HTTP_HOST header: '127.0.0.1:8001'. You may need to add '127.0.0.1' to ALLOWED_HOSTS.
2018-03-02 20:43:48,237,556,django.security.DisallowedHost,ERROR,exception.py:74,Invalid HTTP_HOST header: '127.0.0.1:8001'. You may need to add '127.0.0.1' to ALLOWED_HOSTS.
2018-03-02 20:43:54,363,556,django.security.DisallowedHost,ERROR,exception.py:74,Invalid HTTP_HOST header: '127.0.0.1:8001'. You may need to add '127.0.0.1' to ALLOWED_HOSTS.
2018-03-02 20:45:21,702,556,django.security.DisallowedHost,ERROR,exception.py:74,Invalid HTTP_HOST header: '127.0.0.1:8001'. You may need to add '127.0.0.1' to ALLOWED_HOSTS.
2018-03-02 20:40:18,497,8100,django.request,ERROR,exception.py:118,Internal Server Error: /api/member/project_member
Traceback (most recent call last):
  File "D:\Program Files (x86)\Python36-32\lib\site-packages\django\core\handlers\exception.py", line 35, in inner
    response = get_response(request)
  File "D:\Program Files (x86)\Python36-32\lib\site-packages\django\core\handlers\base.py", line 128, in _get_response
    response = self.process_exception_by_middleware(e, request)
  File "D:\Program Files (x86)\Python36-32\lib\site-packages\django\core\handlers\base.py", line 126, in _get_response
    response = wrapped_callback(request, *callback_args, **callback_kwargs)
  File "D:\Program Files (x86)\Python36-32\lib\site-packages\django\views\decorators\csrf.py", line 54, in wrapped_view
    return view_func(*args, **kwargs)
  File "D:\Program Files (x86)\Python36-32\lib\site-packages\django\views\generic\base.py", line 69, in view
    return self.dispatch(request, *args, **kwargs)
  File "D:\Program Files (x86)\Python36-32\lib\site-packages\rest_framework\views.py", line 494, in dispatch
    response = self.handle_exception(exc)
  File "D:\Program Files (x86)\Python36-32\lib\site-packages\rest_framework\views.py", line 454, in handle_exception
    self.raise_uncaught_exception(exc)
  File "D:\Program Files (x86)\Python36-32\lib\site-packages\rest_framework\views.py", line 491, in dispatch
    response = handler(request, *args, **kwargs)
  File "D:\Program Files (x86)\Python36-32\lib\site-packages\rest_framework\decorators.py", line 53, in handler
    return func(*args, **kwargs)
  File "d:\project\api_automation_test\api_test\common\common.py", line 66, in verify
    return func(reality_parameter)
  File "d:\project\api_automation_test\api_test\api\member.py", line 33, in project_member
    paginator = Paginator(obi, page_size)  # paginator对象
NameError: name 'Paginator' is not defined
2018-03-02 20:40:18,637,8100,django.server,ERROR,basehttp.py:124,"GET /api/member/project_member?project_id=1 HTTP/1.1" 500 17399
2018-03-02 20:40:19,520,8100,django.request,ERROR,exception.py:118,Internal Server Error: /api/member/project_member
Traceback (most recent call last):
  File "D:\Program Files (x86)\Python36-32\lib\site-packages\django\core\handlers\exception.py", line 35, in inner
    response = get_response(request)
  File "D:\Program Files (x86)\Python36-32\lib\site-packages\django\core\handlers\base.py", line 128, in _get_response
    response = self.process_exception_by_middleware(e, request)
  File "D:\Program Files (x86)\Python36-32\lib\site-packages\django\core\handlers\base.py", line 126, in _get_response
    response = wrapped_callback(request, *callback_args, **callback_kwargs)
  File "D:\Program Files (x86)\Python36-32\lib\site-packages\django\views\decorators\csrf.py", line 54, in wrapped_view
    return view_func(*args, **kwargs)
  File "D:\Program Files (x86)\Python36-32\lib\site-packages\django\views\generic\base.py", line 69, in view
    return self.dispatch(request, *args, **kwargs)
  File "D:\Program Files (x86)\Python36-32\lib\site-packages\rest_framework\views.py", line 494, in dispatch
    response = self.handle_exception(exc)
  File "D:\Program Files (x86)\Python36-32\lib\site-packages\rest_framework\views.py", line 454, in handle_exception
    self.raise_uncaught_exception(exc)
  File "D:\Program Files (x86)\Python36-32\lib\site-packages\rest_framework\views.py", line 491, in dispatch
    response = handler(request, *args, **kwargs)
  File "D:\Program Files (x86)\Python36-32\lib\site-packages\rest_framework\decorators.py", line 53, in handler
    return func(*args, **kwargs)
  File "d:\project\api_automation_test\api_test\common\common.py", line 66, in verify
    return func(reality_parameter)
  File "d:\project\api_automation_test\api_test\api\member.py", line 33, in project_member
    paginator = Paginator(obi, page_size)  # paginator对象
NameError: name 'Paginator' is not defined
2018-03-02 20:40:19,587,8100,django.server,ERROR,basehttp.py:124,"GET /api/member/project_member?project_id=1 HTTP/1.1" 500 17399
2018-03-03 09:32:50,490,5088,django.request,ERROR,exception.py:118,Internal Server Error: /api/user/login
Traceback (most recent call last):
  File "D:\Program Files (x86)\Python36-32\lib\site-packages\rest_framework\fields.py", line 441, in get_attribute
    return get_attribute(instance, self.source_attrs)
  File "D:\Program Files (x86)\Python36-32\lib\site-packages\rest_framework\fields.py", line 100, in get_attribute
    instance = getattr(instance, attr)
AttributeError: 'User' object has no attribute 'phone'

During handling of the above exception, another exception occurred:

Traceback (most recent call last):
  File "D:\Program Files (x86)\Python36-32\lib\site-packages\django\core\handlers\exception.py", line 35, in inner
    response = get_response(request)
  File "D:\Program Files (x86)\Python36-32\lib\site-packages\django\core\handlers\base.py", line 128, in _get_response
    response = self.process_exception_by_middleware(e, request)
  File "D:\Program Files (x86)\Python36-32\lib\site-packages\django\core\handlers\base.py", line 126, in _get_response
    response = wrapped_callback(request, *callback_args, **callback_kwargs)
  File "D:\Program Files (x86)\Python36-32\lib\site-packages\django\views\decorators\csrf.py", line 54, in wrapped_view
    return view_func(*args, **kwargs)
  File "D:\Program Files (x86)\Python36-32\lib\site-packages\django\views\generic\base.py", line 69, in view
    return self.dispatch(request, *args, **kwargs)
  File "D:\Program Files (x86)\Python36-32\lib\site-packages\rest_framework\views.py", line 494, in dispatch
    response = self.handle_exception(exc)
  File "D:\Program Files (x86)\Python36-32\lib\site-packages\rest_framework\views.py", line 454, in handle_exception
    self.raise_uncaught_exception(exc)
  File "D:\Program Files (x86)\Python36-32\lib\site-packages\rest_framework\views.py", line 491, in dispatch
    response = handler(request, *args, **kwargs)
  File "D:\Program Files (x86)\Python36-32\lib\site-packages\rest_framework\authtoken\views.py", line 24, in post
    data = TokenSerializer(Token.objects.get(user=user)).data
  File "D:\Program Files (x86)\Python36-32\lib\site-packages\rest_framework\serializers.py", line 537, in data
    ret = super(Serializer, self).data
  File "D:\Program Files (x86)\Python36-32\lib\site-packages\rest_framework\serializers.py", line 262, in data
    self._data = self.to_representation(self.instance)
  File "D:\Program Files (x86)\Python36-32\lib\site-packages\rest_framework\serializers.py", line 491, in to_representation
    attribute = field.get_attribute(instance)
  File "D:\Program Files (x86)\Python36-32\lib\site-packages\rest_framework\fields.py", line 462, in get_attribute
    raise type(exc)(msg)
AttributeError: Got AttributeError when attempting to get a value for field `phone` on serializer `TokenSerializer`.
The serializer field might be named incorrectly and not match any attribute or key on the `Token` instance.
Original exception text was: 'User' object has no attribute 'phone'.
2018-03-03 09:32:50,740,5088,django.server,ERROR,basehttp.py:124,"POST /api/user/login HTTP/1.1" 500 18685
2018-03-03 09:34:32,006,5508,django.request,ERROR,exception.py:118,Internal Server Error: /api/user/login
Traceback (most recent call last):
  File "D:\Program Files (x86)\Python36-32\lib\site-packages\rest_framework\fields.py", line 441, in get_attribute
    return get_attribute(instance, self.source_attrs)
  File "D:\Program Files (x86)\Python36-32\lib\site-packages\rest_framework\fields.py", line 100, in get_attribute
    instance = getattr(instance, attr)
AttributeError: 'Token' object has no attribute 'userPhone'

During handling of the above exception, another exception occurred:

Traceback (most recent call last):
  File "D:\Program Files (x86)\Python36-32\lib\site-packages\django\core\handlers\exception.py", line 35, in inner
    response = get_response(request)
  File "D:\Program Files (x86)\Python36-32\lib\site-packages\django\core\handlers\base.py", line 128, in _get_response
    response = self.process_exception_by_middleware(e, request)
  File "D:\Program Files (x86)\Python36-32\lib\site-packages\django\core\handlers\base.py", line 126, in _get_response
    response = wrapped_callback(request, *callback_args, **callback_kwargs)
  File "D:\Program Files (x86)\Python36-32\lib\site-packages\django\views\decorators\csrf.py", line 54, in wrapped_view
    return view_func(*args, **kwargs)
  File "D:\Program Files (x86)\Python36-32\lib\site-packages\django\views\generic\base.py", line 69, in view
    return self.dispatch(request, *args, **kwargs)
  File "D:\Program Files (x86)\Python36-32\lib\site-packages\rest_framework\views.py", line 494, in dispatch
    response = self.handle_exception(exc)
  File "D:\Program Files (x86)\Python36-32\lib\site-packages\rest_framework\views.py", line 454, in handle_exception
    self.raise_uncaught_exception(exc)
  File "D:\Program Files (x86)\Python36-32\lib\site-packages\rest_framework\views.py", line 491, in dispatch
    response = handler(request, *args, **kwargs)
  File "D:\Program Files (x86)\Python36-32\lib\site-packages\rest_framework\authtoken\views.py", line 24, in post
    data = TokenSerializer(Token.objects.get(user=user)).data
  File "D:\Program Files (x86)\Python36-32\lib\site-packages\rest_framework\serializers.py", line 537, in data
    ret = super(Serializer, self).data
  File "D:\Program Files (x86)\Python36-32\lib\site-packages\rest_framework\serializers.py", line 262, in data
    self._data = self.to_representation(self.instance)
  File "D:\Program Files (x86)\Python36-32\lib\site-packages\rest_framework\serializers.py", line 491, in to_representation
    attribute = field.get_attribute(instance)
  File "D:\Program Files (x86)\Python36-32\lib\site-packages\rest_framework\fields.py", line 462, in get_attribute
    raise type(exc)(msg)
AttributeError: Got AttributeError when attempting to get a value for field `phone` on serializer `TokenSerializer`.
The serializer field might be named incorrectly and not match any attribute or key on the `Token` instance.
Original exception text was: 'Token' object has no attribute 'userPhone'.
2018-03-03 09:34:32,093,5508,django.server,ERROR,basehttp.py:124,"POST /api/user/login HTTP/1.1" 500 18700
2018-03-03 09:36:59,933,5492,django.request,ERROR,exception.py:118,Internal Server Error: /api/user/login
Traceback (most recent call last):
  File "D:\Program Files (x86)\Python36-32\lib\site-packages\rest_framework\fields.py", line 441, in get_attribute
    return get_attribute(instance, self.source_attrs)
  File "D:\Program Files (x86)\Python36-32\lib\site-packages\rest_framework\fields.py", line 100, in get_attribute
    instance = getattr(instance, attr)
AttributeError: 'User' object has no attribute 'phone'

During handling of the above exception, another exception occurred:

Traceback (most recent call last):
  File "D:\Program Files (x86)\Python36-32\lib\site-packages\django\core\handlers\exception.py", line 35, in inner
    response = get_response(request)
  File "D:\Program Files (x86)\Python36-32\lib\site-packages\django\core\handlers\base.py", line 128, in _get_response
    response = self.process_exception_by_middleware(e, request)
  File "D:\Program Files (x86)\Python36-32\lib\site-packages\django\core\handlers\base.py", line 126, in _get_response
    response = wrapped_callback(request, *callback_args, **callback_kwargs)
  File "D:\Program Files (x86)\Python36-32\lib\site-packages\django\views\decorators\csrf.py", line 54, in wrapped_view
    return view_func(*args, **kwargs)
  File "D:\Program Files (x86)\Python36-32\lib\site-packages\django\views\generic\base.py", line 69, in view
    return self.dispatch(request, *args, **kwargs)
  File "D:\Program Files (x86)\Python36-32\lib\site-packages\rest_framework\views.py", line 494, in dispatch
    response = self.handle_exception(exc)
  File "D:\Program Files (x86)\Python36-32\lib\site-packages\rest_framework\views.py", line 454, in handle_exception
    self.raise_uncaught_exception(exc)
  File "D:\Program Files (x86)\Python36-32\lib\site-packages\rest_framework\views.py", line 491, in dispatch
    response = handler(request, *args, **kwargs)
  File "D:\Program Files (x86)\Python36-32\lib\site-packages\rest_framework\authtoken\views.py", line 24, in post
    data = TokenSerializer(Token.objects.get(user=user)).data
  File "D:\Program Files (x86)\Python36-32\lib\site-packages\rest_framework\serializers.py", line 537, in data
    ret = super(Serializer, self).data
  File "D:\Program Files (x86)\Python36-32\lib\site-packages\rest_framework\serializers.py", line 262, in data
    self._data = self.to_representation(self.instance)
  File "D:\Program Files (x86)\Python36-32\lib\site-packages\rest_framework\serializers.py", line 491, in to_representation
    attribute = field.get_attribute(instance)
  File "D:\Program Files (x86)\Python36-32\lib\site-packages\rest_framework\fields.py", line 462, in get_attribute
    raise type(exc)(msg)
AttributeError: Got AttributeError when attempting to get a value for field `phone` on serializer `TokenSerializer`.
The serializer field might be named incorrectly and not match any attribute or key on the `Token` instance.
Original exception text was: 'User' object has no attribute 'phone'.
2018-03-03 09:37:00,024,5492,django.server,ERROR,basehttp.py:124,"POST /api/user/login HTTP/1.1" 500 18685
2018-03-03 09:45:04,775,5576,django.request,ERROR,exception.py:118,Internal Server Error: /api/member/project_member
Traceback (most recent call last):
  File "D:\Program Files (x86)\Python36-32\lib\site-packages\rest_framework\fields.py", line 441, in get_attribute
    return get_attribute(instance, self.source_attrs)
  File "D:\Program Files (x86)\Python36-32\lib\site-packages\rest_framework\fields.py", line 100, in get_attribute
    instance = getattr(instance, attr)
AttributeError: 'User' object has no attribute 'phone'

During handling of the above exception, another exception occurred:

Traceback (most recent call last):
  File "D:\Program Files (x86)\Python36-32\lib\site-packages\django\core\handlers\exception.py", line 35, in inner
    response = get_response(request)
  File "D:\Program Files (x86)\Python36-32\lib\site-packages\django\core\handlers\base.py", line 128, in _get_response
    response = self.process_exception_by_middleware(e, request)
  File "D:\Program Files (x86)\Python36-32\lib\site-packages\django\core\handlers\base.py", line 126, in _get_response
    response = wrapped_callback(request, *callback_args, **callback_kwargs)
  File "D:\Program Files (x86)\Python36-32\lib\site-packages\django\views\decorators\csrf.py", line 54, in wrapped_view
    return view_func(*args, **kwargs)
  File "D:\Program Files (x86)\Python36-32\lib\site-packages\django\views\generic\base.py", line 69, in view
    return self.dispatch(request, *args, **kwargs)
  File "D:\Program Files (x86)\Python36-32\lib\site-packages\rest_framework\views.py", line 494, in dispatch
    response = self.handle_exception(exc)
  File "D:\Program Files (x86)\Python36-32\lib\site-packages\rest_framework\views.py", line 454, in handle_exception
    self.raise_uncaught_exception(exc)
  File "D:\Program Files (x86)\Python36-32\lib\site-packages\rest_framework\views.py", line 491, in dispatch
    response = handler(request, *args, **kwargs)
  File "D:\Program Files (x86)\Python36-32\lib\site-packages\rest_framework\decorators.py", line 53, in handler
    return func(*args, **kwargs)
  File "D:\project\api_automation_test\api_test\common\common.py", line 66, in verify
    return func(reality_parameter)
  File "D:\project\api_automation_test\api_test\api\member.py", line 43, in project_member
    return JsonResponse(data={'data': serialize.data,
  File "D:\Program Files (x86)\Python36-32\lib\site-packages\rest_framework\serializers.py", line 742, in data
    ret = super(ListSerializer, self).data
  File "D:\Program Files (x86)\Python36-32\lib\site-packages\rest_framework\serializers.py", line 262, in data
    self._data = self.to_representation(self.instance)
  File "D:\Program Files (x86)\Python36-32\lib\site-packages\rest_framework\serializers.py", line 660, in to_representation
    self.child.to_representation(item) for item in iterable
  File "D:\Program Files (x86)\Python36-32\lib\site-packages\rest_framework\serializers.py", line 660, in <listcomp>
    self.child.to_representation(item) for item in iterable
  File "D:\Program Files (x86)\Python36-32\lib\site-packages\rest_framework\serializers.py", line 491, in to_representation
    attribute = field.get_attribute(instance)
  File "D:\Program Files (x86)\Python36-32\lib\site-packages\rest_framework\fields.py", line 462, in get_attribute
    raise type(exc)(msg)
AttributeError: Got AttributeError when attempting to get a value for field `userPhone` on serializer `ProjectMemberSerializer`.
The serializer field might be named incorrectly and not match any attribute or key on the `ProjectMember` instance.
Original exception text was: 'User' object has no attribute 'phone'.
2018-03-03 09:45:04,961,5576,django.server,ERROR,basehttp.py:124,"GET /api/member/project_member?project_id=1&page=1 HTTP/1.1" 500 19512
2018-03-03 09:45:12,716,5576,django.request,ERROR,exception.py:118,Internal Server Error: /api/member/project_member
Traceback (most recent call last):
  File "D:\Program Files (x86)\Python36-32\lib\site-packages\rest_framework\fields.py", line 441, in get_attribute
    return get_attribute(instance, self.source_attrs)
  File "D:\Program Files (x86)\Python36-32\lib\site-packages\rest_framework\fields.py", line 100, in get_attribute
    instance = getattr(instance, attr)
AttributeError: 'User' object has no attribute 'phone'

During handling of the above exception, another exception occurred:

Traceback (most recent call last):
  File "D:\Program Files (x86)\Python36-32\lib\site-packages\django\core\handlers\exception.py", line 35, in inner
    response = get_response(request)
  File "D:\Program Files (x86)\Python36-32\lib\site-packages\django\core\handlers\base.py", line 128, in _get_response
    response = self.process_exception_by_middleware(e, request)
  File "D:\Program Files (x86)\Python36-32\lib\site-packages\django\core\handlers\base.py", line 126, in _get_response
    response = wrapped_callback(request, *callback_args, **callback_kwargs)
  File "D:\Program Files (x86)\Python36-32\lib\site-packages\django\views\decorators\csrf.py", line 54, in wrapped_view
    return view_func(*args, **kwargs)
  File "D:\Program Files (x86)\Python36-32\lib\site-packages\django\views\generic\base.py", line 69, in view
    return self.dispatch(request, *args, **kwargs)
  File "D:\Program Files (x86)\Python36-32\lib\site-packages\rest_framework\views.py", line 494, in dispatch
    response = self.handle_exception(exc)
  File "D:\Program Files (x86)\Python36-32\lib\site-packages\rest_framework\views.py", line 454, in handle_exception
    self.raise_uncaught_exception(exc)
  File "D:\Program Files (x86)\Python36-32\lib\site-packages\rest_framework\views.py", line 491, in dispatch
    response = handler(request, *args, **kwargs)
  File "D:\Program Files (x86)\Python36-32\lib\site-packages\rest_framework\decorators.py", line 53, in handler
    return func(*args, **kwargs)
  File "D:\project\api_automation_test\api_test\common\common.py", line 66, in verify
    return func(reality_parameter)
  File "D:\project\api_automation_test\api_test\api\member.py", line 43, in project_member
    return JsonResponse(data={'data': serialize.data,
  File "D:\Program Files (x86)\Python36-32\lib\site-packages\rest_framework\serializers.py", line 742, in data
    ret = super(ListSerializer, self).data
  File "D:\Program Files (x86)\Python36-32\lib\site-packages\rest_framework\serializers.py", line 262, in data
    self._data = self.to_representation(self.instance)
  File "D:\Program Files (x86)\Python36-32\lib\site-packages\rest_framework\serializers.py", line 660, in to_representation
    self.child.to_representation(item) for item in iterable
  File "D:\Program Files (x86)\Python36-32\lib\site-packages\rest_framework\serializers.py", line 660, in <listcomp>
    self.child.to_representation(item) for item in iterable
  File "D:\Program Files (x86)\Python36-32\lib\site-packages\rest_framework\serializers.py", line 491, in to_representation
    attribute = field.get_attribute(instance)
  File "D:\Program Files (x86)\Python36-32\lib\site-packages\rest_framework\fields.py", line 462, in get_attribute
    raise type(exc)(msg)
AttributeError: Got AttributeError when attempting to get a value for field `userPhone` on serializer `ProjectMemberSerializer`.
The serializer field might be named incorrectly and not match any attribute or key on the `ProjectMember` instance.
Original exception text was: 'User' object has no attribute 'phone'.
2018-03-03 09:45:12,824,5576,django.server,ERROR,basehttp.py:124,"GET /api/member/project_member?project_id=1&page=1 HTTP/1.1" 500 19512
2018-03-03 09:46:19,248,4284,django.request,ERROR,exception.py:118,Internal Server Error: /admin/auth/user/2/change/
Traceback (most recent call last):
  File "D:\Program Files (x86)\Python36-32\lib\site-packages\django\core\handlers\exception.py", line 35, in inner
    response = get_response(request)
  File "D:\Program Files (x86)\Python36-32\lib\site-packages\django\core\handlers\base.py", line 128, in _get_response
    response = self.process_exception_by_middleware(e, request)
  File "D:\Program Files (x86)\Python36-32\lib\site-packages\django\core\handlers\base.py", line 126, in _get_response
    response = wrapped_callback(request, *callback_args, **callback_kwargs)
  File "D:\Program Files (x86)\Python36-32\lib\site-packages\django\contrib\admin\options.py", line 574, in wrapper
    return self.admin_site.admin_view(view)(*args, **kwargs)
  File "D:\Program Files (x86)\Python36-32\lib\site-packages\django\utils\decorators.py", line 142, in _wrapped_view
    response = view_func(request, *args, **kwargs)
  File "D:\Program Files (x86)\Python36-32\lib\site-packages\django\views\decorators\cache.py", line 44, in _wrapped_view_func
    response = view_func(request, *args, **kwargs)
  File "D:\Program Files (x86)\Python36-32\lib\site-packages\django\contrib\admin\sites.py", line 223, in inner
    return view(request, *args, **kwargs)
  File "D:\Program Files (x86)\Python36-32\lib\site-packages\django\contrib\admin\options.py", line 1556, in change_view
    return self.changeform_view(request, object_id, form_url, extra_context)
  File "D:\Program Files (x86)\Python36-32\lib\site-packages\django\utils\decorators.py", line 62, in _wrapper
    return bound_func(*args, **kwargs)
  File "D:\Program Files (x86)\Python36-32\lib\site-packages\django\utils\decorators.py", line 142, in _wrapped_view
    response = view_func(request, *args, **kwargs)
  File "D:\Program Files (x86)\Python36-32\lib\site-packages\django\utils\decorators.py", line 58, in bound_func
    return func.__get__(self, type(self))(*args2, **kwargs2)
  File "D:\Program Files (x86)\Python36-32\lib\site-packages\django\contrib\admin\options.py", line 1450, in changeform_view
    return self._changeform_view(request, object_id, form_url, extra_context)
  File "D:\Program Files (x86)\Python36-32\lib\site-packages\django\contrib\admin\options.py", line 1489, in _changeform_view
    if all_valid(formsets) and form_validated:
  File "D:\Program Files (x86)\Python36-32\lib\site-packages\django\forms\formsets.py", line 442, in all_valid
    if not formset.is_valid():
  File "D:\Program Files (x86)\Python36-32\lib\site-packages\django\forms\formsets.py", line 301, in is_valid
    self.errors
  File "D:\Program Files (x86)\Python36-32\lib\site-packages\django\forms\formsets.py", line 281, in errors
    self.full_clean()
  File "D:\Program Files (x86)\Python36-32\lib\site-packages\django\forms\formsets.py", line 322, in full_clean
    for i in range(0, self.total_form_count()):
  File "D:\Program Files (x86)\Python36-32\lib\site-packages\django\forms\formsets.py", line 110, in total_form_count
    return min(self.management_form.cleaned_data[TOTAL_FORM_COUNT], self.absolute_max)
  File "D:\Program Files (x86)\Python36-32\lib\site-packages\django\utils\functional.py", line 36, in __get__
    res = instance.__dict__[self.name] = self.func(instance)
  File "D:\Program Files (x86)\Python36-32\lib\site-packages\django\forms\formsets.py", line 92, in management_form
    code='missing_management_form',
django.core.exceptions.ValidationError: ['管理表单的数据缺失或者已被篡改']
2018-03-03 09:46:19,738,4284,django.server,ERROR,basehttp.py:124,"POST /admin/auth/user/2/change/ HTTP/1.1" 500 142368
2018-03-03 09:46:31,709,4284,django.request,ERROR,exception.py:118,Internal Server Error: /admin/auth/user/2/change/
Traceback (most recent call last):
  File "D:\Program Files (x86)\Python36-32\lib\site-packages\django\core\handlers\exception.py", line 35, in inner
    response = get_response(request)
  File "D:\Program Files (x86)\Python36-32\lib\site-packages\django\core\handlers\base.py", line 128, in _get_response
    response = self.process_exception_by_middleware(e, request)
  File "D:\Program Files (x86)\Python36-32\lib\site-packages\django\core\handlers\base.py", line 126, in _get_response
    response = wrapped_callback(request, *callback_args, **callback_kwargs)
  File "D:\Program Files (x86)\Python36-32\lib\site-packages\django\contrib\admin\options.py", line 574, in wrapper
    return self.admin_site.admin_view(view)(*args, **kwargs)
  File "D:\Program Files (x86)\Python36-32\lib\site-packages\django\utils\decorators.py", line 142, in _wrapped_view
    response = view_func(request, *args, **kwargs)
  File "D:\Program Files (x86)\Python36-32\lib\site-packages\django\views\decorators\cache.py", line 44, in _wrapped_view_func
    response = view_func(request, *args, **kwargs)
  File "D:\Program Files (x86)\Python36-32\lib\site-packages\django\contrib\admin\sites.py", line 223, in inner
    return view(request, *args, **kwargs)
  File "D:\Program Files (x86)\Python36-32\lib\site-packages\django\contrib\admin\options.py", line 1556, in change_view
    return self.changeform_view(request, object_id, form_url, extra_context)
  File "D:\Program Files (x86)\Python36-32\lib\site-packages\django\utils\decorators.py", line 62, in _wrapper
    return bound_func(*args, **kwargs)
  File "D:\Program Files (x86)\Python36-32\lib\site-packages\django\utils\decorators.py", line 142, in _wrapped_view
    response = view_func(request, *args, **kwargs)
  File "D:\Program Files (x86)\Python36-32\lib\site-packages\django\utils\decorators.py", line 58, in bound_func
    return func.__get__(self, type(self))(*args2, **kwargs2)
  File "D:\Program Files (x86)\Python36-32\lib\site-packages\django\contrib\admin\options.py", line 1450, in changeform_view
    return self._changeform_view(request, object_id, form_url, extra_context)
  File "D:\Program Files (x86)\Python36-32\lib\site-packages\django\contrib\admin\options.py", line 1489, in _changeform_view
    if all_valid(formsets) and form_validated:
  File "D:\Program Files (x86)\Python36-32\lib\site-packages\django\forms\formsets.py", line 442, in all_valid
    if not formset.is_valid():
  File "D:\Program Files (x86)\Python36-32\lib\site-packages\django\forms\formsets.py", line 301, in is_valid
    self.errors
  File "D:\Program Files (x86)\Python36-32\lib\site-packages\django\forms\formsets.py", line 281, in errors
    self.full_clean()
  File "D:\Program Files (x86)\Python36-32\lib\site-packages\django\forms\formsets.py", line 322, in full_clean
    for i in range(0, self.total_form_count()):
  File "D:\Program Files (x86)\Python36-32\lib\site-packages\django\forms\formsets.py", line 110, in total_form_count
    return min(self.management_form.cleaned_data[TOTAL_FORM_COUNT], self.absolute_max)
  File "D:\Program Files (x86)\Python36-32\lib\site-packages\django\utils\functional.py", line 36, in __get__
    res = instance.__dict__[self.name] = self.func(instance)
  File "D:\Program Files (x86)\Python36-32\lib\site-packages\django\forms\formsets.py", line 92, in management_form
    code='missing_management_form',
django.core.exceptions.ValidationError: ['管理表单的数据缺失或者已被篡改']
2018-03-03 09:46:32,060,4284,django.server,ERROR,basehttp.py:124,"POST /admin/auth/user/2/change/ HTTP/1.1" 500 142368
2018-03-03 09:19:24,857,10104,django.request,ERROR,exception.py:118,Internal Server Error: /api/api/group
Traceback (most recent call last):
  File "D:\Program Files (x86)\Python36-32\lib\site-packages\django\core\handlers\exception.py", line 35, in inner
    response = get_response(request)
  File "D:\Program Files (x86)\Python36-32\lib\site-packages\django\core\handlers\base.py", line 128, in _get_response
    response = self.process_exception_by_middleware(e, request)
  File "D:\Program Files (x86)\Python36-32\lib\site-packages\django\core\handlers\base.py", line 126, in _get_response
    response = wrapped_callback(request, *callback_args, **callback_kwargs)
  File "D:\Program Files (x86)\Python36-32\lib\site-packages\django\views\decorators\csrf.py", line 54, in wrapped_view
    return view_func(*args, **kwargs)
  File "D:\Program Files (x86)\Python36-32\lib\site-packages\django\views\generic\base.py", line 69, in view
    return self.dispatch(request, *args, **kwargs)
  File "D:\Program Files (x86)\Python36-32\lib\site-packages\rest_framework\views.py", line 494, in dispatch
    response = self.handle_exception(exc)
  File "D:\Program Files (x86)\Python36-32\lib\site-packages\rest_framework\views.py", line 454, in handle_exception
    self.raise_uncaught_exception(exc)
  File "D:\Program Files (x86)\Python36-32\lib\site-packages\rest_framework\views.py", line 491, in dispatch
    response = handler(request, *args, **kwargs)
  File "D:\Program Files (x86)\Python36-32\lib\site-packages\rest_framework\decorators.py", line 53, in handler
    return func(*args, **kwargs)
  File "D:\project\api_automation_test\api_test\common\common.py", line 66, in verify
    return func(reality_parameter)
  File "D:\project\api_automation_test\api_test\api\ApiDoc.py", line 32, in group
    obi = ApiGroupLevelFirst.objects.filter(project=project_id).ord_by("id")
AttributeError: 'QuerySet' object has no attribute 'ord_by'
2018-03-03 09:19:25,062,10104,django.server,ERROR,basehttp.py:124,"GET /api/api/group?project_id=1 HTTP/1.1" 500 17568
2018-03-03 09:45:01,165,8904,django.request,ERROR,exception.py:118,Internal Server Error: /api/api/group
Traceback (most recent call last):
  File "D:\Program Files (x86)\Python36-32\lib\site-packages\django\core\handlers\exception.py", line 35, in inner
    response = get_response(request)
  File "D:\Program Files (x86)\Python36-32\lib\site-packages\django\core\handlers\base.py", line 128, in _get_response
    response = self.process_exception_by_middleware(e, request)
  File "D:\Program Files (x86)\Python36-32\lib\site-packages\django\core\handlers\base.py", line 126, in _get_response
    response = wrapped_callback(request, *callback_args, **callback_kwargs)
  File "D:\Program Files (x86)\Python36-32\lib\site-packages\django\views\decorators\csrf.py", line 54, in wrapped_view
    return view_func(*args, **kwargs)
  File "D:\Program Files (x86)\Python36-32\lib\site-packages\django\views\generic\base.py", line 69, in view
    return self.dispatch(request, *args, **kwargs)
  File "D:\Program Files (x86)\Python36-32\lib\site-packages\rest_framework\views.py", line 494, in dispatch
    response = self.handle_exception(exc)
  File "D:\Program Files (x86)\Python36-32\lib\site-packages\rest_framework\views.py", line 454, in handle_exception
    self.raise_uncaught_exception(exc)
  File "D:\Program Files (x86)\Python36-32\lib\site-packages\rest_framework\views.py", line 491, in dispatch
    response = handler(request, *args, **kwargs)
  File "D:\Program Files (x86)\Python36-32\lib\site-packages\rest_framework\decorators.py", line 53, in handler
    return func(*args, **kwargs)
  File "D:\project\api_automation_test\api_test\common\common.py", line 53, in verify
    print(expect_parameter, parameter)
UnboundLocalError: local variable 'parameter' referenced before assignment
2018-03-03 09:45:01,246,8904,django.server,ERROR,basehttp.py:124,"GET /api/api/group?project_id=1 HTTP/1.1" 500 17444
2018-03-05 09:47:16,900,12812,django.request,ERROR,exception.py:118,Internal Server Error: /api/user/login
Traceback (most recent call last):
  File "D:\Users\SIMO\AppData\Local\Programs\Python\Python36\lib\site-packages\django\db\models\fields\related_descriptors.py", line 367, in __get__
    rel_obj = self.related.get_cached_value(instance)
  File "D:\Users\SIMO\AppData\Local\Programs\Python\Python36\lib\site-packages\django\db\models\fields\mixins.py", line 13, in get_cached_value
    return instance._state.fields_cache[cache_name]
KeyError: 'user'

During handling of the above exception, another exception occurred:

Traceback (most recent call last):
  File "D:\Users\SIMO\AppData\Local\Programs\Python\Python36\lib\site-packages\django\db\backends\utils.py", line 85, in _execute
    return self.cursor.execute(sql, params)
  File "D:\Users\SIMO\AppData\Local\Programs\Python\Python36\lib\site-packages\django\db\backends\mysql\base.py", line 71, in execute
    return self.cursor.execute(query, args)
  File "D:\Users\SIMO\AppData\Local\Programs\Python\Python36\lib\site-packages\MySQLdb\cursors.py", line 250, in execute
    self.errorhandler(self, exc, value)
  File "D:\Users\SIMO\AppData\Local\Programs\Python\Python36\lib\site-packages\MySQLdb\connections.py", line 50, in defaulterrorhandler
    raise errorvalue
  File "D:\Users\SIMO\AppData\Local\Programs\Python\Python36\lib\site-packages\MySQLdb\cursors.py", line 247, in execute
    res = self._query(query)
  File "D:\Users\SIMO\AppData\Local\Programs\Python\Python36\lib\site-packages\MySQLdb\cursors.py", line 411, in _query
    rowcount = self._do_query(q)
  File "D:\Users\SIMO\AppData\Local\Programs\Python\Python36\lib\site-packages\MySQLdb\cursors.py", line 374, in _do_query
    db.query(q)
  File "D:\Users\SIMO\AppData\Local\Programs\Python\Python36\lib\site-packages\MySQLdb\connections.py", line 277, in query
    _mysql.connection.query(self, query)
_mysql_exceptions.ProgrammingError: (1146, "Table 'api_test.api_test_userprofile' doesn't exist")

The above exception was the direct cause of the following exception:

Traceback (most recent call last):
  File "D:\Users\SIMO\AppData\Local\Programs\Python\Python36\lib\site-packages\django\core\handlers\exception.py", line 35, in inner
    response = get_response(request)
  File "D:\Users\SIMO\AppData\Local\Programs\Python\Python36\lib\site-packages\django\core\handlers\base.py", line 128, in _get_response
    response = self.process_exception_by_middleware(e, request)
  File "D:\Users\SIMO\AppData\Local\Programs\Python\Python36\lib\site-packages\django\core\handlers\base.py", line 126, in _get_response
    response = wrapped_callback(request, *callback_args, **callback_kwargs)
  File "D:\Users\SIMO\AppData\Local\Programs\Python\Python36\lib\site-packages\django\views\decorators\csrf.py", line 54, in wrapped_view
    return view_func(*args, **kwargs)
  File "D:\Users\SIMO\AppData\Local\Programs\Python\Python36\lib\site-packages\django\views\generic\base.py", line 69, in view
    return self.dispatch(request, *args, **kwargs)
  File "D:\Users\SIMO\AppData\Local\Programs\Python\Python36\lib\site-packages\rest_framework\views.py", line 494, in dispatch
    response = self.handle_exception(exc)
  File "D:\Users\SIMO\AppData\Local\Programs\Python\Python36\lib\site-packages\rest_framework\views.py", line 454, in handle_exception
    self.raise_uncaught_exception(exc)
  File "D:\Users\SIMO\AppData\Local\Programs\Python\Python36\lib\site-packages\rest_framework\views.py", line 491, in dispatch
    response = handler(request, *args, **kwargs)
  File "H:\project\api_automation_test\api_test\api\user.py", line 23, in post
    data = TokenSerializer(Token.objects.get(user=user)).data
  File "D:\Users\SIMO\AppData\Local\Programs\Python\Python36\lib\site-packages\rest_framework\serializers.py", line 535, in data
    ret = super(Serializer, self).data
  File "D:\Users\SIMO\AppData\Local\Programs\Python\Python36\lib\site-packages\rest_framework\serializers.py", line 260, in data
    self._data = self.to_representation(self.instance)
  File "D:\Users\SIMO\AppData\Local\Programs\Python\Python36\lib\site-packages\rest_framework\serializers.py", line 489, in to_representation
    attribute = field.get_attribute(instance)
  File "D:\Users\SIMO\AppData\Local\Programs\Python\Python36\lib\site-packages\rest_framework\fields.py", line 441, in get_attribute
    return get_attribute(instance, self.source_attrs)
  File "D:\Users\SIMO\AppData\Local\Programs\Python\Python36\lib\site-packages\rest_framework\fields.py", line 100, in get_attribute
    instance = getattr(instance, attr)
  File "D:\Users\SIMO\AppData\Local\Programs\Python\Python36\lib\site-packages\django\db\models\fields\related_descriptors.py", line 375, in __get__
    rel_obj = self.get_queryset(instance=instance).get(**filter_args)
  File "D:\Users\SIMO\AppData\Local\Programs\Python\Python36\lib\site-packages\django\db\models\query.py", line 397, in get
    num = len(clone)
  File "D:\Users\SIMO\AppData\Local\Programs\Python\Python36\lib\site-packages\django\db\models\query.py", line 254, in __len__
    self._fetch_all()
  File "D:\Users\SIMO\AppData\Local\Programs\Python\Python36\lib\site-packages\django\db\models\query.py", line 1179, in _fetch_all
    self._result_cache = list(self._iterable_class(self))
  File "D:\Users\SIMO\AppData\Local\Programs\Python\Python36\lib\site-packages\django\db\models\query.py", line 53, in __iter__
    results = compiler.execute_sql(chunked_fetch=self.chunked_fetch, chunk_size=self.chunk_size)
  File "D:\Users\SIMO\AppData\Local\Programs\Python\Python36\lib\site-packages\django\db\models\sql\compiler.py", line 1064, in execute_sql
    cursor.execute(sql, params)
  File "D:\Users\SIMO\AppData\Local\Programs\Python\Python36\lib\site-packages\django\db\backends\utils.py", line 100, in execute
    return super().execute(sql, params)
  File "D:\Users\SIMO\AppData\Local\Programs\Python\Python36\lib\site-packages\django\db\backends\utils.py", line 68, in execute
    return self._execute_with_wrappers(sql, params, many=False, executor=self._execute)
  File "D:\Users\SIMO\AppData\Local\Programs\Python\Python36\lib\site-packages\django\db\backends\utils.py", line 77, in _execute_with_wrappers
    return executor(sql, params, many, context)
  File "D:\Users\SIMO\AppData\Local\Programs\Python\Python36\lib\site-packages\django\db\backends\utils.py", line 85, in _execute
    return self.cursor.execute(sql, params)
  File "D:\Users\SIMO\AppData\Local\Programs\Python\Python36\lib\site-packages\django\db\utils.py", line 89, in __exit__
    raise dj_exc_value.with_traceback(traceback) from exc_value
  File "D:\Users\SIMO\AppData\Local\Programs\Python\Python36\lib\site-packages\django\db\backends\utils.py", line 85, in _execute
    return self.cursor.execute(sql, params)
  File "D:\Users\SIMO\AppData\Local\Programs\Python\Python36\lib\site-packages\django\db\backends\mysql\base.py", line 71, in execute
    return self.cursor.execute(query, args)
  File "D:\Users\SIMO\AppData\Local\Programs\Python\Python36\lib\site-packages\MySQLdb\cursors.py", line 250, in execute
    self.errorhandler(self, exc, value)
  File "D:\Users\SIMO\AppData\Local\Programs\Python\Python36\lib\site-packages\MySQLdb\connections.py", line 50, in defaulterrorhandler
    raise errorvalue
  File "D:\Users\SIMO\AppData\Local\Programs\Python\Python36\lib\site-packages\MySQLdb\cursors.py", line 247, in execute
    res = self._query(query)
  File "D:\Users\SIMO\AppData\Local\Programs\Python\Python36\lib\site-packages\MySQLdb\cursors.py", line 411, in _query
    rowcount = self._do_query(q)
  File "D:\Users\SIMO\AppData\Local\Programs\Python\Python36\lib\site-packages\MySQLdb\cursors.py", line 374, in _do_query
    db.query(q)
  File "D:\Users\SIMO\AppData\Local\Programs\Python\Python36\lib\site-packages\MySQLdb\connections.py", line 277, in query
    _mysql.connection.query(self, query)
django.db.utils.ProgrammingError: (1146, "Table 'api_test.api_test_userprofile' doesn't exist")
2018-03-05 09:47:16,997,12812,django.server,ERROR,basehttp.py:124,"POST /api/user/login HTTP/1.1" 500 24622
2018-03-05 09:47:36,201,12812,django.request,ERROR,exception.py:118,Internal Server Error: /api/user/login
Traceback (most recent call last):
  File "D:\Users\SIMO\AppData\Local\Programs\Python\Python36\lib\site-packages\django\db\models\fields\related_descriptors.py", line 367, in __get__
    rel_obj = self.related.get_cached_value(instance)
  File "D:\Users\SIMO\AppData\Local\Programs\Python\Python36\lib\site-packages\django\db\models\fields\mixins.py", line 13, in get_cached_value
    return instance._state.fields_cache[cache_name]
KeyError: 'user'

During handling of the above exception, another exception occurred:

Traceback (most recent call last):
  File "D:\Users\SIMO\AppData\Local\Programs\Python\Python36\lib\site-packages\django\db\backends\utils.py", line 85, in _execute
    return self.cursor.execute(sql, params)
  File "D:\Users\SIMO\AppData\Local\Programs\Python\Python36\lib\site-packages\django\db\backends\mysql\base.py", line 71, in execute
    return self.cursor.execute(query, args)
  File "D:\Users\SIMO\AppData\Local\Programs\Python\Python36\lib\site-packages\MySQLdb\cursors.py", line 250, in execute
    self.errorhandler(self, exc, value)
  File "D:\Users\SIMO\AppData\Local\Programs\Python\Python36\lib\site-packages\MySQLdb\connections.py", line 50, in defaulterrorhandler
    raise errorvalue
  File "D:\Users\SIMO\AppData\Local\Programs\Python\Python36\lib\site-packages\MySQLdb\cursors.py", line 247, in execute
    res = self._query(query)
  File "D:\Users\SIMO\AppData\Local\Programs\Python\Python36\lib\site-packages\MySQLdb\cursors.py", line 411, in _query
    rowcount = self._do_query(q)
  File "D:\Users\SIMO\AppData\Local\Programs\Python\Python36\lib\site-packages\MySQLdb\cursors.py", line 374, in _do_query
    db.query(q)
  File "D:\Users\SIMO\AppData\Local\Programs\Python\Python36\lib\site-packages\MySQLdb\connections.py", line 277, in query
    _mysql.connection.query(self, query)
_mysql_exceptions.ProgrammingError: (1146, "Table 'api_test.api_test_userprofile' doesn't exist")

The above exception was the direct cause of the following exception:

Traceback (most recent call last):
  File "D:\Users\SIMO\AppData\Local\Programs\Python\Python36\lib\site-packages\django\core\handlers\exception.py", line 35, in inner
    response = get_response(request)
  File "D:\Users\SIMO\AppData\Local\Programs\Python\Python36\lib\site-packages\django\core\handlers\base.py", line 128, in _get_response
    response = self.process_exception_by_middleware(e, request)
  File "D:\Users\SIMO\AppData\Local\Programs\Python\Python36\lib\site-packages\django\core\handlers\base.py", line 126, in _get_response
    response = wrapped_callback(request, *callback_args, **callback_kwargs)
  File "D:\Users\SIMO\AppData\Local\Programs\Python\Python36\lib\site-packages\django\views\decorators\csrf.py", line 54, in wrapped_view
    return view_func(*args, **kwargs)
  File "D:\Users\SIMO\AppData\Local\Programs\Python\Python36\lib\site-packages\django\views\generic\base.py", line 69, in view
    return self.dispatch(request, *args, **kwargs)
  File "D:\Users\SIMO\AppData\Local\Programs\Python\Python36\lib\site-packages\rest_framework\views.py", line 494, in dispatch
    response = self.handle_exception(exc)
  File "D:\Users\SIMO\AppData\Local\Programs\Python\Python36\lib\site-packages\rest_framework\views.py", line 454, in handle_exception
    self.raise_uncaught_exception(exc)
  File "D:\Users\SIMO\AppData\Local\Programs\Python\Python36\lib\site-packages\rest_framework\views.py", line 491, in dispatch
    response = handler(request, *args, **kwargs)
  File "H:\project\api_automation_test\api_test\api\user.py", line 23, in post
    data = TokenSerializer(Token.objects.get(user=user)).data
  File "D:\Users\SIMO\AppData\Local\Programs\Python\Python36\lib\site-packages\rest_framework\serializers.py", line 535, in data
    ret = super(Serializer, self).data
  File "D:\Users\SIMO\AppData\Local\Programs\Python\Python36\lib\site-packages\rest_framework\serializers.py", line 260, in data
    self._data = self.to_representation(self.instance)
  File "D:\Users\SIMO\AppData\Local\Programs\Python\Python36\lib\site-packages\rest_framework\serializers.py", line 489, in to_representation
    attribute = field.get_attribute(instance)
  File "D:\Users\SIMO\AppData\Local\Programs\Python\Python36\lib\site-packages\rest_framework\fields.py", line 441, in get_attribute
    return get_attribute(instance, self.source_attrs)
  File "D:\Users\SIMO\AppData\Local\Programs\Python\Python36\lib\site-packages\rest_framework\fields.py", line 100, in get_attribute
    instance = getattr(instance, attr)
  File "D:\Users\SIMO\AppData\Local\Programs\Python\Python36\lib\site-packages\django\db\models\fields\related_descriptors.py", line 375, in __get__
    rel_obj = self.get_queryset(instance=instance).get(**filter_args)
  File "D:\Users\SIMO\AppData\Local\Programs\Python\Python36\lib\site-packages\django\db\models\query.py", line 397, in get
    num = len(clone)
  File "D:\Users\SIMO\AppData\Local\Programs\Python\Python36\lib\site-packages\django\db\models\query.py", line 254, in __len__
    self._fetch_all()
  File "D:\Users\SIMO\AppData\Local\Programs\Python\Python36\lib\site-packages\django\db\models\query.py", line 1179, in _fetch_all
    self._result_cache = list(self._iterable_class(self))
  File "D:\Users\SIMO\AppData\Local\Programs\Python\Python36\lib\site-packages\django\db\models\query.py", line 53, in __iter__
    results = compiler.execute_sql(chunked_fetch=self.chunked_fetch, chunk_size=self.chunk_size)
  File "D:\Users\SIMO\AppData\Local\Programs\Python\Python36\lib\site-packages\django\db\models\sql\compiler.py", line 1064, in execute_sql
    cursor.execute(sql, params)
  File "D:\Users\SIMO\AppData\Local\Programs\Python\Python36\lib\site-packages\django\db\backends\utils.py", line 100, in execute
    return super().execute(sql, params)
  File "D:\Users\SIMO\AppData\Local\Programs\Python\Python36\lib\site-packages\django\db\backends\utils.py", line 68, in execute
    return self._execute_with_wrappers(sql, params, many=False, executor=self._execute)
  File "D:\Users\SIMO\AppData\Local\Programs\Python\Python36\lib\site-packages\django\db\backends\utils.py", line 77, in _execute_with_wrappers
    return executor(sql, params, many, context)
  File "D:\Users\SIMO\AppData\Local\Programs\Python\Python36\lib\site-packages\django\db\backends\utils.py", line 85, in _execute
    return self.cursor.execute(sql, params)
  File "D:\Users\SIMO\AppData\Local\Programs\Python\Python36\lib\site-packages\django\db\utils.py", line 89, in __exit__
    raise dj_exc_value.with_traceback(traceback) from exc_value
  File "D:\Users\SIMO\AppData\Local\Programs\Python\Python36\lib\site-packages\django\db\backends\utils.py", line 85, in _execute
    return self.cursor.execute(sql, params)
  File "D:\Users\SIMO\AppData\Local\Programs\Python\Python36\lib\site-packages\django\db\backends\mysql\base.py", line 71, in execute
    return self.cursor.execute(query, args)
  File "D:\Users\SIMO\AppData\Local\Programs\Python\Python36\lib\site-packages\MySQLdb\cursors.py", line 250, in execute
    self.errorhandler(self, exc, value)
  File "D:\Users\SIMO\AppData\Local\Programs\Python\Python36\lib\site-packages\MySQLdb\connections.py", line 50, in defaulterrorhandler
    raise errorvalue
  File "D:\Users\SIMO\AppData\Local\Programs\Python\Python36\lib\site-packages\MySQLdb\cursors.py", line 247, in execute
    res = self._query(query)
  File "D:\Users\SIMO\AppData\Local\Programs\Python\Python36\lib\site-packages\MySQLdb\cursors.py", line 411, in _query
    rowcount = self._do_query(q)
  File "D:\Users\SIMO\AppData\Local\Programs\Python\Python36\lib\site-packages\MySQLdb\cursors.py", line 374, in _do_query
    db.query(q)
  File "D:\Users\SIMO\AppData\Local\Programs\Python\Python36\lib\site-packages\MySQLdb\connections.py", line 277, in query
    _mysql.connection.query(self, query)
django.db.utils.ProgrammingError: (1146, "Table 'api_test.api_test_userprofile' doesn't exist")
2018-03-05 09:47:36,225,12812,django.server,ERROR,basehttp.py:124,"POST /api/user/login HTTP/1.1" 500 24622
2018-03-05 16:56:30,300,18316,django.request,ERROR,exception.py:118,Internal Server Error: /admin/api_test/apiinfo/
Traceback (most recent call last):
  File "D:\Users\SIMO\AppData\Local\Programs\Python\Python36\lib\site-packages\django\db\backends\utils.py", line 85, in _execute
    return self.cursor.execute(sql, params)
  File "D:\Users\SIMO\AppData\Local\Programs\Python\Python36\lib\site-packages\django\db\backends\mysql\base.py", line 71, in execute
    return self.cursor.execute(query, args)
  File "D:\Users\SIMO\AppData\Local\Programs\Python\Python36\lib\site-packages\MySQLdb\cursors.py", line 250, in execute
    self.errorhandler(self, exc, value)
  File "D:\Users\SIMO\AppData\Local\Programs\Python\Python36\lib\site-packages\MySQLdb\connections.py", line 50, in defaulterrorhandler
    raise errorvalue
  File "D:\Users\SIMO\AppData\Local\Programs\Python\Python36\lib\site-packages\MySQLdb\cursors.py", line 247, in execute
    res = self._query(query)
  File "D:\Users\SIMO\AppData\Local\Programs\Python\Python36\lib\site-packages\MySQLdb\cursors.py", line 411, in _query
    rowcount = self._do_query(q)
  File "D:\Users\SIMO\AppData\Local\Programs\Python\Python36\lib\site-packages\MySQLdb\cursors.py", line 374, in _do_query
    db.query(q)
  File "D:\Users\SIMO\AppData\Local\Programs\Python\Python36\lib\site-packages\MySQLdb\connections.py", line 277, in query
    _mysql.connection.query(self, query)
_mysql_exceptions.OperationalError: (1054, "Unknown column 'api_test_project.user_id' in 'field list'")

The above exception was the direct cause of the following exception:

Traceback (most recent call last):
  File "D:\Users\SIMO\AppData\Local\Programs\Python\Python36\lib\site-packages\django\core\handlers\exception.py", line 35, in inner
    response = get_response(request)
  File "D:\Users\SIMO\AppData\Local\Programs\Python\Python36\lib\site-packages\django\core\handlers\base.py", line 128, in _get_response
    response = self.process_exception_by_middleware(e, request)
  File "D:\Users\SIMO\AppData\Local\Programs\Python\Python36\lib\site-packages\django\core\handlers\base.py", line 126, in _get_response
    response = wrapped_callback(request, *callback_args, **callback_kwargs)
  File "D:\Users\SIMO\AppData\Local\Programs\Python\Python36\lib\site-packages\django\contrib\admin\options.py", line 574, in wrapper
    return self.admin_site.admin_view(view)(*args, **kwargs)
  File "D:\Users\SIMO\AppData\Local\Programs\Python\Python36\lib\site-packages\django\utils\decorators.py", line 142, in _wrapped_view
    response = view_func(request, *args, **kwargs)
  File "D:\Users\SIMO\AppData\Local\Programs\Python\Python36\lib\site-packages\django\views\decorators\cache.py", line 44, in _wrapped_view_func
    response = view_func(request, *args, **kwargs)
  File "D:\Users\SIMO\AppData\Local\Programs\Python\Python36\lib\site-packages\django\contrib\admin\sites.py", line 223, in inner
    return view(request, *args, **kwargs)
  File "D:\Users\SIMO\AppData\Local\Programs\Python\Python36\lib\site-packages\django\utils\decorators.py", line 62, in _wrapper
    return bound_func(*args, **kwargs)
  File "D:\Users\SIMO\AppData\Local\Programs\Python\Python36\lib\site-packages\django\utils\decorators.py", line 142, in _wrapped_view
    response = view_func(request, *args, **kwargs)
  File "D:\Users\SIMO\AppData\Local\Programs\Python\Python36\lib\site-packages\django\utils\decorators.py", line 58, in bound_func
    return func.__get__(self, type(self))(*args2, **kwargs2)
  File "D:\Users\SIMO\AppData\Local\Programs\Python\Python36\lib\site-packages\django\contrib\admin\options.py", line 1570, in changelist_view
    cl = self.get_changelist_instance(request)
  File "D:\Users\SIMO\AppData\Local\Programs\Python\Python36\lib\site-packages\django\contrib\admin\options.py", line 705, in get_changelist_instance
    self,
  File "D:\Users\SIMO\AppData\Local\Programs\Python\Python36\lib\site-packages\django\contrib\admin\views\main.py", line 76, in __init__
    self.queryset = self.get_queryset(request)
  File "D:\Users\SIMO\AppData\Local\Programs\Python\Python36\lib\site-packages\django\contrib\admin\views\main.py", line 320, in get_queryset
    filters_use_distinct) = self.get_filters(request)
  File "D:\Users\SIMO\AppData\Local\Programs\Python\Python36\lib\site-packages\django\contrib\admin\views\main.py", line 130, in get_filters
    self.model, self.model_admin, field_path=field_path
  File "D:\Users\SIMO\AppData\Local\Programs\Python\Python36\lib\site-packages\django\contrib\admin\filters.py", line 157, in create
    return list_filter_class(field, request, params, model, model_admin, field_path=field_path)
  File "D:\Users\SIMO\AppData\Local\Programs\Python\Python36\lib\site-packages\django\contrib\admin\filters.py", line 168, in __init__
    self.lookup_choices = self.field_choices(field, request, model_admin)
  File "D:\Users\SIMO\AppData\Local\Programs\Python\Python36\lib\site-packages\django\contrib\admin\filters.py", line 195, in field_choices
    return field.get_choices(include_blank=False)
  File "D:\Users\SIMO\AppData\Local\Programs\Python\Python36\lib\site-packages\django\db\models\fields\__init__.py", line 812, in get_choices
    limit_choices_to)]
  File "D:\Users\SIMO\AppData\Local\Programs\Python\Python36\lib\site-packages\django\db\models\query.py", line 272, in __iter__
    self._fetch_all()
  File "D:\Users\SIMO\AppData\Local\Programs\Python\Python36\lib\site-packages\django\db\models\query.py", line 1179, in _fetch_all
    self._result_cache = list(self._iterable_class(self))
  File "D:\Users\SIMO\AppData\Local\Programs\Python\Python36\lib\site-packages\django\db\models\query.py", line 53, in __iter__
    results = compiler.execute_sql(chunked_fetch=self.chunked_fetch, chunk_size=self.chunk_size)
  File "D:\Users\SIMO\AppData\Local\Programs\Python\Python36\lib\site-packages\django\db\models\sql\compiler.py", line 1064, in execute_sql
    cursor.execute(sql, params)
  File "D:\Users\SIMO\AppData\Local\Programs\Python\Python36\lib\site-packages\django\db\backends\utils.py", line 100, in execute
    return super().execute(sql, params)
  File "D:\Users\SIMO\AppData\Local\Programs\Python\Python36\lib\site-packages\django\db\backends\utils.py", line 68, in execute
    return self._execute_with_wrappers(sql, params, many=False, executor=self._execute)
  File "D:\Users\SIMO\AppData\Local\Programs\Python\Python36\lib\site-packages\django\db\backends\utils.py", line 77, in _execute_with_wrappers
    return executor(sql, params, many, context)
  File "D:\Users\SIMO\AppData\Local\Programs\Python\Python36\lib\site-packages\django\db\backends\utils.py", line 85, in _execute
    return self.cursor.execute(sql, params)
  File "D:\Users\SIMO\AppData\Local\Programs\Python\Python36\lib\site-packages\django\db\utils.py", line 89, in __exit__
    raise dj_exc_value.with_traceback(traceback) from exc_value
  File "D:\Users\SIMO\AppData\Local\Programs\Python\Python36\lib\site-packages\django\db\backends\utils.py", line 85, in _execute
    return self.cursor.execute(sql, params)
  File "D:\Users\SIMO\AppData\Local\Programs\Python\Python36\lib\site-packages\django\db\backends\mysql\base.py", line 71, in execute
    return self.cursor.execute(query, args)
  File "D:\Users\SIMO\AppData\Local\Programs\Python\Python36\lib\site-packages\MySQLdb\cursors.py", line 250, in execute
    self.errorhandler(self, exc, value)
  File "D:\Users\SIMO\AppData\Local\Programs\Python\Python36\lib\site-packages\MySQLdb\connections.py", line 50, in defaulterrorhandler
    raise errorvalue
  File "D:\Users\SIMO\AppData\Local\Programs\Python\Python36\lib\site-packages\MySQLdb\cursors.py", line 247, in execute
    res = self._query(query)
  File "D:\Users\SIMO\AppData\Local\Programs\Python\Python36\lib\site-packages\MySQLdb\cursors.py", line 411, in _query
    rowcount = self._do_query(q)
  File "D:\Users\SIMO\AppData\Local\Programs\Python\Python36\lib\site-packages\MySQLdb\cursors.py", line 374, in _do_query
    db.query(q)
  File "D:\Users\SIMO\AppData\Local\Programs\Python\Python36\lib\site-packages\MySQLdb\connections.py", line 277, in query
    _mysql.connection.query(self, query)
django.db.utils.OperationalError: (1054, "Unknown column 'api_test_project.user_id' in 'field list'")
2018-03-05 16:56:30,431,18316,django.server,ERROR,basehttp.py:124,"GET /admin/api_test/apiinfo/ HTTP/1.1" 500 261309
2018-03-05 16:56:33,653,18316,django.request,ERROR,exception.py:118,Internal Server Error: /admin/api_test/project/
Traceback (most recent call last):
  File "D:\Users\SIMO\AppData\Local\Programs\Python\Python36\lib\site-packages\django\db\backends\utils.py", line 85, in _execute
    return self.cursor.execute(sql, params)
  File "D:\Users\SIMO\AppData\Local\Programs\Python\Python36\lib\site-packages\django\db\backends\mysql\base.py", line 71, in execute
    return self.cursor.execute(query, args)
  File "D:\Users\SIMO\AppData\Local\Programs\Python\Python36\lib\site-packages\MySQLdb\cursors.py", line 250, in execute
    self.errorhandler(self, exc, value)
  File "D:\Users\SIMO\AppData\Local\Programs\Python\Python36\lib\site-packages\MySQLdb\connections.py", line 50, in defaulterrorhandler
    raise errorvalue
  File "D:\Users\SIMO\AppData\Local\Programs\Python\Python36\lib\site-packages\MySQLdb\cursors.py", line 247, in execute
    res = self._query(query)
  File "D:\Users\SIMO\AppData\Local\Programs\Python\Python36\lib\site-packages\MySQLdb\cursors.py", line 411, in _query
    rowcount = self._do_query(q)
  File "D:\Users\SIMO\AppData\Local\Programs\Python\Python36\lib\site-packages\MySQLdb\cursors.py", line 374, in _do_query
    db.query(q)
  File "D:\Users\SIMO\AppData\Local\Programs\Python\Python36\lib\site-packages\MySQLdb\connections.py", line 277, in query
    _mysql.connection.query(self, query)
_mysql_exceptions.OperationalError: (1054, "Unknown column 'api_test_project.user_id' in 'field list'")

The above exception was the direct cause of the following exception:

Traceback (most recent call last):
  File "D:\Users\SIMO\AppData\Local\Programs\Python\Python36\lib\site-packages\django\core\handlers\exception.py", line 35, in inner
    response = get_response(request)
  File "D:\Users\SIMO\AppData\Local\Programs\Python\Python36\lib\site-packages\django\core\handlers\base.py", line 128, in _get_response
    response = self.process_exception_by_middleware(e, request)
  File "D:\Users\SIMO\AppData\Local\Programs\Python\Python36\lib\site-packages\django\core\handlers\base.py", line 126, in _get_response
    response = wrapped_callback(request, *callback_args, **callback_kwargs)
  File "D:\Users\SIMO\AppData\Local\Programs\Python\Python36\lib\site-packages\django\contrib\admin\options.py", line 574, in wrapper
    return self.admin_site.admin_view(view)(*args, **kwargs)
  File "D:\Users\SIMO\AppData\Local\Programs\Python\Python36\lib\site-packages\django\utils\decorators.py", line 142, in _wrapped_view
    response = view_func(request, *args, **kwargs)
  File "D:\Users\SIMO\AppData\Local\Programs\Python\Python36\lib\site-packages\django\views\decorators\cache.py", line 44, in _wrapped_view_func
    response = view_func(request, *args, **kwargs)
  File "D:\Users\SIMO\AppData\Local\Programs\Python\Python36\lib\site-packages\django\contrib\admin\sites.py", line 223, in inner
    return view(request, *args, **kwargs)
  File "D:\Users\SIMO\AppData\Local\Programs\Python\Python36\lib\site-packages\django\utils\decorators.py", line 62, in _wrapper
    return bound_func(*args, **kwargs)
  File "D:\Users\SIMO\AppData\Local\Programs\Python\Python36\lib\site-packages\django\utils\decorators.py", line 142, in _wrapped_view
    response = view_func(request, *args, **kwargs)
  File "D:\Users\SIMO\AppData\Local\Programs\Python\Python36\lib\site-packages\django\utils\decorators.py", line 58, in bound_func
    return func.__get__(self, type(self))(*args2, **kwargs2)
  File "D:\Users\SIMO\AppData\Local\Programs\Python\Python36\lib\site-packages\django\contrib\admin\options.py", line 1685, in changelist_view
    selection_note=_('0 of %(cnt)s selected') % {'cnt': len(cl.result_list)},
  File "D:\Users\SIMO\AppData\Local\Programs\Python\Python36\lib\site-packages\django\db\models\query.py", line 254, in __len__
    self._fetch_all()
  File "D:\Users\SIMO\AppData\Local\Programs\Python\Python36\lib\site-packages\django\db\models\query.py", line 1179, in _fetch_all
    self._result_cache = list(self._iterable_class(self))
  File "D:\Users\SIMO\AppData\Local\Programs\Python\Python36\lib\site-packages\django\db\models\query.py", line 53, in __iter__
    results = compiler.execute_sql(chunked_fetch=self.chunked_fetch, chunk_size=self.chunk_size)
  File "D:\Users\SIMO\AppData\Local\Programs\Python\Python36\lib\site-packages\django\db\models\sql\compiler.py", line 1064, in execute_sql
    cursor.execute(sql, params)
  File "D:\Users\SIMO\AppData\Local\Programs\Python\Python36\lib\site-packages\django\db\backends\utils.py", line 100, in execute
    return super().execute(sql, params)
  File "D:\Users\SIMO\AppData\Local\Programs\Python\Python36\lib\site-packages\django\db\backends\utils.py", line 68, in execute
    return self._execute_with_wrappers(sql, params, many=False, executor=self._execute)
  File "D:\Users\SIMO\AppData\Local\Programs\Python\Python36\lib\site-packages\django\db\backends\utils.py", line 77, in _execute_with_wrappers
    return executor(sql, params, many, context)
  File "D:\Users\SIMO\AppData\Local\Programs\Python\Python36\lib\site-packages\django\db\backends\utils.py", line 85, in _execute
    return self.cursor.execute(sql, params)
  File "D:\Users\SIMO\AppData\Local\Programs\Python\Python36\lib\site-packages\django\db\utils.py", line 89, in __exit__
    raise dj_exc_value.with_traceback(traceback) from exc_value
  File "D:\Users\SIMO\AppData\Local\Programs\Python\Python36\lib\site-packages\django\db\backends\utils.py", line 85, in _execute
    return self.cursor.execute(sql, params)
  File "D:\Users\SIMO\AppData\Local\Programs\Python\Python36\lib\site-packages\django\db\backends\mysql\base.py", line 71, in execute
    return self.cursor.execute(query, args)
  File "D:\Users\SIMO\AppData\Local\Programs\Python\Python36\lib\site-packages\MySQLdb\cursors.py", line 250, in execute
    self.errorhandler(self, exc, value)
  File "D:\Users\SIMO\AppData\Local\Programs\Python\Python36\lib\site-packages\MySQLdb\connections.py", line 50, in defaulterrorhandler
    raise errorvalue
  File "D:\Users\SIMO\AppData\Local\Programs\Python\Python36\lib\site-packages\MySQLdb\cursors.py", line 247, in execute
    res = self._query(query)
  File "D:\Users\SIMO\AppData\Local\Programs\Python\Python36\lib\site-packages\MySQLdb\cursors.py", line 411, in _query
    rowcount = self._do_query(q)
  File "D:\Users\SIMO\AppData\Local\Programs\Python\Python36\lib\site-packages\MySQLdb\cursors.py", line 374, in _do_query
    db.query(q)
  File "D:\Users\SIMO\AppData\Local\Programs\Python\Python36\lib\site-packages\MySQLdb\connections.py", line 277, in query
    _mysql.connection.query(self, query)
django.db.utils.OperationalError: (1054, "Unknown column 'api_test_project.user_id' in 'field list'")
2018-03-05 16:56:33,710,18316,django.server,ERROR,basehttp.py:124,"GET /admin/api_test/project/ HTTP/1.1" 500 222096
2018-03-05 17:14:55,490,6980,django.request,ERROR,exception.py:118,Internal Server Error: /api/api/api_list
Traceback (most recent call last):
  File "D:\Users\SIMO\AppData\Local\Programs\Python\Python36\lib\site-packages\django\core\handlers\exception.py", line 35, in inner
    response = get_response(request)
  File "D:\Users\SIMO\AppData\Local\Programs\Python\Python36\lib\site-packages\django\core\handlers\base.py", line 128, in _get_response
    response = self.process_exception_by_middleware(e, request)
  File "D:\Users\SIMO\AppData\Local\Programs\Python\Python36\lib\site-packages\django\core\handlers\base.py", line 126, in _get_response
    response = wrapped_callback(request, *callback_args, **callback_kwargs)
  File "D:\Users\SIMO\AppData\Local\Programs\Python\Python36\lib\site-packages\django\views\decorators\csrf.py", line 54, in wrapped_view
    return view_func(*args, **kwargs)
  File "D:\Users\SIMO\AppData\Local\Programs\Python\Python36\lib\site-packages\django\views\generic\base.py", line 69, in view
    return self.dispatch(request, *args, **kwargs)
  File "D:\Users\SIMO\AppData\Local\Programs\Python\Python36\lib\site-packages\rest_framework\views.py", line 494, in dispatch
    response = self.handle_exception(exc)
  File "D:\Users\SIMO\AppData\Local\Programs\Python\Python36\lib\site-packages\rest_framework\views.py", line 454, in handle_exception
    self.raise_uncaught_exception(exc)
  File "D:\Users\SIMO\AppData\Local\Programs\Python\Python36\lib\site-packages\rest_framework\views.py", line 491, in dispatch
    response = handler(request, *args, **kwargs)
  File "D:\Users\SIMO\AppData\Local\Programs\Python\Python36\lib\site-packages\rest_framework\decorators.py", line 53, in handler
    return func(*args, **kwargs)
  File "H:\project\api_automation_test\api_test\common\common.py", line 66, in verify
    return func(reality_parameter)
  File "H:\project\api_automation_test\api_test\api\ApiDoc.py", line 206, in api_list
    return JsonResponse(data={'data': serialize.data,
  File "D:\Users\SIMO\AppData\Local\Programs\Python\Python36\lib\site-packages\rest_framework\serializers.py", line 740, in data
    ret = super(ListSerializer, self).data
  File "D:\Users\SIMO\AppData\Local\Programs\Python\Python36\lib\site-packages\rest_framework\serializers.py", line 260, in data
    self._data = self.to_representation(self.instance)
  File "D:\Users\SIMO\AppData\Local\Programs\Python\Python36\lib\site-packages\rest_framework\serializers.py", line 658, in to_representation
    self.child.to_representation(item) for item in iterable
  File "D:\Users\SIMO\AppData\Local\Programs\Python\Python36\lib\site-packages\rest_framework\serializers.py", line 658, in <listcomp>
    self.child.to_representation(item) for item in iterable
  File "D:\Users\SIMO\AppData\Local\Programs\Python\Python36\lib\site-packages\rest_framework\serializers.py", line 485, in to_representation
    fields = self._readable_fields
  File "D:\Users\SIMO\AppData\Local\Programs\Python\Python36\lib\site-packages\django\utils\functional.py", line 36, in __get__
    res = instance.__dict__[self.name] = self.func(instance)
  File "D:\Users\SIMO\AppData\Local\Programs\Python\Python36\lib\site-packages\rest_framework\serializers.py", line 375, in _readable_fields
    field for field in self.fields.values()
  File "D:\Users\SIMO\AppData\Local\Programs\Python\Python36\lib\site-packages\rest_framework\serializers.py", line 361, in fields
    for key, value in self.get_fields().items():
  File "D:\Users\SIMO\AppData\Local\Programs\Python\Python36\lib\site-packages\rest_framework\serializers.py", line 995, in get_fields
    field_names = self.get_field_names(declared_fields, info)
  File "D:\Users\SIMO\AppData\Local\Programs\Python\Python36\lib\site-packages\rest_framework\serializers.py", line 1096, in get_field_names
    serializer_class=self.__class__.__name__
AssertionError: The field 'userUpdata' was declared on serializer ApiInfoListSerializer, but has not been included in the 'fields' option.
2018-03-05 17:14:55,529,6980,django.server,ERROR,basehttp.py:124,"GET /api/api/api_list?project_id=1&page=1&page_size=6 HTTP/1.1" 500 20856
2018-03-05 17:15:08,558,17460,django.request,ERROR,exception.py:118,Internal Server Error: /api/api/api_list
Traceback (most recent call last):
  File "D:\Users\SIMO\AppData\Local\Programs\Python\Python36\lib\site-packages\rest_framework\fields.py", line 441, in get_attribute
    return get_attribute(instance, self.source_attrs)
  File "D:\Users\SIMO\AppData\Local\Programs\Python\Python36\lib\site-packages\rest_framework\fields.py", line 100, in get_attribute
    instance = getattr(instance, attr)
AttributeError: 'ApiInfo' object has no attribute 'user'

During handling of the above exception, another exception occurred:

Traceback (most recent call last):
  File "D:\Users\SIMO\AppData\Local\Programs\Python\Python36\lib\site-packages\django\core\handlers\exception.py", line 35, in inner
    response = get_response(request)
  File "D:\Users\SIMO\AppData\Local\Programs\Python\Python36\lib\site-packages\django\core\handlers\base.py", line 128, in _get_response
    response = self.process_exception_by_middleware(e, request)
  File "D:\Users\SIMO\AppData\Local\Programs\Python\Python36\lib\site-packages\django\core\handlers\base.py", line 126, in _get_response
    response = wrapped_callback(request, *callback_args, **callback_kwargs)
  File "D:\Users\SIMO\AppData\Local\Programs\Python\Python36\lib\site-packages\django\views\decorators\csrf.py", line 54, in wrapped_view
    return view_func(*args, **kwargs)
  File "D:\Users\SIMO\AppData\Local\Programs\Python\Python36\lib\site-packages\django\views\generic\base.py", line 69, in view
    return self.dispatch(request, *args, **kwargs)
  File "D:\Users\SIMO\AppData\Local\Programs\Python\Python36\lib\site-packages\rest_framework\views.py", line 494, in dispatch
    response = self.handle_exception(exc)
  File "D:\Users\SIMO\AppData\Local\Programs\Python\Python36\lib\site-packages\rest_framework\views.py", line 454, in handle_exception
    self.raise_uncaught_exception(exc)
  File "D:\Users\SIMO\AppData\Local\Programs\Python\Python36\lib\site-packages\rest_framework\views.py", line 491, in dispatch
    response = handler(request, *args, **kwargs)
  File "D:\Users\SIMO\AppData\Local\Programs\Python\Python36\lib\site-packages\rest_framework\decorators.py", line 53, in handler
    return func(*args, **kwargs)
  File "H:\project\api_automation_test\api_test\common\common.py", line 66, in verify
    return func(reality_parameter)
  File "H:\project\api_automation_test\api_test\api\ApiDoc.py", line 206, in api_list
    return JsonResponse(data={'data': serialize.data,
  File "D:\Users\SIMO\AppData\Local\Programs\Python\Python36\lib\site-packages\rest_framework\serializers.py", line 740, in data
    ret = super(ListSerializer, self).data
  File "D:\Users\SIMO\AppData\Local\Programs\Python\Python36\lib\site-packages\rest_framework\serializers.py", line 260, in data
    self._data = self.to_representation(self.instance)
  File "D:\Users\SIMO\AppData\Local\Programs\Python\Python36\lib\site-packages\rest_framework\serializers.py", line 658, in to_representation
    self.child.to_representation(item) for item in iterable
  File "D:\Users\SIMO\AppData\Local\Programs\Python\Python36\lib\site-packages\rest_framework\serializers.py", line 658, in <listcomp>
    self.child.to_representation(item) for item in iterable
  File "D:\Users\SIMO\AppData\Local\Programs\Python\Python36\lib\site-packages\rest_framework\serializers.py", line 489, in to_representation
    attribute = field.get_attribute(instance)
  File "D:\Users\SIMO\AppData\Local\Programs\Python\Python36\lib\site-packages\rest_framework\fields.py", line 462, in get_attribute
    raise type(exc)(msg)
AttributeError: Got AttributeError when attempting to get a value for field `userUpdate` on serializer `ApiInfoListSerializer`.
The serializer field might be named incorrectly and not match any attribute or key on the `ApiInfo` instance.
Original exception text was: 'ApiInfo' object has no attribute 'user'.
2018-03-05 17:15:08,576,17460,django.server,ERROR,basehttp.py:124,"GET /api/api/api_list?project_id=1&page=1&page_size=6 HTTP/1.1" 500 20902
2018-03-05 17:15:25,900,7312,django.request,ERROR,exception.py:118,Internal Server Error: /api/api/api_list
Traceback (most recent call last):
  File "D:\Users\SIMO\AppData\Local\Programs\Python\Python36\lib\site-packages\rest_framework\fields.py", line 441, in get_attribute
    return get_attribute(instance, self.source_attrs)
  File "D:\Users\SIMO\AppData\Local\Programs\Python\Python36\lib\site-packages\rest_framework\fields.py", line 100, in get_attribute
    instance = getattr(instance, attr)
AttributeError: 'ApiInfo' object has no attribute 'userUpadte'

During handling of the above exception, another exception occurred:

Traceback (most recent call last):
  File "D:\Users\SIMO\AppData\Local\Programs\Python\Python36\lib\site-packages\django\core\handlers\exception.py", line 35, in inner
    response = get_response(request)
  File "D:\Users\SIMO\AppData\Local\Programs\Python\Python36\lib\site-packages\django\core\handlers\base.py", line 128, in _get_response
    response = self.process_exception_by_middleware(e, request)
  File "D:\Users\SIMO\AppData\Local\Programs\Python\Python36\lib\site-packages\django\core\handlers\base.py", line 126, in _get_response
    response = wrapped_callback(request, *callback_args, **callback_kwargs)
  File "D:\Users\SIMO\AppData\Local\Programs\Python\Python36\lib\site-packages\django\views\decorators\csrf.py", line 54, in wrapped_view
    return view_func(*args, **kwargs)
  File "D:\Users\SIMO\AppData\Local\Programs\Python\Python36\lib\site-packages\django\views\generic\base.py", line 69, in view
    return self.dispatch(request, *args, **kwargs)
  File "D:\Users\SIMO\AppData\Local\Programs\Python\Python36\lib\site-packages\rest_framework\views.py", line 494, in dispatch
    response = self.handle_exception(exc)
  File "D:\Users\SIMO\AppData\Local\Programs\Python\Python36\lib\site-packages\rest_framework\views.py", line 454, in handle_exception
    self.raise_uncaught_exception(exc)
  File "D:\Users\SIMO\AppData\Local\Programs\Python\Python36\lib\site-packages\rest_framework\views.py", line 491, in dispatch
    response = handler(request, *args, **kwargs)
  File "D:\Users\SIMO\AppData\Local\Programs\Python\Python36\lib\site-packages\rest_framework\decorators.py", line 53, in handler
    return func(*args, **kwargs)
  File "H:\project\api_automation_test\api_test\common\common.py", line 66, in verify
    return func(reality_parameter)
  File "H:\project\api_automation_test\api_test\api\ApiDoc.py", line 206, in api_list
    return JsonResponse(data={'data': serialize.data,
  File "D:\Users\SIMO\AppData\Local\Programs\Python\Python36\lib\site-packages\rest_framework\serializers.py", line 740, in data
    ret = super(ListSerializer, self).data
  File "D:\Users\SIMO\AppData\Local\Programs\Python\Python36\lib\site-packages\rest_framework\serializers.py", line 260, in data
    self._data = self.to_representation(self.instance)
  File "D:\Users\SIMO\AppData\Local\Programs\Python\Python36\lib\site-packages\rest_framework\serializers.py", line 658, in to_representation
    self.child.to_representation(item) for item in iterable
  File "D:\Users\SIMO\AppData\Local\Programs\Python\Python36\lib\site-packages\rest_framework\serializers.py", line 658, in <listcomp>
    self.child.to_representation(item) for item in iterable
  File "D:\Users\SIMO\AppData\Local\Programs\Python\Python36\lib\site-packages\rest_framework\serializers.py", line 489, in to_representation
    attribute = field.get_attribute(instance)
  File "D:\Users\SIMO\AppData\Local\Programs\Python\Python36\lib\site-packages\rest_framework\fields.py", line 462, in get_attribute
    raise type(exc)(msg)
AttributeError: Got AttributeError when attempting to get a value for field `userUpdate` on serializer `ApiInfoListSerializer`.
The serializer field might be named incorrectly and not match any attribute or key on the `ApiInfo` instance.
Original exception text was: 'ApiInfo' object has no attribute 'userUpadte'.
2018-03-05 17:15:25,919,7312,django.server,ERROR,basehttp.py:124,"GET /api/api/api_list?project_id=1&page=1&page_size=6 HTTP/1.1" 500 20919
2018-03-08 16:10:28,077,11976,django.server,ERROR,basehttp.py:124,"GET /api/project/project_list?page=1&name= HTTP/1.1" 500 59
2018-03-08 17:05:33,080,3008,django.request,ERROR,exception.py:118,Internal Server Error: /api/api/add_api
Traceback (most recent call last):
  File "D:\Users\SIMO\AppData\Local\Programs\Python\Python36\lib\site-packages\django\core\handlers\exception.py", line 35, in inner
    response = get_response(request)
  File "D:\Users\SIMO\AppData\Local\Programs\Python\Python36\lib\site-packages\django\core\handlers\base.py", line 128, in _get_response
    response = self.process_exception_by_middleware(e, request)
  File "D:\Users\SIMO\AppData\Local\Programs\Python\Python36\lib\site-packages\django\core\handlers\base.py", line 126, in _get_response
    response = wrapped_callback(request, *callback_args, **callback_kwargs)
  File "D:\Users\SIMO\AppData\Local\Programs\Python\Python36\lib\site-packages\django\views\decorators\csrf.py", line 54, in wrapped_view
    return view_func(*args, **kwargs)
  File "D:\Users\SIMO\AppData\Local\Programs\Python\Python36\lib\site-packages\django\views\generic\base.py", line 69, in view
    return self.dispatch(request, *args, **kwargs)
  File "D:\Users\SIMO\AppData\Local\Programs\Python\Python36\lib\site-packages\rest_framework\views.py", line 494, in dispatch
    response = self.handle_exception(exc)
  File "D:\Users\SIMO\AppData\Local\Programs\Python\Python36\lib\site-packages\rest_framework\views.py", line 454, in handle_exception
    self.raise_uncaught_exception(exc)
  File "D:\Users\SIMO\AppData\Local\Programs\Python\Python36\lib\site-packages\rest_framework\views.py", line 491, in dispatch
    response = handler(request, *args, **kwargs)
  File "D:\Users\SIMO\AppData\Local\Programs\Python\Python36\lib\site-packages\rest_framework\decorators.py", line 53, in handler
    return func(*args, **kwargs)
  File "H:\project\api_automation_test\api_test\common\common.py", line 66, in verify
    return func(reality_parameter)
  File "H:\project\api_automation_test\api_test\api\ApiDoc.py", line 303, in add_api
    ApiResponse(api=ApiInfo.objects.get(id=oba.id), name=response_list[i]['name'],
  File "D:\Users\SIMO\AppData\Local\Programs\Python\Python36\lib\site-packages\django\db\models\base.py", line 495, in __init__
    raise TypeError("'%s' is an invalid keyword argument for this function" % kwarg)
TypeError: 'ApiGroupLevelFirst' is an invalid keyword argument for this function
2018-03-08 17:05:33,192,3008,django.server,ERROR,basehttp.py:124,"POST /api/api/add_api HTTP/1.1" 500 19289
2018-03-08 17:08:51,120,3008,django.request,ERROR,exception.py:118,Internal Server Error: /api/api/add_api
Traceback (most recent call last):
  File "D:\Users\SIMO\AppData\Local\Programs\Python\Python36\lib\site-packages\django\core\handlers\exception.py", line 35, in inner
    response = get_response(request)
  File "D:\Users\SIMO\AppData\Local\Programs\Python\Python36\lib\site-packages\django\core\handlers\base.py", line 128, in _get_response
    response = self.process_exception_by_middleware(e, request)
  File "D:\Users\SIMO\AppData\Local\Programs\Python\Python36\lib\site-packages\django\core\handlers\base.py", line 126, in _get_response
    response = wrapped_callback(request, *callback_args, **callback_kwargs)
  File "D:\Users\SIMO\AppData\Local\Programs\Python\Python36\lib\site-packages\django\views\decorators\csrf.py", line 54, in wrapped_view
    return view_func(*args, **kwargs)
  File "D:\Users\SIMO\AppData\Local\Programs\Python\Python36\lib\site-packages\django\views\generic\base.py", line 69, in view
    return self.dispatch(request, *args, **kwargs)
  File "D:\Users\SIMO\AppData\Local\Programs\Python\Python36\lib\site-packages\rest_framework\views.py", line 494, in dispatch
    response = self.handle_exception(exc)
  File "D:\Users\SIMO\AppData\Local\Programs\Python\Python36\lib\site-packages\rest_framework\views.py", line 454, in handle_exception
    self.raise_uncaught_exception(exc)
  File "D:\Users\SIMO\AppData\Local\Programs\Python\Python36\lib\site-packages\rest_framework\views.py", line 491, in dispatch
    response = handler(request, *args, **kwargs)
  File "D:\Users\SIMO\AppData\Local\Programs\Python\Python36\lib\site-packages\rest_framework\decorators.py", line 53, in handler
    return func(*args, **kwargs)
  File "H:\project\api_automation_test\api_test\common\common.py", line 66, in verify
    return func(reality_parameter)
  File "H:\project\api_automation_test\api_test\api\ApiDoc.py", line 303, in add_api
    ApiResponse(api=ApiInfo.objects.get(id=oba.id), name=response_list[i]['name'],
  File "D:\Users\SIMO\AppData\Local\Programs\Python\Python36\lib\site-packages\django\db\models\base.py", line 495, in __init__
    raise TypeError("'%s' is an invalid keyword argument for this function" % kwarg)
TypeError: 'ApiGroupLevelFirst' is an invalid keyword argument for this function
2018-03-08 17:08:51,131,3008,django.server,ERROR,basehttp.py:124,"POST /api/api/add_api HTTP/1.1" 500 19776
2018-03-08 17:08:58,244,12880,root,ERROR,ApiDoc.py:315,error
Traceback (most recent call last):
  File "H:\project\api_automation_test\api_test\api\ApiDoc.py", line 290, in add_api
    data=code, userUpdate=User.objects.get(id=request.user.pk), description=description)
  File "D:\Users\SIMO\AppData\Local\Programs\Python\Python36\lib\site-packages\django\db\models\base.py", line 495, in __init__
    raise TypeError("'%s' is an invalid keyword argument for this function" % kwarg)
TypeError: 'ApiGroupLevelFirst' is an invalid keyword argument for this function
2018-03-08 17:08:58,245,12880,root,ERROR,ApiDoc.py:316,'ApiGroupLevelFirst' is an invalid keyword argument for this function
2018-03-08 17:10:53,544,17432,root,ERROR,ApiDoc.py:317,error
Traceback (most recent call last):
  File "H:\project\api_automation_test\api_test\api\ApiDoc.py", line 292, in add_api
    description=description)
  File "D:\Users\SIMO\AppData\Local\Programs\Python\Python36\lib\site-packages\django\db\models\base.py", line 495, in __init__
    raise TypeError("'%s' is an invalid keyword argument for this function" % kwarg)
TypeError: 'ApiGroupLevelFirst' is an invalid keyword argument for this function
2018-03-08 17:10:53,545,17432,root,ERROR,ApiDoc.py:318,'ApiGroupLevelFirst' is an invalid keyword argument for this function
2018-03-08 17:11:45,722,12020,root,ERROR,ApiDoc.py:316,error
Traceback (most recent call last):
  File "H:\project\api_automation_test\api_test\api\ApiDoc.py", line 282, in add_api
    data=code, userUpdate=User.objects.get(id=request.user.pk), description=description)
  File "D:\Users\SIMO\AppData\Local\Programs\Python\Python36\lib\site-packages\django\db\models\base.py", line 495, in __init__
    raise TypeError("'%s' is an invalid keyword argument for this function" % kwarg)
TypeError: 'requestParameterType' is an invalid keyword argument for this function
2018-03-08 17:11:45,723,12020,root,ERROR,ApiDoc.py:317,'requestParameterType' is an invalid keyword argument for this function
2018-03-08 17:12:54,171,5144,root,ERROR,ApiDoc.py:316,error
Traceback (most recent call last):
  File "H:\project\api_automation_test\api_test\api\ApiDoc.py", line 282, in add_api
    data=code, userUpdate=User.objects.get(id=request.user.pk), description=desc)
  File "D:\Users\SIMO\AppData\Local\Programs\Python\Python36\lib\site-packages\django\db\models\base.py", line 495, in __init__
    raise TypeError("'%s' is an invalid keyword argument for this function" % kwarg)
TypeError: 'requestParameterType' is an invalid keyword argument for this function
2018-03-08 17:12:54,172,5144,root,ERROR,ApiDoc.py:317,'requestParameterType' is an invalid keyword argument for this function
2018-03-08 17:14:53,719,8844,root,ERROR,ApiDoc.py:316,error
Traceback (most recent call last):
  File "H:\project\api_automation_test\api_test\api\ApiDoc.py", line 296, in add_api
    ApiHead(api=ApiInfo.objects.get(id=oba.id), name=head_dict[i]['name'],
TypeError: string indices must be integers
2018-03-08 17:14:53,720,8844,root,ERROR,ApiDoc.py:317,string indices must be integers
2018-03-08 17:15:34,626,16516,root,ERROR,ApiDoc.py:316,error
Traceback (most recent call last):
  File "H:\project\api_automation_test\api_test\api\ApiDoc.py", line 296, in add_api
    ApiHead(api=ApiInfo.objects.get(id=oba.pk), name=head_dict[i]['name'],
TypeError: string indices must be integers
2018-03-08 17:15:34,627,16516,root,ERROR,ApiDoc.py:317,string indices must be integers
2018-03-08 17:15:41,689,13368,root,ERROR,ApiDoc.py:316,error
Traceback (most recent call last):
  File "H:\project\api_automation_test\api_test\api\ApiDoc.py", line 296, in add_api
    ApiHead(api=ApiInfo.objects.get(id=oba.pk), name=head_dict[i]['name'],
TypeError: string indices must be integers
2018-03-08 17:15:41,689,13368,root,ERROR,ApiDoc.py:317,string indices must be integers
2018-03-08 17:18:26,968,18892,root,ERROR,ApiDoc.py:316,error
Traceback (most recent call last):
  File "H:\project\api_automation_test\api_test\api\ApiDoc.py", line 296, in add_api
    ApiHead(api=ApiInfo.objects.get(id=oba.pk), name=head_dict[i]['name'],
TypeError: string indices must be integers
2018-03-08 17:18:26,969,18892,root,ERROR,ApiDoc.py:317,string indices must be integers
2018-03-08 17:18:43,834,2068,root,ERROR,ApiDoc.py:317,error
Traceback (most recent call last):
  File "H:\project\api_automation_test\api_test\api\ApiDoc.py", line 297, in add_api
    ApiHead(api=ApiInfo.objects.get(id=oba.pk), name=head_dict[i]['name'],
TypeError: string indices must be integers
2018-03-08 17:18:43,835,2068,root,ERROR,ApiDoc.py:318,string indices must be integers
2018-03-08 17:19:04,996,8300,root,ERROR,ApiDoc.py:318,error
Traceback (most recent call last):
  File "H:\project\api_automation_test\api_test\api\ApiDoc.py", line 298, in add_api
    ApiHead(api=ApiInfo.objects.get(id=oba.pk), name=head_dict[i]['name'],
TypeError: string indices must be integers
2018-03-08 17:19:04,996,8300,root,ERROR,ApiDoc.py:319,string indices must be integers
2018-03-08 17:19:22,214,11716,root,ERROR,ApiDoc.py:317,error
Traceback (most recent call last):
  File "H:\project\api_automation_test\api_test\api\ApiDoc.py", line 297, in add_api
    ApiHead(api=ApiInfo.objects.get(id=oba.pk), name=head_dict[i]['name'],
TypeError: string indices must be integers
2018-03-08 17:19:22,215,11716,root,ERROR,ApiDoc.py:318,string indices must be integers
2018-03-08 17:20:45,218,3440,root,ERROR,ApiDoc.py:317,error
Traceback (most recent call last):
  File "H:\project\api_automation_test\api_test\api\ApiDoc.py", line 297, in add_api
    ApiHead(api=ApiInfo.objects.get(id=oba.pk), name=head_dict[i]['name'],
TypeError: string indices must be integers
2018-03-08 17:20:45,219,3440,root,ERROR,ApiDoc.py:318,string indices must be integers
2018-03-08 17:20:58,567,16560,root,ERROR,ApiDoc.py:317,error
Traceback (most recent call last):
  File "H:\project\api_automation_test\api_test\api\ApiDoc.py", line 297, in add_api
    ApiHead(api=ApiInfo.objects.get(id=oba.pk), name=head_dict[i]['name'],
TypeError: string indices must be integers
2018-03-08 17:20:58,567,16560,root,ERROR,ApiDoc.py:318,string indices must be integers
2018-03-08 17:23:07,334,8056,django.request,ERROR,exception.py:118,Internal Server Error: /api/api/add_api
Traceback (most recent call last):
  File "D:\Users\SIMO\AppData\Local\Programs\Python\Python36\lib\site-packages\django\core\handlers\exception.py", line 35, in inner
    response = get_response(request)
  File "D:\Users\SIMO\AppData\Local\Programs\Python\Python36\lib\site-packages\django\core\handlers\base.py", line 128, in _get_response
    response = self.process_exception_by_middleware(e, request)
  File "D:\Users\SIMO\AppData\Local\Programs\Python\Python36\lib\site-packages\django\core\handlers\base.py", line 126, in _get_response
    response = wrapped_callback(request, *callback_args, **callback_kwargs)
  File "D:\Users\SIMO\AppData\Local\Programs\Python\Python36\lib\site-packages\django\views\decorators\csrf.py", line 54, in wrapped_view
    return view_func(*args, **kwargs)
  File "D:\Users\SIMO\AppData\Local\Programs\Python\Python36\lib\site-packages\django\views\generic\base.py", line 69, in view
    return self.dispatch(request, *args, **kwargs)
  File "D:\Users\SIMO\AppData\Local\Programs\Python\Python36\lib\site-packages\rest_framework\views.py", line 494, in dispatch
    response = self.handle_exception(exc)
  File "D:\Users\SIMO\AppData\Local\Programs\Python\Python36\lib\site-packages\rest_framework\views.py", line 454, in handle_exception
    self.raise_uncaught_exception(exc)
  File "D:\Users\SIMO\AppData\Local\Programs\Python\Python36\lib\site-packages\rest_framework\views.py", line 491, in dispatch
    response = handler(request, *args, **kwargs)
  File "D:\Users\SIMO\AppData\Local\Programs\Python\Python36\lib\site-packages\rest_framework\decorators.py", line 53, in handler
    return func(*args, **kwargs)
  File "H:\project\api_automation_test\api_test\common\common.py", line 66, in verify
    return func(reality_parameter)
  File "H:\project\api_automation_test\api_test\api\ApiDoc.py", line 244, in add_api
    head_dict = list(eval(request.POST.get('headDict')))
  File "<string>", line 1, in <module>
NameError: name 'value' is not defined
2018-03-08 17:23:07,348,8056,django.server,ERROR,basehttp.py:124,"POST /api/api/add_api HTTP/1.1" 500 19497
2018-03-08 17:29:19,540,13328,root,ERROR,ApiDoc.py:320,error
Traceback (most recent call last):
  File "H:\project\api_automation_test\api_test\api\ApiDoc.py", line 299, in add_api
    i = eval(i)
  File "<string>", line 1, in <module>
NameError: name 'value' is not defined
2018-03-08 17:29:19,541,13328,root,ERROR,ApiDoc.py:321,name 'value' is not defined
2018-03-08 17:29:36,126,19108,root,ERROR,ApiDoc.py:321,error
Traceback (most recent call last):
  File "H:\project\api_automation_test\api_test\api\ApiDoc.py", line 300, in add_api
    i = eval(i)
  File "<string>", line 1, in <module>
NameError: name 'value' is not defined
2018-03-08 17:29:36,127,19108,root,ERROR,ApiDoc.py:322,name 'value' is not defined
2018-03-08 17:29:49,579,19108,root,ERROR,ApiDoc.py:321,error
Traceback (most recent call last):
  File "H:\project\api_automation_test\api_test\api\ApiDoc.py", line 300, in add_api
    i = eval(i)
  File "<string>", line 1, in <module>
NameError: name 'value' is not defined
2018-03-08 17:29:49,579,19108,root,ERROR,ApiDoc.py:322,name 'value' is not defined
2018-03-08 17:30:19,275,19108,root,ERROR,ApiDoc.py:321,error
Traceback (most recent call last):
  File "H:\project\api_automation_test\api_test\api\ApiDoc.py", line 300, in add_api
    i = eval(i)
  File "<string>", line 1, in <module>
NameError: name 'key' is not defined
2018-03-08 17:30:19,275,19108,root,ERROR,ApiDoc.py:322,name 'key' is not defined
2018-03-08 17:30:34,113,19108,root,ERROR,ApiDoc.py:321,error
Traceback (most recent call last):
  File "H:\project\api_automation_test\api_test\api\ApiDoc.py", line 300, in add_api
    i = eval(i)
  File "<string>", line 1, in <module>
NameError: name 'name1' is not defined
2018-03-08 17:30:34,113,19108,root,ERROR,ApiDoc.py:322,name 'name1' is not defined
2018-03-08 17:30:47,106,19108,root,ERROR,ApiDoc.py:321,error
Traceback (most recent call last):
  File "H:\project\api_automation_test\api_test\api\ApiDoc.py", line 300, in add_api
    i = eval(i)
  File "<string>", line 1, in <module>
NameError: name 'vase' is not defined
2018-03-08 17:30:47,106,19108,root,ERROR,ApiDoc.py:322,name 'vase' is not defined
2018-03-08 17:31:16,062,19108,root,ERROR,ApiDoc.py:321,error
Traceback (most recent call last):
  File "H:\project\api_automation_test\api_test\api\ApiDoc.py", line 304, in add_api
    ApiParameter(api=ApiInfo.objects.get(id=oba.pk), name=request_list[i]['name'],
TypeError: string indices must be integers
2018-03-08 17:31:16,062,19108,root,ERROR,ApiDoc.py:322,string indices must be integers
2018-03-08 17:33:43,553,17428,root,ERROR,ApiDoc.py:326,error
Traceback (most recent call last):
  File "H:\project\api_automation_test\api_test\api\ApiDoc.py", line 305, in add_api
    i = eval(i)
  File "<string>", line 1, in <module>
NameError: name 'value' is not defined
2018-03-08 17:33:43,555,17428,root,ERROR,ApiDoc.py:327,name 'value' is not defined
2018-03-08 17:34:33,408,17428,root,ERROR,ApiDoc.py:326,error
Traceback (most recent call last):
  File "H:\project\api_automation_test\api_test\api\ApiDoc.py", line 305, in add_api
    i = eval(i)
  File "<string>", line 1, in <module>
NameError: name 'true' is not defined
2018-03-08 17:34:33,408,17428,root,ERROR,ApiDoc.py:327,name 'true' is not defined
2018-03-08 17:34:46,456,17428,root,ERROR,ApiDoc.py:326,error
Traceback (most recent call last):
  File "H:\project\api_automation_test\api_test\api\ApiDoc.py", line 305, in add_api
    i = eval(i)
  File "<string>", line 1, in <module>
NameError: name 'true' is not defined
2018-03-08 17:34:46,457,17428,root,ERROR,ApiDoc.py:327,name 'true' is not defined
2018-03-08 17:35:04,163,17428,root,ERROR,ApiDoc.py:326,error
Traceback (most recent call last):
  File "H:\project\api_automation_test\api_test\api\ApiDoc.py", line 313, in add_api
    i = eval(i)
  File "<string>", line 1, in <module>
NameError: name 'true' is not defined
2018-03-08 17:35:04,163,17428,root,ERROR,ApiDoc.py:327,name 'true' is not defined
2018-03-08 17:35:46,301,5584,root,ERROR,ApiDoc.py:326,error
Traceback (most recent call last):
  File "H:\project\api_automation_test\api_test\api\ApiDoc.py", line 299, in add_api
    i = eval(i)
  File "<string>", line 1
    {"name": "321", value": "测试"}
                            ^
SyntaxError: invalid syntax
2018-03-08 17:35:46,327,5584,root,ERROR,ApiDoc.py:327,invalid syntax (<string>, line 1)
2018-03-08 17:42:29,202,18944,root,ERROR,ApiDoc.py:328,error
Traceback (most recent call last):
  File "D:\Users\SIMO\AppData\Local\Programs\Python\Python36\lib\site-packages\django\db\backends\mysql\base.py", line 71, in execute
    return self.cursor.execute(query, args)
  File "D:\Users\SIMO\AppData\Local\Programs\Python\Python36\lib\site-packages\MySQLdb\cursors.py", line 250, in execute
    self.errorhandler(self, exc, value)
  File "D:\Users\SIMO\AppData\Local\Programs\Python\Python36\lib\site-packages\MySQLdb\connections.py", line 50, in defaulterrorhandler
    raise errorvalue
  File "D:\Users\SIMO\AppData\Local\Programs\Python\Python36\lib\site-packages\MySQLdb\cursors.py", line 247, in execute
    res = self._query(query)
  File "D:\Users\SIMO\AppData\Local\Programs\Python\Python36\lib\site-packages\MySQLdb\cursors.py", line 411, in _query
    rowcount = self._do_query(q)
  File "D:\Users\SIMO\AppData\Local\Programs\Python\Python36\lib\site-packages\MySQLdb\cursors.py", line 374, in _do_query
    db.query(q)
  File "D:\Users\SIMO\AppData\Local\Programs\Python\Python36\lib\site-packages\MySQLdb\connections.py", line 277, in query
    _mysql.connection.query(self, query)
_mysql_exceptions.OperationalError: (1048, "Column 'status' cannot be null")

During handling of the above exception, another exception occurred:

Traceback (most recent call last):
  File "H:\project\api_automation_test\api_test\api\ApiDoc.py", line 297, in add_api
    oba.save()
  File "D:\Users\SIMO\AppData\Local\Programs\Python\Python36\lib\site-packages\django\db\models\base.py", line 729, in save
    force_update=force_update, update_fields=update_fields)
  File "D:\Users\SIMO\AppData\Local\Programs\Python\Python36\lib\site-packages\django\db\models\base.py", line 759, in save_base
    updated = self._save_table(raw, cls, force_insert, force_update, using, update_fields)
  File "D:\Users\SIMO\AppData\Local\Programs\Python\Python36\lib\site-packages\django\db\models\base.py", line 842, in _save_table
    result = self._do_insert(cls._base_manager, using, fields, update_pk, raw)
  File "D:\Users\SIMO\AppData\Local\Programs\Python\Python36\lib\site-packages\django\db\models\base.py", line 880, in _do_insert
    using=using, raw=raw)
  File "D:\Users\SIMO\AppData\Local\Programs\Python\Python36\lib\site-packages\django\db\models\manager.py", line 82, in manager_method
    return getattr(self.get_queryset(), name)(*args, **kwargs)
  File "D:\Users\SIMO\AppData\Local\Programs\Python\Python36\lib\site-packages\django\db\models\query.py", line 1125, in _insert
    return query.get_compiler(using=using).execute_sql(return_id)
  File "D:\Users\SIMO\AppData\Local\Programs\Python\Python36\lib\site-packages\django\db\models\sql\compiler.py", line 1281, in execute_sql
    cursor.execute(sql, params)
  File "D:\Users\SIMO\AppData\Local\Programs\Python\Python36\lib\site-packages\django\db\backends\utils.py", line 100, in execute
    return super().execute(sql, params)
  File "D:\Users\SIMO\AppData\Local\Programs\Python\Python36\lib\site-packages\django\db\backends\utils.py", line 68, in execute
    return self._execute_with_wrappers(sql, params, many=False, executor=self._execute)
  File "D:\Users\SIMO\AppData\Local\Programs\Python\Python36\lib\site-packages\django\db\backends\utils.py", line 77, in _execute_with_wrappers
    return executor(sql, params, many, context)
  File "D:\Users\SIMO\AppData\Local\Programs\Python\Python36\lib\site-packages\django\db\backends\utils.py", line 85, in _execute
    return self.cursor.execute(sql, params)
  File "D:\Users\SIMO\AppData\Local\Programs\Python\Python36\lib\site-packages\django\db\backends\mysql\base.py", line 76, in execute
    raise utils.IntegrityError(*tuple(e.args))
django.db.utils.IntegrityError: (1048, "Column 'status' cannot be null")
2018-03-08 17:42:29,272,18944,root,ERROR,ApiDoc.py:329,(1048, "Column 'status' cannot be null")
2018-03-08 17:43:27,616,8512,root,ERROR,ApiDoc.py:328,error
Traceback (most recent call last):
  File "H:\project\api_automation_test\api_test\api\ApiDoc.py", line 297, in add_api
    oba.save()
  File "D:\Users\SIMO\AppData\Local\Programs\Python\Python36\lib\site-packages\django\db\models\base.py", line 729, in save
    force_update=force_update, update_fields=update_fields)
  File "D:\Users\SIMO\AppData\Local\Programs\Python\Python36\lib\site-packages\django\db\models\base.py", line 759, in save_base
    updated = self._save_table(raw, cls, force_insert, force_update, using, update_fields)
  File "D:\Users\SIMO\AppData\Local\Programs\Python\Python36\lib\site-packages\django\db\models\base.py", line 842, in _save_table
    result = self._do_insert(cls._base_manager, using, fields, update_pk, raw)
  File "D:\Users\SIMO\AppData\Local\Programs\Python\Python36\lib\site-packages\django\db\models\base.py", line 880, in _do_insert
    using=using, raw=raw)
  File "D:\Users\SIMO\AppData\Local\Programs\Python\Python36\lib\site-packages\django\db\models\manager.py", line 82, in manager_method
    return getattr(self.get_queryset(), name)(*args, **kwargs)
  File "D:\Users\SIMO\AppData\Local\Programs\Python\Python36\lib\site-packages\django\db\models\query.py", line 1125, in _insert
    return query.get_compiler(using=using).execute_sql(return_id)
  File "D:\Users\SIMO\AppData\Local\Programs\Python\Python36\lib\site-packages\django\db\models\sql\compiler.py", line 1280, in execute_sql
    for sql, params in self.as_sql():
  File "D:\Users\SIMO\AppData\Local\Programs\Python\Python36\lib\site-packages\django\db\models\sql\compiler.py", line 1233, in as_sql
    for obj in self.query.objs
  File "D:\Users\SIMO\AppData\Local\Programs\Python\Python36\lib\site-packages\django\db\models\sql\compiler.py", line 1233, in <listcomp>
    for obj in self.query.objs
  File "D:\Users\SIMO\AppData\Local\Programs\Python\Python36\lib\site-packages\django\db\models\sql\compiler.py", line 1232, in <listcomp>
    [self.prepare_value(field, self.pre_save_val(field, obj)) for field in fields]
  File "D:\Users\SIMO\AppData\Local\Programs\Python\Python36\lib\site-packages\django\db\models\sql\compiler.py", line 1172, in prepare_value
    value = field.get_db_prep_save(value, connection=self.connection)
  File "D:\Users\SIMO\AppData\Local\Programs\Python\Python36\lib\site-packages\django\db\models\fields\__init__.py", line 767, in get_db_prep_save
    return self.get_db_prep_value(value, connection=connection, prepared=False)
  File "D:\Users\SIMO\AppData\Local\Programs\Python\Python36\lib\site-packages\django\db\models\fields\__init__.py", line 762, in get_db_prep_value
    value = self.get_prep_value(value)
  File "D:\Users\SIMO\AppData\Local\Programs\Python\Python36\lib\site-packages\django\db\models\fields\__init__.py", line 1024, in get_prep_value
    return self.to_python(value)
  File "D:\Users\SIMO\AppData\Local\Programs\Python\Python36\lib\site-packages\django\db\models\fields\__init__.py", line 1017, in to_python
    params={'value': value},
django.core.exceptions.ValidationError: ['’true‘ 必须为 True 或者 False。']
2018-03-08 17:43:27,644,8512,root,ERROR,ApiDoc.py:329,['’true‘ 必须为 True 或者 False。']
2018-03-08 17:43:43,188,6640,root,ERROR,ApiDoc.py:328,error
Traceback (most recent call last):
  File "H:\project\api_automation_test\api_test\api\ApiDoc.py", line 297, in add_api
    oba.save()
  File "D:\Users\SIMO\AppData\Local\Programs\Python\Python36\lib\site-packages\django\db\models\base.py", line 729, in save
    force_update=force_update, update_fields=update_fields)
  File "D:\Users\SIMO\AppData\Local\Programs\Python\Python36\lib\site-packages\django\db\models\base.py", line 759, in save_base
    updated = self._save_table(raw, cls, force_insert, force_update, using, update_fields)
  File "D:\Users\SIMO\AppData\Local\Programs\Python\Python36\lib\site-packages\django\db\models\base.py", line 842, in _save_table
    result = self._do_insert(cls._base_manager, using, fields, update_pk, raw)
  File "D:\Users\SIMO\AppData\Local\Programs\Python\Python36\lib\site-packages\django\db\models\base.py", line 880, in _do_insert
    using=using, raw=raw)
  File "D:\Users\SIMO\AppData\Local\Programs\Python\Python36\lib\site-packages\django\db\models\manager.py", line 82, in manager_method
    return getattr(self.get_queryset(), name)(*args, **kwargs)
  File "D:\Users\SIMO\AppData\Local\Programs\Python\Python36\lib\site-packages\django\db\models\query.py", line 1125, in _insert
    return query.get_compiler(using=using).execute_sql(return_id)
  File "D:\Users\SIMO\AppData\Local\Programs\Python\Python36\lib\site-packages\django\db\models\sql\compiler.py", line 1280, in execute_sql
    for sql, params in self.as_sql():
  File "D:\Users\SIMO\AppData\Local\Programs\Python\Python36\lib\site-packages\django\db\models\sql\compiler.py", line 1233, in as_sql
    for obj in self.query.objs
  File "D:\Users\SIMO\AppData\Local\Programs\Python\Python36\lib\site-packages\django\db\models\sql\compiler.py", line 1233, in <listcomp>
    for obj in self.query.objs
  File "D:\Users\SIMO\AppData\Local\Programs\Python\Python36\lib\site-packages\django\db\models\sql\compiler.py", line 1232, in <listcomp>
    [self.prepare_value(field, self.pre_save_val(field, obj)) for field in fields]
  File "D:\Users\SIMO\AppData\Local\Programs\Python\Python36\lib\site-packages\django\db\models\sql\compiler.py", line 1172, in prepare_value
    value = field.get_db_prep_save(value, connection=self.connection)
  File "D:\Users\SIMO\AppData\Local\Programs\Python\Python36\lib\site-packages\django\db\models\fields\__init__.py", line 767, in get_db_prep_save
    return self.get_db_prep_value(value, connection=connection, prepared=False)
  File "D:\Users\SIMO\AppData\Local\Programs\Python\Python36\lib\site-packages\django\db\models\fields\__init__.py", line 762, in get_db_prep_value
    value = self.get_prep_value(value)
  File "D:\Users\SIMO\AppData\Local\Programs\Python\Python36\lib\site-packages\django\db\models\fields\__init__.py", line 1024, in get_prep_value
    return self.to_python(value)
  File "D:\Users\SIMO\AppData\Local\Programs\Python\Python36\lib\site-packages\django\db\models\fields\__init__.py", line 1017, in to_python
    params={'value': value},
django.core.exceptions.ValidationError: ['’true‘ 必须为 True 或者 False。']
2018-03-08 17:43:43,190,6640,root,ERROR,ApiDoc.py:329,['’true‘ 必须为 True 或者 False。']
2018-03-08 17:44:10,150,10096,root,ERROR,ApiDoc.py:328,error
Traceback (most recent call last):
  File "H:\project\api_automation_test\api_test\api\ApiDoc.py", line 297, in add_api
    oba.save()
  File "D:\Users\SIMO\AppData\Local\Programs\Python\Python36\lib\site-packages\django\db\models\base.py", line 729, in save
    force_update=force_update, update_fields=update_fields)
  File "D:\Users\SIMO\AppData\Local\Programs\Python\Python36\lib\site-packages\django\db\models\base.py", line 759, in save_base
    updated = self._save_table(raw, cls, force_insert, force_update, using, update_fields)
  File "D:\Users\SIMO\AppData\Local\Programs\Python\Python36\lib\site-packages\django\db\models\base.py", line 842, in _save_table
    result = self._do_insert(cls._base_manager, using, fields, update_pk, raw)
  File "D:\Users\SIMO\AppData\Local\Programs\Python\Python36\lib\site-packages\django\db\models\base.py", line 880, in _do_insert
    using=using, raw=raw)
  File "D:\Users\SIMO\AppData\Local\Programs\Python\Python36\lib\site-packages\django\db\models\manager.py", line 82, in manager_method
    return getattr(self.get_queryset(), name)(*args, **kwargs)
  File "D:\Users\SIMO\AppData\Local\Programs\Python\Python36\lib\site-packages\django\db\models\query.py", line 1125, in _insert
    return query.get_compiler(using=using).execute_sql(return_id)
  File "D:\Users\SIMO\AppData\Local\Programs\Python\Python36\lib\site-packages\django\db\models\sql\compiler.py", line 1280, in execute_sql
    for sql, params in self.as_sql():
  File "D:\Users\SIMO\AppData\Local\Programs\Python\Python36\lib\site-packages\django\db\models\sql\compiler.py", line 1233, in as_sql
    for obj in self.query.objs
  File "D:\Users\SIMO\AppData\Local\Programs\Python\Python36\lib\site-packages\django\db\models\sql\compiler.py", line 1233, in <listcomp>
    for obj in self.query.objs
  File "D:\Users\SIMO\AppData\Local\Programs\Python\Python36\lib\site-packages\django\db\models\sql\compiler.py", line 1232, in <listcomp>
    [self.prepare_value(field, self.pre_save_val(field, obj)) for field in fields]
  File "D:\Users\SIMO\AppData\Local\Programs\Python\Python36\lib\site-packages\django\db\models\sql\compiler.py", line 1172, in prepare_value
    value = field.get_db_prep_save(value, connection=self.connection)
  File "D:\Users\SIMO\AppData\Local\Programs\Python\Python36\lib\site-packages\django\db\models\fields\__init__.py", line 767, in get_db_prep_save
    return self.get_db_prep_value(value, connection=connection, prepared=False)
  File "D:\Users\SIMO\AppData\Local\Programs\Python\Python36\lib\site-packages\django\db\models\fields\__init__.py", line 762, in get_db_prep_value
    value = self.get_prep_value(value)
  File "D:\Users\SIMO\AppData\Local\Programs\Python\Python36\lib\site-packages\django\db\models\fields\__init__.py", line 1024, in get_prep_value
    return self.to_python(value)
  File "D:\Users\SIMO\AppData\Local\Programs\Python\Python36\lib\site-packages\django\db\models\fields\__init__.py", line 1017, in to_python
    params={'value': value},
django.core.exceptions.ValidationError: ["’'True'‘ 必须为 True 或者 False。"]
2018-03-08 17:44:10,152,10096,root,ERROR,ApiDoc.py:329,["’'True'‘ 必须为 True 或者 False。"]
2018-03-08 17:49:38,616,16352,root,ERROR,ApiDoc.py:331,error
Traceback (most recent call last):
  File "H:\project\api_automation_test\api_test\api\ApiDoc.py", line 300, in add_api
    oba.save()
  File "D:\Users\SIMO\AppData\Local\Programs\Python\Python36\lib\site-packages\django\db\models\base.py", line 729, in save
    force_update=force_update, update_fields=update_fields)
  File "D:\Users\SIMO\AppData\Local\Programs\Python\Python36\lib\site-packages\django\db\models\base.py", line 759, in save_base
    updated = self._save_table(raw, cls, force_insert, force_update, using, update_fields)
  File "D:\Users\SIMO\AppData\Local\Programs\Python\Python36\lib\site-packages\django\db\models\base.py", line 842, in _save_table
    result = self._do_insert(cls._base_manager, using, fields, update_pk, raw)
  File "D:\Users\SIMO\AppData\Local\Programs\Python\Python36\lib\site-packages\django\db\models\base.py", line 880, in _do_insert
    using=using, raw=raw)
  File "D:\Users\SIMO\AppData\Local\Programs\Python\Python36\lib\site-packages\django\db\models\manager.py", line 82, in manager_method
    return getattr(self.get_queryset(), name)(*args, **kwargs)
  File "D:\Users\SIMO\AppData\Local\Programs\Python\Python36\lib\site-packages\django\db\models\query.py", line 1125, in _insert
    return query.get_compiler(using=using).execute_sql(return_id)
  File "D:\Users\SIMO\AppData\Local\Programs\Python\Python36\lib\site-packages\django\db\models\sql\compiler.py", line 1280, in execute_sql
    for sql, params in self.as_sql():
  File "D:\Users\SIMO\AppData\Local\Programs\Python\Python36\lib\site-packages\django\db\models\sql\compiler.py", line 1233, in as_sql
    for obj in self.query.objs
  File "D:\Users\SIMO\AppData\Local\Programs\Python\Python36\lib\site-packages\django\db\models\sql\compiler.py", line 1233, in <listcomp>
    for obj in self.query.objs
  File "D:\Users\SIMO\AppData\Local\Programs\Python\Python36\lib\site-packages\django\db\models\sql\compiler.py", line 1232, in <listcomp>
    [self.prepare_value(field, self.pre_save_val(field, obj)) for field in fields]
  File "D:\Users\SIMO\AppData\Local\Programs\Python\Python36\lib\site-packages\django\db\models\sql\compiler.py", line 1172, in prepare_value
    value = field.get_db_prep_save(value, connection=self.connection)
  File "D:\Users\SIMO\AppData\Local\Programs\Python\Python36\lib\site-packages\django\db\models\fields\__init__.py", line 767, in get_db_prep_save
    return self.get_db_prep_value(value, connection=connection, prepared=False)
  File "D:\Users\SIMO\AppData\Local\Programs\Python\Python36\lib\site-packages\django\db\models\fields\__init__.py", line 762, in get_db_prep_value
    value = self.get_prep_value(value)
  File "D:\Users\SIMO\AppData\Local\Programs\Python\Python36\lib\site-packages\django\db\models\fields\__init__.py", line 1024, in get_prep_value
    return self.to_python(value)
  File "D:\Users\SIMO\AppData\Local\Programs\Python\Python36\lib\site-packages\django\db\models\fields\__init__.py", line 1017, in to_python
    params={'value': value},
django.core.exceptions.ValidationError: ['’true‘ 必须为 True 或者 False。']
2018-03-08 17:49:38,618,16352,root,ERROR,ApiDoc.py:332,['’true‘ 必须为 True 或者 False。']
2018-03-08 17:49:54,402,12788,root,ERROR,ApiDoc.py:331,error
Traceback (most recent call last):
  File "H:\project\api_automation_test\api_test\api\ApiDoc.py", line 300, in add_api
    oba.save()
  File "D:\Users\SIMO\AppData\Local\Programs\Python\Python36\lib\site-packages\django\db\models\base.py", line 729, in save
    force_update=force_update, update_fields=update_fields)
  File "D:\Users\SIMO\AppData\Local\Programs\Python\Python36\lib\site-packages\django\db\models\base.py", line 759, in save_base
    updated = self._save_table(raw, cls, force_insert, force_update, using, update_fields)
  File "D:\Users\SIMO\AppData\Local\Programs\Python\Python36\lib\site-packages\django\db\models\base.py", line 842, in _save_table
    result = self._do_insert(cls._base_manager, using, fields, update_pk, raw)
  File "D:\Users\SIMO\AppData\Local\Programs\Python\Python36\lib\site-packages\django\db\models\base.py", line 880, in _do_insert
    using=using, raw=raw)
  File "D:\Users\SIMO\AppData\Local\Programs\Python\Python36\lib\site-packages\django\db\models\manager.py", line 82, in manager_method
    return getattr(self.get_queryset(), name)(*args, **kwargs)
  File "D:\Users\SIMO\AppData\Local\Programs\Python\Python36\lib\site-packages\django\db\models\query.py", line 1125, in _insert
    return query.get_compiler(using=using).execute_sql(return_id)
  File "D:\Users\SIMO\AppData\Local\Programs\Python\Python36\lib\site-packages\django\db\models\sql\compiler.py", line 1280, in execute_sql
    for sql, params in self.as_sql():
  File "D:\Users\SIMO\AppData\Local\Programs\Python\Python36\lib\site-packages\django\db\models\sql\compiler.py", line 1233, in as_sql
    for obj in self.query.objs
  File "D:\Users\SIMO\AppData\Local\Programs\Python\Python36\lib\site-packages\django\db\models\sql\compiler.py", line 1233, in <listcomp>
    for obj in self.query.objs
  File "D:\Users\SIMO\AppData\Local\Programs\Python\Python36\lib\site-packages\django\db\models\sql\compiler.py", line 1232, in <listcomp>
    [self.prepare_value(field, self.pre_save_val(field, obj)) for field in fields]
  File "D:\Users\SIMO\AppData\Local\Programs\Python\Python36\lib\site-packages\django\db\models\sql\compiler.py", line 1172, in prepare_value
    value = field.get_db_prep_save(value, connection=self.connection)
  File "D:\Users\SIMO\AppData\Local\Programs\Python\Python36\lib\site-packages\django\db\models\fields\__init__.py", line 767, in get_db_prep_save
    return self.get_db_prep_value(value, connection=connection, prepared=False)
  File "D:\Users\SIMO\AppData\Local\Programs\Python\Python36\lib\site-packages\django\db\models\fields\__init__.py", line 762, in get_db_prep_value
    value = self.get_prep_value(value)
  File "D:\Users\SIMO\AppData\Local\Programs\Python\Python36\lib\site-packages\django\db\models\fields\__init__.py", line 1024, in get_prep_value
    return self.to_python(value)
  File "D:\Users\SIMO\AppData\Local\Programs\Python\Python36\lib\site-packages\django\db\models\fields\__init__.py", line 1017, in to_python
    params={'value': value},
django.core.exceptions.ValidationError: ['’true‘ 必须为 True 或者 False。']
2018-03-08 17:49:54,405,12788,root,ERROR,ApiDoc.py:332,['’true‘ 必须为 True 或者 False。']
2018-03-08 18:08:04,928,1812,django.request,ERROR,exception.py:118,Internal Server Error: /admin/api_test/apiinfo/1/change/
Traceback (most recent call last):
  File "D:\Users\SIMO\AppData\Local\Programs\Python\Python36\lib\site-packages\django\contrib\admin\options.py", line 668, in get_form
    return modelform_factory(self.model, **defaults)
  File "D:\Users\SIMO\AppData\Local\Programs\Python\Python36\lib\site-packages\django\forms\models.py", line 549, in modelform_factory
    return type(form)(class_name, (form,), form_class_attrs)
  File "D:\Users\SIMO\AppData\Local\Programs\Python\Python36\lib\site-packages\django\forms\models.py", line 266, in __new__
    raise FieldError(message)
django.core.exceptions.FieldError: Unknown field(s) (response) specified for ApiInfo

During handling of the above exception, another exception occurred:

Traceback (most recent call last):
  File "D:\Users\SIMO\AppData\Local\Programs\Python\Python36\lib\site-packages\django\core\handlers\exception.py", line 35, in inner
    response = get_response(request)
  File "D:\Users\SIMO\AppData\Local\Programs\Python\Python36\lib\site-packages\django\core\handlers\base.py", line 128, in _get_response
    response = self.process_exception_by_middleware(e, request)
  File "D:\Users\SIMO\AppData\Local\Programs\Python\Python36\lib\site-packages\django\core\handlers\base.py", line 126, in _get_response
    response = wrapped_callback(request, *callback_args, **callback_kwargs)
  File "D:\Users\SIMO\AppData\Local\Programs\Python\Python36\lib\site-packages\django\contrib\admin\options.py", line 574, in wrapper
    return self.admin_site.admin_view(view)(*args, **kwargs)
  File "D:\Users\SIMO\AppData\Local\Programs\Python\Python36\lib\site-packages\django\utils\decorators.py", line 142, in _wrapped_view
    response = view_func(request, *args, **kwargs)
  File "D:\Users\SIMO\AppData\Local\Programs\Python\Python36\lib\site-packages\django\views\decorators\cache.py", line 44, in _wrapped_view_func
    response = view_func(request, *args, **kwargs)
  File "D:\Users\SIMO\AppData\Local\Programs\Python\Python36\lib\site-packages\django\contrib\admin\sites.py", line 223, in inner
    return view(request, *args, **kwargs)
  File "D:\Users\SIMO\AppData\Local\Programs\Python\Python36\lib\site-packages\django\contrib\admin\options.py", line 1556, in change_view
    return self.changeform_view(request, object_id, form_url, extra_context)
  File "D:\Users\SIMO\AppData\Local\Programs\Python\Python36\lib\site-packages\django\utils\decorators.py", line 62, in _wrapper
    return bound_func(*args, **kwargs)
  File "D:\Users\SIMO\AppData\Local\Programs\Python\Python36\lib\site-packages\django\utils\decorators.py", line 142, in _wrapped_view
    response = view_func(request, *args, **kwargs)
  File "D:\Users\SIMO\AppData\Local\Programs\Python\Python36\lib\site-packages\django\utils\decorators.py", line 58, in bound_func
    return func.__get__(self, type(self))(*args2, **kwargs2)
  File "D:\Users\SIMO\AppData\Local\Programs\Python\Python36\lib\site-packages\django\contrib\admin\options.py", line 1450, in changeform_view
    return self._changeform_view(request, object_id, form_url, extra_context)
  File "D:\Users\SIMO\AppData\Local\Programs\Python\Python36\lib\site-packages\django\contrib\admin\options.py", line 1479, in _changeform_view
    ModelForm = self.get_form(request, obj)
  File "D:\Users\SIMO\AppData\Local\Programs\Python\Python36\lib\site-packages\django\contrib\admin\options.py", line 672, in get_form
    % (e, self.__class__.__name__)
django.core.exceptions.FieldError: Unknown field(s) (response) specified for ApiInfo. Check fields/fieldsets/exclude attributes of class ApiInfoForm.
2018-03-08 18:08:05,015,1812,django.server,ERROR,basehttp.py:124,"GET /admin/api_test/apiinfo/1/change/ HTTP/1.1" 500 144263
2018-03-08 18:10:51,776,10736,root,ERROR,ApiDoc.py:464,ERROR
Traceback (most recent call last):
  File "H:\project\api_automation_test\api_test\api\ApiDoc.py", line 424, in update_api
    if i['id']:
KeyError: 'id'
2018-03-08 18:10:51,777,10736,root,ERROR,ApiDoc.py:465,'id'
2018-03-08 18:11:19,202,8976,root,ERROR,ApiDoc.py:465,ERROR
Traceback (most recent call last):
  File "H:\project\api_automation_test\api_test\api\ApiDoc.py", line 425, in update_api
    if i['id']:
KeyError: 'id'
2018-03-08 18:11:19,202,8976,root,ERROR,ApiDoc.py:466,'id'
2018-03-08 18:12:37,118,8976,root,ERROR,ApiDoc.py:465,ERROR
Traceback (most recent call last):
  File "H:\project\api_automation_test\api_test\api\ApiDoc.py", line 423, in update_api
    i = eval(i)
  File "<string>", line 1
    {"id":“”, "name": "321", "value": "测试"}
           ^
SyntaxError: invalid character in identifier
2018-03-08 18:12:37,118,8976,root,ERROR,ApiDoc.py:466,invalid character in identifier (<string>, line 1)
2018-03-09 17:15:18,877,504,root,ERROR,ApiDoc.py:337,error
Traceback (most recent call last):
  File "H:\project\api_automation_test\api_test\api\ApiDoc.py", line 297, in add_api
    description=desc)
  File "D:\Users\SIMO\AppData\Local\Programs\Python\Python36\lib\site-packages\django\db\models\base.py", line 495, in __init__
    raise TypeError("'%s' is an invalid keyword argument for this function" % kwarg)
TypeError: 'ApiGroupLevelFirst' is an invalid keyword argument for this function
2018-03-09 17:15:18,918,504,root,ERROR,ApiDoc.py:338,'ApiGroupLevelFirst' is an invalid keyword argument for this function
2018-03-14 11:58:38,488,13408,django.request,ERROR,exception.py:118,Internal Server Error: /api/api/api_info
Traceback (most recent call last):
  File "D:\Users\SIMO\AppData\Local\Programs\Python\Python36\lib\site-packages\django\core\handlers\exception.py", line 35, in inner
    response = get_response(request)
  File "D:\Users\SIMO\AppData\Local\Programs\Python\Python36\lib\site-packages\django\core\handlers\base.py", line 128, in _get_response
    response = self.process_exception_by_middleware(e, request)
  File "D:\Users\SIMO\AppData\Local\Programs\Python\Python36\lib\site-packages\django\core\handlers\base.py", line 126, in _get_response
    response = wrapped_callback(request, *callback_args, **callback_kwargs)
  File "D:\Users\SIMO\AppData\Local\Programs\Python\Python36\lib\site-packages\django\views\decorators\csrf.py", line 54, in wrapped_view
    return view_func(*args, **kwargs)
  File "D:\Users\SIMO\AppData\Local\Programs\Python\Python36\lib\site-packages\django\views\generic\base.py", line 69, in view
    return self.dispatch(request, *args, **kwargs)
  File "D:\Users\SIMO\AppData\Local\Programs\Python\Python36\lib\site-packages\rest_framework\views.py", line 494, in dispatch
    response = self.handle_exception(exc)
  File "D:\Users\SIMO\AppData\Local\Programs\Python\Python36\lib\site-packages\rest_framework\views.py", line 454, in handle_exception
    self.raise_uncaught_exception(exc)
  File "D:\Users\SIMO\AppData\Local\Programs\Python\Python36\lib\site-packages\rest_framework\views.py", line 491, in dispatch
    response = handler(request, *args, **kwargs)
  File "D:\Users\SIMO\AppData\Local\Programs\Python\Python36\lib\site-packages\rest_framework\decorators.py", line 53, in handler
    return func(*args, **kwargs)
  File "H:\project\api_automation_test\api_test\common\common.py", line 66, in verify
    return func(reality_parameter)
  File "H:\project\api_automation_test\api_test\api\ApiDoc.py", line 576, in api_info
    return JsonResponse(data=serialize.data, code_msg=GlobalStatusCode.success())
  File "D:\Users\SIMO\AppData\Local\Programs\Python\Python36\lib\site-packages\rest_framework\serializers.py", line 535, in data
    ret = super(Serializer, self).data
  File "D:\Users\SIMO\AppData\Local\Programs\Python\Python36\lib\site-packages\rest_framework\serializers.py", line 260, in data
    self._data = self.to_representation(self.instance)
  File "D:\Users\SIMO\AppData\Local\Programs\Python\Python36\lib\site-packages\rest_framework\serializers.py", line 502, in to_representation
    ret[field.field_name] = field.to_representation(attribute)
  File "D:\Users\SIMO\AppData\Local\Programs\Python\Python36\lib\site-packages\rest_framework\serializers.py", line 658, in to_representation
    self.child.to_representation(item) for item in iterable
  File "D:\Users\SIMO\AppData\Local\Programs\Python\Python36\lib\site-packages\rest_framework\serializers.py", line 658, in <listcomp>
    self.child.to_representation(item) for item in iterable
  File "D:\Users\SIMO\AppData\Local\Programs\Python\Python36\lib\site-packages\rest_framework\serializers.py", line 485, in to_representation
    fields = self._readable_fields
  File "D:\Users\SIMO\AppData\Local\Programs\Python\Python36\lib\site-packages\django\utils\functional.py", line 36, in __get__
    res = instance.__dict__[self.name] = self.func(instance)
  File "D:\Users\SIMO\AppData\Local\Programs\Python\Python36\lib\site-packages\rest_framework\serializers.py", line 375, in _readable_fields
    field for field in self.fields.values()
  File "D:\Users\SIMO\AppData\Local\Programs\Python\Python36\lib\site-packages\rest_framework\serializers.py", line 361, in fields
    for key, value in self.get_fields().items():
  File "D:\Users\SIMO\AppData\Local\Programs\Python\Python36\lib\site-packages\rest_framework\serializers.py", line 1020, in get_fields
    source, info, model, depth
  File "D:\Users\SIMO\AppData\Local\Programs\Python\Python36\lib\site-packages\rest_framework\serializers.py", line 1165, in build_field
    return self.build_unknown_field(field_name, model_class)
  File "D:\Users\SIMO\AppData\Local\Programs\Python\Python36\lib\site-packages\rest_framework\serializers.py", line 1277, in build_unknown_field
    (field_name, model_class.__name__)
django.core.exceptions.ImproperlyConfigured: Field name `restrict` is not valid for model `ApiResponse`.
2018-03-14 11:58:38,701,13408,django.server,ERROR,basehttp.py:124,"GET /api/api/api_info?api_id=13&project_id=1 HTTP/1.1" 500 21113
2018-03-14 13:28:54,895,2588,django.request,ERROR,exception.py:118,Internal Server Error: /api/api/api_info
Traceback (most recent call last):
  File "D:\Users\SIMO\AppData\Local\Programs\Python\Python36\lib\site-packages\rest_framework\fields.py", line 441, in get_attribute
    return get_attribute(instance, self.source_attrs)
  File "D:\Users\SIMO\AppData\Local\Programs\Python\Python36\lib\site-packages\rest_framework\fields.py", line 100, in get_attribute
    instance = getattr(instance, attr)
AttributeError: 'ApiInfo' object has no attribute 'user'

During handling of the above exception, another exception occurred:

Traceback (most recent call last):
  File "D:\Users\SIMO\AppData\Local\Programs\Python\Python36\lib\site-packages\django\core\handlers\exception.py", line 35, in inner
    response = get_response(request)
  File "D:\Users\SIMO\AppData\Local\Programs\Python\Python36\lib\site-packages\django\core\handlers\base.py", line 128, in _get_response
    response = self.process_exception_by_middleware(e, request)
  File "D:\Users\SIMO\AppData\Local\Programs\Python\Python36\lib\site-packages\django\core\handlers\base.py", line 126, in _get_response
    response = wrapped_callback(request, *callback_args, **callback_kwargs)
  File "D:\Users\SIMO\AppData\Local\Programs\Python\Python36\lib\site-packages\django\views\decorators\csrf.py", line 54, in wrapped_view
    return view_func(*args, **kwargs)
  File "D:\Users\SIMO\AppData\Local\Programs\Python\Python36\lib\site-packages\django\views\generic\base.py", line 69, in view
    return self.dispatch(request, *args, **kwargs)
  File "D:\Users\SIMO\AppData\Local\Programs\Python\Python36\lib\site-packages\rest_framework\views.py", line 494, in dispatch
    response = self.handle_exception(exc)
  File "D:\Users\SIMO\AppData\Local\Programs\Python\Python36\lib\site-packages\rest_framework\views.py", line 454, in handle_exception
    self.raise_uncaught_exception(exc)
  File "D:\Users\SIMO\AppData\Local\Programs\Python\Python36\lib\site-packages\rest_framework\views.py", line 491, in dispatch
    response = handler(request, *args, **kwargs)
  File "D:\Users\SIMO\AppData\Local\Programs\Python\Python36\lib\site-packages\rest_framework\decorators.py", line 53, in handler
    return func(*args, **kwargs)
  File "H:\project\api_automation_test\api_test\common\common.py", line 66, in verify
    return func(reality_parameter)
  File "H:\project\api_automation_test\api_test\api\ApiDoc.py", line 576, in api_info
    return JsonResponse(data=serialize.data, code_msg=GlobalStatusCode.success())
  File "D:\Users\SIMO\AppData\Local\Programs\Python\Python36\lib\site-packages\rest_framework\serializers.py", line 535, in data
    ret = super(Serializer, self).data
  File "D:\Users\SIMO\AppData\Local\Programs\Python\Python36\lib\site-packages\rest_framework\serializers.py", line 260, in data
    self._data = self.to_representation(self.instance)
  File "D:\Users\SIMO\AppData\Local\Programs\Python\Python36\lib\site-packages\rest_framework\serializers.py", line 489, in to_representation
    attribute = field.get_attribute(instance)
  File "D:\Users\SIMO\AppData\Local\Programs\Python\Python36\lib\site-packages\rest_framework\fields.py", line 462, in get_attribute
    raise type(exc)(msg)
AttributeError: Got AttributeError when attempting to get a value for field `userUpdate` on serializer `ApiInfoSerializer`.
The serializer field might be named incorrectly and not match any attribute or key on the `ApiInfo` instance.
Original exception text was: 'ApiInfo' object has no attribute 'user'.
2018-03-14 13:28:55,092,2588,django.server,ERROR,basehttp.py:124,"GET /api/api/api_info?project_id=1&api_id=13 HTTP/1.1" 500 20451
2018-03-14 13:28:58,602,2588,django.request,ERROR,exception.py:118,Internal Server Error: /api/api/api_info
Traceback (most recent call last):
  File "D:\Users\SIMO\AppData\Local\Programs\Python\Python36\lib\site-packages\rest_framework\fields.py", line 441, in get_attribute
    return get_attribute(instance, self.source_attrs)
  File "D:\Users\SIMO\AppData\Local\Programs\Python\Python36\lib\site-packages\rest_framework\fields.py", line 100, in get_attribute
    instance = getattr(instance, attr)
AttributeError: 'ApiInfo' object has no attribute 'user'

During handling of the above exception, another exception occurred:

Traceback (most recent call last):
  File "D:\Users\SIMO\AppData\Local\Programs\Python\Python36\lib\site-packages\django\core\handlers\exception.py", line 35, in inner
    response = get_response(request)
  File "D:\Users\SIMO\AppData\Local\Programs\Python\Python36\lib\site-packages\django\core\handlers\base.py", line 128, in _get_response
    response = self.process_exception_by_middleware(e, request)
  File "D:\Users\SIMO\AppData\Local\Programs\Python\Python36\lib\site-packages\django\core\handlers\base.py", line 126, in _get_response
    response = wrapped_callback(request, *callback_args, **callback_kwargs)
  File "D:\Users\SIMO\AppData\Local\Programs\Python\Python36\lib\site-packages\django\views\decorators\csrf.py", line 54, in wrapped_view
    return view_func(*args, **kwargs)
  File "D:\Users\SIMO\AppData\Local\Programs\Python\Python36\lib\site-packages\django\views\generic\base.py", line 69, in view
    return self.dispatch(request, *args, **kwargs)
  File "D:\Users\SIMO\AppData\Local\Programs\Python\Python36\lib\site-packages\rest_framework\views.py", line 494, in dispatch
    response = self.handle_exception(exc)
  File "D:\Users\SIMO\AppData\Local\Programs\Python\Python36\lib\site-packages\rest_framework\views.py", line 454, in handle_exception
    self.raise_uncaught_exception(exc)
  File "D:\Users\SIMO\AppData\Local\Programs\Python\Python36\lib\site-packages\rest_framework\views.py", line 491, in dispatch
    response = handler(request, *args, **kwargs)
  File "D:\Users\SIMO\AppData\Local\Programs\Python\Python36\lib\site-packages\rest_framework\decorators.py", line 53, in handler
    return func(*args, **kwargs)
  File "H:\project\api_automation_test\api_test\common\common.py", line 66, in verify
    return func(reality_parameter)
  File "H:\project\api_automation_test\api_test\api\ApiDoc.py", line 576, in api_info
    return JsonResponse(data=serialize.data, code_msg=GlobalStatusCode.success())
  File "D:\Users\SIMO\AppData\Local\Programs\Python\Python36\lib\site-packages\rest_framework\serializers.py", line 535, in data
    ret = super(Serializer, self).data
  File "D:\Users\SIMO\AppData\Local\Programs\Python\Python36\lib\site-packages\rest_framework\serializers.py", line 260, in data
    self._data = self.to_representation(self.instance)
  File "D:\Users\SIMO\AppData\Local\Programs\Python\Python36\lib\site-packages\rest_framework\serializers.py", line 489, in to_representation
    attribute = field.get_attribute(instance)
  File "D:\Users\SIMO\AppData\Local\Programs\Python\Python36\lib\site-packages\rest_framework\fields.py", line 462, in get_attribute
    raise type(exc)(msg)
AttributeError: Got AttributeError when attempting to get a value for field `userUpdate` on serializer `ApiInfoSerializer`.
The serializer field might be named incorrectly and not match any attribute or key on the `ApiInfo` instance.
Original exception text was: 'ApiInfo' object has no attribute 'user'.
2018-03-14 13:28:58,627,2588,django.server,ERROR,basehttp.py:124,"GET /api/api/api_info?project_id=1&api_id=13 HTTP/1.1" 500 20451
2018-03-14 13:29:04,352,2588,django.request,ERROR,exception.py:118,Internal Server Error: /api/api/api_info
Traceback (most recent call last):
  File "D:\Users\SIMO\AppData\Local\Programs\Python\Python36\lib\site-packages\rest_framework\fields.py", line 441, in get_attribute
    return get_attribute(instance, self.source_attrs)
  File "D:\Users\SIMO\AppData\Local\Programs\Python\Python36\lib\site-packages\rest_framework\fields.py", line 100, in get_attribute
    instance = getattr(instance, attr)
AttributeError: 'ApiInfo' object has no attribute 'user'

During handling of the above exception, another exception occurred:

Traceback (most recent call last):
  File "D:\Users\SIMO\AppData\Local\Programs\Python\Python36\lib\site-packages\django\core\handlers\exception.py", line 35, in inner
    response = get_response(request)
  File "D:\Users\SIMO\AppData\Local\Programs\Python\Python36\lib\site-packages\django\core\handlers\base.py", line 128, in _get_response
    response = self.process_exception_by_middleware(e, request)
  File "D:\Users\SIMO\AppData\Local\Programs\Python\Python36\lib\site-packages\django\core\handlers\base.py", line 126, in _get_response
    response = wrapped_callback(request, *callback_args, **callback_kwargs)
  File "D:\Users\SIMO\AppData\Local\Programs\Python\Python36\lib\site-packages\django\views\decorators\csrf.py", line 54, in wrapped_view
    return view_func(*args, **kwargs)
  File "D:\Users\SIMO\AppData\Local\Programs\Python\Python36\lib\site-packages\django\views\generic\base.py", line 69, in view
    return self.dispatch(request, *args, **kwargs)
  File "D:\Users\SIMO\AppData\Local\Programs\Python\Python36\lib\site-packages\rest_framework\views.py", line 494, in dispatch
    response = self.handle_exception(exc)
  File "D:\Users\SIMO\AppData\Local\Programs\Python\Python36\lib\site-packages\rest_framework\views.py", line 454, in handle_exception
    self.raise_uncaught_exception(exc)
  File "D:\Users\SIMO\AppData\Local\Programs\Python\Python36\lib\site-packages\rest_framework\views.py", line 491, in dispatch
    response = handler(request, *args, **kwargs)
  File "D:\Users\SIMO\AppData\Local\Programs\Python\Python36\lib\site-packages\rest_framework\decorators.py", line 53, in handler
    return func(*args, **kwargs)
  File "H:\project\api_automation_test\api_test\common\common.py", line 66, in verify
    return func(reality_parameter)
  File "H:\project\api_automation_test\api_test\api\ApiDoc.py", line 576, in api_info
    return JsonResponse(data=serialize.data, code_msg=GlobalStatusCode.success())
  File "D:\Users\SIMO\AppData\Local\Programs\Python\Python36\lib\site-packages\rest_framework\serializers.py", line 535, in data
    ret = super(Serializer, self).data
  File "D:\Users\SIMO\AppData\Local\Programs\Python\Python36\lib\site-packages\rest_framework\serializers.py", line 260, in data
    self._data = self.to_representation(self.instance)
  File "D:\Users\SIMO\AppData\Local\Programs\Python\Python36\lib\site-packages\rest_framework\serializers.py", line 489, in to_representation
    attribute = field.get_attribute(instance)
  File "D:\Users\SIMO\AppData\Local\Programs\Python\Python36\lib\site-packages\rest_framework\fields.py", line 462, in get_attribute
    raise type(exc)(msg)
AttributeError: Got AttributeError when attempting to get a value for field `userUpdate` on serializer `ApiInfoSerializer`.
The serializer field might be named incorrectly and not match any attribute or key on the `ApiInfo` instance.
Original exception text was: 'ApiInfo' object has no attribute 'user'.
2018-03-14 13:29:04,376,2588,django.server,ERROR,basehttp.py:124,"GET /api/api/api_info?api_id=13&project_id=1 HTTP/1.1" 500 20488
2018-03-14 13:30:14,495,9980,django.request,ERROR,exception.py:118,Internal Server Error: /api/api/api_info
Traceback (most recent call last):
  File "D:\Users\SIMO\AppData\Local\Programs\Python\Python36\lib\site-packages\rest_framework\fields.py", line 441, in get_attribute
    return get_attribute(instance, self.source_attrs)
  File "D:\Users\SIMO\AppData\Local\Programs\Python\Python36\lib\site-packages\rest_framework\fields.py", line 100, in get_attribute
    instance = getattr(instance, attr)
AttributeError: 'ApiInfo' object has no attribute 'ApiUpdateUser'

During handling of the above exception, another exception occurred:

Traceback (most recent call last):
  File "D:\Users\SIMO\AppData\Local\Programs\Python\Python36\lib\site-packages\django\core\handlers\exception.py", line 35, in inner
    response = get_response(request)
  File "D:\Users\SIMO\AppData\Local\Programs\Python\Python36\lib\site-packages\django\core\handlers\base.py", line 128, in _get_response
    response = self.process_exception_by_middleware(e, request)
  File "D:\Users\SIMO\AppData\Local\Programs\Python\Python36\lib\site-packages\django\core\handlers\base.py", line 126, in _get_response
    response = wrapped_callback(request, *callback_args, **callback_kwargs)
  File "D:\Users\SIMO\AppData\Local\Programs\Python\Python36\lib\site-packages\django\views\decorators\csrf.py", line 54, in wrapped_view
    return view_func(*args, **kwargs)
  File "D:\Users\SIMO\AppData\Local\Programs\Python\Python36\lib\site-packages\django\views\generic\base.py", line 69, in view
    return self.dispatch(request, *args, **kwargs)
  File "D:\Users\SIMO\AppData\Local\Programs\Python\Python36\lib\site-packages\rest_framework\views.py", line 494, in dispatch
    response = self.handle_exception(exc)
  File "D:\Users\SIMO\AppData\Local\Programs\Python\Python36\lib\site-packages\rest_framework\views.py", line 454, in handle_exception
    self.raise_uncaught_exception(exc)
  File "D:\Users\SIMO\AppData\Local\Programs\Python\Python36\lib\site-packages\rest_framework\views.py", line 491, in dispatch
    response = handler(request, *args, **kwargs)
  File "D:\Users\SIMO\AppData\Local\Programs\Python\Python36\lib\site-packages\rest_framework\decorators.py", line 53, in handler
    return func(*args, **kwargs)
  File "H:\project\api_automation_test\api_test\common\common.py", line 66, in verify
    return func(reality_parameter)
  File "H:\project\api_automation_test\api_test\api\ApiDoc.py", line 576, in api_info
    return JsonResponse(data=serialize.data, code_msg=GlobalStatusCode.success())
  File "D:\Users\SIMO\AppData\Local\Programs\Python\Python36\lib\site-packages\rest_framework\serializers.py", line 535, in data
    ret = super(Serializer, self).data
  File "D:\Users\SIMO\AppData\Local\Programs\Python\Python36\lib\site-packages\rest_framework\serializers.py", line 260, in data
    self._data = self.to_representation(self.instance)
  File "D:\Users\SIMO\AppData\Local\Programs\Python\Python36\lib\site-packages\rest_framework\serializers.py", line 489, in to_representation
    attribute = field.get_attribute(instance)
  File "D:\Users\SIMO\AppData\Local\Programs\Python\Python36\lib\site-packages\rest_framework\fields.py", line 462, in get_attribute
    raise type(exc)(msg)
AttributeError: Got AttributeError when attempting to get a value for field `userUpdate` on serializer `ApiInfoSerializer`.
The serializer field might be named incorrectly and not match any attribute or key on the `ApiInfo` instance.
Original exception text was: 'ApiInfo' object has no attribute 'ApiUpdateUser'.
2018-03-14 13:30:14,523,9980,django.server,ERROR,basehttp.py:124,"GET /api/api/api_info?api_id=13&project_id=1 HTTP/1.1" 500 20515
2018-03-14 13:30:53,975,10632,django.request,ERROR,exception.py:118,Internal Server Error: /api/api/api_info
Traceback (most recent call last):
  File "D:\Users\SIMO\AppData\Local\Programs\Python\Python36\lib\site-packages\rest_framework\fields.py", line 441, in get_attribute
    return get_attribute(instance, self.source_attrs)
  File "D:\Users\SIMO\AppData\Local\Programs\Python\Python36\lib\site-packages\rest_framework\fields.py", line 100, in get_attribute
    instance = getattr(instance, attr)
AttributeError: 'ApiInfo' object has no attribute 'user'

During handling of the above exception, another exception occurred:

Traceback (most recent call last):
  File "D:\Users\SIMO\AppData\Local\Programs\Python\Python36\lib\site-packages\django\core\handlers\exception.py", line 35, in inner
    response = get_response(request)
  File "D:\Users\SIMO\AppData\Local\Programs\Python\Python36\lib\site-packages\django\core\handlers\base.py", line 128, in _get_response
    response = self.process_exception_by_middleware(e, request)
  File "D:\Users\SIMO\AppData\Local\Programs\Python\Python36\lib\site-packages\django\core\handlers\base.py", line 126, in _get_response
    response = wrapped_callback(request, *callback_args, **callback_kwargs)
  File "D:\Users\SIMO\AppData\Local\Programs\Python\Python36\lib\site-packages\django\views\decorators\csrf.py", line 54, in wrapped_view
    return view_func(*args, **kwargs)
  File "D:\Users\SIMO\AppData\Local\Programs\Python\Python36\lib\site-packages\django\views\generic\base.py", line 69, in view
    return self.dispatch(request, *args, **kwargs)
  File "D:\Users\SIMO\AppData\Local\Programs\Python\Python36\lib\site-packages\rest_framework\views.py", line 494, in dispatch
    response = self.handle_exception(exc)
  File "D:\Users\SIMO\AppData\Local\Programs\Python\Python36\lib\site-packages\rest_framework\views.py", line 454, in handle_exception
    self.raise_uncaught_exception(exc)
  File "D:\Users\SIMO\AppData\Local\Programs\Python\Python36\lib\site-packages\rest_framework\views.py", line 491, in dispatch
    response = handler(request, *args, **kwargs)
  File "D:\Users\SIMO\AppData\Local\Programs\Python\Python36\lib\site-packages\rest_framework\decorators.py", line 53, in handler
    return func(*args, **kwargs)
  File "H:\project\api_automation_test\api_test\common\common.py", line 66, in verify
    return func(reality_parameter)
  File "H:\project\api_automation_test\api_test\api\ApiDoc.py", line 576, in api_info
    return JsonResponse(data=serialize.data, code_msg=GlobalStatusCode.success())
  File "D:\Users\SIMO\AppData\Local\Programs\Python\Python36\lib\site-packages\rest_framework\serializers.py", line 535, in data
    ret = super(Serializer, self).data
  File "D:\Users\SIMO\AppData\Local\Programs\Python\Python36\lib\site-packages\rest_framework\serializers.py", line 260, in data
    self._data = self.to_representation(self.instance)
  File "D:\Users\SIMO\AppData\Local\Programs\Python\Python36\lib\site-packages\rest_framework\serializers.py", line 489, in to_representation
    attribute = field.get_attribute(instance)
  File "D:\Users\SIMO\AppData\Local\Programs\Python\Python36\lib\site-packages\rest_framework\fields.py", line 462, in get_attribute
    raise type(exc)(msg)
AttributeError: Got AttributeError when attempting to get a value for field `userUpdate` on serializer `ApiInfoSerializer`.
The serializer field might be named incorrectly and not match any attribute or key on the `ApiInfo` instance.
Original exception text was: 'ApiInfo' object has no attribute 'user'.
2018-03-14 13:30:54,003,10632,django.server,ERROR,basehttp.py:124,"GET /api/api/api_info?api_id=13&project_id=1 HTTP/1.1" 500 20488
2018-03-14 15:09:15,471,4868,django.server,ERROR,basehttp.py:124,"GET /api/api/api_info?project_id=1&api_id=13 HTTP/1.1" 500 59
2018-03-14 15:55:22,187,15872,django.request,ERROR,exception.py:118,Internal Server Error: /admin/api_test/apiinfo/1/change/
Traceback (most recent call last):
  File "D:\Users\SIMO\AppData\Local\Programs\Python\Python36\lib\site-packages\django\core\handlers\exception.py", line 35, in inner
    response = get_response(request)
  File "D:\Users\SIMO\AppData\Local\Programs\Python\Python36\lib\site-packages\django\core\handlers\base.py", line 128, in _get_response
    response = self.process_exception_by_middleware(e, request)
  File "D:\Users\SIMO\AppData\Local\Programs\Python\Python36\lib\site-packages\django\core\handlers\base.py", line 126, in _get_response
    response = wrapped_callback(request, *callback_args, **callback_kwargs)
  File "D:\Users\SIMO\AppData\Local\Programs\Python\Python36\lib\site-packages\django\contrib\admin\options.py", line 574, in wrapper
    return self.admin_site.admin_view(view)(*args, **kwargs)
  File "D:\Users\SIMO\AppData\Local\Programs\Python\Python36\lib\site-packages\django\utils\decorators.py", line 142, in _wrapped_view
    response = view_func(request, *args, **kwargs)
  File "D:\Users\SIMO\AppData\Local\Programs\Python\Python36\lib\site-packages\django\views\decorators\cache.py", line 44, in _wrapped_view_func
    response = view_func(request, *args, **kwargs)
  File "D:\Users\SIMO\AppData\Local\Programs\Python\Python36\lib\site-packages\django\contrib\admin\sites.py", line 223, in inner
    return view(request, *args, **kwargs)
  File "D:\Users\SIMO\AppData\Local\Programs\Python\Python36\lib\site-packages\django\contrib\admin\options.py", line 1556, in change_view
    return self.changeform_view(request, object_id, form_url, extra_context)
  File "D:\Users\SIMO\AppData\Local\Programs\Python\Python36\lib\site-packages\django\utils\decorators.py", line 62, in _wrapper
    return bound_func(*args, **kwargs)
  File "D:\Users\SIMO\AppData\Local\Programs\Python\Python36\lib\site-packages\django\utils\decorators.py", line 142, in _wrapped_view
    response = view_func(request, *args, **kwargs)
  File "D:\Users\SIMO\AppData\Local\Programs\Python\Python36\lib\site-packages\django\utils\decorators.py", line 58, in bound_func
    return func.__get__(self, type(self))(*args2, **kwargs2)
  File "D:\Users\SIMO\AppData\Local\Programs\Python\Python36\lib\site-packages\django\contrib\admin\options.py", line 1450, in changeform_view
    return self._changeform_view(request, object_id, form_url, extra_context)
  File "D:\Users\SIMO\AppData\Local\Programs\Python\Python36\lib\site-packages\django\contrib\admin\options.py", line 1489, in _changeform_view
    if all_valid(formsets) and form_validated:
  File "D:\Users\SIMO\AppData\Local\Programs\Python\Python36\lib\site-packages\django\forms\formsets.py", line 442, in all_valid
    if not formset.is_valid():
  File "D:\Users\SIMO\AppData\Local\Programs\Python\Python36\lib\site-packages\django\forms\formsets.py", line 301, in is_valid
    self.errors
  File "D:\Users\SIMO\AppData\Local\Programs\Python\Python36\lib\site-packages\django\forms\formsets.py", line 281, in errors
    self.full_clean()
  File "D:\Users\SIMO\AppData\Local\Programs\Python\Python36\lib\site-packages\django\forms\formsets.py", line 322, in full_clean
    for i in range(0, self.total_form_count()):
  File "D:\Users\SIMO\AppData\Local\Programs\Python\Python36\lib\site-packages\django\forms\formsets.py", line 110, in total_form_count
    return min(self.management_form.cleaned_data[TOTAL_FORM_COUNT], self.absolute_max)
  File "D:\Users\SIMO\AppData\Local\Programs\Python\Python36\lib\site-packages\django\utils\functional.py", line 36, in __get__
    res = instance.__dict__[self.name] = self.func(instance)
  File "D:\Users\SIMO\AppData\Local\Programs\Python\Python36\lib\site-packages\django\forms\formsets.py", line 92, in management_form
    code='missing_management_form',
django.core.exceptions.ValidationError: ['管理表单的数据缺失或者已被篡改']
2018-03-14 15:55:22,316,15872,django.server,ERROR,basehttp.py:124,"POST /admin/api_test/apiinfo/1/change/ HTTP/1.1" 500 166737
2018-03-14 15:58:08,140,1308,django.server,ERROR,basehttp.py:124,"GET /api/api/api_info?project_id=1&api_id=1 HTTP/1.1" 500 59
2018-03-14 16:16:05,705,7120,django.server,ERROR,basehttp.py:124,"GET /api/api/api_info?project_id=1&api_id=1 HTTP/1.1" 500 59
2018-03-06 21:44:53,514,5156,root,ERROR,ApiDoc.py:334,error
Traceback (most recent call last):
  File "D:\project\api_automation_test\api_test\api\ApiDoc.py", line 314, in add_api
    description=i['description']).save()
  File "D:\Program Files (x86)\Python36-32\lib\site-packages\django\db\models\base.py", line 729, in save
    force_update=force_update, update_fields=update_fields)
  File "D:\Program Files (x86)\Python36-32\lib\site-packages\django\db\models\base.py", line 759, in save_base
    updated = self._save_table(raw, cls, force_insert, force_update, using, update_fields)
  File "D:\Program Files (x86)\Python36-32\lib\site-packages\django\db\models\base.py", line 842, in _save_table
    result = self._do_insert(cls._base_manager, using, fields, update_pk, raw)
  File "D:\Program Files (x86)\Python36-32\lib\site-packages\django\db\models\base.py", line 880, in _do_insert
    using=using, raw=raw)
  File "D:\Program Files (x86)\Python36-32\lib\site-packages\django\db\models\manager.py", line 82, in manager_method
    return getattr(self.get_queryset(), name)(*args, **kwargs)
  File "D:\Program Files (x86)\Python36-32\lib\site-packages\django\db\models\query.py", line 1125, in _insert
    return query.get_compiler(using=using).execute_sql(return_id)
  File "D:\Program Files (x86)\Python36-32\lib\site-packages\django\db\models\sql\compiler.py", line 1280, in execute_sql
    for sql, params in self.as_sql():
  File "D:\Program Files (x86)\Python36-32\lib\site-packages\django\db\models\sql\compiler.py", line 1233, in as_sql
    for obj in self.query.objs
  File "D:\Program Files (x86)\Python36-32\lib\site-packages\django\db\models\sql\compiler.py", line 1233, in <listcomp>
    for obj in self.query.objs
  File "D:\Program Files (x86)\Python36-32\lib\site-packages\django\db\models\sql\compiler.py", line 1232, in <listcomp>
    [self.prepare_value(field, self.pre_save_val(field, obj)) for field in fields]
  File "D:\Program Files (x86)\Python36-32\lib\site-packages\django\db\models\sql\compiler.py", line 1172, in prepare_value
    value = field.get_db_prep_save(value, connection=self.connection)
  File "D:\Program Files (x86)\Python36-32\lib\site-packages\django\db\models\fields\__init__.py", line 767, in get_db_prep_save
    return self.get_db_prep_value(value, connection=connection, prepared=False)
  File "D:\Program Files (x86)\Python36-32\lib\site-packages\django\db\models\fields\__init__.py", line 762, in get_db_prep_value
    value = self.get_prep_value(value)
  File "D:\Program Files (x86)\Python36-32\lib\site-packages\django\db\models\fields\__init__.py", line 1024, in get_prep_value
    return self.to_python(value)
  File "D:\Program Files (x86)\Python36-32\lib\site-packages\django\db\models\fields\__init__.py", line 1017, in to_python
    params={'value': value},
django.core.exceptions.ValidationError: ['’‘ 必须为 True 或者 False。']
2018-03-06 21:44:53,532,5156,root,ERROR,ApiDoc.py:335,['’‘ 必须为 True 或者 False。']
2018-03-06 21:49:26,009,5960,root,ERROR,ApiDoc.py:334,error
Traceback (most recent call last):
  File "D:\project\api_automation_test\api_test\api\ApiDoc.py", line 314, in add_api
    description=i['description']).save()
  File "D:\Program Files (x86)\Python36-32\lib\site-packages\django\db\models\base.py", line 729, in save
    force_update=force_update, update_fields=update_fields)
  File "D:\Program Files (x86)\Python36-32\lib\site-packages\django\db\models\base.py", line 759, in save_base
    updated = self._save_table(raw, cls, force_insert, force_update, using, update_fields)
  File "D:\Program Files (x86)\Python36-32\lib\site-packages\django\db\models\base.py", line 842, in _save_table
    result = self._do_insert(cls._base_manager, using, fields, update_pk, raw)
  File "D:\Program Files (x86)\Python36-32\lib\site-packages\django\db\models\base.py", line 880, in _do_insert
    using=using, raw=raw)
  File "D:\Program Files (x86)\Python36-32\lib\site-packages\django\db\models\manager.py", line 82, in manager_method
    return getattr(self.get_queryset(), name)(*args, **kwargs)
  File "D:\Program Files (x86)\Python36-32\lib\site-packages\django\db\models\query.py", line 1125, in _insert
    return query.get_compiler(using=using).execute_sql(return_id)
  File "D:\Program Files (x86)\Python36-32\lib\site-packages\django\db\models\sql\compiler.py", line 1280, in execute_sql
    for sql, params in self.as_sql():
  File "D:\Program Files (x86)\Python36-32\lib\site-packages\django\db\models\sql\compiler.py", line 1233, in as_sql
    for obj in self.query.objs
  File "D:\Program Files (x86)\Python36-32\lib\site-packages\django\db\models\sql\compiler.py", line 1233, in <listcomp>
    for obj in self.query.objs
  File "D:\Program Files (x86)\Python36-32\lib\site-packages\django\db\models\sql\compiler.py", line 1232, in <listcomp>
    [self.prepare_value(field, self.pre_save_val(field, obj)) for field in fields]
  File "D:\Program Files (x86)\Python36-32\lib\site-packages\django\db\models\sql\compiler.py", line 1172, in prepare_value
    value = field.get_db_prep_save(value, connection=self.connection)
  File "D:\Program Files (x86)\Python36-32\lib\site-packages\django\db\models\fields\__init__.py", line 767, in get_db_prep_save
    return self.get_db_prep_value(value, connection=connection, prepared=False)
  File "D:\Program Files (x86)\Python36-32\lib\site-packages\django\db\models\fields\__init__.py", line 762, in get_db_prep_value
    value = self.get_prep_value(value)
  File "D:\Program Files (x86)\Python36-32\lib\site-packages\django\db\models\fields\__init__.py", line 1024, in get_prep_value
    return self.to_python(value)
  File "D:\Program Files (x86)\Python36-32\lib\site-packages\django\db\models\fields\__init__.py", line 1017, in to_python
    params={'value': value},
django.core.exceptions.ValidationError: ['’‘ 必须为 True 或者 False。']
2018-03-06 21:49:26,021,5960,root,ERROR,ApiDoc.py:335,['’‘ 必须为 True 或者 False。']
2018-03-06 21:51:15,243,2832,root,ERROR,ApiDoc.py:336,error
Traceback (most recent call last):
  File "D:\project\api_automation_test\api_test\api\ApiDoc.py", line 316, in add_api
    description=i['description']).save()
  File "D:\Program Files (x86)\Python36-32\lib\site-packages\django\db\models\base.py", line 729, in save
    force_update=force_update, update_fields=update_fields)
  File "D:\Program Files (x86)\Python36-32\lib\site-packages\django\db\models\base.py", line 759, in save_base
    updated = self._save_table(raw, cls, force_insert, force_update, using, update_fields)
  File "D:\Program Files (x86)\Python36-32\lib\site-packages\django\db\models\base.py", line 842, in _save_table
    result = self._do_insert(cls._base_manager, using, fields, update_pk, raw)
  File "D:\Program Files (x86)\Python36-32\lib\site-packages\django\db\models\base.py", line 880, in _do_insert
    using=using, raw=raw)
  File "D:\Program Files (x86)\Python36-32\lib\site-packages\django\db\models\manager.py", line 82, in manager_method
    return getattr(self.get_queryset(), name)(*args, **kwargs)
  File "D:\Program Files (x86)\Python36-32\lib\site-packages\django\db\models\query.py", line 1125, in _insert
    return query.get_compiler(using=using).execute_sql(return_id)
  File "D:\Program Files (x86)\Python36-32\lib\site-packages\django\db\models\sql\compiler.py", line 1280, in execute_sql
    for sql, params in self.as_sql():
  File "D:\Program Files (x86)\Python36-32\lib\site-packages\django\db\models\sql\compiler.py", line 1233, in as_sql
    for obj in self.query.objs
  File "D:\Program Files (x86)\Python36-32\lib\site-packages\django\db\models\sql\compiler.py", line 1233, in <listcomp>
    for obj in self.query.objs
  File "D:\Program Files (x86)\Python36-32\lib\site-packages\django\db\models\sql\compiler.py", line 1232, in <listcomp>
    [self.prepare_value(field, self.pre_save_val(field, obj)) for field in fields]
  File "D:\Program Files (x86)\Python36-32\lib\site-packages\django\db\models\sql\compiler.py", line 1172, in prepare_value
    value = field.get_db_prep_save(value, connection=self.connection)
  File "D:\Program Files (x86)\Python36-32\lib\site-packages\django\db\models\fields\__init__.py", line 767, in get_db_prep_save
    return self.get_db_prep_value(value, connection=connection, prepared=False)
  File "D:\Program Files (x86)\Python36-32\lib\site-packages\django\db\models\fields\__init__.py", line 762, in get_db_prep_value
    value = self.get_prep_value(value)
  File "D:\Program Files (x86)\Python36-32\lib\site-packages\django\db\models\fields\__init__.py", line 1024, in get_prep_value
    return self.to_python(value)
  File "D:\Program Files (x86)\Python36-32\lib\site-packages\django\db\models\fields\__init__.py", line 1017, in to_python
    params={'value': value},
django.core.exceptions.ValidationError: ['’‘ 必须为 True 或者 False。']
2018-03-06 21:51:15,253,2832,root,ERROR,ApiDoc.py:337,['’‘ 必须为 True 或者 False。']
2018-03-06 21:57:40,181,4688,root,ERROR,ApiDoc.py:338,error
Traceback (most recent call last):
  File "D:\project\api_automation_test\api_test\api\ApiDoc.py", line 329, in add_api
    description=i['description']).save()
  File "D:\Program Files (x86)\Python36-32\lib\site-packages\django\db\models\base.py", line 495, in __init__
    raise TypeError("'%s' is an invalid keyword argument for this function" % kwarg)
TypeError: 'restrict' is an invalid keyword argument for this function
2018-03-06 21:57:40,185,4688,root,ERROR,ApiDoc.py:339,'restrict' is an invalid keyword argument for this function
2018-03-06 21:59:34,135,5836,root,ERROR,ApiDoc.py:337,error
Traceback (most recent call last):
  File "D:\project\api_automation_test\api_test\api\ApiDoc.py", line 328, in add_api
    description=i['description']).save()
  File "D:\Program Files (x86)\Python36-32\lib\site-packages\django\db\models\base.py", line 729, in save
    force_update=force_update, update_fields=update_fields)
  File "D:\Program Files (x86)\Python36-32\lib\site-packages\django\db\models\base.py", line 759, in save_base
    updated = self._save_table(raw, cls, force_insert, force_update, using, update_fields)
  File "D:\Program Files (x86)\Python36-32\lib\site-packages\django\db\models\base.py", line 842, in _save_table
    result = self._do_insert(cls._base_manager, using, fields, update_pk, raw)
  File "D:\Program Files (x86)\Python36-32\lib\site-packages\django\db\models\base.py", line 880, in _do_insert
    using=using, raw=raw)
  File "D:\Program Files (x86)\Python36-32\lib\site-packages\django\db\models\manager.py", line 82, in manager_method
    return getattr(self.get_queryset(), name)(*args, **kwargs)
  File "D:\Program Files (x86)\Python36-32\lib\site-packages\django\db\models\query.py", line 1125, in _insert
    return query.get_compiler(using=using).execute_sql(return_id)
  File "D:\Program Files (x86)\Python36-32\lib\site-packages\django\db\models\sql\compiler.py", line 1280, in execute_sql
    for sql, params in self.as_sql():
  File "D:\Program Files (x86)\Python36-32\lib\site-packages\django\db\models\sql\compiler.py", line 1233, in as_sql
    for obj in self.query.objs
  File "D:\Program Files (x86)\Python36-32\lib\site-packages\django\db\models\sql\compiler.py", line 1233, in <listcomp>
    for obj in self.query.objs
  File "D:\Program Files (x86)\Python36-32\lib\site-packages\django\db\models\sql\compiler.py", line 1232, in <listcomp>
    [self.prepare_value(field, self.pre_save_val(field, obj)) for field in fields]
  File "D:\Program Files (x86)\Python36-32\lib\site-packages\django\db\models\sql\compiler.py", line 1172, in prepare_value
    value = field.get_db_prep_save(value, connection=self.connection)
  File "D:\Program Files (x86)\Python36-32\lib\site-packages\django\db\models\fields\__init__.py", line 767, in get_db_prep_save
    return self.get_db_prep_value(value, connection=connection, prepared=False)
  File "D:\Program Files (x86)\Python36-32\lib\site-packages\django\db\models\fields\__init__.py", line 762, in get_db_prep_value
    value = self.get_prep_value(value)
  File "D:\Program Files (x86)\Python36-32\lib\site-packages\django\db\models\fields\__init__.py", line 1024, in get_prep_value
    return self.to_python(value)
  File "D:\Program Files (x86)\Python36-32\lib\site-packages\django\db\models\fields\__init__.py", line 1017, in to_python
    params={'value': value},
django.core.exceptions.ValidationError: ['’‘ 必须为 True 或者 False。']
2018-03-06 21:59:34,147,5836,root,ERROR,ApiDoc.py:338,['’‘ 必须为 True 或者 False。']
2018-03-06 21:07:44,629,2740,root,ERROR,ApiDoc.py:344,error
Traceback (most recent call last):
  File "D:\project\api_automation_test\api_test\api\ApiDoc.py", line 334, in add_api
    value=i['value'], required=a,
UnboundLocalError: local variable 'a' referenced before assignment
2018-03-06 21:07:44,632,2740,root,ERROR,ApiDoc.py:345,local variable 'a' referenced before assignment
