2018-05-14 13:50:46,136,1216,root,ERROR,confighttp.py:87,ERROR
Traceback (most recent call last):
  File "H:\project\api_automation_test\api_test\common\confighttp.py", line 80, in test_api
    print(type( AutomationTestResult.objects.filter(automationCaseApi=api_id[0]))[0]['fields']["responseData"])
TypeError: 'type' object is not subscriptable
2018-05-14 13:50:46,136,1216,root,ERROR,confighttp.py:88,'type' object is not subscriptable
2018-05-14 13:51:10,989,13088,root,ERROR,confighttp.py:87,ERROR
Traceback (most recent call last):
  File "H:\project\api_automation_test\api_test\common\confighttp.py", line 80, in test_api
    print(AutomationTestResult.objects.filter(automationCaseApi=api_id[0])[0]['fields']["responseData"])
TypeError: 'AutomationTestResult' object is not subscriptable
2018-05-14 13:51:10,990,13088,root,ERROR,confighttp.py:88,'AutomationTestResult' object is not subscriptable
2018-05-14 13:53:27,124,4668,root,ERROR,confighttp.py:87,ERROR
Traceback (most recent call last):
  File "H:\project\api_automation_test\api_test\common\confighttp.py", line 80, in test_api
    print(type(json.loads(serializers.serialize('json', AutomationTestResult.objects.filter(automationCaseApi=api_id[0]))))[0]['fields']["responseData"])
TypeError: 'type' object is not subscriptable
2018-05-14 13:53:27,125,4668,root,ERROR,confighttp.py:88,'type' object is not subscriptable
2018-05-14 13:53:39,867,7240,root,ERROR,confighttp.py:87,ERROR
Traceback (most recent call last):
  File "H:\project\api_automation_test\api_test\common\confighttp.py", line 80, in test_api
    print(type(json.loads(serializers.serialize('json', AutomationTestResult.objects.filter(automationCaseApi=api_id[0]))))[0])
TypeError: 'type' object is not subscriptable
2018-05-14 13:53:39,867,7240,root,ERROR,confighttp.py:88,'type' object is not subscriptable
2018-05-14 13:54:32,569,10868,root,ERROR,confighttp.py:87,ERROR
Traceback (most recent call last):
  File "H:\project\api_automation_test\api_test\common\confighttp.py", line 80, in test_api
    print(type(json.loads(json.loads(serializers.serialize('json', AutomationTestResult.objects.filter(automationCaseApi=api_id[0])))[0]['fields']["responseData"])))
  File "D:\Users\SIMO\AppData\Local\Programs\Python\Python36\lib\json\__init__.py", line 354, in loads
    return _default_decoder.decode(s)
  File "D:\Users\SIMO\AppData\Local\Programs\Python\Python36\lib\json\decoder.py", line 339, in decode
    obj, end = self.raw_decode(s, idx=_w(s, 0).end())
  File "D:\Users\SIMO\AppData\Local\Programs\Python\Python36\lib\json\decoder.py", line 355, in raw_decode
    obj, end = self.scan_once(s, idx)
json.decoder.JSONDecodeError: Expecting property name enclosed in double quotes: line 1 column 2 (char 1)
2018-05-14 13:54:32,583,10868,root,ERROR,confighttp.py:88,Expecting property name enclosed in double quotes: line 1 column 2 (char 1)
2018-05-14 13:55:40,453,9276,root,ERROR,confighttp.py:87,ERROR
Traceback (most recent call last):
  File "H:\project\api_automation_test\api_test\common\confighttp.py", line 80, in test_api
    print(json.loads(json.loads(serializers.serialize('json', AutomationTestResult.objects.filter(automationCaseApi=api_id[0])))[0]['fields']["responseData"]))
  File "D:\Users\SIMO\AppData\Local\Programs\Python\Python36\lib\json\__init__.py", line 354, in loads
    return _default_decoder.decode(s)
  File "D:\Users\SIMO\AppData\Local\Programs\Python\Python36\lib\json\decoder.py", line 339, in decode
    obj, end = self.raw_decode(s, idx=_w(s, 0).end())
  File "D:\Users\SIMO\AppData\Local\Programs\Python\Python36\lib\json\decoder.py", line 355, in raw_decode
    obj, end = self.scan_once(s, idx)
json.decoder.JSONDecodeError: Expecting property name enclosed in double quotes: line 1 column 2 (char 1)
2018-05-14 13:55:40,454,9276,root,ERROR,confighttp.py:88,Expecting property name enclosed in double quotes: line 1 column 2 (char 1)
2018-05-14 13:58:47,234,14168,root,ERROR,confighttp.py:87,ERROR
Traceback (most recent call last):
  File "H:\project\api_automation_test\api_test\common\confighttp.py", line 83, in test_api
    AutomationTestResult.objects.filter(automationCaseApi=api_id[0])))[0]['fields']["responseData"].replace('\'', '"'))
  File "D:\Users\SIMO\AppData\Local\Programs\Python\Python36\lib\json\__init__.py", line 354, in loads
    return _default_decoder.decode(s)
  File "D:\Users\SIMO\AppData\Local\Programs\Python\Python36\lib\json\decoder.py", line 339, in decode
    obj, end = self.raw_decode(s, idx=_w(s, 0).end())
  File "D:\Users\SIMO\AppData\Local\Programs\Python\Python36\lib\json\decoder.py", line 357, in raw_decode
    raise JSONDecodeError("Expecting value", s, err.value) from None
json.decoder.JSONDecodeError: Expecting value: line 1 column 575 (char 574)
2018-05-14 13:58:47,235,14168,root,ERROR,confighttp.py:88,Expecting value: line 1 column 575 (char 574)
2018-05-14 13:59:06,908,5168,root,ERROR,confighttp.py:87,ERROR
Traceback (most recent call last):
  File "H:\project\api_automation_test\api_test\common\confighttp.py", line 83, in test_api
    AutomationTestResult.objects.filter(automationCaseApi=api_id[0])))[0]['fields']["responseData"].replace('\'', '"'))
  File "D:\Users\SIMO\AppData\Local\Programs\Python\Python36\lib\json\__init__.py", line 354, in loads
    return _default_decoder.decode(s)
  File "D:\Users\SIMO\AppData\Local\Programs\Python\Python36\lib\json\decoder.py", line 339, in decode
    obj, end = self.raw_decode(s, idx=_w(s, 0).end())
  File "D:\Users\SIMO\AppData\Local\Programs\Python\Python36\lib\json\decoder.py", line 357, in raw_decode
    raise JSONDecodeError("Expecting value", s, err.value) from None
json.decoder.JSONDecodeError: Expecting value: line 1 column 575 (char 574)
2018-05-14 13:59:06,909,5168,root,ERROR,confighttp.py:88,Expecting value: line 1 column 575 (char 574)
2018-05-14 14:15:53,430,14044,root,ERROR,confighttp.py:88,ERROR
Traceback (most recent call last):
  File "H:\project\api_automation_test\api_test\common\confighttp.py", line 81, in test_api
    print(json.loads(json.loads(serializers.serialize('json', AutomationTestResult.objects.filter(automationCaseApi=api_id[0])))[0]['fields']["responseData"].replace('\'', '"')))
  File "D:\Users\SIMO\AppData\Local\Programs\Python\Python36\lib\json\__init__.py", line 354, in loads
    return _default_decoder.decode(s)
  File "D:\Users\SIMO\AppData\Local\Programs\Python\Python36\lib\json\decoder.py", line 339, in decode
    obj, end = self.raw_decode(s, idx=_w(s, 0).end())
  File "D:\Users\SIMO\AppData\Local\Programs\Python\Python36\lib\json\decoder.py", line 357, in raw_decode
    raise JSONDecodeError("Expecting value", s, err.value) from None
json.decoder.JSONDecodeError: Expecting value: line 1 column 575 (char 574)
2018-05-14 14:15:53,431,14044,root,ERROR,confighttp.py:89,Expecting value: line 1 column 575 (char 574)
2018-05-14 14:17:57,399,10908,root,ERROR,confighttp.py:87,ERROR
Traceback (most recent call last):
  File "H:\project\api_automation_test\api_test\common\confighttp.py", line 83, in test_api
    AutomationTestResult.objects.filter(automationCaseApi=api_id[0])))[0]['fields']["responseData"][0])
  File "<string>", line 1
    {
    ^
SyntaxError: unexpected EOF while parsing
2018-05-14 14:17:57,399,10908,root,ERROR,confighttp.py:88,unexpected EOF while parsing (<string>, line 1)
2018-05-14 14:18:38,764,11144,root,ERROR,confighttp.py:87,ERROR
Traceback (most recent call last):
  File "H:\project\api_automation_test\api_test\common\confighttp.py", line 83, in test_api
    AutomationTestResult.objects.filter(automationCaseApi=api_id[0])))[0]['fields']["responseData"].replace('True', 'true'))
  File "<string>", line 1, in <module>
NameError: name 'true' is not defined
2018-05-14 14:18:38,765,11144,root,ERROR,confighttp.py:88,name 'true' is not defined
2018-05-14 14:31:43,948,9740,root,ERROR,confighttp.py:87,ERROR
Traceback (most recent call last):
  File "H:\project\api_automation_test\api_test\common\confighttp.py", line 85, in test_api
    value = value[j]
KeyError: 'data'
2018-05-14 14:31:43,949,9740,root,ERROR,confighttp.py:88,'data'
2018-05-14 14:39:00,484,13740,root,ERROR,confighttp.py:130,eee
Traceback (most recent call last):
  File "H:\project\api_automation_test\api_test\common\confighttp.py", line 127, in test_api
    print(json.loads(response_parameter_list))
  File "D:\Users\SIMO\AppData\Local\Programs\Python\Python36\lib\json\__init__.py", line 354, in loads
    return _default_decoder.decode(s)
  File "D:\Users\SIMO\AppData\Local\Programs\Python\Python36\lib\json\decoder.py", line 339, in decode
    obj, end = self.raw_decode(s, idx=_w(s, 0).end())
  File "D:\Users\SIMO\AppData\Local\Programs\Python\Python36\lib\json\decoder.py", line 357, in raw_decode
    raise JSONDecodeError("Expecting value", s, err.value) from None
json.decoder.JSONDecodeError: Expecting value: line 1 column 396 (char 395)
2018-05-14 14:39:16,575,13740,root,ERROR,confighttp.py:130,eee
Traceback (most recent call last):
  File "H:\project\api_automation_test\api_test\common\confighttp.py", line 127, in test_api
    print(response_parameter_list)
  File "D:\Users\SIMO\AppData\Local\Programs\Python\Python36\lib\json\__init__.py", line 354, in loads
    return _default_decoder.decode(s)
  File "D:\Users\SIMO\AppData\Local\Programs\Python\Python36\lib\json\decoder.py", line 339, in decode
    obj, end = self.raw_decode(s, idx=_w(s, 0).end())
  File "D:\Users\SIMO\AppData\Local\Programs\Python\Python36\lib\json\decoder.py", line 357, in raw_decode
    raise JSONDecodeError("Expecting value", s, err.value) from None
json.decoder.JSONDecodeError: Expecting value: line 1 column 396 (char 395)
2018-05-14 14:39:22,893,13064,root,ERROR,confighttp.py:131,eee
Traceback (most recent call last):
  File "H:\project\api_automation_test\api_test\common\confighttp.py", line 128, in test_api
    print(json.loads(response_parameter_list))
  File "D:\Users\SIMO\AppData\Local\Programs\Python\Python36\lib\json\__init__.py", line 354, in loads
    return _default_decoder.decode(s)
  File "D:\Users\SIMO\AppData\Local\Programs\Python\Python36\lib\json\decoder.py", line 339, in decode
    obj, end = self.raw_decode(s, idx=_w(s, 0).end())
  File "D:\Users\SIMO\AppData\Local\Programs\Python\Python36\lib\json\decoder.py", line 357, in raw_decode
    raise JSONDecodeError("Expecting value", s, err.value) from None
json.decoder.JSONDecodeError: Expecting value: line 1 column 396 (char 395)
2018-05-14 14:39:49,299,8624,root,ERROR,confighttp.py:131,eee
Traceback (most recent call last):
  File "H:\project\api_automation_test\api_test\common\confighttp.py", line 129, in test_api
    result = check_json(json.loads(response_parameter_list), response_data)
  File "D:\Users\SIMO\AppData\Local\Programs\Python\Python36\lib\json\__init__.py", line 354, in loads
    return _default_decoder.decode(s)
  File "D:\Users\SIMO\AppData\Local\Programs\Python\Python36\lib\json\decoder.py", line 339, in decode
    obj, end = self.raw_decode(s, idx=_w(s, 0).end())
  File "D:\Users\SIMO\AppData\Local\Programs\Python\Python36\lib\json\decoder.py", line 357, in raw_decode
    raise JSONDecodeError("Expecting value", s, err.value) from None
json.decoder.JSONDecodeError: Expecting value: line 1 column 396 (char 395)
2018-05-14 14:42:34,221,10852,root,ERROR,confighttp.py:129,eee
Traceback (most recent call last):
  File "H:\project\api_automation_test\api_test\common\confighttp.py", line 127, in test_api
    result = check_json(eval(response_parameter_list), response_data)
  File "<string>", line 1, in <module>
NameError: name 'true' is not defined
2018-05-14 14:42:40,931,10852,root,ERROR,confighttp.py:129,eee
Traceback (most recent call last):
  File "H:\project\api_automation_test\api_test\common\confighttp.py", line 127, in test_api
    result = check_json(eval(response_parameter_list), response_data)
  File "<string>", line 1, in <module>
NameError: name 'true' is not defined
2018-05-14 14:43:32,390,3948,django.request,ERROR,exception.py:118,Internal Server Error: /api/automation/start_test
Traceback (most recent call last):
  File "D:\Users\SIMO\AppData\Local\Programs\Python\Python36\lib\site-packages\django\core\handlers\exception.py", line 35, in inner
    response = get_response(request)
  File "D:\Users\SIMO\AppData\Local\Programs\Python\Python36\lib\site-packages\django\core\handlers\base.py", line 128, in _get_response
    response = self.process_exception_by_middleware(e, request)
  File "D:\Users\SIMO\AppData\Local\Programs\Python\Python36\lib\site-packages\django\core\handlers\base.py", line 126, in _get_response
    response = wrapped_callback(request, *callback_args, **callback_kwargs)
  File "D:\Users\SIMO\AppData\Local\Programs\Python\Python36\lib\site-packages\django\views\decorators\csrf.py", line 54, in wrapped_view
    return view_func(*args, **kwargs)
  File "D:\Users\SIMO\AppData\Local\Programs\Python\Python36\lib\site-packages\django\views\generic\base.py", line 69, in view
    return self.dispatch(request, *args, **kwargs)
  File "D:\Users\SIMO\AppData\Local\Programs\Python\Python36\lib\site-packages\rest_framework\views.py", line 494, in dispatch
    response = self.handle_exception(exc)
  File "D:\Users\SIMO\AppData\Local\Programs\Python\Python36\lib\site-packages\rest_framework\views.py", line 454, in handle_exception
    self.raise_uncaught_exception(exc)
  File "D:\Users\SIMO\AppData\Local\Programs\Python\Python36\lib\site-packages\rest_framework\views.py", line 491, in dispatch
    response = handler(request, *args, **kwargs)
  File "D:\Users\SIMO\AppData\Local\Programs\Python\Python36\lib\site-packages\rest_framework\decorators.py", line 53, in handler
    return func(*args, **kwargs)
  File "H:\project\api_automation_test\api_test\common\common.py", line 65, in verify
    return func(reality_parameter)
  File "H:\project\api_automation_test\api_test\api\automationCase.py", line 859, in start_test
    result = test_api(host_id=host_id, case_id=case_id, _id=_id, project_id=project_id1)
NameError: name 'project_id1' is not defined
2018-05-14 14:43:32,480,3948,django.server,ERROR,basehttp.py:124,"POST /api/automation/start_test HTTP/1.1" 500 18910
2018-05-14 14:53:45,070,14168,root,ERROR,confighttp.py:107,ERROR
Traceback (most recent call last):
  File "H:\project\api_automation_test\api_test\common\confighttp.py", line 103, in test_api
    AutomationTestResult.objects.filter(automationCaseApi=api_id[0])))[0]['fields']["responseData"])
IndexError: list index out of range
2018-05-14 14:53:45,070,14168,root,ERROR,confighttp.py:108,list index out of range
2018-05-14 14:55:00,857,13900,root,ERROR,confighttp.py:107,ERROR
Traceback (most recent call last):
  File "H:\project\api_automation_test\api_test\common\confighttp.py", line 103, in test_api
    AutomationTestResult.objects.filter(automationCaseApi=api_id[0])))[0]['fields']["responseData"])
IndexError: list index out of range
2018-05-14 14:55:00,857,13900,root,ERROR,confighttp.py:108,list index out of range
2018-05-14 15:30:07,357,4496,django.request,ERROR,exception.py:118,Internal Server Error: /api/automation/start_test
Traceback (most recent call last):
  File "H:\project\api_automation_test\api_test\common\confighttp.py", line 176, in test_api
    result = operator.eq(json.loads(response_parameter_list), response_data)
  File "D:\Users\SIMO\AppData\Local\Programs\Python\Python36\lib\json\__init__.py", line 354, in loads
    return _default_decoder.decode(s)
  File "D:\Users\SIMO\AppData\Local\Programs\Python\Python36\lib\json\decoder.py", line 339, in decode
    obj, end = self.raw_decode(s, idx=_w(s, 0).end())
  File "D:\Users\SIMO\AppData\Local\Programs\Python\Python36\lib\json\decoder.py", line 355, in raw_decode
    obj, end = self.scan_once(s, idx)
json.decoder.JSONDecodeError: Expecting property name enclosed in double quotes: line 1 column 2 (char 1)

During handling of the above exception, another exception occurred:

Traceback (most recent call last):
  File "D:\Users\SIMO\AppData\Local\Programs\Python\Python36\lib\site-packages\django\core\handlers\exception.py", line 35, in inner
    response = get_response(request)
  File "D:\Users\SIMO\AppData\Local\Programs\Python\Python36\lib\site-packages\django\core\handlers\base.py", line 128, in _get_response
    response = self.process_exception_by_middleware(e, request)
  File "D:\Users\SIMO\AppData\Local\Programs\Python\Python36\lib\site-packages\django\core\handlers\base.py", line 126, in _get_response
    response = wrapped_callback(request, *callback_args, **callback_kwargs)
  File "D:\Users\SIMO\AppData\Local\Programs\Python\Python36\lib\site-packages\django\views\decorators\csrf.py", line 54, in wrapped_view
    return view_func(*args, **kwargs)
  File "D:\Users\SIMO\AppData\Local\Programs\Python\Python36\lib\site-packages\django\views\generic\base.py", line 69, in view
    return self.dispatch(request, *args, **kwargs)
  File "D:\Users\SIMO\AppData\Local\Programs\Python\Python36\lib\site-packages\rest_framework\views.py", line 494, in dispatch
    response = self.handle_exception(exc)
  File "D:\Users\SIMO\AppData\Local\Programs\Python\Python36\lib\site-packages\rest_framework\views.py", line 454, in handle_exception
    self.raise_uncaught_exception(exc)
  File "D:\Users\SIMO\AppData\Local\Programs\Python\Python36\lib\site-packages\rest_framework\views.py", line 491, in dispatch
    response = handler(request, *args, **kwargs)
  File "D:\Users\SIMO\AppData\Local\Programs\Python\Python36\lib\site-packages\rest_framework\decorators.py", line 53, in handler
    return func(*args, **kwargs)
  File "H:\project\api_automation_test\api_test\common\common.py", line 65, in verify
    return func(reality_parameter)
  File "H:\project\api_automation_test\api_test\api\automationCase.py", line 859, in start_test
    result = test_api(host_id=host_id, case_id=case_id, _id=_id, project_id=project_id)
  File "H:\project\api_automation_test\api_test\common\confighttp.py", line 178, in test_api
    result = operator.eq(json.loads(response_parameter_list.replace('True', 'true').replace('False', 'false')), response_data)
  File "D:\Users\SIMO\AppData\Local\Programs\Python\Python36\lib\json\__init__.py", line 354, in loads
    return _default_decoder.decode(s)
  File "D:\Users\SIMO\AppData\Local\Programs\Python\Python36\lib\json\decoder.py", line 339, in decode
    obj, end = self.raw_decode(s, idx=_w(s, 0).end())
  File "D:\Users\SIMO\AppData\Local\Programs\Python\Python36\lib\json\decoder.py", line 355, in raw_decode
    obj, end = self.scan_once(s, idx)
json.decoder.JSONDecodeError: Expecting property name enclosed in double quotes: line 1 column 2 (char 1)
2018-05-14 15:30:07,377,4496,django.server,ERROR,basehttp.py:124,"POST /api/automation/start_test HTTP/1.1" 500 20444
2018-05-14 15:30:13,624,4496,django.request,ERROR,exception.py:118,Internal Server Error: /api/automation/start_test
Traceback (most recent call last):
  File "H:\project\api_automation_test\api_test\common\confighttp.py", line 176, in test_api
    result = operator.eq(json.loads(response_parameter_list), response_data)
  File "D:\Users\SIMO\AppData\Local\Programs\Python\Python36\lib\json\__init__.py", line 354, in loads
    return _default_decoder.decode(s)
  File "D:\Users\SIMO\AppData\Local\Programs\Python\Python36\lib\json\decoder.py", line 339, in decode
    obj, end = self.raw_decode(s, idx=_w(s, 0).end())
  File "D:\Users\SIMO\AppData\Local\Programs\Python\Python36\lib\json\decoder.py", line 355, in raw_decode
    obj, end = self.scan_once(s, idx)
json.decoder.JSONDecodeError: Expecting property name enclosed in double quotes: line 1 column 2 (char 1)

During handling of the above exception, another exception occurred:

Traceback (most recent call last):
  File "D:\Users\SIMO\AppData\Local\Programs\Python\Python36\lib\site-packages\django\core\handlers\exception.py", line 35, in inner
    response = get_response(request)
  File "D:\Users\SIMO\AppData\Local\Programs\Python\Python36\lib\site-packages\django\core\handlers\base.py", line 128, in _get_response
    response = self.process_exception_by_middleware(e, request)
  File "D:\Users\SIMO\AppData\Local\Programs\Python\Python36\lib\site-packages\django\core\handlers\base.py", line 126, in _get_response
    response = wrapped_callback(request, *callback_args, **callback_kwargs)
  File "D:\Users\SIMO\AppData\Local\Programs\Python\Python36\lib\site-packages\django\views\decorators\csrf.py", line 54, in wrapped_view
    return view_func(*args, **kwargs)
  File "D:\Users\SIMO\AppData\Local\Programs\Python\Python36\lib\site-packages\django\views\generic\base.py", line 69, in view
    return self.dispatch(request, *args, **kwargs)
  File "D:\Users\SIMO\AppData\Local\Programs\Python\Python36\lib\site-packages\rest_framework\views.py", line 494, in dispatch
    response = self.handle_exception(exc)
  File "D:\Users\SIMO\AppData\Local\Programs\Python\Python36\lib\site-packages\rest_framework\views.py", line 454, in handle_exception
    self.raise_uncaught_exception(exc)
  File "D:\Users\SIMO\AppData\Local\Programs\Python\Python36\lib\site-packages\rest_framework\views.py", line 491, in dispatch
    response = handler(request, *args, **kwargs)
  File "D:\Users\SIMO\AppData\Local\Programs\Python\Python36\lib\site-packages\rest_framework\decorators.py", line 53, in handler
    return func(*args, **kwargs)
  File "H:\project\api_automation_test\api_test\common\common.py", line 65, in verify
    return func(reality_parameter)
  File "H:\project\api_automation_test\api_test\api\automationCase.py", line 859, in start_test
    result = test_api(host_id=host_id, case_id=case_id, _id=_id, project_id=project_id)
  File "H:\project\api_automation_test\api_test\common\confighttp.py", line 178, in test_api
    result = operator.eq(json.loads(response_parameter_list.replace('True', 'true').replace('False', 'false')), response_data)
  File "D:\Users\SIMO\AppData\Local\Programs\Python\Python36\lib\json\__init__.py", line 354, in loads
    return _default_decoder.decode(s)
  File "D:\Users\SIMO\AppData\Local\Programs\Python\Python36\lib\json\decoder.py", line 339, in decode
    obj, end = self.raw_decode(s, idx=_w(s, 0).end())
  File "D:\Users\SIMO\AppData\Local\Programs\Python\Python36\lib\json\decoder.py", line 355, in raw_decode
    obj, end = self.scan_once(s, idx)
json.decoder.JSONDecodeError: Expecting property name enclosed in double quotes: line 1 column 2 (char 1)
2018-05-14 15:30:13,641,4496,django.server,ERROR,basehttp.py:124,"POST /api/automation/start_test HTTP/1.1" 500 20444
2018-05-14 15:30:15,109,4496,django.request,ERROR,exception.py:118,Internal Server Error: /api/automation/start_test
Traceback (most recent call last):
  File "H:\project\api_automation_test\api_test\common\confighttp.py", line 176, in test_api
    result = operator.eq(json.loads(response_parameter_list), response_data)
  File "D:\Users\SIMO\AppData\Local\Programs\Python\Python36\lib\json\__init__.py", line 354, in loads
    return _default_decoder.decode(s)
  File "D:\Users\SIMO\AppData\Local\Programs\Python\Python36\lib\json\decoder.py", line 339, in decode
    obj, end = self.raw_decode(s, idx=_w(s, 0).end())
  File "D:\Users\SIMO\AppData\Local\Programs\Python\Python36\lib\json\decoder.py", line 355, in raw_decode
    obj, end = self.scan_once(s, idx)
json.decoder.JSONDecodeError: Expecting property name enclosed in double quotes: line 1 column 2 (char 1)

During handling of the above exception, another exception occurred:

Traceback (most recent call last):
  File "D:\Users\SIMO\AppData\Local\Programs\Python\Python36\lib\site-packages\django\core\handlers\exception.py", line 35, in inner
    response = get_response(request)
  File "D:\Users\SIMO\AppData\Local\Programs\Python\Python36\lib\site-packages\django\core\handlers\base.py", line 128, in _get_response
    response = self.process_exception_by_middleware(e, request)
  File "D:\Users\SIMO\AppData\Local\Programs\Python\Python36\lib\site-packages\django\core\handlers\base.py", line 126, in _get_response
    response = wrapped_callback(request, *callback_args, **callback_kwargs)
  File "D:\Users\SIMO\AppData\Local\Programs\Python\Python36\lib\site-packages\django\views\decorators\csrf.py", line 54, in wrapped_view
    return view_func(*args, **kwargs)
  File "D:\Users\SIMO\AppData\Local\Programs\Python\Python36\lib\site-packages\django\views\generic\base.py", line 69, in view
    return self.dispatch(request, *args, **kwargs)
  File "D:\Users\SIMO\AppData\Local\Programs\Python\Python36\lib\site-packages\rest_framework\views.py", line 494, in dispatch
    response = self.handle_exception(exc)
  File "D:\Users\SIMO\AppData\Local\Programs\Python\Python36\lib\site-packages\rest_framework\views.py", line 454, in handle_exception
    self.raise_uncaught_exception(exc)
  File "D:\Users\SIMO\AppData\Local\Programs\Python\Python36\lib\site-packages\rest_framework\views.py", line 491, in dispatch
    response = handler(request, *args, **kwargs)
  File "D:\Users\SIMO\AppData\Local\Programs\Python\Python36\lib\site-packages\rest_framework\decorators.py", line 53, in handler
    return func(*args, **kwargs)
  File "H:\project\api_automation_test\api_test\common\common.py", line 65, in verify
    return func(reality_parameter)
  File "H:\project\api_automation_test\api_test\api\automationCase.py", line 859, in start_test
    result = test_api(host_id=host_id, case_id=case_id, _id=_id, project_id=project_id)
  File "H:\project\api_automation_test\api_test\common\confighttp.py", line 178, in test_api
    result = operator.eq(json.loads(response_parameter_list.replace('True', 'true').replace('False', 'false')), response_data)
  File "D:\Users\SIMO\AppData\Local\Programs\Python\Python36\lib\json\__init__.py", line 354, in loads
    return _default_decoder.decode(s)
  File "D:\Users\SIMO\AppData\Local\Programs\Python\Python36\lib\json\decoder.py", line 339, in decode
    obj, end = self.raw_decode(s, idx=_w(s, 0).end())
  File "D:\Users\SIMO\AppData\Local\Programs\Python\Python36\lib\json\decoder.py", line 355, in raw_decode
    obj, end = self.scan_once(s, idx)
json.decoder.JSONDecodeError: Expecting property name enclosed in double quotes: line 1 column 2 (char 1)
2018-05-14 15:30:15,126,4496,django.server,ERROR,basehttp.py:124,"POST /api/automation/start_test HTTP/1.1" 500 20444
2018-05-14 15:30:25,989,9768,django.request,ERROR,exception.py:118,Internal Server Error: /api/automation/start_test
Traceback (most recent call last):
  File "H:\project\api_automation_test\api_test\common\confighttp.py", line 176, in test_api
    result = operator.eq(json.loads(response_parameter_list), response_data)
  File "D:\Users\SIMO\AppData\Local\Programs\Python\Python36\lib\json\__init__.py", line 354, in loads
    return _default_decoder.decode(s)
  File "D:\Users\SIMO\AppData\Local\Programs\Python\Python36\lib\json\decoder.py", line 339, in decode
    obj, end = self.raw_decode(s, idx=_w(s, 0).end())
  File "D:\Users\SIMO\AppData\Local\Programs\Python\Python36\lib\json\decoder.py", line 355, in raw_decode
    obj, end = self.scan_once(s, idx)
json.decoder.JSONDecodeError: Expecting property name enclosed in double quotes: line 1 column 2 (char 1)

During handling of the above exception, another exception occurred:

Traceback (most recent call last):
  File "D:\Users\SIMO\AppData\Local\Programs\Python\Python36\lib\site-packages\django\core\handlers\exception.py", line 35, in inner
    response = get_response(request)
  File "D:\Users\SIMO\AppData\Local\Programs\Python\Python36\lib\site-packages\django\core\handlers\base.py", line 128, in _get_response
    response = self.process_exception_by_middleware(e, request)
  File "D:\Users\SIMO\AppData\Local\Programs\Python\Python36\lib\site-packages\django\core\handlers\base.py", line 126, in _get_response
    response = wrapped_callback(request, *callback_args, **callback_kwargs)
  File "D:\Users\SIMO\AppData\Local\Programs\Python\Python36\lib\site-packages\django\views\decorators\csrf.py", line 54, in wrapped_view
    return view_func(*args, **kwargs)
  File "D:\Users\SIMO\AppData\Local\Programs\Python\Python36\lib\site-packages\django\views\generic\base.py", line 69, in view
    return self.dispatch(request, *args, **kwargs)
  File "D:\Users\SIMO\AppData\Local\Programs\Python\Python36\lib\site-packages\rest_framework\views.py", line 494, in dispatch
    response = self.handle_exception(exc)
  File "D:\Users\SIMO\AppData\Local\Programs\Python\Python36\lib\site-packages\rest_framework\views.py", line 454, in handle_exception
    self.raise_uncaught_exception(exc)
  File "D:\Users\SIMO\AppData\Local\Programs\Python\Python36\lib\site-packages\rest_framework\views.py", line 491, in dispatch
    response = handler(request, *args, **kwargs)
  File "D:\Users\SIMO\AppData\Local\Programs\Python\Python36\lib\site-packages\rest_framework\decorators.py", line 53, in handler
    return func(*args, **kwargs)
  File "H:\project\api_automation_test\api_test\common\common.py", line 65, in verify
    return func(reality_parameter)
  File "H:\project\api_automation_test\api_test\api\automationCase.py", line 859, in start_test
    result = test_api(host_id=host_id, case_id=case_id, _id=_id, project_id=project_id)
  File "H:\project\api_automation_test\api_test\common\confighttp.py", line 178, in test_api
    result = operator.eq(json.loads(response_parameter_list.replace('True', 'true').replace('False', 'false')), response_data)
  File "D:\Users\SIMO\AppData\Local\Programs\Python\Python36\lib\json\__init__.py", line 354, in loads
    return _default_decoder.decode(s)
  File "D:\Users\SIMO\AppData\Local\Programs\Python\Python36\lib\json\decoder.py", line 339, in decode
    obj, end = self.raw_decode(s, idx=_w(s, 0).end())
  File "D:\Users\SIMO\AppData\Local\Programs\Python\Python36\lib\json\decoder.py", line 355, in raw_decode
    obj, end = self.scan_once(s, idx)
json.decoder.JSONDecodeError: Expecting property name enclosed in double quotes: line 1 column 2 (char 1)
2018-05-14 15:30:26,008,9768,django.server,ERROR,basehttp.py:124,"POST /api/automation/start_test HTTP/1.1" 500 20445
2018-05-14 15:33:26,693,4620,django.request,ERROR,exception.py:118,Internal Server Error: /api/automation/start_test
Traceback (most recent call last):
  File "H:\project\api_automation_test\api_test\common\confighttp.py", line 176, in test_api
    result = operator.eq(eval(response_parameter_list), response_data)
  File "<string>", line 1, in <module>
NameError: name 'true' is not defined

During handling of the above exception, another exception occurred:

Traceback (most recent call last):
  File "D:\Users\SIMO\AppData\Local\Programs\Python\Python36\lib\site-packages\django\core\handlers\exception.py", line 35, in inner
    response = get_response(request)
  File "D:\Users\SIMO\AppData\Local\Programs\Python\Python36\lib\site-packages\django\core\handlers\base.py", line 128, in _get_response
    response = self.process_exception_by_middleware(e, request)
  File "D:\Users\SIMO\AppData\Local\Programs\Python\Python36\lib\site-packages\django\core\handlers\base.py", line 126, in _get_response
    response = wrapped_callback(request, *callback_args, **callback_kwargs)
  File "D:\Users\SIMO\AppData\Local\Programs\Python\Python36\lib\site-packages\django\views\decorators\csrf.py", line 54, in wrapped_view
    return view_func(*args, **kwargs)
  File "D:\Users\SIMO\AppData\Local\Programs\Python\Python36\lib\site-packages\django\views\generic\base.py", line 69, in view
    return self.dispatch(request, *args, **kwargs)
  File "D:\Users\SIMO\AppData\Local\Programs\Python\Python36\lib\site-packages\rest_framework\views.py", line 494, in dispatch
    response = self.handle_exception(exc)
  File "D:\Users\SIMO\AppData\Local\Programs\Python\Python36\lib\site-packages\rest_framework\views.py", line 454, in handle_exception
    self.raise_uncaught_exception(exc)
  File "D:\Users\SIMO\AppData\Local\Programs\Python\Python36\lib\site-packages\rest_framework\views.py", line 491, in dispatch
    response = handler(request, *args, **kwargs)
  File "D:\Users\SIMO\AppData\Local\Programs\Python\Python36\lib\site-packages\rest_framework\decorators.py", line 53, in handler
    return func(*args, **kwargs)
  File "H:\project\api_automation_test\api_test\common\common.py", line 65, in verify
    return func(reality_parameter)
  File "H:\project\api_automation_test\api_test\api\automationCase.py", line 859, in start_test
    result = test_api(host_id=host_id, case_id=case_id, _id=_id, project_id=project_id)
  File "H:\project\api_automation_test\api_test\common\confighttp.py", line 178, in test_api
    result = operator.eq(eval(response_parameter_list.replace('true', True)), response_data)
TypeError: replace() argument 2 must be str, not bool
2018-05-14 15:33:26,712,4620,django.server,ERROR,basehttp.py:124,"POST /api/automation/start_test HTTP/1.1" 500 19436
2018-05-14 15:36:10,776,14056,root,ERROR,confighttp.py:107,ERROR
Traceback (most recent call last):
  File "H:\project\api_automation_test\api_test\common\confighttp.py", line 103, in test_api
    AutomationTestResult.objects.filter(automationCaseApi=api_id[0])))[0]['fields']["responseData"])
IndexError: list index out of range
2018-05-14 15:36:10,779,14056,root,ERROR,confighttp.py:108,list index out of range
2018-05-14 15:36:10,831,14056,root,ERROR,confighttp.py:107,ERROR
Traceback (most recent call last):
  File "H:\project\api_automation_test\api_test\common\confighttp.py", line 103, in test_api
    AutomationTestResult.objects.filter(automationCaseApi=api_id[0])))[0]['fields']["responseData"])
IndexError: list index out of range
2018-05-14 15:36:10,831,14056,root,ERROR,confighttp.py:108,list index out of range
2018-05-14 15:36:17,879,14056,root,ERROR,confighttp.py:107,ERROR
Traceback (most recent call last):
  File "H:\project\api_automation_test\api_test\common\confighttp.py", line 103, in test_api
    AutomationTestResult.objects.filter(automationCaseApi=api_id[0])))[0]['fields']["responseData"])
IndexError: list index out of range
2018-05-14 15:36:17,882,14056,root,ERROR,confighttp.py:107,ERROR
Traceback (most recent call last):
  File "H:\project\api_automation_test\api_test\common\confighttp.py", line 103, in test_api
    AutomationTestResult.objects.filter(automationCaseApi=api_id[0])))[0]['fields']["responseData"])
IndexError: list index out of range
2018-05-14 15:36:17,883,14056,root,ERROR,confighttp.py:108,list index out of range
2018-05-14 15:36:17,885,14056,root,ERROR,confighttp.py:108,list index out of range
2018-05-14 15:36:26,890,14056,root,ERROR,confighttp.py:107,ERROR
Traceback (most recent call last):
  File "H:\project\api_automation_test\api_test\common\confighttp.py", line 103, in test_api
    AutomationTestResult.objects.filter(automationCaseApi=api_id[0])))[0]['fields']["responseData"])
IndexError: list index out of range
2018-05-14 15:36:26,893,14056,root,ERROR,confighttp.py:108,list index out of range
2018-05-14 15:36:32,566,14056,root,ERROR,confighttp.py:107,ERROR
Traceback (most recent call last):
  File "H:\project\api_automation_test\api_test\common\confighttp.py", line 103, in test_api
    AutomationTestResult.objects.filter(automationCaseApi=api_id[0])))[0]['fields']["responseData"])
IndexError: list index out of range
2018-05-14 15:36:32,566,14056,root,ERROR,confighttp.py:108,list index out of range
2018-05-14 15:36:32,597,14056,root,ERROR,confighttp.py:107,ERROR
Traceback (most recent call last):
  File "H:\project\api_automation_test\api_test\common\confighttp.py", line 103, in test_api
    AutomationTestResult.objects.filter(automationCaseApi=api_id[0])))[0]['fields']["responseData"])
IndexError: list index out of range
2018-05-14 15:36:32,600,14056,root,ERROR,confighttp.py:108,list index out of range
2018-05-14 15:37:53,619,14056,root,ERROR,confighttp.py:107,ERROR
Traceback (most recent call last):
  File "H:\project\api_automation_test\api_test\common\confighttp.py", line 103, in test_api
    AutomationTestResult.objects.filter(automationCaseApi=api_id[0])))[0]['fields']["responseData"])
IndexError: list index out of range
2018-05-14 15:37:53,621,14056,root,ERROR,confighttp.py:108,list index out of range
2018-05-14 15:45:57,350,7000,root,ERROR,confighttp.py:107,ERROR
Traceback (most recent call last):
  File "H:\project\api_automation_test\api_test\common\confighttp.py", line 103, in test_api
    AutomationTestResult.objects.filter(automationCaseApi=api_id[0])))[0]['fields']["responseData"])
IndexError: list index out of range
2018-05-14 15:45:57,350,7000,root,ERROR,confighttp.py:108,list index out of range
2018-05-14 15:45:57,365,7000,root,ERROR,confighttp.py:107,ERROR
Traceback (most recent call last):
  File "H:\project\api_automation_test\api_test\common\confighttp.py", line 103, in test_api
    AutomationTestResult.objects.filter(automationCaseApi=api_id[0])))[0]['fields']["responseData"])
IndexError: list index out of range
2018-05-14 15:45:57,366,7000,root,ERROR,confighttp.py:108,list index out of range
2018-05-15 11:45:39,766,14152,django.server,ERROR,basehttp.py:124,"GET /static/admin/css/changelists.css HTTP/1.1" 500 59
2018-05-15 11:45:39,768,14152,django.server,ERROR,basehttp.py:124,"GET /static/suit/css/font-awesome.min.css HTTP/1.1" 500 59
2018-05-17 15:11:13,207,12132,root,ERROR,confighttp.py:121,ERROR
Traceback (most recent call last):
  File "H:\project\api_automation_test\api_test\common\confighttp.py", line 119, in test_api
    value = value[j]
KeyError: 'data'
2018-05-17 15:11:13,238,12132,root,ERROR,confighttp.py:122,'data'
2018-05-17 15:11:13,307,12132,root,ERROR,confighttp.py:121,ERROR
Traceback (most recent call last):
  File "H:\project\api_automation_test\api_test\common\confighttp.py", line 119, in test_api
    value = value[j]
KeyError: 'data'
2018-05-17 15:11:13,307,12132,root,ERROR,confighttp.py:122,'data'
2018-05-17 15:11:13,378,12132,root,ERROR,confighttp.py:121,ERROR
Traceback (most recent call last):
  File "H:\project\api_automation_test\api_test\common\confighttp.py", line 119, in test_api
    value = value[j]
KeyError: 'data'
2018-05-17 15:11:13,379,12132,root,ERROR,confighttp.py:122,'data'
2018-05-17 15:11:13,448,12132,root,ERROR,confighttp.py:121,ERROR
Traceback (most recent call last):
  File "H:\project\api_automation_test\api_test\common\confighttp.py", line 119, in test_api
    value = value[j]
KeyError: 'data'
2018-05-17 15:11:13,449,12132,root,ERROR,confighttp.py:122,'data'
2018-05-17 15:24:19,388,14164,root,ERROR,confighttp.py:121,ERROR
Traceback (most recent call last):
  File "H:\project\api_automation_test\api_test\common\confighttp.py", line 117, in test_api
    AutomationTestResult.objects.filter(automationCaseApi=api_id[0])))[0]['fields']["responseData"])
  File "<string>", line 0
    
    ^
SyntaxError: unexpected EOF while parsing
2018-05-17 15:24:19,389,14164,root,ERROR,confighttp.py:122,unexpected EOF while parsing (<string>, line 0)
2018-05-17 15:24:19,453,14164,root,ERROR,confighttp.py:121,ERROR
Traceback (most recent call last):
  File "H:\project\api_automation_test\api_test\common\confighttp.py", line 117, in test_api
    AutomationTestResult.objects.filter(automationCaseApi=api_id[0])))[0]['fields']["responseData"])
  File "<string>", line 0
    
    ^
SyntaxError: unexpected EOF while parsing
2018-05-17 15:24:19,453,14164,root,ERROR,confighttp.py:122,unexpected EOF while parsing (<string>, line 0)
2018-05-17 15:24:19,538,14164,root,ERROR,confighttp.py:121,ERROR
Traceback (most recent call last):
  File "H:\project\api_automation_test\api_test\common\confighttp.py", line 117, in test_api
    AutomationTestResult.objects.filter(automationCaseApi=api_id[0])))[0]['fields']["responseData"])
  File "<string>", line 0
    
    ^
SyntaxError: unexpected EOF while parsing
2018-05-17 15:24:19,539,14164,root,ERROR,confighttp.py:122,unexpected EOF while parsing (<string>, line 0)
2018-05-17 15:24:19,605,14164,root,ERROR,confighttp.py:121,ERROR
Traceback (most recent call last):
  File "H:\project\api_automation_test\api_test\common\confighttp.py", line 117, in test_api
    AutomationTestResult.objects.filter(automationCaseApi=api_id[0])))[0]['fields']["responseData"])
  File "<string>", line 0
    
    ^
SyntaxError: unexpected EOF while parsing
2018-05-17 15:24:19,605,14164,root,ERROR,confighttp.py:122,unexpected EOF while parsing (<string>, line 0)
2018-05-17 15:29:41,574,14164,root,ERROR,confighttp.py:121,ERROR
Traceback (most recent call last):
  File "H:\project\api_automation_test\api_test\common\confighttp.py", line 119, in test_api
    value = value[j]
KeyError: 'data'
2018-05-17 15:29:41,574,14164,root,ERROR,confighttp.py:122,'data'
2018-05-17 15:29:41,645,14164,root,ERROR,confighttp.py:121,ERROR
Traceback (most recent call last):
  File "H:\project\api_automation_test\api_test\common\confighttp.py", line 119, in test_api
    value = value[j]
KeyError: 'data'
2018-05-17 15:29:41,645,14164,root,ERROR,confighttp.py:122,'data'
2018-05-17 15:29:41,715,14164,root,ERROR,confighttp.py:121,ERROR
Traceback (most recent call last):
  File "H:\project\api_automation_test\api_test\common\confighttp.py", line 119, in test_api
    value = value[j]
KeyError: 'data'
2018-05-17 15:29:41,716,14164,root,ERROR,confighttp.py:122,'data'
2018-05-17 15:29:41,780,14164,root,ERROR,confighttp.py:121,ERROR
Traceback (most recent call last):
  File "H:\project\api_automation_test\api_test\common\confighttp.py", line 119, in test_api
    value = value[j]
KeyError: 'data'
2018-05-17 15:29:41,780,14164,root,ERROR,confighttp.py:122,'data'
2018-05-17 15:29:41,845,14164,root,ERROR,confighttp.py:121,ERROR
Traceback (most recent call last):
  File "H:\project\api_automation_test\api_test\common\confighttp.py", line 119, in test_api
    value = value[j]
KeyError: 'data'
2018-05-17 15:29:41,845,14164,root,ERROR,confighttp.py:122,'data'
2018-05-18 17:11:53,731,11288,django.request,ERROR,exception.py:118,Internal Server Error: /api/automation/auto_test_report
Traceback (most recent call last):
  File "D:\Users\SIMO\AppData\Local\Programs\Python\Python36\lib\site-packages\rest_framework\fields.py", line 441, in get_attribute
    return get_attribute(instance, self.source_attrs)
  File "D:\Users\SIMO\AppData\Local\Programs\Python\Python36\lib\site-packages\rest_framework\fields.py", line 100, in get_attribute
    instance = getattr(instance, attr)
AttributeError: 'AutomationCaseTestResult' object has no attribute 'automationTestCase'

During handling of the above exception, another exception occurred:

Traceback (most recent call last):
  File "D:\Users\SIMO\AppData\Local\Programs\Python\Python36\lib\site-packages\django\core\handlers\exception.py", line 35, in inner
    response = get_response(request)
  File "D:\Users\SIMO\AppData\Local\Programs\Python\Python36\lib\site-packages\django\core\handlers\base.py", line 128, in _get_response
    response = self.process_exception_by_middleware(e, request)
  File "D:\Users\SIMO\AppData\Local\Programs\Python\Python36\lib\site-packages\django\core\handlers\base.py", line 126, in _get_response
    response = wrapped_callback(request, *callback_args, **callback_kwargs)
  File "D:\Users\SIMO\AppData\Local\Programs\Python\Python36\lib\site-packages\django\views\decorators\csrf.py", line 54, in wrapped_view
    return view_func(*args, **kwargs)
  File "D:\Users\SIMO\AppData\Local\Programs\Python\Python36\lib\site-packages\django\views\generic\base.py", line 69, in view
    return self.dispatch(request, *args, **kwargs)
  File "D:\Users\SIMO\AppData\Local\Programs\Python\Python36\lib\site-packages\rest_framework\views.py", line 494, in dispatch
    response = self.handle_exception(exc)
  File "D:\Users\SIMO\AppData\Local\Programs\Python\Python36\lib\site-packages\rest_framework\views.py", line 454, in handle_exception
    self.raise_uncaught_exception(exc)
  File "D:\Users\SIMO\AppData\Local\Programs\Python\Python36\lib\site-packages\rest_framework\views.py", line 491, in dispatch
    response = handler(request, *args, **kwargs)
  File "D:\Users\SIMO\AppData\Local\Programs\Python\Python36\lib\site-packages\rest_framework\decorators.py", line 53, in handler
    return func(*args, **kwargs)
  File "H:\project\api_automation_test\api_test\common\common.py", line 79, in verify
    return func(reality_parameter)
  File "H:\project\api_automation_test\api_test\api\automationCase.py", line 1149, in auto_test_report
    AutomationCaseTestResult.objects.filter(api), many=True).data
  File "D:\Users\SIMO\AppData\Local\Programs\Python\Python36\lib\site-packages\rest_framework\serializers.py", line 740, in data
    ret = super(ListSerializer, self).data
  File "D:\Users\SIMO\AppData\Local\Programs\Python\Python36\lib\site-packages\rest_framework\serializers.py", line 260, in data
    self._data = self.to_representation(self.instance)
  File "D:\Users\SIMO\AppData\Local\Programs\Python\Python36\lib\site-packages\rest_framework\serializers.py", line 658, in to_representation
    self.child.to_representation(item) for item in iterable
  File "D:\Users\SIMO\AppData\Local\Programs\Python\Python36\lib\site-packages\rest_framework\serializers.py", line 658, in <listcomp>
    self.child.to_representation(item) for item in iterable
  File "D:\Users\SIMO\AppData\Local\Programs\Python\Python36\lib\site-packages\rest_framework\serializers.py", line 489, in to_representation
    attribute = field.get_attribute(instance)
  File "D:\Users\SIMO\AppData\Local\Programs\Python\Python36\lib\site-packages\rest_framework\fields.py", line 462, in get_attribute
    raise type(exc)(msg)
AttributeError: Got AttributeError when attempting to get a value for field `automationTestCase` on serializer `AutomationTestReportSerializer`.
The serializer field might be named incorrectly and not match any attribute or key on the `AutomationCaseTestResult` instance.
Original exception text was: 'AutomationCaseTestResult' object has no attribute 'automationTestCase'.
2018-05-18 17:11:53,866,11288,django.server,ERROR,basehttp.py:124,"GET /api/automation/auto_test_report?project_id=1&time=2018-05-18%2015:53:53.797176 HTTP/1.1" 500 21380
2018-05-18 17:12:33,472,1964,django.request,ERROR,exception.py:118,Internal Server Error: /api/automation/auto_test_report
Traceback (most recent call last):
  File "D:\Users\SIMO\AppData\Local\Programs\Python\Python36\lib\site-packages\rest_framework\fields.py", line 441, in get_attribute
    return get_attribute(instance, self.source_attrs)
  File "D:\Users\SIMO\AppData\Local\Programs\Python\Python36\lib\site-packages\rest_framework\fields.py", line 100, in get_attribute
    instance = getattr(instance, attr)
AttributeError: 'AutomationCaseTestResult' object has no attribute 'automationTestCase'

During handling of the above exception, another exception occurred:

Traceback (most recent call last):
  File "D:\Users\SIMO\AppData\Local\Programs\Python\Python36\lib\site-packages\django\core\handlers\exception.py", line 35, in inner
    response = get_response(request)
  File "D:\Users\SIMO\AppData\Local\Programs\Python\Python36\lib\site-packages\django\core\handlers\base.py", line 128, in _get_response
    response = self.process_exception_by_middleware(e, request)
  File "D:\Users\SIMO\AppData\Local\Programs\Python\Python36\lib\site-packages\django\core\handlers\base.py", line 126, in _get_response
    response = wrapped_callback(request, *callback_args, **callback_kwargs)
  File "D:\Users\SIMO\AppData\Local\Programs\Python\Python36\lib\site-packages\django\views\decorators\csrf.py", line 54, in wrapped_view
    return view_func(*args, **kwargs)
  File "D:\Users\SIMO\AppData\Local\Programs\Python\Python36\lib\site-packages\django\views\generic\base.py", line 69, in view
    return self.dispatch(request, *args, **kwargs)
  File "D:\Users\SIMO\AppData\Local\Programs\Python\Python36\lib\site-packages\rest_framework\views.py", line 494, in dispatch
    response = self.handle_exception(exc)
  File "D:\Users\SIMO\AppData\Local\Programs\Python\Python36\lib\site-packages\rest_framework\views.py", line 454, in handle_exception
    self.raise_uncaught_exception(exc)
  File "D:\Users\SIMO\AppData\Local\Programs\Python\Python36\lib\site-packages\rest_framework\views.py", line 491, in dispatch
    response = handler(request, *args, **kwargs)
  File "D:\Users\SIMO\AppData\Local\Programs\Python\Python36\lib\site-packages\rest_framework\decorators.py", line 53, in handler
    return func(*args, **kwargs)
  File "H:\project\api_automation_test\api_test\common\common.py", line 79, in verify
    return func(reality_parameter)
  File "H:\project\api_automation_test\api_test\api\automationCase.py", line 1150, in auto_test_report
    AutomationCaseTestResult.objects.filter(api), many=True).data
  File "D:\Users\SIMO\AppData\Local\Programs\Python\Python36\lib\site-packages\rest_framework\serializers.py", line 740, in data
    ret = super(ListSerializer, self).data
  File "D:\Users\SIMO\AppData\Local\Programs\Python\Python36\lib\site-packages\rest_framework\serializers.py", line 260, in data
    self._data = self.to_representation(self.instance)
  File "D:\Users\SIMO\AppData\Local\Programs\Python\Python36\lib\site-packages\rest_framework\serializers.py", line 658, in to_representation
    self.child.to_representation(item) for item in iterable
  File "D:\Users\SIMO\AppData\Local\Programs\Python\Python36\lib\site-packages\rest_framework\serializers.py", line 658, in <listcomp>
    self.child.to_representation(item) for item in iterable
  File "D:\Users\SIMO\AppData\Local\Programs\Python\Python36\lib\site-packages\rest_framework\serializers.py", line 489, in to_representation
    attribute = field.get_attribute(instance)
  File "D:\Users\SIMO\AppData\Local\Programs\Python\Python36\lib\site-packages\rest_framework\fields.py", line 462, in get_attribute
    raise type(exc)(msg)
AttributeError: Got AttributeError when attempting to get a value for field `automationTestCase` on serializer `AutomationTestReportSerializer`.
The serializer field might be named incorrectly and not match any attribute or key on the `AutomationCaseTestResult` instance.
Original exception text was: 'AutomationCaseTestResult' object has no attribute 'automationTestCase'.
2018-05-18 17:12:33,496,1964,django.server,ERROR,basehttp.py:124,"GET /api/automation/auto_test_report?project_id=1&time=2018-05-18%2015:53:53.797176 HTTP/1.1" 500 21380
2018-05-18 17:12:53,449,3016,django.request,ERROR,exception.py:118,Internal Server Error: /api/automation/auto_test_report
Traceback (most recent call last):
  File "D:\Users\SIMO\AppData\Local\Programs\Python\Python36\lib\site-packages\rest_framework\fields.py", line 441, in get_attribute
    return get_attribute(instance, self.source_attrs)
  File "D:\Users\SIMO\AppData\Local\Programs\Python\Python36\lib\site-packages\rest_framework\fields.py", line 100, in get_attribute
    instance = getattr(instance, attr)
AttributeError: 'AutomationCaseTestResult' object has no attribute 'automationTestCase'

During handling of the above exception, another exception occurred:

Traceback (most recent call last):
  File "D:\Users\SIMO\AppData\Local\Programs\Python\Python36\lib\site-packages\django\core\handlers\exception.py", line 35, in inner
    response = get_response(request)
  File "D:\Users\SIMO\AppData\Local\Programs\Python\Python36\lib\site-packages\django\core\handlers\base.py", line 128, in _get_response
    response = self.process_exception_by_middleware(e, request)
  File "D:\Users\SIMO\AppData\Local\Programs\Python\Python36\lib\site-packages\django\core\handlers\base.py", line 126, in _get_response
    response = wrapped_callback(request, *callback_args, **callback_kwargs)
  File "D:\Users\SIMO\AppData\Local\Programs\Python\Python36\lib\site-packages\django\views\decorators\csrf.py", line 54, in wrapped_view
    return view_func(*args, **kwargs)
  File "D:\Users\SIMO\AppData\Local\Programs\Python\Python36\lib\site-packages\django\views\generic\base.py", line 69, in view
    return self.dispatch(request, *args, **kwargs)
  File "D:\Users\SIMO\AppData\Local\Programs\Python\Python36\lib\site-packages\rest_framework\views.py", line 494, in dispatch
    response = self.handle_exception(exc)
  File "D:\Users\SIMO\AppData\Local\Programs\Python\Python36\lib\site-packages\rest_framework\views.py", line 454, in handle_exception
    self.raise_uncaught_exception(exc)
  File "D:\Users\SIMO\AppData\Local\Programs\Python\Python36\lib\site-packages\rest_framework\views.py", line 491, in dispatch
    response = handler(request, *args, **kwargs)
  File "D:\Users\SIMO\AppData\Local\Programs\Python\Python36\lib\site-packages\rest_framework\decorators.py", line 53, in handler
    return func(*args, **kwargs)
  File "H:\project\api_automation_test\api_test\common\common.py", line 79, in verify
    return func(reality_parameter)
  File "H:\project\api_automation_test\api_test\api\automationCase.py", line 1150, in auto_test_report
    AutomationCaseTestResult.objects.filter(api), many=True).data
  File "D:\Users\SIMO\AppData\Local\Programs\Python\Python36\lib\site-packages\rest_framework\serializers.py", line 740, in data
    ret = super(ListSerializer, self).data
  File "D:\Users\SIMO\AppData\Local\Programs\Python\Python36\lib\site-packages\rest_framework\serializers.py", line 260, in data
    self._data = self.to_representation(self.instance)
  File "D:\Users\SIMO\AppData\Local\Programs\Python\Python36\lib\site-packages\rest_framework\serializers.py", line 658, in to_representation
    self.child.to_representation(item) for item in iterable
  File "D:\Users\SIMO\AppData\Local\Programs\Python\Python36\lib\site-packages\rest_framework\serializers.py", line 658, in <listcomp>
    self.child.to_representation(item) for item in iterable
  File "D:\Users\SIMO\AppData\Local\Programs\Python\Python36\lib\site-packages\rest_framework\serializers.py", line 489, in to_representation
    attribute = field.get_attribute(instance)
  File "D:\Users\SIMO\AppData\Local\Programs\Python\Python36\lib\site-packages\rest_framework\fields.py", line 462, in get_attribute
    raise type(exc)(msg)
AttributeError: Got AttributeError when attempting to get a value for field `automationTestCase` on serializer `AutomationTestReportSerializer`.
The serializer field might be named incorrectly and not match any attribute or key on the `AutomationCaseTestResult` instance.
Original exception text was: 'AutomationCaseTestResult' object has no attribute 'automationTestCase'.
2018-05-18 17:12:53,474,3016,django.server,ERROR,basehttp.py:124,"GET /api/automation/auto_test_report?project_id=1&time=2018-05-18%2015:53:53.797176 HTTP/1.1" 500 21380
2018-05-18 17:13:06,807,3016,django.request,ERROR,exception.py:118,Internal Server Error: /api/automation/auto_test_report
Traceback (most recent call last):
  File "D:\Users\SIMO\AppData\Local\Programs\Python\Python36\lib\site-packages\rest_framework\fields.py", line 441, in get_attribute
    return get_attribute(instance, self.source_attrs)
  File "D:\Users\SIMO\AppData\Local\Programs\Python\Python36\lib\site-packages\rest_framework\fields.py", line 100, in get_attribute
    instance = getattr(instance, attr)
AttributeError: 'AutomationCaseTestResult' object has no attribute 'automationTestCase'

During handling of the above exception, another exception occurred:

Traceback (most recent call last):
  File "D:\Users\SIMO\AppData\Local\Programs\Python\Python36\lib\site-packages\django\core\handlers\exception.py", line 35, in inner
    response = get_response(request)
  File "D:\Users\SIMO\AppData\Local\Programs\Python\Python36\lib\site-packages\django\core\handlers\base.py", line 128, in _get_response
    response = self.process_exception_by_middleware(e, request)
  File "D:\Users\SIMO\AppData\Local\Programs\Python\Python36\lib\site-packages\django\core\handlers\base.py", line 126, in _get_response
    response = wrapped_callback(request, *callback_args, **callback_kwargs)
  File "D:\Users\SIMO\AppData\Local\Programs\Python\Python36\lib\site-packages\django\views\decorators\csrf.py", line 54, in wrapped_view
    return view_func(*args, **kwargs)
  File "D:\Users\SIMO\AppData\Local\Programs\Python\Python36\lib\site-packages\django\views\generic\base.py", line 69, in view
    return self.dispatch(request, *args, **kwargs)
  File "D:\Users\SIMO\AppData\Local\Programs\Python\Python36\lib\site-packages\rest_framework\views.py", line 494, in dispatch
    response = self.handle_exception(exc)
  File "D:\Users\SIMO\AppData\Local\Programs\Python\Python36\lib\site-packages\rest_framework\views.py", line 454, in handle_exception
    self.raise_uncaught_exception(exc)
  File "D:\Users\SIMO\AppData\Local\Programs\Python\Python36\lib\site-packages\rest_framework\views.py", line 491, in dispatch
    response = handler(request, *args, **kwargs)
  File "D:\Users\SIMO\AppData\Local\Programs\Python\Python36\lib\site-packages\rest_framework\decorators.py", line 53, in handler
    return func(*args, **kwargs)
  File "H:\project\api_automation_test\api_test\common\common.py", line 79, in verify
    return func(reality_parameter)
  File "H:\project\api_automation_test\api_test\api\automationCase.py", line 1150, in auto_test_report
    AutomationCaseTestResult.objects.filter(api), many=True).data
  File "D:\Users\SIMO\AppData\Local\Programs\Python\Python36\lib\site-packages\rest_framework\serializers.py", line 740, in data
    ret = super(ListSerializer, self).data
  File "D:\Users\SIMO\AppData\Local\Programs\Python\Python36\lib\site-packages\rest_framework\serializers.py", line 260, in data
    self._data = self.to_representation(self.instance)
  File "D:\Users\SIMO\AppData\Local\Programs\Python\Python36\lib\site-packages\rest_framework\serializers.py", line 658, in to_representation
    self.child.to_representation(item) for item in iterable
  File "D:\Users\SIMO\AppData\Local\Programs\Python\Python36\lib\site-packages\rest_framework\serializers.py", line 658, in <listcomp>
    self.child.to_representation(item) for item in iterable
  File "D:\Users\SIMO\AppData\Local\Programs\Python\Python36\lib\site-packages\rest_framework\serializers.py", line 489, in to_representation
    attribute = field.get_attribute(instance)
  File "D:\Users\SIMO\AppData\Local\Programs\Python\Python36\lib\site-packages\rest_framework\fields.py", line 462, in get_attribute
    raise type(exc)(msg)
AttributeError: Got AttributeError when attempting to get a value for field `automationTestCase` on serializer `AutomationTestReportSerializer`.
The serializer field might be named incorrectly and not match any attribute or key on the `AutomationCaseTestResult` instance.
Original exception text was: 'AutomationCaseTestResult' object has no attribute 'automationTestCase'.
2018-05-18 17:13:06,823,3016,django.server,ERROR,basehttp.py:124,"GET /api/automation/auto_test_report?project_id=1&time=2018-05-18%2015:53:53.797176 HTTP/1.1" 500 21381
2018-05-18 17:14:26,883,9748,django.request,ERROR,exception.py:118,Internal Server Error: /api/automation/auto_test_report
Traceback (most recent call last):
  File "D:\Users\SIMO\AppData\Local\Programs\Python\Python36\lib\site-packages\rest_framework\fields.py", line 441, in get_attribute
    return get_attribute(instance, self.source_attrs)
  File "D:\Users\SIMO\AppData\Local\Programs\Python\Python36\lib\site-packages\rest_framework\fields.py", line 100, in get_attribute
    instance = getattr(instance, attr)
AttributeError: 'AutomationCaseTestResult' object has no attribute 'automationTestCase'

During handling of the above exception, another exception occurred:

Traceback (most recent call last):
  File "D:\Users\SIMO\AppData\Local\Programs\Python\Python36\lib\site-packages\django\core\handlers\exception.py", line 35, in inner
    response = get_response(request)
  File "D:\Users\SIMO\AppData\Local\Programs\Python\Python36\lib\site-packages\django\core\handlers\base.py", line 128, in _get_response
    response = self.process_exception_by_middleware(e, request)
  File "D:\Users\SIMO\AppData\Local\Programs\Python\Python36\lib\site-packages\django\core\handlers\base.py", line 126, in _get_response
    response = wrapped_callback(request, *callback_args, **callback_kwargs)
  File "D:\Users\SIMO\AppData\Local\Programs\Python\Python36\lib\site-packages\django\views\decorators\csrf.py", line 54, in wrapped_view
    return view_func(*args, **kwargs)
  File "D:\Users\SIMO\AppData\Local\Programs\Python\Python36\lib\site-packages\django\views\generic\base.py", line 69, in view
    return self.dispatch(request, *args, **kwargs)
  File "D:\Users\SIMO\AppData\Local\Programs\Python\Python36\lib\site-packages\rest_framework\views.py", line 494, in dispatch
    response = self.handle_exception(exc)
  File "D:\Users\SIMO\AppData\Local\Programs\Python\Python36\lib\site-packages\rest_framework\views.py", line 454, in handle_exception
    self.raise_uncaught_exception(exc)
  File "D:\Users\SIMO\AppData\Local\Programs\Python\Python36\lib\site-packages\rest_framework\views.py", line 491, in dispatch
    response = handler(request, *args, **kwargs)
  File "D:\Users\SIMO\AppData\Local\Programs\Python\Python36\lib\site-packages\rest_framework\decorators.py", line 53, in handler
    return func(*args, **kwargs)
  File "H:\project\api_automation_test\api_test\common\common.py", line 79, in verify
    return func(reality_parameter)
  File "H:\project\api_automation_test\api_test\api\automationCase.py", line 1150, in auto_test_report
    AutomationCaseTestResult.objects.filter(api), many=True).data
  File "D:\Users\SIMO\AppData\Local\Programs\Python\Python36\lib\site-packages\rest_framework\serializers.py", line 740, in data
    ret = super(ListSerializer, self).data
  File "D:\Users\SIMO\AppData\Local\Programs\Python\Python36\lib\site-packages\rest_framework\serializers.py", line 260, in data
    self._data = self.to_representation(self.instance)
  File "D:\Users\SIMO\AppData\Local\Programs\Python\Python36\lib\site-packages\rest_framework\serializers.py", line 658, in to_representation
    self.child.to_representation(item) for item in iterable
  File "D:\Users\SIMO\AppData\Local\Programs\Python\Python36\lib\site-packages\rest_framework\serializers.py", line 658, in <listcomp>
    self.child.to_representation(item) for item in iterable
  File "D:\Users\SIMO\AppData\Local\Programs\Python\Python36\lib\site-packages\rest_framework\serializers.py", line 489, in to_representation
    attribute = field.get_attribute(instance)
  File "D:\Users\SIMO\AppData\Local\Programs\Python\Python36\lib\site-packages\rest_framework\fields.py", line 462, in get_attribute
    raise type(exc)(msg)
AttributeError: Got AttributeError when attempting to get a value for field `automationTestCase` on serializer `AutomationTestReportSerializer`.
The serializer field might be named incorrectly and not match any attribute or key on the `AutomationCaseTestResult` instance.
Original exception text was: 'AutomationCaseTestResult' object has no attribute 'automationTestCase'.
2018-05-18 17:14:26,905,9748,django.server,ERROR,basehttp.py:124,"GET /api/automation/auto_test_report?project_id=1&time=2018-05-18%2015:53:53.797176 HTTP/1.1" 500 21381
2018-05-18 17:14:38,024,6516,django.request,ERROR,exception.py:118,Internal Server Error: /api/automation/auto_test_report
Traceback (most recent call last):
  File "D:\Users\SIMO\AppData\Local\Programs\Python\Python36\lib\site-packages\rest_framework\fields.py", line 441, in get_attribute
    return get_attribute(instance, self.source_attrs)
  File "D:\Users\SIMO\AppData\Local\Programs\Python\Python36\lib\site-packages\rest_framework\fields.py", line 100, in get_attribute
    instance = getattr(instance, attr)
AttributeError: 'AutomationCaseTestResult' object has no attribute 'automationTestCase'

During handling of the above exception, another exception occurred:

Traceback (most recent call last):
  File "D:\Users\SIMO\AppData\Local\Programs\Python\Python36\lib\site-packages\django\core\handlers\exception.py", line 35, in inner
    response = get_response(request)
  File "D:\Users\SIMO\AppData\Local\Programs\Python\Python36\lib\site-packages\django\core\handlers\base.py", line 128, in _get_response
    response = self.process_exception_by_middleware(e, request)
  File "D:\Users\SIMO\AppData\Local\Programs\Python\Python36\lib\site-packages\django\core\handlers\base.py", line 126, in _get_response
    response = wrapped_callback(request, *callback_args, **callback_kwargs)
  File "D:\Users\SIMO\AppData\Local\Programs\Python\Python36\lib\site-packages\django\views\decorators\csrf.py", line 54, in wrapped_view
    return view_func(*args, **kwargs)
  File "D:\Users\SIMO\AppData\Local\Programs\Python\Python36\lib\site-packages\django\views\generic\base.py", line 69, in view
    return self.dispatch(request, *args, **kwargs)
  File "D:\Users\SIMO\AppData\Local\Programs\Python\Python36\lib\site-packages\rest_framework\views.py", line 494, in dispatch
    response = self.handle_exception(exc)
  File "D:\Users\SIMO\AppData\Local\Programs\Python\Python36\lib\site-packages\rest_framework\views.py", line 454, in handle_exception
    self.raise_uncaught_exception(exc)
  File "D:\Users\SIMO\AppData\Local\Programs\Python\Python36\lib\site-packages\rest_framework\views.py", line 491, in dispatch
    response = handler(request, *args, **kwargs)
  File "D:\Users\SIMO\AppData\Local\Programs\Python\Python36\lib\site-packages\rest_framework\decorators.py", line 53, in handler
    return func(*args, **kwargs)
  File "H:\project\api_automation_test\api_test\common\common.py", line 79, in verify
    return func(reality_parameter)
  File "H:\project\api_automation_test\api_test\api\automationCase.py", line 1150, in auto_test_report
    AutomationCaseTestResult.objects.filter(api), many=True).data
  File "D:\Users\SIMO\AppData\Local\Programs\Python\Python36\lib\site-packages\rest_framework\serializers.py", line 740, in data
    ret = super(ListSerializer, self).data
  File "D:\Users\SIMO\AppData\Local\Programs\Python\Python36\lib\site-packages\rest_framework\serializers.py", line 260, in data
    self._data = self.to_representation(self.instance)
  File "D:\Users\SIMO\AppData\Local\Programs\Python\Python36\lib\site-packages\rest_framework\serializers.py", line 658, in to_representation
    self.child.to_representation(item) for item in iterable
  File "D:\Users\SIMO\AppData\Local\Programs\Python\Python36\lib\site-packages\rest_framework\serializers.py", line 658, in <listcomp>
    self.child.to_representation(item) for item in iterable
  File "D:\Users\SIMO\AppData\Local\Programs\Python\Python36\lib\site-packages\rest_framework\serializers.py", line 489, in to_representation
    attribute = field.get_attribute(instance)
  File "D:\Users\SIMO\AppData\Local\Programs\Python\Python36\lib\site-packages\rest_framework\fields.py", line 462, in get_attribute
    raise type(exc)(msg)
AttributeError: Got AttributeError when attempting to get a value for field `automationTestCase` on serializer `AutomationTestReportSerializer`.
The serializer field might be named incorrectly and not match any attribute or key on the `AutomationCaseTestResult` instance.
Original exception text was: 'AutomationCaseTestResult' object has no attribute 'automationTestCase'.
2018-05-18 17:14:38,043,6516,django.server,ERROR,basehttp.py:124,"GET /api/automation/auto_test_report?project_id=1&time=2018-05-18%2015:53:53.797176 HTTP/1.1" 500 21380
2018-05-18 17:15:58,112,1404,django.request,ERROR,exception.py:118,Internal Server Error: /api/automation/auto_test_report
Traceback (most recent call last):
  File "D:\Users\SIMO\AppData\Local\Programs\Python\Python36\lib\site-packages\rest_framework\fields.py", line 441, in get_attribute
    return get_attribute(instance, self.source_attrs)
  File "D:\Users\SIMO\AppData\Local\Programs\Python\Python36\lib\site-packages\rest_framework\fields.py", line 100, in get_attribute
    instance = getattr(instance, attr)
AttributeError: 'AutomationCaseTestResult' object has no attribute 'automationTestCase'

During handling of the above exception, another exception occurred:

Traceback (most recent call last):
  File "D:\Users\SIMO\AppData\Local\Programs\Python\Python36\lib\site-packages\django\core\handlers\exception.py", line 35, in inner
    response = get_response(request)
  File "D:\Users\SIMO\AppData\Local\Programs\Python\Python36\lib\site-packages\django\core\handlers\base.py", line 128, in _get_response
    response = self.process_exception_by_middleware(e, request)
  File "D:\Users\SIMO\AppData\Local\Programs\Python\Python36\lib\site-packages\django\core\handlers\base.py", line 126, in _get_response
    response = wrapped_callback(request, *callback_args, **callback_kwargs)
  File "D:\Users\SIMO\AppData\Local\Programs\Python\Python36\lib\site-packages\django\views\decorators\csrf.py", line 54, in wrapped_view
    return view_func(*args, **kwargs)
  File "D:\Users\SIMO\AppData\Local\Programs\Python\Python36\lib\site-packages\django\views\generic\base.py", line 69, in view
    return self.dispatch(request, *args, **kwargs)
  File "D:\Users\SIMO\AppData\Local\Programs\Python\Python36\lib\site-packages\rest_framework\views.py", line 494, in dispatch
    response = self.handle_exception(exc)
  File "D:\Users\SIMO\AppData\Local\Programs\Python\Python36\lib\site-packages\rest_framework\views.py", line 454, in handle_exception
    self.raise_uncaught_exception(exc)
  File "D:\Users\SIMO\AppData\Local\Programs\Python\Python36\lib\site-packages\rest_framework\views.py", line 491, in dispatch
    response = handler(request, *args, **kwargs)
  File "D:\Users\SIMO\AppData\Local\Programs\Python\Python36\lib\site-packages\rest_framework\decorators.py", line 53, in handler
    return func(*args, **kwargs)
  File "H:\project\api_automation_test\api_test\common\common.py", line 79, in verify
    return func(reality_parameter)
  File "H:\project\api_automation_test\api_test\api\automationCase.py", line 1150, in auto_test_report
    AutomationCaseTestResult.objects.filter(api), many=True).data
  File "D:\Users\SIMO\AppData\Local\Programs\Python\Python36\lib\site-packages\rest_framework\serializers.py", line 740, in data
    ret = super(ListSerializer, self).data
  File "D:\Users\SIMO\AppData\Local\Programs\Python\Python36\lib\site-packages\rest_framework\serializers.py", line 260, in data
    self._data = self.to_representation(self.instance)
  File "D:\Users\SIMO\AppData\Local\Programs\Python\Python36\lib\site-packages\rest_framework\serializers.py", line 658, in to_representation
    self.child.to_representation(item) for item in iterable
  File "D:\Users\SIMO\AppData\Local\Programs\Python\Python36\lib\site-packages\rest_framework\serializers.py", line 658, in <listcomp>
    self.child.to_representation(item) for item in iterable
  File "D:\Users\SIMO\AppData\Local\Programs\Python\Python36\lib\site-packages\rest_framework\serializers.py", line 489, in to_representation
    attribute = field.get_attribute(instance)
  File "D:\Users\SIMO\AppData\Local\Programs\Python\Python36\lib\site-packages\rest_framework\fields.py", line 462, in get_attribute
    raise type(exc)(msg)
AttributeError: Got AttributeError when attempting to get a value for field `automationTestCase` on serializer `AutomationTestReportSerializer`.
The serializer field might be named incorrectly and not match any attribute or key on the `AutomationCaseTestResult` instance.
Original exception text was: 'AutomationCaseTestResult' object has no attribute 'automationTestCase'.
2018-05-18 17:15:58,136,1404,django.server,ERROR,basehttp.py:124,"GET /api/automation/auto_test_report?project_id=1&time=2018-05-18%2015:53:53.797176 HTTP/1.1" 500 21380
2018-05-18 17:17:09,487,13512,django.request,ERROR,exception.py:118,Internal Server Error: /api/automation/auto_test_report
Traceback (most recent call last):
  File "D:\Users\SIMO\AppData\Local\Programs\Python\Python36\lib\site-packages\rest_framework\fields.py", line 441, in get_attribute
    return get_attribute(instance, self.source_attrs)
  File "D:\Users\SIMO\AppData\Local\Programs\Python\Python36\lib\site-packages\rest_framework\fields.py", line 100, in get_attribute
    instance = getattr(instance, attr)
AttributeError: 'AutomationCaseTestResult' object has no attribute 'automationTestCase'

During handling of the above exception, another exception occurred:

Traceback (most recent call last):
  File "D:\Users\SIMO\AppData\Local\Programs\Python\Python36\lib\site-packages\django\core\handlers\exception.py", line 35, in inner
    response = get_response(request)
  File "D:\Users\SIMO\AppData\Local\Programs\Python\Python36\lib\site-packages\django\core\handlers\base.py", line 128, in _get_response
    response = self.process_exception_by_middleware(e, request)
  File "D:\Users\SIMO\AppData\Local\Programs\Python\Python36\lib\site-packages\django\core\handlers\base.py", line 126, in _get_response
    response = wrapped_callback(request, *callback_args, **callback_kwargs)
  File "D:\Users\SIMO\AppData\Local\Programs\Python\Python36\lib\site-packages\django\views\decorators\csrf.py", line 54, in wrapped_view
    return view_func(*args, **kwargs)
  File "D:\Users\SIMO\AppData\Local\Programs\Python\Python36\lib\site-packages\django\views\generic\base.py", line 69, in view
    return self.dispatch(request, *args, **kwargs)
  File "D:\Users\SIMO\AppData\Local\Programs\Python\Python36\lib\site-packages\rest_framework\views.py", line 494, in dispatch
    response = self.handle_exception(exc)
  File "D:\Users\SIMO\AppData\Local\Programs\Python\Python36\lib\site-packages\rest_framework\views.py", line 454, in handle_exception
    self.raise_uncaught_exception(exc)
  File "D:\Users\SIMO\AppData\Local\Programs\Python\Python36\lib\site-packages\rest_framework\views.py", line 491, in dispatch
    response = handler(request, *args, **kwargs)
  File "D:\Users\SIMO\AppData\Local\Programs\Python\Python36\lib\site-packages\rest_framework\decorators.py", line 53, in handler
    return func(*args, **kwargs)
  File "H:\project\api_automation_test\api_test\common\common.py", line 79, in verify
    return func(reality_parameter)
  File "H:\project\api_automation_test\api_test\api\automationCase.py", line 1150, in auto_test_report
    AutomationCaseTestResult.objects.filter(testTime="2018-05-18 15:53:53.797176"), many=True).data
  File "D:\Users\SIMO\AppData\Local\Programs\Python\Python36\lib\site-packages\rest_framework\serializers.py", line 740, in data
    ret = super(ListSerializer, self).data
  File "D:\Users\SIMO\AppData\Local\Programs\Python\Python36\lib\site-packages\rest_framework\serializers.py", line 260, in data
    self._data = self.to_representation(self.instance)
  File "D:\Users\SIMO\AppData\Local\Programs\Python\Python36\lib\site-packages\rest_framework\serializers.py", line 658, in to_representation
    self.child.to_representation(item) for item in iterable
  File "D:\Users\SIMO\AppData\Local\Programs\Python\Python36\lib\site-packages\rest_framework\serializers.py", line 658, in <listcomp>
    self.child.to_representation(item) for item in iterable
  File "D:\Users\SIMO\AppData\Local\Programs\Python\Python36\lib\site-packages\rest_framework\serializers.py", line 489, in to_representation
    attribute = field.get_attribute(instance)
  File "D:\Users\SIMO\AppData\Local\Programs\Python\Python36\lib\site-packages\rest_framework\fields.py", line 462, in get_attribute
    raise type(exc)(msg)
AttributeError: Got AttributeError when attempting to get a value for field `automationTestCase` on serializer `AutomationTestReportSerializer`.
The serializer field might be named incorrectly and not match any attribute or key on the `AutomationCaseTestResult` instance.
Original exception text was: 'AutomationCaseTestResult' object has no attribute 'automationTestCase'.
2018-05-18 17:17:09,511,13512,django.server,ERROR,basehttp.py:124,"GET /api/automation/auto_test_report?project_id=1&time=2018-05-18%2015:53:53.797176 HTTP/1.1" 500 21415
2018-05-18 17:17:16,277,13512,django.request,ERROR,exception.py:118,Internal Server Error: /api/automation/auto_test_report
Traceback (most recent call last):
  File "D:\Users\SIMO\AppData\Local\Programs\Python\Python36\lib\site-packages\rest_framework\fields.py", line 441, in get_attribute
    return get_attribute(instance, self.source_attrs)
  File "D:\Users\SIMO\AppData\Local\Programs\Python\Python36\lib\site-packages\rest_framework\fields.py", line 100, in get_attribute
    instance = getattr(instance, attr)
AttributeError: 'AutomationCaseTestResult' object has no attribute 'automationTestCase'

During handling of the above exception, another exception occurred:

Traceback (most recent call last):
  File "D:\Users\SIMO\AppData\Local\Programs\Python\Python36\lib\site-packages\django\core\handlers\exception.py", line 35, in inner
    response = get_response(request)
  File "D:\Users\SIMO\AppData\Local\Programs\Python\Python36\lib\site-packages\django\core\handlers\base.py", line 128, in _get_response
    response = self.process_exception_by_middleware(e, request)
  File "D:\Users\SIMO\AppData\Local\Programs\Python\Python36\lib\site-packages\django\core\handlers\base.py", line 126, in _get_response
    response = wrapped_callback(request, *callback_args, **callback_kwargs)
  File "D:\Users\SIMO\AppData\Local\Programs\Python\Python36\lib\site-packages\django\views\decorators\csrf.py", line 54, in wrapped_view
    return view_func(*args, **kwargs)
  File "D:\Users\SIMO\AppData\Local\Programs\Python\Python36\lib\site-packages\django\views\generic\base.py", line 69, in view
    return self.dispatch(request, *args, **kwargs)
  File "D:\Users\SIMO\AppData\Local\Programs\Python\Python36\lib\site-packages\rest_framework\views.py", line 494, in dispatch
    response = self.handle_exception(exc)
  File "D:\Users\SIMO\AppData\Local\Programs\Python\Python36\lib\site-packages\rest_framework\views.py", line 454, in handle_exception
    self.raise_uncaught_exception(exc)
  File "D:\Users\SIMO\AppData\Local\Programs\Python\Python36\lib\site-packages\rest_framework\views.py", line 491, in dispatch
    response = handler(request, *args, **kwargs)
  File "D:\Users\SIMO\AppData\Local\Programs\Python\Python36\lib\site-packages\rest_framework\decorators.py", line 53, in handler
    return func(*args, **kwargs)
  File "H:\project\api_automation_test\api_test\common\common.py", line 79, in verify
    return func(reality_parameter)
  File "H:\project\api_automation_test\api_test\api\automationCase.py", line 1150, in auto_test_report
    AutomationCaseTestResult.objects.filter(testTime="2018-05-18 15:53:53.797176"), many=True).data
  File "D:\Users\SIMO\AppData\Local\Programs\Python\Python36\lib\site-packages\rest_framework\serializers.py", line 740, in data
    ret = super(ListSerializer, self).data
  File "D:\Users\SIMO\AppData\Local\Programs\Python\Python36\lib\site-packages\rest_framework\serializers.py", line 260, in data
    self._data = self.to_representation(self.instance)
  File "D:\Users\SIMO\AppData\Local\Programs\Python\Python36\lib\site-packages\rest_framework\serializers.py", line 658, in to_representation
    self.child.to_representation(item) for item in iterable
  File "D:\Users\SIMO\AppData\Local\Programs\Python\Python36\lib\site-packages\rest_framework\serializers.py", line 658, in <listcomp>
    self.child.to_representation(item) for item in iterable
  File "D:\Users\SIMO\AppData\Local\Programs\Python\Python36\lib\site-packages\rest_framework\serializers.py", line 489, in to_representation
    attribute = field.get_attribute(instance)
  File "D:\Users\SIMO\AppData\Local\Programs\Python\Python36\lib\site-packages\rest_framework\fields.py", line 462, in get_attribute
    raise type(exc)(msg)
AttributeError: Got AttributeError when attempting to get a value for field `automationTestCase` on serializer `AutomationTestReportSerializer`.
The serializer field might be named incorrectly and not match any attribute or key on the `AutomationCaseTestResult` instance.
Original exception text was: 'AutomationCaseTestResult' object has no attribute 'automationTestCase'.
2018-05-18 17:17:16,298,13512,django.server,ERROR,basehttp.py:124,"GET /api/automation/auto_test_report?project_id=1&time=2018-05-18%2015:53:53.797176 HTTP/1.1" 500 21415
2018-05-18 17:18:53,855,5220,django.request,ERROR,exception.py:118,Internal Server Error: /api/automation/auto_test_report
Traceback (most recent call last):
  File "D:\Users\SIMO\AppData\Local\Programs\Python\Python36\lib\site-packages\rest_framework\fields.py", line 441, in get_attribute
    return get_attribute(instance, self.source_attrs)
  File "D:\Users\SIMO\AppData\Local\Programs\Python\Python36\lib\site-packages\rest_framework\fields.py", line 100, in get_attribute
    instance = getattr(instance, attr)
AttributeError: 'AutomationCaseTestResult' object has no attribute 'automationTestCase'

During handling of the above exception, another exception occurred:

Traceback (most recent call last):
  File "D:\Users\SIMO\AppData\Local\Programs\Python\Python36\lib\site-packages\django\core\handlers\exception.py", line 35, in inner
    response = get_response(request)
  File "D:\Users\SIMO\AppData\Local\Programs\Python\Python36\lib\site-packages\django\core\handlers\base.py", line 128, in _get_response
    response = self.process_exception_by_middleware(e, request)
  File "D:\Users\SIMO\AppData\Local\Programs\Python\Python36\lib\site-packages\django\core\handlers\base.py", line 126, in _get_response
    response = wrapped_callback(request, *callback_args, **callback_kwargs)
  File "D:\Users\SIMO\AppData\Local\Programs\Python\Python36\lib\site-packages\django\views\decorators\csrf.py", line 54, in wrapped_view
    return view_func(*args, **kwargs)
  File "D:\Users\SIMO\AppData\Local\Programs\Python\Python36\lib\site-packages\django\views\generic\base.py", line 69, in view
    return self.dispatch(request, *args, **kwargs)
  File "D:\Users\SIMO\AppData\Local\Programs\Python\Python36\lib\site-packages\rest_framework\views.py", line 494, in dispatch
    response = self.handle_exception(exc)
  File "D:\Users\SIMO\AppData\Local\Programs\Python\Python36\lib\site-packages\rest_framework\views.py", line 454, in handle_exception
    self.raise_uncaught_exception(exc)
  File "D:\Users\SIMO\AppData\Local\Programs\Python\Python36\lib\site-packages\rest_framework\views.py", line 491, in dispatch
    response = handler(request, *args, **kwargs)
  File "D:\Users\SIMO\AppData\Local\Programs\Python\Python36\lib\site-packages\rest_framework\decorators.py", line 53, in handler
    return func(*args, **kwargs)
  File "H:\project\api_automation_test\api_test\common\common.py", line 79, in verify
    return func(reality_parameter)
  File "H:\project\api_automation_test\api_test\api\automationCase.py", line 1150, in auto_test_report
    AutomationCaseTestResult.objects.filter(api), many=True).data
  File "D:\Users\SIMO\AppData\Local\Programs\Python\Python36\lib\site-packages\rest_framework\serializers.py", line 740, in data
    ret = super(ListSerializer, self).data
  File "D:\Users\SIMO\AppData\Local\Programs\Python\Python36\lib\site-packages\rest_framework\serializers.py", line 260, in data
    self._data = self.to_representation(self.instance)
  File "D:\Users\SIMO\AppData\Local\Programs\Python\Python36\lib\site-packages\rest_framework\serializers.py", line 658, in to_representation
    self.child.to_representation(item) for item in iterable
  File "D:\Users\SIMO\AppData\Local\Programs\Python\Python36\lib\site-packages\rest_framework\serializers.py", line 658, in <listcomp>
    self.child.to_representation(item) for item in iterable
  File "D:\Users\SIMO\AppData\Local\Programs\Python\Python36\lib\site-packages\rest_framework\serializers.py", line 489, in to_representation
    attribute = field.get_attribute(instance)
  File "D:\Users\SIMO\AppData\Local\Programs\Python\Python36\lib\site-packages\rest_framework\fields.py", line 462, in get_attribute
    raise type(exc)(msg)
AttributeError: Got AttributeError when attempting to get a value for field `automationTestCase` on serializer `AutomationTestReportSerializer`.
The serializer field might be named incorrectly and not match any attribute or key on the `AutomationCaseTestResult` instance.
Original exception text was: 'AutomationCaseTestResult' object has no attribute 'automationTestCase'.
2018-05-18 17:18:53,876,5220,django.server,ERROR,basehttp.py:124,"GET /api/automation/auto_test_report?project_id=1&time=2018-05-18 HTTP/1.1" 500 21329
2018-05-18 17:20:25,930,12900,django.request,ERROR,exception.py:118,Internal Server Error: /api/automation/auto_test_report
Traceback (most recent call last):
  File "D:\Users\SIMO\AppData\Local\Programs\Python\Python36\lib\site-packages\rest_framework\fields.py", line 441, in get_attribute
    return get_attribute(instance, self.source_attrs)
  File "D:\Users\SIMO\AppData\Local\Programs\Python\Python36\lib\site-packages\rest_framework\fields.py", line 100, in get_attribute
    instance = getattr(instance, attr)
AttributeError: 'AutomationCaseTestResult' object has no attribute 'automationTestCase'

During handling of the above exception, another exception occurred:

Traceback (most recent call last):
  File "D:\Users\SIMO\AppData\Local\Programs\Python\Python36\lib\site-packages\django\core\handlers\exception.py", line 35, in inner
    response = get_response(request)
  File "D:\Users\SIMO\AppData\Local\Programs\Python\Python36\lib\site-packages\django\core\handlers\base.py", line 128, in _get_response
    response = self.process_exception_by_middleware(e, request)
  File "D:\Users\SIMO\AppData\Local\Programs\Python\Python36\lib\site-packages\django\core\handlers\base.py", line 126, in _get_response
    response = wrapped_callback(request, *callback_args, **callback_kwargs)
  File "D:\Users\SIMO\AppData\Local\Programs\Python\Python36\lib\site-packages\django\views\decorators\csrf.py", line 54, in wrapped_view
    return view_func(*args, **kwargs)
  File "D:\Users\SIMO\AppData\Local\Programs\Python\Python36\lib\site-packages\django\views\generic\base.py", line 69, in view
    return self.dispatch(request, *args, **kwargs)
  File "D:\Users\SIMO\AppData\Local\Programs\Python\Python36\lib\site-packages\rest_framework\views.py", line 494, in dispatch
    response = self.handle_exception(exc)
  File "D:\Users\SIMO\AppData\Local\Programs\Python\Python36\lib\site-packages\rest_framework\views.py", line 454, in handle_exception
    self.raise_uncaught_exception(exc)
  File "D:\Users\SIMO\AppData\Local\Programs\Python\Python36\lib\site-packages\rest_framework\views.py", line 491, in dispatch
    response = handler(request, *args, **kwargs)
  File "D:\Users\SIMO\AppData\Local\Programs\Python\Python36\lib\site-packages\rest_framework\decorators.py", line 53, in handler
    return func(*args, **kwargs)
  File "H:\project\api_automation_test\api_test\common\common.py", line 79, in verify
    return func(reality_parameter)
  File "H:\project\api_automation_test\api_test\api\automationCase.py", line 1150, in auto_test_report
    AutomationCaseTestResult.objects.filter(testTime="2018-05-18"), many=True).data
  File "D:\Users\SIMO\AppData\Local\Programs\Python\Python36\lib\site-packages\rest_framework\serializers.py", line 740, in data
    ret = super(ListSerializer, self).data
  File "D:\Users\SIMO\AppData\Local\Programs\Python\Python36\lib\site-packages\rest_framework\serializers.py", line 260, in data
    self._data = self.to_representation(self.instance)
  File "D:\Users\SIMO\AppData\Local\Programs\Python\Python36\lib\site-packages\rest_framework\serializers.py", line 658, in to_representation
    self.child.to_representation(item) for item in iterable
  File "D:\Users\SIMO\AppData\Local\Programs\Python\Python36\lib\site-packages\rest_framework\serializers.py", line 658, in <listcomp>
    self.child.to_representation(item) for item in iterable
  File "D:\Users\SIMO\AppData\Local\Programs\Python\Python36\lib\site-packages\rest_framework\serializers.py", line 489, in to_representation
    attribute = field.get_attribute(instance)
  File "D:\Users\SIMO\AppData\Local\Programs\Python\Python36\lib\site-packages\rest_framework\fields.py", line 462, in get_attribute
    raise type(exc)(msg)
AttributeError: Got AttributeError when attempting to get a value for field `automationTestCase` on serializer `AutomationTestReportSerializer`.
The serializer field might be named incorrectly and not match any attribute or key on the `AutomationCaseTestResult` instance.
Original exception text was: 'AutomationCaseTestResult' object has no attribute 'automationTestCase'.
2018-05-18 17:20:25,954,12900,django.server,ERROR,basehttp.py:124,"GET /api/automation/auto_test_report?project_id=1&time=2018-05-18 HTTP/1.1" 500 21347
2018-05-18 17:21:35,281,12908,django.request,ERROR,exception.py:118,Internal Server Error: /api/automation/auto_test_report
Traceback (most recent call last):
  File "D:\Users\SIMO\AppData\Local\Programs\Python\Python36\lib\site-packages\rest_framework\fields.py", line 441, in get_attribute
    return get_attribute(instance, self.source_attrs)
  File "D:\Users\SIMO\AppData\Local\Programs\Python\Python36\lib\site-packages\rest_framework\fields.py", line 100, in get_attribute
    instance = getattr(instance, attr)
AttributeError: 'AutomationCaseTestResult' object has no attribute 'automationTestCase'

During handling of the above exception, another exception occurred:

Traceback (most recent call last):
  File "D:\Users\SIMO\AppData\Local\Programs\Python\Python36\lib\site-packages\django\core\handlers\exception.py", line 35, in inner
    response = get_response(request)
  File "D:\Users\SIMO\AppData\Local\Programs\Python\Python36\lib\site-packages\django\core\handlers\base.py", line 128, in _get_response
    response = self.process_exception_by_middleware(e, request)
  File "D:\Users\SIMO\AppData\Local\Programs\Python\Python36\lib\site-packages\django\core\handlers\base.py", line 126, in _get_response
    response = wrapped_callback(request, *callback_args, **callback_kwargs)
  File "D:\Users\SIMO\AppData\Local\Programs\Python\Python36\lib\site-packages\django\views\decorators\csrf.py", line 54, in wrapped_view
    return view_func(*args, **kwargs)
  File "D:\Users\SIMO\AppData\Local\Programs\Python\Python36\lib\site-packages\django\views\generic\base.py", line 69, in view
    return self.dispatch(request, *args, **kwargs)
  File "D:\Users\SIMO\AppData\Local\Programs\Python\Python36\lib\site-packages\rest_framework\views.py", line 494, in dispatch
    response = self.handle_exception(exc)
  File "D:\Users\SIMO\AppData\Local\Programs\Python\Python36\lib\site-packages\rest_framework\views.py", line 454, in handle_exception
    self.raise_uncaught_exception(exc)
  File "D:\Users\SIMO\AppData\Local\Programs\Python\Python36\lib\site-packages\rest_framework\views.py", line 491, in dispatch
    response = handler(request, *args, **kwargs)
  File "D:\Users\SIMO\AppData\Local\Programs\Python\Python36\lib\site-packages\rest_framework\decorators.py", line 53, in handler
    return func(*args, **kwargs)
  File "H:\project\api_automation_test\api_test\common\common.py", line 79, in verify
    return func(reality_parameter)
  File "H:\project\api_automation_test\api_test\api\automationCase.py", line 1150, in auto_test_report
    AutomationCaseTestResult.objects.filter(testTime="2018-05-18"), many=True).data
  File "D:\Users\SIMO\AppData\Local\Programs\Python\Python36\lib\site-packages\rest_framework\serializers.py", line 740, in data
    ret = super(ListSerializer, self).data
  File "D:\Users\SIMO\AppData\Local\Programs\Python\Python36\lib\site-packages\rest_framework\serializers.py", line 260, in data
    self._data = self.to_representation(self.instance)
  File "D:\Users\SIMO\AppData\Local\Programs\Python\Python36\lib\site-packages\rest_framework\serializers.py", line 658, in to_representation
    self.child.to_representation(item) for item in iterable
  File "D:\Users\SIMO\AppData\Local\Programs\Python\Python36\lib\site-packages\rest_framework\serializers.py", line 658, in <listcomp>
    self.child.to_representation(item) for item in iterable
  File "D:\Users\SIMO\AppData\Local\Programs\Python\Python36\lib\site-packages\rest_framework\serializers.py", line 489, in to_representation
    attribute = field.get_attribute(instance)
  File "D:\Users\SIMO\AppData\Local\Programs\Python\Python36\lib\site-packages\rest_framework\fields.py", line 462, in get_attribute
    raise type(exc)(msg)
AttributeError: Got AttributeError when attempting to get a value for field `automationTestCase` on serializer `AutomationAutoTestResultSerializer`.
The serializer field might be named incorrectly and not match any attribute or key on the `AutomationCaseTestResult` instance.
Original exception text was: 'AutomationCaseTestResult' object has no attribute 'automationTestCase'.
2018-05-18 17:21:35,305,12908,django.server,ERROR,basehttp.py:124,"GET /api/automation/auto_test_report?project_id=1&time=2018-05-18 HTTP/1.1" 500 21355
2018-05-18 17:21:52,469,14432,django.request,ERROR,exception.py:118,Internal Server Error: /api/automation/auto_test_report
Traceback (most recent call last):
  File "D:\Users\SIMO\AppData\Local\Programs\Python\Python36\lib\site-packages\rest_framework\fields.py", line 441, in get_attribute
    return get_attribute(instance, self.source_attrs)
  File "D:\Users\SIMO\AppData\Local\Programs\Python\Python36\lib\site-packages\rest_framework\fields.py", line 100, in get_attribute
    instance = getattr(instance, attr)
AttributeError: 'AutomationCaseTestResult' object has no attribute 'auto_test_result'

During handling of the above exception, another exception occurred:

Traceback (most recent call last):
  File "D:\Users\SIMO\AppData\Local\Programs\Python\Python36\lib\site-packages\django\core\handlers\exception.py", line 35, in inner
    response = get_response(request)
  File "D:\Users\SIMO\AppData\Local\Programs\Python\Python36\lib\site-packages\django\core\handlers\base.py", line 128, in _get_response
    response = self.process_exception_by_middleware(e, request)
  File "D:\Users\SIMO\AppData\Local\Programs\Python\Python36\lib\site-packages\django\core\handlers\base.py", line 126, in _get_response
    response = wrapped_callback(request, *callback_args, **callback_kwargs)
  File "D:\Users\SIMO\AppData\Local\Programs\Python\Python36\lib\site-packages\django\views\decorators\csrf.py", line 54, in wrapped_view
    return view_func(*args, **kwargs)
  File "D:\Users\SIMO\AppData\Local\Programs\Python\Python36\lib\site-packages\django\views\generic\base.py", line 69, in view
    return self.dispatch(request, *args, **kwargs)
  File "D:\Users\SIMO\AppData\Local\Programs\Python\Python36\lib\site-packages\rest_framework\views.py", line 494, in dispatch
    response = self.handle_exception(exc)
  File "D:\Users\SIMO\AppData\Local\Programs\Python\Python36\lib\site-packages\rest_framework\views.py", line 454, in handle_exception
    self.raise_uncaught_exception(exc)
  File "D:\Users\SIMO\AppData\Local\Programs\Python\Python36\lib\site-packages\rest_framework\views.py", line 491, in dispatch
    response = handler(request, *args, **kwargs)
  File "D:\Users\SIMO\AppData\Local\Programs\Python\Python36\lib\site-packages\rest_framework\decorators.py", line 53, in handler
    return func(*args, **kwargs)
  File "H:\project\api_automation_test\api_test\common\common.py", line 79, in verify
    return func(reality_parameter)
  File "H:\project\api_automation_test\api_test\api\automationCase.py", line 1150, in auto_test_report
    AutomationCaseTestResult.objects.filter(testTime="2018-05-18"), many=True).data
  File "D:\Users\SIMO\AppData\Local\Programs\Python\Python36\lib\site-packages\rest_framework\serializers.py", line 740, in data
    ret = super(ListSerializer, self).data
  File "D:\Users\SIMO\AppData\Local\Programs\Python\Python36\lib\site-packages\rest_framework\serializers.py", line 260, in data
    self._data = self.to_representation(self.instance)
  File "D:\Users\SIMO\AppData\Local\Programs\Python\Python36\lib\site-packages\rest_framework\serializers.py", line 658, in to_representation
    self.child.to_representation(item) for item in iterable
  File "D:\Users\SIMO\AppData\Local\Programs\Python\Python36\lib\site-packages\rest_framework\serializers.py", line 658, in <listcomp>
    self.child.to_representation(item) for item in iterable
  File "D:\Users\SIMO\AppData\Local\Programs\Python\Python36\lib\site-packages\rest_framework\serializers.py", line 489, in to_representation
    attribute = field.get_attribute(instance)
  File "D:\Users\SIMO\AppData\Local\Programs\Python\Python36\lib\site-packages\rest_framework\fields.py", line 462, in get_attribute
    raise type(exc)(msg)
AttributeError: Got AttributeError when attempting to get a value for field `name` on serializer `AutomationAutoTestResultSerializer`.
The serializer field might be named incorrectly and not match any attribute or key on the `AutomationCaseTestResult` instance.
Original exception text was: 'AutomationCaseTestResult' object has no attribute 'auto_test_result'.
2018-05-18 17:21:52,492,14432,django.server,ERROR,basehttp.py:124,"GET /api/automation/auto_test_report?project_id=1&time=2018-05-18 HTTP/1.1" 500 21321
2018-05-18 17:22:28,252,10016,django.request,ERROR,exception.py:118,Internal Server Error: /api/automation/auto_test_report
Traceback (most recent call last):
  File "D:\Users\SIMO\AppData\Local\Programs\Python\Python36\lib\site-packages\rest_framework\fields.py", line 441, in get_attribute
    return get_attribute(instance, self.source_attrs)
  File "D:\Users\SIMO\AppData\Local\Programs\Python\Python36\lib\site-packages\rest_framework\fields.py", line 100, in get_attribute
    instance = getattr(instance, attr)
AttributeError: 'AutomationCaseTestResult' object has no attribute 'case_name'

During handling of the above exception, another exception occurred:

Traceback (most recent call last):
  File "D:\Users\SIMO\AppData\Local\Programs\Python\Python36\lib\site-packages\django\core\handlers\exception.py", line 35, in inner
    response = get_response(request)
  File "D:\Users\SIMO\AppData\Local\Programs\Python\Python36\lib\site-packages\django\core\handlers\base.py", line 128, in _get_response
    response = self.process_exception_by_middleware(e, request)
  File "D:\Users\SIMO\AppData\Local\Programs\Python\Python36\lib\site-packages\django\core\handlers\base.py", line 126, in _get_response
    response = wrapped_callback(request, *callback_args, **callback_kwargs)
  File "D:\Users\SIMO\AppData\Local\Programs\Python\Python36\lib\site-packages\django\views\decorators\csrf.py", line 54, in wrapped_view
    return view_func(*args, **kwargs)
  File "D:\Users\SIMO\AppData\Local\Programs\Python\Python36\lib\site-packages\django\views\generic\base.py", line 69, in view
    return self.dispatch(request, *args, **kwargs)
  File "D:\Users\SIMO\AppData\Local\Programs\Python\Python36\lib\site-packages\rest_framework\views.py", line 494, in dispatch
    response = self.handle_exception(exc)
  File "D:\Users\SIMO\AppData\Local\Programs\Python\Python36\lib\site-packages\rest_framework\views.py", line 454, in handle_exception
    self.raise_uncaught_exception(exc)
  File "D:\Users\SIMO\AppData\Local\Programs\Python\Python36\lib\site-packages\rest_framework\views.py", line 491, in dispatch
    response = handler(request, *args, **kwargs)
  File "D:\Users\SIMO\AppData\Local\Programs\Python\Python36\lib\site-packages\rest_framework\decorators.py", line 53, in handler
    return func(*args, **kwargs)
  File "H:\project\api_automation_test\api_test\common\common.py", line 79, in verify
    return func(reality_parameter)
  File "H:\project\api_automation_test\api_test\api\automationCase.py", line 1150, in auto_test_report
    AutomationCaseTestResult.objects.filter(testTime="2018-05-18"), many=True).data
  File "D:\Users\SIMO\AppData\Local\Programs\Python\Python36\lib\site-packages\rest_framework\serializers.py", line 740, in data
    ret = super(ListSerializer, self).data
  File "D:\Users\SIMO\AppData\Local\Programs\Python\Python36\lib\site-packages\rest_framework\serializers.py", line 260, in data
    self._data = self.to_representation(self.instance)
  File "D:\Users\SIMO\AppData\Local\Programs\Python\Python36\lib\site-packages\rest_framework\serializers.py", line 658, in to_representation
    self.child.to_representation(item) for item in iterable
  File "D:\Users\SIMO\AppData\Local\Programs\Python\Python36\lib\site-packages\rest_framework\serializers.py", line 658, in <listcomp>
    self.child.to_representation(item) for item in iterable
  File "D:\Users\SIMO\AppData\Local\Programs\Python\Python36\lib\site-packages\rest_framework\serializers.py", line 489, in to_representation
    attribute = field.get_attribute(instance)
  File "D:\Users\SIMO\AppData\Local\Programs\Python\Python36\lib\site-packages\rest_framework\fields.py", line 462, in get_attribute
    raise type(exc)(msg)
AttributeError: Got AttributeError when attempting to get a value for field `name` on serializer `AutomationAutoTestResultSerializer`.
The serializer field might be named incorrectly and not match any attribute or key on the `AutomationCaseTestResult` instance.
Original exception text was: 'AutomationCaseTestResult' object has no attribute 'case_name'.
2018-05-18 17:22:28,275,10016,django.server,ERROR,basehttp.py:124,"GET /api/automation/auto_test_report?project_id=1&time=2018-05-18 HTTP/1.1" 500 21299
2018-05-18 17:25:38,370,10516,django.request,ERROR,exception.py:118,Internal Server Error: /api/automation/auto_test_report
Traceback (most recent call last):
  File "D:\Users\SIMO\AppData\Local\Programs\Python\Python36\lib\site-packages\rest_framework\fields.py", line 441, in get_attribute
    return get_attribute(instance, self.source_attrs)
  File "D:\Users\SIMO\AppData\Local\Programs\Python\Python36\lib\site-packages\rest_framework\fields.py", line 100, in get_attribute
    instance = getattr(instance, attr)
AttributeError: 'AutomationCaseTestResult' object has no attribute 'auto_test_result'

During handling of the above exception, another exception occurred:

Traceback (most recent call last):
  File "D:\Users\SIMO\AppData\Local\Programs\Python\Python36\lib\site-packages\django\core\handlers\exception.py", line 35, in inner
    response = get_response(request)
  File "D:\Users\SIMO\AppData\Local\Programs\Python\Python36\lib\site-packages\django\core\handlers\base.py", line 128, in _get_response
    response = self.process_exception_by_middleware(e, request)
  File "D:\Users\SIMO\AppData\Local\Programs\Python\Python36\lib\site-packages\django\core\handlers\base.py", line 126, in _get_response
    response = wrapped_callback(request, *callback_args, **callback_kwargs)
  File "D:\Users\SIMO\AppData\Local\Programs\Python\Python36\lib\site-packages\django\views\decorators\csrf.py", line 54, in wrapped_view
    return view_func(*args, **kwargs)
  File "D:\Users\SIMO\AppData\Local\Programs\Python\Python36\lib\site-packages\django\views\generic\base.py", line 69, in view
    return self.dispatch(request, *args, **kwargs)
  File "D:\Users\SIMO\AppData\Local\Programs\Python\Python36\lib\site-packages\rest_framework\views.py", line 494, in dispatch
    response = self.handle_exception(exc)
  File "D:\Users\SIMO\AppData\Local\Programs\Python\Python36\lib\site-packages\rest_framework\views.py", line 454, in handle_exception
    self.raise_uncaught_exception(exc)
  File "D:\Users\SIMO\AppData\Local\Programs\Python\Python36\lib\site-packages\rest_framework\views.py", line 491, in dispatch
    response = handler(request, *args, **kwargs)
  File "D:\Users\SIMO\AppData\Local\Programs\Python\Python36\lib\site-packages\rest_framework\decorators.py", line 53, in handler
    return func(*args, **kwargs)
  File "H:\project\api_automation_test\api_test\common\common.py", line 79, in verify
    return func(reality_parameter)
  File "H:\project\api_automation_test\api_test\api\automationCase.py", line 1150, in auto_test_report
    AutomationCaseTestResult.objects.filter(api, testTime=time), many=True).data
  File "D:\Users\SIMO\AppData\Local\Programs\Python\Python36\lib\site-packages\rest_framework\serializers.py", line 740, in data
    ret = super(ListSerializer, self).data
  File "D:\Users\SIMO\AppData\Local\Programs\Python\Python36\lib\site-packages\rest_framework\serializers.py", line 260, in data
    self._data = self.to_representation(self.instance)
  File "D:\Users\SIMO\AppData\Local\Programs\Python\Python36\lib\site-packages\rest_framework\serializers.py", line 658, in to_representation
    self.child.to_representation(item) for item in iterable
  File "D:\Users\SIMO\AppData\Local\Programs\Python\Python36\lib\site-packages\rest_framework\serializers.py", line 658, in <listcomp>
    self.child.to_representation(item) for item in iterable
  File "D:\Users\SIMO\AppData\Local\Programs\Python\Python36\lib\site-packages\rest_framework\serializers.py", line 489, in to_representation
    attribute = field.get_attribute(instance)
  File "D:\Users\SIMO\AppData\Local\Programs\Python\Python36\lib\site-packages\rest_framework\fields.py", line 462, in get_attribute
    raise type(exc)(msg)
AttributeError: Got AttributeError when attempting to get a value for field `name` on serializer `AutomationAutoTestResultSerializer`.
The serializer field might be named incorrectly and not match any attribute or key on the `AutomationCaseTestResult` instance.
Original exception text was: 'AutomationCaseTestResult' object has no attribute 'auto_test_result'.
2018-05-18 17:25:38,391,10516,django.server,ERROR,basehttp.py:124,"GET /api/automation/auto_test_report?project_id=1&time=2018-05-18%2015:21:58.166434 HTTP/1.1" 500 21370
2018-05-18 17:26:03,130,364,django.request,ERROR,exception.py:118,Internal Server Error: /api/automation/auto_test_report
Traceback (most recent call last):
  File "D:\Users\SIMO\AppData\Local\Programs\Python\Python36\lib\site-packages\rest_framework\fields.py", line 441, in get_attribute
    return get_attribute(instance, self.source_attrs)
  File "D:\Users\SIMO\AppData\Local\Programs\Python\Python36\lib\site-packages\rest_framework\fields.py", line 100, in get_attribute
    instance = getattr(instance, attr)
AttributeError: 'str' object has no attribute 'name'

During handling of the above exception, another exception occurred:

Traceback (most recent call last):
  File "D:\Users\SIMO\AppData\Local\Programs\Python\Python36\lib\site-packages\django\core\handlers\exception.py", line 35, in inner
    response = get_response(request)
  File "D:\Users\SIMO\AppData\Local\Programs\Python\Python36\lib\site-packages\django\core\handlers\base.py", line 128, in _get_response
    response = self.process_exception_by_middleware(e, request)
  File "D:\Users\SIMO\AppData\Local\Programs\Python\Python36\lib\site-packages\django\core\handlers\base.py", line 126, in _get_response
    response = wrapped_callback(request, *callback_args, **callback_kwargs)
  File "D:\Users\SIMO\AppData\Local\Programs\Python\Python36\lib\site-packages\django\views\decorators\csrf.py", line 54, in wrapped_view
    return view_func(*args, **kwargs)
  File "D:\Users\SIMO\AppData\Local\Programs\Python\Python36\lib\site-packages\django\views\generic\base.py", line 69, in view
    return self.dispatch(request, *args, **kwargs)
  File "D:\Users\SIMO\AppData\Local\Programs\Python\Python36\lib\site-packages\rest_framework\views.py", line 494, in dispatch
    response = self.handle_exception(exc)
  File "D:\Users\SIMO\AppData\Local\Programs\Python\Python36\lib\site-packages\rest_framework\views.py", line 454, in handle_exception
    self.raise_uncaught_exception(exc)
  File "D:\Users\SIMO\AppData\Local\Programs\Python\Python36\lib\site-packages\rest_framework\views.py", line 491, in dispatch
    response = handler(request, *args, **kwargs)
  File "D:\Users\SIMO\AppData\Local\Programs\Python\Python36\lib\site-packages\rest_framework\decorators.py", line 53, in handler
    return func(*args, **kwargs)
  File "H:\project\api_automation_test\api_test\common\common.py", line 79, in verify
    return func(reality_parameter)
  File "H:\project\api_automation_test\api_test\api\automationCase.py", line 1150, in auto_test_report
    AutomationCaseTestResult.objects.filter(api, testTime=time), many=True).data
  File "D:\Users\SIMO\AppData\Local\Programs\Python\Python36\lib\site-packages\rest_framework\serializers.py", line 740, in data
    ret = super(ListSerializer, self).data
  File "D:\Users\SIMO\AppData\Local\Programs\Python\Python36\lib\site-packages\rest_framework\serializers.py", line 260, in data
    self._data = self.to_representation(self.instance)
  File "D:\Users\SIMO\AppData\Local\Programs\Python\Python36\lib\site-packages\rest_framework\serializers.py", line 658, in to_representation
    self.child.to_representation(item) for item in iterable
  File "D:\Users\SIMO\AppData\Local\Programs\Python\Python36\lib\site-packages\rest_framework\serializers.py", line 658, in <listcomp>
    self.child.to_representation(item) for item in iterable
  File "D:\Users\SIMO\AppData\Local\Programs\Python\Python36\lib\site-packages\rest_framework\serializers.py", line 489, in to_representation
    attribute = field.get_attribute(instance)
  File "D:\Users\SIMO\AppData\Local\Programs\Python\Python36\lib\site-packages\rest_framework\fields.py", line 462, in get_attribute
    raise type(exc)(msg)
AttributeError: Got AttributeError when attempting to get a value for field `name` on serializer `AutomationAutoTestResultSerializer`.
The serializer field might be named incorrectly and not match any attribute or key on the `AutomationCaseTestResult` instance.
Original exception text was: 'str' object has no attribute 'name'.
2018-05-18 17:26:03,149,364,django.server,ERROR,basehttp.py:124,"GET /api/automation/auto_test_report?project_id=1&time=2018-05-18%2015:21:58.166434 HTTP/1.1" 500 21270
2018-05-18 17:26:53,017,14852,django.request,ERROR,exception.py:118,Internal Server Error: /api/automation/auto_test_report
Traceback (most recent call last):
  File "D:\Users\SIMO\AppData\Local\Programs\Python\Python36\lib\site-packages\rest_framework\fields.py", line 441, in get_attribute
    return get_attribute(instance, self.source_attrs)
  File "D:\Users\SIMO\AppData\Local\Programs\Python\Python36\lib\site-packages\rest_framework\fields.py", line 100, in get_attribute
    instance = getattr(instance, attr)
AttributeError: 'AutomationCaseTestResult' object has no attribute 'auto_result'

During handling of the above exception, another exception occurred:

Traceback (most recent call last):
  File "D:\Users\SIMO\AppData\Local\Programs\Python\Python36\lib\site-packages\django\core\handlers\exception.py", line 35, in inner
    response = get_response(request)
  File "D:\Users\SIMO\AppData\Local\Programs\Python\Python36\lib\site-packages\django\core\handlers\base.py", line 128, in _get_response
    response = self.process_exception_by_middleware(e, request)
  File "D:\Users\SIMO\AppData\Local\Programs\Python\Python36\lib\site-packages\django\core\handlers\base.py", line 126, in _get_response
    response = wrapped_callback(request, *callback_args, **callback_kwargs)
  File "D:\Users\SIMO\AppData\Local\Programs\Python\Python36\lib\site-packages\django\views\decorators\csrf.py", line 54, in wrapped_view
    return view_func(*args, **kwargs)
  File "D:\Users\SIMO\AppData\Local\Programs\Python\Python36\lib\site-packages\django\views\generic\base.py", line 69, in view
    return self.dispatch(request, *args, **kwargs)
  File "D:\Users\SIMO\AppData\Local\Programs\Python\Python36\lib\site-packages\rest_framework\views.py", line 494, in dispatch
    response = self.handle_exception(exc)
  File "D:\Users\SIMO\AppData\Local\Programs\Python\Python36\lib\site-packages\rest_framework\views.py", line 454, in handle_exception
    self.raise_uncaught_exception(exc)
  File "D:\Users\SIMO\AppData\Local\Programs\Python\Python36\lib\site-packages\rest_framework\views.py", line 491, in dispatch
    response = handler(request, *args, **kwargs)
  File "D:\Users\SIMO\AppData\Local\Programs\Python\Python36\lib\site-packages\rest_framework\decorators.py", line 53, in handler
    return func(*args, **kwargs)
  File "H:\project\api_automation_test\api_test\common\common.py", line 79, in verify
    return func(reality_parameter)
  File "H:\project\api_automation_test\api_test\api\automationCase.py", line 1150, in auto_test_report
    AutomationCaseTestResult.objects.filter(api, testTime=time), many=True).data
  File "D:\Users\SIMO\AppData\Local\Programs\Python\Python36\lib\site-packages\rest_framework\serializers.py", line 740, in data
    ret = super(ListSerializer, self).data
  File "D:\Users\SIMO\AppData\Local\Programs\Python\Python36\lib\site-packages\rest_framework\serializers.py", line 260, in data
    self._data = self.to_representation(self.instance)
  File "D:\Users\SIMO\AppData\Local\Programs\Python\Python36\lib\site-packages\rest_framework\serializers.py", line 658, in to_representation
    self.child.to_representation(item) for item in iterable
  File "D:\Users\SIMO\AppData\Local\Programs\Python\Python36\lib\site-packages\rest_framework\serializers.py", line 658, in <listcomp>
    self.child.to_representation(item) for item in iterable
  File "D:\Users\SIMO\AppData\Local\Programs\Python\Python36\lib\site-packages\rest_framework\serializers.py", line 489, in to_representation
    attribute = field.get_attribute(instance)
  File "D:\Users\SIMO\AppData\Local\Programs\Python\Python36\lib\site-packages\rest_framework\fields.py", line 462, in get_attribute
    raise type(exc)(msg)
AttributeError: Got AttributeError when attempting to get a value for field `name` on serializer `AutomationAutoTestResultSerializer`.
The serializer field might be named incorrectly and not match any attribute or key on the `AutomationCaseTestResult` instance.
Original exception text was: 'AutomationCaseTestResult' object has no attribute 'auto_result'.
2018-05-18 17:26:53,041,14852,django.server,ERROR,basehttp.py:124,"GET /api/automation/auto_test_report?project_id=1&time=2018-05-18%2015:21:58.166434 HTTP/1.1" 500 21355
2018-05-18 17:28:30,848,6164,django.request,ERROR,exception.py:118,Internal Server Error: /api/automation/auto_test_report
Traceback (most recent call last):
  File "D:\Users\SIMO\AppData\Local\Programs\Python\Python36\lib\site-packages\rest_framework\fields.py", line 441, in get_attribute
    return get_attribute(instance, self.source_attrs)
  File "D:\Users\SIMO\AppData\Local\Programs\Python\Python36\lib\site-packages\rest_framework\fields.py", line 100, in get_attribute
    instance = getattr(instance, attr)
AttributeError: 'AutomationCaseTestResult' object has no attribute 'case_name'

During handling of the above exception, another exception occurred:

Traceback (most recent call last):
  File "D:\Users\SIMO\AppData\Local\Programs\Python\Python36\lib\site-packages\django\core\handlers\exception.py", line 35, in inner
    response = get_response(request)
  File "D:\Users\SIMO\AppData\Local\Programs\Python\Python36\lib\site-packages\django\core\handlers\base.py", line 128, in _get_response
    response = self.process_exception_by_middleware(e, request)
  File "D:\Users\SIMO\AppData\Local\Programs\Python\Python36\lib\site-packages\django\core\handlers\base.py", line 126, in _get_response
    response = wrapped_callback(request, *callback_args, **callback_kwargs)
  File "D:\Users\SIMO\AppData\Local\Programs\Python\Python36\lib\site-packages\django\views\decorators\csrf.py", line 54, in wrapped_view
    return view_func(*args, **kwargs)
  File "D:\Users\SIMO\AppData\Local\Programs\Python\Python36\lib\site-packages\django\views\generic\base.py", line 69, in view
    return self.dispatch(request, *args, **kwargs)
  File "D:\Users\SIMO\AppData\Local\Programs\Python\Python36\lib\site-packages\rest_framework\views.py", line 494, in dispatch
    response = self.handle_exception(exc)
  File "D:\Users\SIMO\AppData\Local\Programs\Python\Python36\lib\site-packages\rest_framework\views.py", line 454, in handle_exception
    self.raise_uncaught_exception(exc)
  File "D:\Users\SIMO\AppData\Local\Programs\Python\Python36\lib\site-packages\rest_framework\views.py", line 491, in dispatch
    response = handler(request, *args, **kwargs)
  File "D:\Users\SIMO\AppData\Local\Programs\Python\Python36\lib\site-packages\rest_framework\decorators.py", line 53, in handler
    return func(*args, **kwargs)
  File "H:\project\api_automation_test\api_test\common\common.py", line 79, in verify
    return func(reality_parameter)
  File "H:\project\api_automation_test\api_test\api\automationCase.py", line 1150, in auto_test_report
    AutomationCaseTestResult.objects.filter(api, testTime=time), many=True).data
  File "D:\Users\SIMO\AppData\Local\Programs\Python\Python36\lib\site-packages\rest_framework\serializers.py", line 740, in data
    ret = super(ListSerializer, self).data
  File "D:\Users\SIMO\AppData\Local\Programs\Python\Python36\lib\site-packages\rest_framework\serializers.py", line 260, in data
    self._data = self.to_representation(self.instance)
  File "D:\Users\SIMO\AppData\Local\Programs\Python\Python36\lib\site-packages\rest_framework\serializers.py", line 658, in to_representation
    self.child.to_representation(item) for item in iterable
  File "D:\Users\SIMO\AppData\Local\Programs\Python\Python36\lib\site-packages\rest_framework\serializers.py", line 658, in <listcomp>
    self.child.to_representation(item) for item in iterable
  File "D:\Users\SIMO\AppData\Local\Programs\Python\Python36\lib\site-packages\rest_framework\serializers.py", line 489, in to_representation
    attribute = field.get_attribute(instance)
  File "D:\Users\SIMO\AppData\Local\Programs\Python\Python36\lib\site-packages\rest_framework\fields.py", line 462, in get_attribute
    raise type(exc)(msg)
AttributeError: Got AttributeError when attempting to get a value for field `name` on serializer `AutomationAutoTestResultSerializer`.
The serializer field might be named incorrectly and not match any attribute or key on the `AutomationCaseTestResult` instance.
Original exception text was: 'AutomationCaseTestResult' object has no attribute 'case_name'.
2018-05-18 17:28:30,871,6164,django.server,ERROR,basehttp.py:124,"GET /api/automation/auto_test_report?project_id=1&time=2018-05-18%2015:21:58.166434 HTTP/1.1" 500 21349
2018-05-18 17:29:25,554,4936,django.request,ERROR,exception.py:118,Internal Server Error: /api/automation/auto_test_report
Traceback (most recent call last):
  File "D:\Users\SIMO\AppData\Local\Programs\Python\Python36\lib\site-packages\rest_framework\fields.py", line 441, in get_attribute
    return get_attribute(instance, self.source_attrs)
  File "D:\Users\SIMO\AppData\Local\Programs\Python\Python36\lib\site-packages\rest_framework\fields.py", line 100, in get_attribute
    instance = getattr(instance, attr)
AttributeError: 'AutomationCaseTestResult' object has no attribute 'case_name_api'

During handling of the above exception, another exception occurred:

Traceback (most recent call last):
  File "D:\Users\SIMO\AppData\Local\Programs\Python\Python36\lib\site-packages\django\core\handlers\exception.py", line 35, in inner
    response = get_response(request)
  File "D:\Users\SIMO\AppData\Local\Programs\Python\Python36\lib\site-packages\django\core\handlers\base.py", line 128, in _get_response
    response = self.process_exception_by_middleware(e, request)
  File "D:\Users\SIMO\AppData\Local\Programs\Python\Python36\lib\site-packages\django\core\handlers\base.py", line 126, in _get_response
    response = wrapped_callback(request, *callback_args, **callback_kwargs)
  File "D:\Users\SIMO\AppData\Local\Programs\Python\Python36\lib\site-packages\django\views\decorators\csrf.py", line 54, in wrapped_view
    return view_func(*args, **kwargs)
  File "D:\Users\SIMO\AppData\Local\Programs\Python\Python36\lib\site-packages\django\views\generic\base.py", line 69, in view
    return self.dispatch(request, *args, **kwargs)
  File "D:\Users\SIMO\AppData\Local\Programs\Python\Python36\lib\site-packages\rest_framework\views.py", line 494, in dispatch
    response = self.handle_exception(exc)
  File "D:\Users\SIMO\AppData\Local\Programs\Python\Python36\lib\site-packages\rest_framework\views.py", line 454, in handle_exception
    self.raise_uncaught_exception(exc)
  File "D:\Users\SIMO\AppData\Local\Programs\Python\Python36\lib\site-packages\rest_framework\views.py", line 491, in dispatch
    response = handler(request, *args, **kwargs)
  File "D:\Users\SIMO\AppData\Local\Programs\Python\Python36\lib\site-packages\rest_framework\decorators.py", line 53, in handler
    return func(*args, **kwargs)
  File "H:\project\api_automation_test\api_test\common\common.py", line 79, in verify
    return func(reality_parameter)
  File "H:\project\api_automation_test\api_test\api\automationCase.py", line 1150, in auto_test_report
    AutomationCaseTestResult.objects.filter(api, testTime=time), many=True).data
  File "D:\Users\SIMO\AppData\Local\Programs\Python\Python36\lib\site-packages\rest_framework\serializers.py", line 740, in data
    ret = super(ListSerializer, self).data
  File "D:\Users\SIMO\AppData\Local\Programs\Python\Python36\lib\site-packages\rest_framework\serializers.py", line 260, in data
    self._data = self.to_representation(self.instance)
  File "D:\Users\SIMO\AppData\Local\Programs\Python\Python36\lib\site-packages\rest_framework\serializers.py", line 658, in to_representation
    self.child.to_representation(item) for item in iterable
  File "D:\Users\SIMO\AppData\Local\Programs\Python\Python36\lib\site-packages\rest_framework\serializers.py", line 658, in <listcomp>
    self.child.to_representation(item) for item in iterable
  File "D:\Users\SIMO\AppData\Local\Programs\Python\Python36\lib\site-packages\rest_framework\serializers.py", line 489, in to_representation
    attribute = field.get_attribute(instance)
  File "D:\Users\SIMO\AppData\Local\Programs\Python\Python36\lib\site-packages\rest_framework\fields.py", line 462, in get_attribute
    raise type(exc)(msg)
AttributeError: Got AttributeError when attempting to get a value for field `name` on serializer `AutomationAutoTestResultSerializer`.
The serializer field might be named incorrectly and not match any attribute or key on the `AutomationCaseTestResult` instance.
Original exception text was: 'AutomationCaseTestResult' object has no attribute 'case_name_api'.
2018-05-18 17:29:25,575,4936,django.server,ERROR,basehttp.py:124,"GET /api/automation/auto_test_report?project_id=1&time=2018-05-18%2015:21:58.166434 HTTP/1.1" 500 21360
2018-05-18 17:31:22,362,1784,django.request,ERROR,exception.py:118,Internal Server Error: /api/automation/auto_test_report
Traceback (most recent call last):
  File "D:\Users\SIMO\AppData\Local\Programs\Python\Python36\lib\site-packages\rest_framework\fields.py", line 441, in get_attribute
    return get_attribute(instance, self.source_attrs)
  File "D:\Users\SIMO\AppData\Local\Programs\Python\Python36\lib\site-packages\rest_framework\fields.py", line 100, in get_attribute
    instance = getattr(instance, attr)
AttributeError: 'AutomationCaseTestResult' object has no attribute 'case_name'

During handling of the above exception, another exception occurred:

Traceback (most recent call last):
  File "D:\Users\SIMO\AppData\Local\Programs\Python\Python36\lib\site-packages\django\core\handlers\exception.py", line 35, in inner
    response = get_response(request)
  File "D:\Users\SIMO\AppData\Local\Programs\Python\Python36\lib\site-packages\django\core\handlers\base.py", line 128, in _get_response
    response = self.process_exception_by_middleware(e, request)
  File "D:\Users\SIMO\AppData\Local\Programs\Python\Python36\lib\site-packages\django\core\handlers\base.py", line 126, in _get_response
    response = wrapped_callback(request, *callback_args, **callback_kwargs)
  File "D:\Users\SIMO\AppData\Local\Programs\Python\Python36\lib\site-packages\django\views\decorators\csrf.py", line 54, in wrapped_view
    return view_func(*args, **kwargs)
  File "D:\Users\SIMO\AppData\Local\Programs\Python\Python36\lib\site-packages\django\views\generic\base.py", line 69, in view
    return self.dispatch(request, *args, **kwargs)
  File "D:\Users\SIMO\AppData\Local\Programs\Python\Python36\lib\site-packages\rest_framework\views.py", line 494, in dispatch
    response = self.handle_exception(exc)
  File "D:\Users\SIMO\AppData\Local\Programs\Python\Python36\lib\site-packages\rest_framework\views.py", line 454, in handle_exception
    self.raise_uncaught_exception(exc)
  File "D:\Users\SIMO\AppData\Local\Programs\Python\Python36\lib\site-packages\rest_framework\views.py", line 491, in dispatch
    response = handler(request, *args, **kwargs)
  File "D:\Users\SIMO\AppData\Local\Programs\Python\Python36\lib\site-packages\rest_framework\decorators.py", line 53, in handler
    return func(*args, **kwargs)
  File "H:\project\api_automation_test\api_test\common\common.py", line 79, in verify
    return func(reality_parameter)
  File "H:\project\api_automation_test\api_test\api\automationCase.py", line 1150, in auto_test_report
    AutomationCaseTestResult.objects.filter(api, testTime=time), many=True).data
  File "D:\Users\SIMO\AppData\Local\Programs\Python\Python36\lib\site-packages\rest_framework\serializers.py", line 740, in data
    ret = super(ListSerializer, self).data
  File "D:\Users\SIMO\AppData\Local\Programs\Python\Python36\lib\site-packages\rest_framework\serializers.py", line 260, in data
    self._data = self.to_representation(self.instance)
  File "D:\Users\SIMO\AppData\Local\Programs\Python\Python36\lib\site-packages\rest_framework\serializers.py", line 658, in to_representation
    self.child.to_representation(item) for item in iterable
  File "D:\Users\SIMO\AppData\Local\Programs\Python\Python36\lib\site-packages\rest_framework\serializers.py", line 658, in <listcomp>
    self.child.to_representation(item) for item in iterable
  File "D:\Users\SIMO\AppData\Local\Programs\Python\Python36\lib\site-packages\rest_framework\serializers.py", line 489, in to_representation
    attribute = field.get_attribute(instance)
  File "D:\Users\SIMO\AppData\Local\Programs\Python\Python36\lib\site-packages\rest_framework\fields.py", line 462, in get_attribute
    raise type(exc)(msg)
AttributeError: Got AttributeError when attempting to get a value for field `name` on serializer `AutomationAutoTestResultSerializer`.
The serializer field might be named incorrectly and not match any attribute or key on the `AutomationCaseTestResult` instance.
Original exception text was: 'AutomationCaseTestResult' object has no attribute 'case_name'.
2018-05-18 17:31:22,382,1784,django.server,ERROR,basehttp.py:124,"GET /api/automation/auto_test_report?project_id=1&time=2018-05-18%2015:21:58.166434 HTTP/1.1" 500 21349
2018-05-18 17:33:35,683,2100,django.request,ERROR,exception.py:118,Internal Server Error: /api/automation/auto_test_report
Traceback (most recent call last):
  File "D:\Users\SIMO\AppData\Local\Programs\Python\Python36\lib\site-packages\django\core\handlers\exception.py", line 35, in inner
    response = get_response(request)
  File "D:\Users\SIMO\AppData\Local\Programs\Python\Python36\lib\site-packages\django\core\handlers\base.py", line 128, in _get_response
    response = self.process_exception_by_middleware(e, request)
  File "D:\Users\SIMO\AppData\Local\Programs\Python\Python36\lib\site-packages\django\core\handlers\base.py", line 126, in _get_response
    response = wrapped_callback(request, *callback_args, **callback_kwargs)
  File "D:\Users\SIMO\AppData\Local\Programs\Python\Python36\lib\site-packages\django\views\decorators\csrf.py", line 54, in wrapped_view
    return view_func(*args, **kwargs)
  File "D:\Users\SIMO\AppData\Local\Programs\Python\Python36\lib\site-packages\django\views\generic\base.py", line 69, in view
    return self.dispatch(request, *args, **kwargs)
  File "D:\Users\SIMO\AppData\Local\Programs\Python\Python36\lib\site-packages\rest_framework\views.py", line 494, in dispatch
    response = self.handle_exception(exc)
  File "D:\Users\SIMO\AppData\Local\Programs\Python\Python36\lib\site-packages\rest_framework\views.py", line 454, in handle_exception
    self.raise_uncaught_exception(exc)
  File "D:\Users\SIMO\AppData\Local\Programs\Python\Python36\lib\site-packages\rest_framework\views.py", line 491, in dispatch
    response = handler(request, *args, **kwargs)
  File "D:\Users\SIMO\AppData\Local\Programs\Python\Python36\lib\site-packages\rest_framework\decorators.py", line 53, in handler
    return func(*args, **kwargs)
  File "H:\project\api_automation_test\api_test\common\common.py", line 79, in verify
    return func(reality_parameter)
  File "H:\project\api_automation_test\api_test\api\automationCase.py", line 1150, in auto_test_report
    AutomationCaseTestResult.objects.filter(api, testTime=time), many=True).data
  File "D:\Users\SIMO\AppData\Local\Programs\Python\Python36\lib\site-packages\rest_framework\serializers.py", line 740, in data
    ret = super(ListSerializer, self).data
  File "D:\Users\SIMO\AppData\Local\Programs\Python\Python36\lib\site-packages\rest_framework\serializers.py", line 260, in data
    self._data = self.to_representation(self.instance)
  File "D:\Users\SIMO\AppData\Local\Programs\Python\Python36\lib\site-packages\rest_framework\serializers.py", line 658, in to_representation
    self.child.to_representation(item) for item in iterable
  File "D:\Users\SIMO\AppData\Local\Programs\Python\Python36\lib\site-packages\rest_framework\serializers.py", line 658, in <listcomp>
    self.child.to_representation(item) for item in iterable
  File "D:\Users\SIMO\AppData\Local\Programs\Python\Python36\lib\site-packages\rest_framework\serializers.py", line 485, in to_representation
    fields = self._readable_fields
  File "D:\Users\SIMO\AppData\Local\Programs\Python\Python36\lib\site-packages\django\utils\functional.py", line 36, in __get__
    res = instance.__dict__[self.name] = self.func(instance)
  File "D:\Users\SIMO\AppData\Local\Programs\Python\Python36\lib\site-packages\rest_framework\serializers.py", line 375, in _readable_fields
    field for field in self.fields.values()
  File "D:\Users\SIMO\AppData\Local\Programs\Python\Python36\lib\site-packages\rest_framework\serializers.py", line 361, in fields
    for key, value in self.get_fields().items():
  File "D:\Users\SIMO\AppData\Local\Programs\Python\Python36\lib\site-packages\rest_framework\serializers.py", line 995, in get_fields
    field_names = self.get_field_names(declared_fields, info)
  File "D:\Users\SIMO\AppData\Local\Programs\Python\Python36\lib\site-packages\rest_framework\serializers.py", line 1096, in get_field_names
    serializer_class=self.__class__.__name__
AssertionError: The field 'automationTestCase' was declared on serializer AutomationAutoTestResultSerializer, but has not been included in the 'fields' option.
2018-05-18 17:33:35,706,2100,django.server,ERROR,basehttp.py:124,"GET /api/automation/auto_test_report?project_id=1&time=2018-05-18%2015:21:58.166434 HTTP/1.1" 500 21232
2018-05-18 17:33:36,850,2100,django.request,ERROR,exception.py:118,Internal Server Error: /api/automation/auto_test_report
Traceback (most recent call last):
  File "D:\Users\SIMO\AppData\Local\Programs\Python\Python36\lib\site-packages\django\core\handlers\exception.py", line 35, in inner
    response = get_response(request)
  File "D:\Users\SIMO\AppData\Local\Programs\Python\Python36\lib\site-packages\django\core\handlers\base.py", line 128, in _get_response
    response = self.process_exception_by_middleware(e, request)
  File "D:\Users\SIMO\AppData\Local\Programs\Python\Python36\lib\site-packages\django\core\handlers\base.py", line 126, in _get_response
    response = wrapped_callback(request, *callback_args, **callback_kwargs)
  File "D:\Users\SIMO\AppData\Local\Programs\Python\Python36\lib\site-packages\django\views\decorators\csrf.py", line 54, in wrapped_view
    return view_func(*args, **kwargs)
  File "D:\Users\SIMO\AppData\Local\Programs\Python\Python36\lib\site-packages\django\views\generic\base.py", line 69, in view
    return self.dispatch(request, *args, **kwargs)
  File "D:\Users\SIMO\AppData\Local\Programs\Python\Python36\lib\site-packages\rest_framework\views.py", line 494, in dispatch
    response = self.handle_exception(exc)
  File "D:\Users\SIMO\AppData\Local\Programs\Python\Python36\lib\site-packages\rest_framework\views.py", line 454, in handle_exception
    self.raise_uncaught_exception(exc)
  File "D:\Users\SIMO\AppData\Local\Programs\Python\Python36\lib\site-packages\rest_framework\views.py", line 491, in dispatch
    response = handler(request, *args, **kwargs)
  File "D:\Users\SIMO\AppData\Local\Programs\Python\Python36\lib\site-packages\rest_framework\decorators.py", line 53, in handler
    return func(*args, **kwargs)
  File "H:\project\api_automation_test\api_test\common\common.py", line 79, in verify
    return func(reality_parameter)
  File "H:\project\api_automation_test\api_test\api\automationCase.py", line 1150, in auto_test_report
    AutomationCaseTestResult.objects.filter(api, testTime=time), many=True).data
  File "D:\Users\SIMO\AppData\Local\Programs\Python\Python36\lib\site-packages\rest_framework\serializers.py", line 740, in data
    ret = super(ListSerializer, self).data
  File "D:\Users\SIMO\AppData\Local\Programs\Python\Python36\lib\site-packages\rest_framework\serializers.py", line 260, in data
    self._data = self.to_representation(self.instance)
  File "D:\Users\SIMO\AppData\Local\Programs\Python\Python36\lib\site-packages\rest_framework\serializers.py", line 658, in to_representation
    self.child.to_representation(item) for item in iterable
  File "D:\Users\SIMO\AppData\Local\Programs\Python\Python36\lib\site-packages\rest_framework\serializers.py", line 658, in <listcomp>
    self.child.to_representation(item) for item in iterable
  File "D:\Users\SIMO\AppData\Local\Programs\Python\Python36\lib\site-packages\rest_framework\serializers.py", line 485, in to_representation
    fields = self._readable_fields
  File "D:\Users\SIMO\AppData\Local\Programs\Python\Python36\lib\site-packages\django\utils\functional.py", line 36, in __get__
    res = instance.__dict__[self.name] = self.func(instance)
  File "D:\Users\SIMO\AppData\Local\Programs\Python\Python36\lib\site-packages\rest_framework\serializers.py", line 375, in _readable_fields
    field for field in self.fields.values()
  File "D:\Users\SIMO\AppData\Local\Programs\Python\Python36\lib\site-packages\rest_framework\serializers.py", line 361, in fields
    for key, value in self.get_fields().items():
  File "D:\Users\SIMO\AppData\Local\Programs\Python\Python36\lib\site-packages\rest_framework\serializers.py", line 995, in get_fields
    field_names = self.get_field_names(declared_fields, info)
  File "D:\Users\SIMO\AppData\Local\Programs\Python\Python36\lib\site-packages\rest_framework\serializers.py", line 1096, in get_field_names
    serializer_class=self.__class__.__name__
AssertionError: The field 'automationTestCase' was declared on serializer AutomationAutoTestResultSerializer, but has not been included in the 'fields' option.
2018-05-18 17:33:36,868,2100,django.server,ERROR,basehttp.py:124,"GET /api/automation/auto_test_report?project_id=1&time=2018-05-18%2015:21:58.166434 HTTP/1.1" 500 21232
2018-05-18 17:33:42,749,9712,django.request,ERROR,exception.py:118,Internal Server Error: /api/automation/auto_test_report
Traceback (most recent call last):
  File "D:\Users\SIMO\AppData\Local\Programs\Python\Python36\lib\site-packages\django\core\handlers\exception.py", line 35, in inner
    response = get_response(request)
  File "D:\Users\SIMO\AppData\Local\Programs\Python\Python36\lib\site-packages\django\core\handlers\base.py", line 128, in _get_response
    response = self.process_exception_by_middleware(e, request)
  File "D:\Users\SIMO\AppData\Local\Programs\Python\Python36\lib\site-packages\django\core\handlers\base.py", line 126, in _get_response
    response = wrapped_callback(request, *callback_args, **callback_kwargs)
  File "D:\Users\SIMO\AppData\Local\Programs\Python\Python36\lib\site-packages\django\views\decorators\csrf.py", line 54, in wrapped_view
    return view_func(*args, **kwargs)
  File "D:\Users\SIMO\AppData\Local\Programs\Python\Python36\lib\site-packages\django\views\generic\base.py", line 69, in view
    return self.dispatch(request, *args, **kwargs)
  File "D:\Users\SIMO\AppData\Local\Programs\Python\Python36\lib\site-packages\rest_framework\views.py", line 494, in dispatch
    response = self.handle_exception(exc)
  File "D:\Users\SIMO\AppData\Local\Programs\Python\Python36\lib\site-packages\rest_framework\views.py", line 454, in handle_exception
    self.raise_uncaught_exception(exc)
  File "D:\Users\SIMO\AppData\Local\Programs\Python\Python36\lib\site-packages\rest_framework\views.py", line 491, in dispatch
    response = handler(request, *args, **kwargs)
  File "D:\Users\SIMO\AppData\Local\Programs\Python\Python36\lib\site-packages\rest_framework\decorators.py", line 53, in handler
    return func(*args, **kwargs)
  File "H:\project\api_automation_test\api_test\common\common.py", line 79, in verify
    return func(reality_parameter)
  File "H:\project\api_automation_test\api_test\api\automationCase.py", line 1150, in auto_test_report
    AutomationCaseTestResult.objects.filter(api, testTime=time), many=True).data
  File "D:\Users\SIMO\AppData\Local\Programs\Python\Python36\lib\site-packages\rest_framework\serializers.py", line 740, in data
    ret = super(ListSerializer, self).data
  File "D:\Users\SIMO\AppData\Local\Programs\Python\Python36\lib\site-packages\rest_framework\serializers.py", line 260, in data
    self._data = self.to_representation(self.instance)
  File "D:\Users\SIMO\AppData\Local\Programs\Python\Python36\lib\site-packages\rest_framework\serializers.py", line 658, in to_representation
    self.child.to_representation(item) for item in iterable
  File "D:\Users\SIMO\AppData\Local\Programs\Python\Python36\lib\site-packages\rest_framework\serializers.py", line 658, in <listcomp>
    self.child.to_representation(item) for item in iterable
  File "D:\Users\SIMO\AppData\Local\Programs\Python\Python36\lib\site-packages\rest_framework\serializers.py", line 485, in to_representation
    fields = self._readable_fields
  File "D:\Users\SIMO\AppData\Local\Programs\Python\Python36\lib\site-packages\django\utils\functional.py", line 36, in __get__
    res = instance.__dict__[self.name] = self.func(instance)
  File "D:\Users\SIMO\AppData\Local\Programs\Python\Python36\lib\site-packages\rest_framework\serializers.py", line 375, in _readable_fields
    field for field in self.fields.values()
  File "D:\Users\SIMO\AppData\Local\Programs\Python\Python36\lib\site-packages\rest_framework\serializers.py", line 361, in fields
    for key, value in self.get_fields().items():
  File "D:\Users\SIMO\AppData\Local\Programs\Python\Python36\lib\site-packages\rest_framework\serializers.py", line 995, in get_fields
    field_names = self.get_field_names(declared_fields, info)
  File "D:\Users\SIMO\AppData\Local\Programs\Python\Python36\lib\site-packages\rest_framework\serializers.py", line 1096, in get_field_names
    serializer_class=self.__class__.__name__
AssertionError: The field 'automationTestCase' was declared on serializer AutomationAutoTestResultSerializer, but has not been included in the 'fields' option.
2018-05-18 17:33:42,776,9712,django.server,ERROR,basehttp.py:124,"GET /api/automation/auto_test_report?project_id=1&time=2018-05-18%2015:21:58.166434 HTTP/1.1" 500 21232
2018-05-18 17:33:54,032,9564,django.request,ERROR,exception.py:118,Internal Server Error: /api/automation/auto_test_report
Traceback (most recent call last):
  File "D:\Users\SIMO\AppData\Local\Programs\Python\Python36\lib\site-packages\django\core\handlers\exception.py", line 35, in inner
    response = get_response(request)
  File "D:\Users\SIMO\AppData\Local\Programs\Python\Python36\lib\site-packages\django\core\handlers\base.py", line 128, in _get_response
    response = self.process_exception_by_middleware(e, request)
  File "D:\Users\SIMO\AppData\Local\Programs\Python\Python36\lib\site-packages\django\core\handlers\base.py", line 126, in _get_response
    response = wrapped_callback(request, *callback_args, **callback_kwargs)
  File "D:\Users\SIMO\AppData\Local\Programs\Python\Python36\lib\site-packages\django\views\decorators\csrf.py", line 54, in wrapped_view
    return view_func(*args, **kwargs)
  File "D:\Users\SIMO\AppData\Local\Programs\Python\Python36\lib\site-packages\django\views\generic\base.py", line 69, in view
    return self.dispatch(request, *args, **kwargs)
  File "D:\Users\SIMO\AppData\Local\Programs\Python\Python36\lib\site-packages\rest_framework\views.py", line 494, in dispatch
    response = self.handle_exception(exc)
  File "D:\Users\SIMO\AppData\Local\Programs\Python\Python36\lib\site-packages\rest_framework\views.py", line 454, in handle_exception
    self.raise_uncaught_exception(exc)
  File "D:\Users\SIMO\AppData\Local\Programs\Python\Python36\lib\site-packages\rest_framework\views.py", line 491, in dispatch
    response = handler(request, *args, **kwargs)
  File "D:\Users\SIMO\AppData\Local\Programs\Python\Python36\lib\site-packages\rest_framework\decorators.py", line 53, in handler
    return func(*args, **kwargs)
  File "H:\project\api_automation_test\api_test\common\common.py", line 79, in verify
    return func(reality_parameter)
  File "H:\project\api_automation_test\api_test\api\automationCase.py", line 1150, in auto_test_report
    AutomationCaseTestResult.objects.filter(api, testTime=time), many=True).data
  File "D:\Users\SIMO\AppData\Local\Programs\Python\Python36\lib\site-packages\rest_framework\serializers.py", line 740, in data
    ret = super(ListSerializer, self).data
  File "D:\Users\SIMO\AppData\Local\Programs\Python\Python36\lib\site-packages\rest_framework\serializers.py", line 260, in data
    self._data = self.to_representation(self.instance)
  File "D:\Users\SIMO\AppData\Local\Programs\Python\Python36\lib\site-packages\rest_framework\serializers.py", line 658, in to_representation
    self.child.to_representation(item) for item in iterable
  File "D:\Users\SIMO\AppData\Local\Programs\Python\Python36\lib\site-packages\rest_framework\serializers.py", line 658, in <listcomp>
    self.child.to_representation(item) for item in iterable
  File "D:\Users\SIMO\AppData\Local\Programs\Python\Python36\lib\site-packages\rest_framework\serializers.py", line 485, in to_representation
    fields = self._readable_fields
  File "D:\Users\SIMO\AppData\Local\Programs\Python\Python36\lib\site-packages\django\utils\functional.py", line 36, in __get__
    res = instance.__dict__[self.name] = self.func(instance)
  File "D:\Users\SIMO\AppData\Local\Programs\Python\Python36\lib\site-packages\rest_framework\serializers.py", line 375, in _readable_fields
    field for field in self.fields.values()
  File "D:\Users\SIMO\AppData\Local\Programs\Python\Python36\lib\site-packages\rest_framework\serializers.py", line 361, in fields
    for key, value in self.get_fields().items():
  File "D:\Users\SIMO\AppData\Local\Programs\Python\Python36\lib\site-packages\rest_framework\serializers.py", line 995, in get_fields
    field_names = self.get_field_names(declared_fields, info)
  File "D:\Users\SIMO\AppData\Local\Programs\Python\Python36\lib\site-packages\rest_framework\serializers.py", line 1096, in get_field_names
    serializer_class=self.__class__.__name__
AssertionError: The field 'automationTestCase' was declared on serializer AutomationAutoTestResultSerializer, but has not been included in the 'fields' option.
2018-05-18 17:33:54,052,9564,django.server,ERROR,basehttp.py:124,"GET /api/automation/auto_test_report?project_id=1&time=2018-05-18%2015:21:58.166434 HTTP/1.1" 500 21232
2018-05-18 17:34:09,524,9508,django.request,ERROR,exception.py:118,Internal Server Error: /api/automation/auto_test_report
Traceback (most recent call last):
  File "D:\Users\SIMO\AppData\Local\Programs\Python\Python36\lib\site-packages\django\core\handlers\exception.py", line 35, in inner
    response = get_response(request)
  File "D:\Users\SIMO\AppData\Local\Programs\Python\Python36\lib\site-packages\django\core\handlers\base.py", line 128, in _get_response
    response = self.process_exception_by_middleware(e, request)
  File "D:\Users\SIMO\AppData\Local\Programs\Python\Python36\lib\site-packages\django\core\handlers\base.py", line 126, in _get_response
    response = wrapped_callback(request, *callback_args, **callback_kwargs)
  File "D:\Users\SIMO\AppData\Local\Programs\Python\Python36\lib\site-packages\django\views\decorators\csrf.py", line 54, in wrapped_view
    return view_func(*args, **kwargs)
  File "D:\Users\SIMO\AppData\Local\Programs\Python\Python36\lib\site-packages\django\views\generic\base.py", line 69, in view
    return self.dispatch(request, *args, **kwargs)
  File "D:\Users\SIMO\AppData\Local\Programs\Python\Python36\lib\site-packages\rest_framework\views.py", line 494, in dispatch
    response = self.handle_exception(exc)
  File "D:\Users\SIMO\AppData\Local\Programs\Python\Python36\lib\site-packages\rest_framework\views.py", line 454, in handle_exception
    self.raise_uncaught_exception(exc)
  File "D:\Users\SIMO\AppData\Local\Programs\Python\Python36\lib\site-packages\rest_framework\views.py", line 491, in dispatch
    response = handler(request, *args, **kwargs)
  File "D:\Users\SIMO\AppData\Local\Programs\Python\Python36\lib\site-packages\rest_framework\decorators.py", line 53, in handler
    return func(*args, **kwargs)
  File "H:\project\api_automation_test\api_test\common\common.py", line 79, in verify
    return func(reality_parameter)
  File "H:\project\api_automation_test\api_test\api\automationCase.py", line 1150, in auto_test_report
    AutomationCaseTestResult.objects.filter(api, testTime=time), many=True).data
  File "D:\Users\SIMO\AppData\Local\Programs\Python\Python36\lib\site-packages\rest_framework\serializers.py", line 740, in data
    ret = super(ListSerializer, self).data
  File "D:\Users\SIMO\AppData\Local\Programs\Python\Python36\lib\site-packages\rest_framework\serializers.py", line 260, in data
    self._data = self.to_representation(self.instance)
  File "D:\Users\SIMO\AppData\Local\Programs\Python\Python36\lib\site-packages\rest_framework\serializers.py", line 658, in to_representation
    self.child.to_representation(item) for item in iterable
  File "D:\Users\SIMO\AppData\Local\Programs\Python\Python36\lib\site-packages\rest_framework\serializers.py", line 658, in <listcomp>
    self.child.to_representation(item) for item in iterable
  File "D:\Users\SIMO\AppData\Local\Programs\Python\Python36\lib\site-packages\rest_framework\serializers.py", line 485, in to_representation
    fields = self._readable_fields
  File "D:\Users\SIMO\AppData\Local\Programs\Python\Python36\lib\site-packages\django\utils\functional.py", line 36, in __get__
    res = instance.__dict__[self.name] = self.func(instance)
  File "D:\Users\SIMO\AppData\Local\Programs\Python\Python36\lib\site-packages\rest_framework\serializers.py", line 375, in _readable_fields
    field for field in self.fields.values()
  File "D:\Users\SIMO\AppData\Local\Programs\Python\Python36\lib\site-packages\rest_framework\serializers.py", line 361, in fields
    for key, value in self.get_fields().items():
  File "D:\Users\SIMO\AppData\Local\Programs\Python\Python36\lib\site-packages\rest_framework\serializers.py", line 995, in get_fields
    field_names = self.get_field_names(declared_fields, info)
  File "D:\Users\SIMO\AppData\Local\Programs\Python\Python36\lib\site-packages\rest_framework\serializers.py", line 1096, in get_field_names
    serializer_class=self.__class__.__name__
AssertionError: The field 'automationTestCase' was declared on serializer AutomationAutoTestResultSerializer, but has not been included in the 'fields' option.
2018-05-18 17:34:09,543,9508,django.server,ERROR,basehttp.py:124,"GET /api/automation/auto_test_report?project_id=1&time=2018-05-18%2015:21:58.166434 HTTP/1.1" 500 21232
2018-05-18 17:34:53,500,14908,django.request,ERROR,exception.py:118,Internal Server Error: /api/automation/auto_test_report
Traceback (most recent call last):
  File "D:\Users\SIMO\AppData\Local\Programs\Python\Python36\lib\site-packages\django\core\handlers\exception.py", line 35, in inner
    response = get_response(request)
  File "D:\Users\SIMO\AppData\Local\Programs\Python\Python36\lib\site-packages\django\core\handlers\base.py", line 128, in _get_response
    response = self.process_exception_by_middleware(e, request)
  File "D:\Users\SIMO\AppData\Local\Programs\Python\Python36\lib\site-packages\django\core\handlers\base.py", line 126, in _get_response
    response = wrapped_callback(request, *callback_args, **callback_kwargs)
  File "D:\Users\SIMO\AppData\Local\Programs\Python\Python36\lib\site-packages\django\views\decorators\csrf.py", line 54, in wrapped_view
    return view_func(*args, **kwargs)
  File "D:\Users\SIMO\AppData\Local\Programs\Python\Python36\lib\site-packages\django\views\generic\base.py", line 69, in view
    return self.dispatch(request, *args, **kwargs)
  File "D:\Users\SIMO\AppData\Local\Programs\Python\Python36\lib\site-packages\rest_framework\views.py", line 494, in dispatch
    response = self.handle_exception(exc)
  File "D:\Users\SIMO\AppData\Local\Programs\Python\Python36\lib\site-packages\rest_framework\views.py", line 454, in handle_exception
    self.raise_uncaught_exception(exc)
  File "D:\Users\SIMO\AppData\Local\Programs\Python\Python36\lib\site-packages\rest_framework\views.py", line 491, in dispatch
    response = handler(request, *args, **kwargs)
  File "D:\Users\SIMO\AppData\Local\Programs\Python\Python36\lib\site-packages\rest_framework\decorators.py", line 53, in handler
    return func(*args, **kwargs)
  File "H:\project\api_automation_test\api_test\common\common.py", line 79, in verify
    return func(reality_parameter)
  File "H:\project\api_automation_test\api_test\api\automationCase.py", line 1150, in auto_test_report
    AutomationCaseTestResult.objects.filter(api, testTime=time), many=True).data
  File "D:\Users\SIMO\AppData\Local\Programs\Python\Python36\lib\site-packages\rest_framework\serializers.py", line 740, in data
    ret = super(ListSerializer, self).data
  File "D:\Users\SIMO\AppData\Local\Programs\Python\Python36\lib\site-packages\rest_framework\serializers.py", line 260, in data
    self._data = self.to_representation(self.instance)
  File "D:\Users\SIMO\AppData\Local\Programs\Python\Python36\lib\site-packages\rest_framework\serializers.py", line 658, in to_representation
    self.child.to_representation(item) for item in iterable
  File "D:\Users\SIMO\AppData\Local\Programs\Python\Python36\lib\site-packages\rest_framework\serializers.py", line 658, in <listcomp>
    self.child.to_representation(item) for item in iterable
  File "D:\Users\SIMO\AppData\Local\Programs\Python\Python36\lib\site-packages\rest_framework\serializers.py", line 485, in to_representation
    fields = self._readable_fields
  File "D:\Users\SIMO\AppData\Local\Programs\Python\Python36\lib\site-packages\django\utils\functional.py", line 36, in __get__
    res = instance.__dict__[self.name] = self.func(instance)
  File "D:\Users\SIMO\AppData\Local\Programs\Python\Python36\lib\site-packages\rest_framework\serializers.py", line 375, in _readable_fields
    field for field in self.fields.values()
  File "D:\Users\SIMO\AppData\Local\Programs\Python\Python36\lib\site-packages\rest_framework\serializers.py", line 361, in fields
    for key, value in self.get_fields().items():
  File "D:\Users\SIMO\AppData\Local\Programs\Python\Python36\lib\site-packages\rest_framework\serializers.py", line 1020, in get_fields
    source, info, model, depth
  File "D:\Users\SIMO\AppData\Local\Programs\Python\Python36\lib\site-packages\rest_framework\serializers.py", line 1165, in build_field
    return self.build_unknown_field(field_name, model_class)
  File "D:\Users\SIMO\AppData\Local\Programs\Python\Python36\lib\site-packages\rest_framework\serializers.py", line 1277, in build_unknown_field
    (field_name, model_class.__name__)
django.core.exceptions.ImproperlyConfigured: Field name `aresult` is not valid for model `AutomationCaseTestResult`.
2018-05-18 17:34:53,521,14908,django.server,ERROR,basehttp.py:124,"GET /api/automation/auto_test_report?project_id=1&time=2018-05-18%2015:21:58.166434 HTTP/1.1" 500 21261
2018-05-18 17:35:06,668,12392,django.request,ERROR,exception.py:118,Internal Server Error: /api/automation/auto_test_report
Traceback (most recent call last):
  File "D:\Users\SIMO\AppData\Local\Programs\Python\Python36\lib\site-packages\django\core\handlers\exception.py", line 35, in inner
    response = get_response(request)
  File "D:\Users\SIMO\AppData\Local\Programs\Python\Python36\lib\site-packages\django\core\handlers\base.py", line 128, in _get_response
    response = self.process_exception_by_middleware(e, request)
  File "D:\Users\SIMO\AppData\Local\Programs\Python\Python36\lib\site-packages\django\core\handlers\base.py", line 126, in _get_response
    response = wrapped_callback(request, *callback_args, **callback_kwargs)
  File "D:\Users\SIMO\AppData\Local\Programs\Python\Python36\lib\site-packages\django\views\decorators\csrf.py", line 54, in wrapped_view
    return view_func(*args, **kwargs)
  File "D:\Users\SIMO\AppData\Local\Programs\Python\Python36\lib\site-packages\django\views\generic\base.py", line 69, in view
    return self.dispatch(request, *args, **kwargs)
  File "D:\Users\SIMO\AppData\Local\Programs\Python\Python36\lib\site-packages\rest_framework\views.py", line 494, in dispatch
    response = self.handle_exception(exc)
  File "D:\Users\SIMO\AppData\Local\Programs\Python\Python36\lib\site-packages\rest_framework\views.py", line 454, in handle_exception
    self.raise_uncaught_exception(exc)
  File "D:\Users\SIMO\AppData\Local\Programs\Python\Python36\lib\site-packages\rest_framework\views.py", line 491, in dispatch
    response = handler(request, *args, **kwargs)
  File "D:\Users\SIMO\AppData\Local\Programs\Python\Python36\lib\site-packages\rest_framework\decorators.py", line 53, in handler
    return func(*args, **kwargs)
  File "H:\project\api_automation_test\api_test\common\common.py", line 79, in verify
    return func(reality_parameter)
  File "H:\project\api_automation_test\api_test\api\automationCase.py", line 1150, in auto_test_report
    AutomationCaseTestResult.objects.filter(api, testTime=time), many=True).data
  File "D:\Users\SIMO\AppData\Local\Programs\Python\Python36\lib\site-packages\rest_framework\serializers.py", line 740, in data
    ret = super(ListSerializer, self).data
  File "D:\Users\SIMO\AppData\Local\Programs\Python\Python36\lib\site-packages\rest_framework\serializers.py", line 260, in data
    self._data = self.to_representation(self.instance)
  File "D:\Users\SIMO\AppData\Local\Programs\Python\Python36\lib\site-packages\rest_framework\serializers.py", line 658, in to_representation
    self.child.to_representation(item) for item in iterable
  File "D:\Users\SIMO\AppData\Local\Programs\Python\Python36\lib\site-packages\rest_framework\serializers.py", line 658, in <listcomp>
    self.child.to_representation(item) for item in iterable
  File "D:\Users\SIMO\AppData\Local\Programs\Python\Python36\lib\site-packages\rest_framework\serializers.py", line 485, in to_representation
    fields = self._readable_fields
  File "D:\Users\SIMO\AppData\Local\Programs\Python\Python36\lib\site-packages\django\utils\functional.py", line 36, in __get__
    res = instance.__dict__[self.name] = self.func(instance)
  File "D:\Users\SIMO\AppData\Local\Programs\Python\Python36\lib\site-packages\rest_framework\serializers.py", line 375, in _readable_fields
    field for field in self.fields.values()
  File "D:\Users\SIMO\AppData\Local\Programs\Python\Python36\lib\site-packages\rest_framework\serializers.py", line 361, in fields
    for key, value in self.get_fields().items():
  File "D:\Users\SIMO\AppData\Local\Programs\Python\Python36\lib\site-packages\rest_framework\serializers.py", line 1020, in get_fields
    source, info, model, depth
  File "D:\Users\SIMO\AppData\Local\Programs\Python\Python36\lib\site-packages\rest_framework\serializers.py", line 1165, in build_field
    return self.build_unknown_field(field_name, model_class)
  File "D:\Users\SIMO\AppData\Local\Programs\Python\Python36\lib\site-packages\rest_framework\serializers.py", line 1277, in build_unknown_field
    (field_name, model_class.__name__)
django.core.exceptions.ImproperlyConfigured: Field name `a` is not valid for model `AutomationCaseTestResult`.
2018-05-18 17:35:06,689,12392,django.server,ERROR,basehttp.py:124,"GET /api/automation/auto_test_report?project_id=1&time=2018-05-18%2015:21:58.166434 HTTP/1.1" 500 21249
2018-05-18 17:35:25,513,4464,django.request,ERROR,exception.py:118,Internal Server Error: /api/automation/auto_test_report
Traceback (most recent call last):
  File "D:\Users\SIMO\AppData\Local\Programs\Python\Python36\lib\site-packages\django\core\handlers\exception.py", line 35, in inner
    response = get_response(request)
  File "D:\Users\SIMO\AppData\Local\Programs\Python\Python36\lib\site-packages\django\core\handlers\base.py", line 128, in _get_response
    response = self.process_exception_by_middleware(e, request)
  File "D:\Users\SIMO\AppData\Local\Programs\Python\Python36\lib\site-packages\django\core\handlers\base.py", line 126, in _get_response
    response = wrapped_callback(request, *callback_args, **callback_kwargs)
  File "D:\Users\SIMO\AppData\Local\Programs\Python\Python36\lib\site-packages\django\views\decorators\csrf.py", line 54, in wrapped_view
    return view_func(*args, **kwargs)
  File "D:\Users\SIMO\AppData\Local\Programs\Python\Python36\lib\site-packages\django\views\generic\base.py", line 69, in view
    return self.dispatch(request, *args, **kwargs)
  File "D:\Users\SIMO\AppData\Local\Programs\Python\Python36\lib\site-packages\rest_framework\views.py", line 494, in dispatch
    response = self.handle_exception(exc)
  File "D:\Users\SIMO\AppData\Local\Programs\Python\Python36\lib\site-packages\rest_framework\views.py", line 454, in handle_exception
    self.raise_uncaught_exception(exc)
  File "D:\Users\SIMO\AppData\Local\Programs\Python\Python36\lib\site-packages\rest_framework\views.py", line 491, in dispatch
    response = handler(request, *args, **kwargs)
  File "D:\Users\SIMO\AppData\Local\Programs\Python\Python36\lib\site-packages\rest_framework\decorators.py", line 53, in handler
    return func(*args, **kwargs)
  File "H:\project\api_automation_test\api_test\common\common.py", line 79, in verify
    return func(reality_parameter)
  File "H:\project\api_automation_test\api_test\api\automationCase.py", line 1150, in auto_test_report
    AutomationCaseTestResult.objects.filter(api, testTime=time), many=True).data
  File "D:\Users\SIMO\AppData\Local\Programs\Python\Python36\lib\site-packages\rest_framework\serializers.py", line 740, in data
    ret = super(ListSerializer, self).data
  File "D:\Users\SIMO\AppData\Local\Programs\Python\Python36\lib\site-packages\rest_framework\serializers.py", line 260, in data
    self._data = self.to_representation(self.instance)
  File "D:\Users\SIMO\AppData\Local\Programs\Python\Python36\lib\site-packages\rest_framework\serializers.py", line 658, in to_representation
    self.child.to_representation(item) for item in iterable
  File "D:\Users\SIMO\AppData\Local\Programs\Python\Python36\lib\site-packages\rest_framework\serializers.py", line 658, in <listcomp>
    self.child.to_representation(item) for item in iterable
  File "D:\Users\SIMO\AppData\Local\Programs\Python\Python36\lib\site-packages\rest_framework\serializers.py", line 485, in to_representation
    fields = self._readable_fields
  File "D:\Users\SIMO\AppData\Local\Programs\Python\Python36\lib\site-packages\django\utils\functional.py", line 36, in __get__
    res = instance.__dict__[self.name] = self.func(instance)
  File "D:\Users\SIMO\AppData\Local\Programs\Python\Python36\lib\site-packages\rest_framework\serializers.py", line 375, in _readable_fields
    field for field in self.fields.values()
  File "D:\Users\SIMO\AppData\Local\Programs\Python\Python36\lib\site-packages\rest_framework\serializers.py", line 361, in fields
    for key, value in self.get_fields().items():
  File "D:\Users\SIMO\AppData\Local\Programs\Python\Python36\lib\site-packages\rest_framework\serializers.py", line 995, in get_fields
    field_names = self.get_field_names(declared_fields, info)
  File "D:\Users\SIMO\AppData\Local\Programs\Python\Python36\lib\site-packages\rest_framework\serializers.py", line 1096, in get_field_names
    serializer_class=self.__class__.__name__
AssertionError: The field 'a' was declared on serializer AutomationAutoTestResultSerializer, but has not been included in the 'fields' option.
2018-05-18 17:35:25,537,4464,django.server,ERROR,basehttp.py:124,"GET /api/automation/auto_test_report?project_id=1&time=2018-05-18%2015:21:58.166434 HTTP/1.1" 500 21197
