2018-02-18 14:27:20,595,5744,django.request,ERROR,exception.py:118,Internal Server Error: /
Traceback (most recent call last):
  File "D:\Program Files (x86)\Python36-32\lib\site-packages\django\core\handlers\exception.py", line 35, in inner
    response = get_response(request)
  File "D:\Program Files (x86)\Python36-32\lib\site-packages\django\core\handlers\base.py", line 158, in _get_response
    response = self.process_exception_by_middleware(e, request)
  File "D:\Program Files (x86)\Python36-32\lib\site-packages\django\core\handlers\base.py", line 156, in _get_response
    response = response.render()
  File "D:\Program Files (x86)\Python36-32\lib\site-packages\django\template\response.py", line 106, in render
    self.content = self.rendered_content
  File "D:\Program Files (x86)\Python36-32\lib\site-packages\django\template\response.py", line 81, in rendered_content
    template = self.resolve_template(self.template_name)
  File "D:\Program Files (x86)\Python36-32\lib\site-packages\django\template\response.py", line 63, in resolve_template
    return select_template(template, using=self.using)
  File "D:\Program Files (x86)\Python36-32\lib\site-packages\django\template\loader.py", line 47, in select_template
    raise TemplateDoesNotExist(', '.join(template_name_list), chain=chain)
django.template.exceptions.TemplateDoesNotExist: index.html
2018-02-18 14:27:20,941,5744,django.server,ERROR,basehttp.py:124,"GET / HTTP/1.1" 500 82910
