DEBUG 2018-01-31 15:51:13,865 F:\工具安装\python3.6.3\lib\site-packages\django\db\backends\utils.py utils.py utils execute 111: (0.000) SELECT @@SQL_AUTO_IS_NULL; args=None
DEBUG 2018-01-31 15:51:13,866 F:\工具安装\python3.6.3\lib\site-packages\django\db\backends\utils.py utils.py utils execute 111: (0.000) SET SESSION TRANSACTION ISOLATION LEVEL READ COMMITTED; args=None
DEBUG 2018-01-31 15:51:13,866 F:\工具安装\python3.6.3\lib\site-packages\django\db\backends\utils.py utils.py utils execute 111: (0.000) SELECT VERSION(); args=None
DEBUG 2018-01-31 15:51:14,027 F:\工具安装\python3.6.3\lib\site-packages\django\db\backends\utils.py utils.py utils execute 111: (0.000) SET SESSION TRANSACTION ISOLATION LEVEL READ COMMITTED; args=None
DEBUG 2018-01-31 15:51:14,028 F:\工具安装\python3.6.3\lib\site-packages\django\db\backends\utils.py utils.py utils execute 111: (0.000) SHOW FULL TABLES; args=None
DEBUG 2018-01-31 15:51:14,031 F:\工具安装\python3.6.3\lib\site-packages\django\db\backends\utils.py utils.py utils execute 111: (0.001) SELECT `django_migrations`.`app`, `django_migrations`.`name` FROM `django_migrations`; args=()
DEBUG 2018-01-31 15:51:18,272 F:\工具安装\python3.6.3\lib\site-packages\django\template\base.py base.py base _resolve_lookup 878: Exception while resolving variable 'name' in template 'unknown'.
Traceback (most recent call last):
  File "F:\工具安装\python3.6.3\lib\site-packages\django\core\handlers\exception.py", line 35, in inner
    response = get_response(request)
  File "F:\工具安装\python3.6.3\lib\site-packages\django\core\handlers\base.py", line 113, in _get_response
    resolver_match = resolver.resolve(request.path_info)
  File "F:\工具安装\python3.6.3\lib\site-packages\django\urls\resolvers.py", line 523, in resolve
    raise Resolver404({'tried': tried, 'path': new_path})
django.urls.exceptions.Resolver404: {'tried': [[<URLResolver <URLPattern list> (admin:admin) 'admin/'>, <URLPattern '' [name='index']>], [<URLResolver <URLPattern list> (admin:admin) 'admin/'>, <URLPattern 'login/' [name='login']>], [<URLResolver <URLPattern list> (admin:admin) 'admin/'>, <URLPattern 'logout/' [name='logout']>], [<URLResolver <URLPattern list> (admin:admin) 'admin/'>, <URLPattern 'password_change/' [name='password_change']>], [<URLResolver <URLPattern list> (admin:admin) 'admin/'>, <URLPattern 'password_change/done/' [name='password_change_done']>], [<URLResolver <URLPattern list> (admin:admin) 'admin/'>, <URLPattern 'jsi18n/' [name='jsi18n']>], [<URLResolver <URLPattern list> (admin:admin) 'admin/'>, <URLPattern 'r/<int:content_type_id>/<path:object_id>/' [name='view_on_site']>], [<URLResolver <URLPattern list> (admin:admin) 'admin/'>, <URLResolver <URLPattern list> (None:None) 'auth/group/'>], [<URLResolver <URLPattern list> (admin:admin) 'admin/'>, <URLResolver <URLPattern list> (None:None) 'auth/user/'>], [<URLResolver <URLPattern list> (admin:admin) 'admin/'>, <URLResolver <URLPattern list> (None:None) 'api_test/project/'>], [<URLResolver <URLPattern list> (admin:admin) 'admin/'>, <URLResolver <URLPattern list> (None:None) 'api_test/projectdynamic/'>], [<URLResolver <URLPattern list> (admin:admin) 'admin/'>, <URLResolver <URLPattern list> (None:None) 'api_test/projectmember/'>], [<URLResolver <URLPattern list> (admin:admin) 'admin/'>, <URLResolver <URLPattern list> (None:None) 'api_test/globalhost/'>], [<URLResolver <URLPattern list> (admin:admin) 'admin/'>, <URLResolver <URLPattern list> (None:None) 'api_test/custommethod/'>], [<URLResolver <URLPattern list> (admin:admin) 'admin/'>, <URLResolver <URLPattern list> (None:None) 'api_test/apigrouplevelfirst/'>], [<URLResolver <URLPattern list> (admin:admin) 'admin/'>, <URLResolver <URLPattern list> (None:None) 'api_test/apiinfo/'>], [<URLResolver <URLPattern list> (admin:admin) 'admin/'>, <URLResolver <URLPattern list> (None:None) 'api_test/apirequesthistory/'>], [<URLResolver <URLPattern list> (admin:admin) 'admin/'>, <URLResolver <URLPattern list> (None:None) 'api_test/apioperationhistory/'>], [<URLResolver <URLPattern list> (admin:admin) 'admin/'>, <URLResolver <URLPattern list> (None:None) 'api_test/automationgrouplevelfirst/'>], [<URLResolver <URLPattern list> (admin:admin) 'admin/'>, <URLResolver <URLPattern list> (None:None) 'api_test/automationtestcase/'>], [<URLResolver <URLPattern list> (admin:admin) 'admin/'>, <URLResolver <URLPattern list> (None:None) 'api_test/automationcaseapi/'>], [<URLResolver <URLPattern list> (admin:admin) 'admin/'>, <URLResolver <URLPattern list> (None:None) 'api_test/automationtestresult/'>], [<URLResolver <URLPattern list> (admin:admin) 'admin/'>, <URLResolver <URLPattern list> (None:None) 'api_test/automationtesttask/'>], [<URLResolver <URLPattern list> (admin:admin) 'admin/'>, <URLPattern '^(?P<app_label>auth|api_test)/$' [name='app_list']>], [<URLResolver <module 'api_test.urls' from 'H:\\project\\api_automation_test\\api_test\\urls.py'> (None:None) '^api/'>]], 'path': 'admin/api_test/apihead/'}

During handling of the above exception, another exception occurred:

Traceback (most recent call last):
  File "F:\工具安装\python3.6.3\lib\site-packages\django\template\base.py", line 835, in _resolve_lookup
    current = current[bit]
TypeError: 'URLResolver' object is not subscriptable

During handling of the above exception, another exception occurred:

Traceback (most recent call last):
  File "F:\工具安装\python3.6.3\lib\site-packages\django\template\base.py", line 843, in _resolve_lookup
    current = getattr(current, bit)
AttributeError: 'URLResolver' object has no attribute 'name'

During handling of the above exception, another exception occurred:

Traceback (most recent call last):
  File "F:\工具安装\python3.6.3\lib\site-packages\django\template\base.py", line 849, in _resolve_lookup
    current = current[int(bit)]
ValueError: invalid literal for int() with base 10: 'name'

During handling of the above exception, another exception occurred:

Traceback (most recent call last):
  File "F:\工具安装\python3.6.3\lib\site-packages\django\template\base.py", line 856, in _resolve_lookup
    (bit, current))  # missing attribute
django.template.base.VariableDoesNotExist: Failed lookup for key [name] in <URLResolver <URLPattern list> (None:None) 'auth/group/'>
DEBUG 2018-01-31 15:51:18,274 F:\工具安装\python3.6.3\lib\site-packages\django\template\base.py base.py base _resolve_lookup 878: Exception while resolving variable 'name' in template 'unknown'.
Traceback (most recent call last):
  File "F:\工具安装\python3.6.3\lib\site-packages\django\core\handlers\exception.py", line 35, in inner
    response = get_response(request)
  File "F:\工具安装\python3.6.3\lib\site-packages\django\core\handlers\base.py", line 113, in _get_response
    resolver_match = resolver.resolve(request.path_info)
  File "F:\工具安装\python3.6.3\lib\site-packages\django\urls\resolvers.py", line 523, in resolve
    raise Resolver404({'tried': tried, 'path': new_path})
django.urls.exceptions.Resolver404: {'tried': [[<URLResolver <URLPattern list> (admin:admin) 'admin/'>, <URLPattern '' [name='index']>], [<URLResolver <URLPattern list> (admin:admin) 'admin/'>, <URLPattern 'login/' [name='login']>], [<URLResolver <URLPattern list> (admin:admin) 'admin/'>, <URLPattern 'logout/' [name='logout']>], [<URLResolver <URLPattern list> (admin:admin) 'admin/'>, <URLPattern 'password_change/' [name='password_change']>], [<URLResolver <URLPattern list> (admin:admin) 'admin/'>, <URLPattern 'password_change/done/' [name='password_change_done']>], [<URLResolver <URLPattern list> (admin:admin) 'admin/'>, <URLPattern 'jsi18n/' [name='jsi18n']>], [<URLResolver <URLPattern list> (admin:admin) 'admin/'>, <URLPattern 'r/<int:content_type_id>/<path:object_id>/' [name='view_on_site']>], [<URLResolver <URLPattern list> (admin:admin) 'admin/'>, <URLResolver <URLPattern list> (None:None) 'auth/group/'>], [<URLResolver <URLPattern list> (admin:admin) 'admin/'>, <URLResolver <URLPattern list> (None:None) 'auth/user/'>], [<URLResolver <URLPattern list> (admin:admin) 'admin/'>, <URLResolver <URLPattern list> (None:None) 'api_test/project/'>], [<URLResolver <URLPattern list> (admin:admin) 'admin/'>, <URLResolver <URLPattern list> (None:None) 'api_test/projectdynamic/'>], [<URLResolver <URLPattern list> (admin:admin) 'admin/'>, <URLResolver <URLPattern list> (None:None) 'api_test/projectmember/'>], [<URLResolver <URLPattern list> (admin:admin) 'admin/'>, <URLResolver <URLPattern list> (None:None) 'api_test/globalhost/'>], [<URLResolver <URLPattern list> (admin:admin) 'admin/'>, <URLResolver <URLPattern list> (None:None) 'api_test/custommethod/'>], [<URLResolver <URLPattern list> (admin:admin) 'admin/'>, <URLResolver <URLPattern list> (None:None) 'api_test/apigrouplevelfirst/'>], [<URLResolver <URLPattern list> (admin:admin) 'admin/'>, <URLResolver <URLPattern list> (None:None) 'api_test/apiinfo/'>], [<URLResolver <URLPattern list> (admin:admin) 'admin/'>, <URLResolver <URLPattern list> (None:None) 'api_test/apirequesthistory/'>], [<URLResolver <URLPattern list> (admin:admin) 'admin/'>, <URLResolver <URLPattern list> (None:None) 'api_test/apioperationhistory/'>], [<URLResolver <URLPattern list> (admin:admin) 'admin/'>, <URLResolver <URLPattern list> (None:None) 'api_test/automationgrouplevelfirst/'>], [<URLResolver <URLPattern list> (admin:admin) 'admin/'>, <URLResolver <URLPattern list> (None:None) 'api_test/automationtestcase/'>], [<URLResolver <URLPattern list> (admin:admin) 'admin/'>, <URLResolver <URLPattern list> (None:None) 'api_test/automationcaseapi/'>], [<URLResolver <URLPattern list> (admin:admin) 'admin/'>, <URLResolver <URLPattern list> (None:None) 'api_test/automationtestresult/'>], [<URLResolver <URLPattern list> (admin:admin) 'admin/'>, <URLResolver <URLPattern list> (None:None) 'api_test/automationtesttask/'>], [<URLResolver <URLPattern list> (admin:admin) 'admin/'>, <URLPattern '^(?P<app_label>auth|api_test)/$' [name='app_list']>], [<URLResolver <module 'api_test.urls' from 'H:\\project\\api_automation_test\\api_test\\urls.py'> (None:None) '^api/'>]], 'path': 'admin/api_test/apihead/'}

During handling of the above exception, another exception occurred:

Traceback (most recent call last):
  File "F:\工具安装\python3.6.3\lib\site-packages\django\template\base.py", line 835, in _resolve_lookup
    current = current[bit]
TypeError: 'URLResolver' object is not subscriptable

During handling of the above exception, another exception occurred:

Traceback (most recent call last):
  File "F:\工具安装\python3.6.3\lib\site-packages\django\template\base.py", line 843, in _resolve_lookup
    current = getattr(current, bit)
AttributeError: 'URLResolver' object has no attribute 'name'

During handling of the above exception, another exception occurred:

Traceback (most recent call last):
  File "F:\工具安装\python3.6.3\lib\site-packages\django\template\base.py", line 849, in _resolve_lookup
    current = current[int(bit)]
ValueError: invalid literal for int() with base 10: 'name'

During handling of the above exception, another exception occurred:

Traceback (most recent call last):
  File "F:\工具安装\python3.6.3\lib\site-packages\django\template\base.py", line 856, in _resolve_lookup
    (bit, current))  # missing attribute
django.template.base.VariableDoesNotExist: Failed lookup for key [name] in <URLResolver <URLPattern list> (None:None) 'auth/user/'>
DEBUG 2018-01-31 15:51:18,274 F:\工具安装\python3.6.3\lib\site-packages\django\template\base.py base.py base _resolve_lookup 878: Exception while resolving variable 'name' in template 'unknown'.
Traceback (most recent call last):
  File "F:\工具安装\python3.6.3\lib\site-packages\django\core\handlers\exception.py", line 35, in inner
    response = get_response(request)
  File "F:\工具安装\python3.6.3\lib\site-packages\django\core\handlers\base.py", line 113, in _get_response
    resolver_match = resolver.resolve(request.path_info)
  File "F:\工具安装\python3.6.3\lib\site-packages\django\urls\resolvers.py", line 523, in resolve
    raise Resolver404({'tried': tried, 'path': new_path})
django.urls.exceptions.Resolver404: {'tried': [[<URLResolver <URLPattern list> (admin:admin) 'admin/'>, <URLPattern '' [name='index']>], [<URLResolver <URLPattern list> (admin:admin) 'admin/'>, <URLPattern 'login/' [name='login']>], [<URLResolver <URLPattern list> (admin:admin) 'admin/'>, <URLPattern 'logout/' [name='logout']>], [<URLResolver <URLPattern list> (admin:admin) 'admin/'>, <URLPattern 'password_change/' [name='password_change']>], [<URLResolver <URLPattern list> (admin:admin) 'admin/'>, <URLPattern 'password_change/done/' [name='password_change_done']>], [<URLResolver <URLPattern list> (admin:admin) 'admin/'>, <URLPattern 'jsi18n/' [name='jsi18n']>], [<URLResolver <URLPattern list> (admin:admin) 'admin/'>, <URLPattern 'r/<int:content_type_id>/<path:object_id>/' [name='view_on_site']>], [<URLResolver <URLPattern list> (admin:admin) 'admin/'>, <URLResolver <URLPattern list> (None:None) 'auth/group/'>], [<URLResolver <URLPattern list> (admin:admin) 'admin/'>, <URLResolver <URLPattern list> (None:None) 'auth/user/'>], [<URLResolver <URLPattern list> (admin:admin) 'admin/'>, <URLResolver <URLPattern list> (None:None) 'api_test/project/'>], [<URLResolver <URLPattern list> (admin:admin) 'admin/'>, <URLResolver <URLPattern list> (None:None) 'api_test/projectdynamic/'>], [<URLResolver <URLPattern list> (admin:admin) 'admin/'>, <URLResolver <URLPattern list> (None:None) 'api_test/projectmember/'>], [<URLResolver <URLPattern list> (admin:admin) 'admin/'>, <URLResolver <URLPattern list> (None:None) 'api_test/globalhost/'>], [<URLResolver <URLPattern list> (admin:admin) 'admin/'>, <URLResolver <URLPattern list> (None:None) 'api_test/custommethod/'>], [<URLResolver <URLPattern list> (admin:admin) 'admin/'>, <URLResolver <URLPattern list> (None:None) 'api_test/apigrouplevelfirst/'>], [<URLResolver <URLPattern list> (admin:admin) 'admin/'>, <URLResolver <URLPattern list> (None:None) 'api_test/apiinfo/'>], [<URLResolver <URLPattern list> (admin:admin) 'admin/'>, <URLResolver <URLPattern list> (None:None) 'api_test/apirequesthistory/'>], [<URLResolver <URLPattern list> (admin:admin) 'admin/'>, <URLResolver <URLPattern list> (None:None) 'api_test/apioperationhistory/'>], [<URLResolver <URLPattern list> (admin:admin) 'admin/'>, <URLResolver <URLPattern list> (None:None) 'api_test/automationgrouplevelfirst/'>], [<URLResolver <URLPattern list> (admin:admin) 'admin/'>, <URLResolver <URLPattern list> (None:None) 'api_test/automationtestcase/'>], [<URLResolver <URLPattern list> (admin:admin) 'admin/'>, <URLResolver <URLPattern list> (None:None) 'api_test/automationcaseapi/'>], [<URLResolver <URLPattern list> (admin:admin) 'admin/'>, <URLResolver <URLPattern list> (None:None) 'api_test/automationtestresult/'>], [<URLResolver <URLPattern list> (admin:admin) 'admin/'>, <URLResolver <URLPattern list> (None:None) 'api_test/automationtesttask/'>], [<URLResolver <URLPattern list> (admin:admin) 'admin/'>, <URLPattern '^(?P<app_label>auth|api_test)/$' [name='app_list']>], [<URLResolver <module 'api_test.urls' from 'H:\\project\\api_automation_test\\api_test\\urls.py'> (None:None) '^api/'>]], 'path': 'admin/api_test/apihead/'}

During handling of the above exception, another exception occurred:

Traceback (most recent call last):
  File "F:\工具安装\python3.6.3\lib\site-packages\django\template\base.py", line 835, in _resolve_lookup
    current = current[bit]
TypeError: 'URLResolver' object is not subscriptable

During handling of the above exception, another exception occurred:

Traceback (most recent call last):
  File "F:\工具安装\python3.6.3\lib\site-packages\django\template\base.py", line 843, in _resolve_lookup
    current = getattr(current, bit)
AttributeError: 'URLResolver' object has no attribute 'name'

During handling of the above exception, another exception occurred:

Traceback (most recent call last):
  File "F:\工具安装\python3.6.3\lib\site-packages\django\template\base.py", line 849, in _resolve_lookup
    current = current[int(bit)]
ValueError: invalid literal for int() with base 10: 'name'

During handling of the above exception, another exception occurred:

Traceback (most recent call last):
  File "F:\工具安装\python3.6.3\lib\site-packages\django\template\base.py", line 856, in _resolve_lookup
    (bit, current))  # missing attribute
django.template.base.VariableDoesNotExist: Failed lookup for key [name] in <URLResolver <URLPattern list> (None:None) 'api_test/project/'>
DEBUG 2018-01-31 15:51:18,275 F:\工具安装\python3.6.3\lib\site-packages\django\template\base.py base.py base _resolve_lookup 878: Exception while resolving variable 'name' in template 'unknown'.
Traceback (most recent call last):
  File "F:\工具安装\python3.6.3\lib\site-packages\django\core\handlers\exception.py", line 35, in inner
    response = get_response(request)
  File "F:\工具安装\python3.6.3\lib\site-packages\django\core\handlers\base.py", line 113, in _get_response
    resolver_match = resolver.resolve(request.path_info)
  File "F:\工具安装\python3.6.3\lib\site-packages\django\urls\resolvers.py", line 523, in resolve
    raise Resolver404({'tried': tried, 'path': new_path})
django.urls.exceptions.Resolver404: {'tried': [[<URLResolver <URLPattern list> (admin:admin) 'admin/'>, <URLPattern '' [name='index']>], [<URLResolver <URLPattern list> (admin:admin) 'admin/'>, <URLPattern 'login/' [name='login']>], [<URLResolver <URLPattern list> (admin:admin) 'admin/'>, <URLPattern 'logout/' [name='logout']>], [<URLResolver <URLPattern list> (admin:admin) 'admin/'>, <URLPattern 'password_change/' [name='password_change']>], [<URLResolver <URLPattern list> (admin:admin) 'admin/'>, <URLPattern 'password_change/done/' [name='password_change_done']>], [<URLResolver <URLPattern list> (admin:admin) 'admin/'>, <URLPattern 'jsi18n/' [name='jsi18n']>], [<URLResolver <URLPattern list> (admin:admin) 'admin/'>, <URLPattern 'r/<int:content_type_id>/<path:object_id>/' [name='view_on_site']>], [<URLResolver <URLPattern list> (admin:admin) 'admin/'>, <URLResolver <URLPattern list> (None:None) 'auth/group/'>], [<URLResolver <URLPattern list> (admin:admin) 'admin/'>, <URLResolver <URLPattern list> (None:None) 'auth/user/'>], [<URLResolver <URLPattern list> (admin:admin) 'admin/'>, <URLResolver <URLPattern list> (None:None) 'api_test/project/'>], [<URLResolver <URLPattern list> (admin:admin) 'admin/'>, <URLResolver <URLPattern list> (None:None) 'api_test/projectdynamic/'>], [<URLResolver <URLPattern list> (admin:admin) 'admin/'>, <URLResolver <URLPattern list> (None:None) 'api_test/projectmember/'>], [<URLResolver <URLPattern list> (admin:admin) 'admin/'>, <URLResolver <URLPattern list> (None:None) 'api_test/globalhost/'>], [<URLResolver <URLPattern list> (admin:admin) 'admin/'>, <URLResolver <URLPattern list> (None:None) 'api_test/custommethod/'>], [<URLResolver <URLPattern list> (admin:admin) 'admin/'>, <URLResolver <URLPattern list> (None:None) 'api_test/apigrouplevelfirst/'>], [<URLResolver <URLPattern list> (admin:admin) 'admin/'>, <URLResolver <URLPattern list> (None:None) 'api_test/apiinfo/'>], [<URLResolver <URLPattern list> (admin:admin) 'admin/'>, <URLResolver <URLPattern list> (None:None) 'api_test/apirequesthistory/'>], [<URLResolver <URLPattern list> (admin:admin) 'admin/'>, <URLResolver <URLPattern list> (None:None) 'api_test/apioperationhistory/'>], [<URLResolver <URLPattern list> (admin:admin) 'admin/'>, <URLResolver <URLPattern list> (None:None) 'api_test/automationgrouplevelfirst/'>], [<URLResolver <URLPattern list> (admin:admin) 'admin/'>, <URLResolver <URLPattern list> (None:None) 'api_test/automationtestcase/'>], [<URLResolver <URLPattern list> (admin:admin) 'admin/'>, <URLResolver <URLPattern list> (None:None) 'api_test/automationcaseapi/'>], [<URLResolver <URLPattern list> (admin:admin) 'admin/'>, <URLResolver <URLPattern list> (None:None) 'api_test/automationtestresult/'>], [<URLResolver <URLPattern list> (admin:admin) 'admin/'>, <URLResolver <URLPattern list> (None:None) 'api_test/automationtesttask/'>], [<URLResolver <URLPattern list> (admin:admin) 'admin/'>, <URLPattern '^(?P<app_label>auth|api_test)/$' [name='app_list']>], [<URLResolver <module 'api_test.urls' from 'H:\\project\\api_automation_test\\api_test\\urls.py'> (None:None) '^api/'>]], 'path': 'admin/api_test/apihead/'}

During handling of the above exception, another exception occurred:

Traceback (most recent call last):
  File "F:\工具安装\python3.6.3\lib\site-packages\django\template\base.py", line 835, in _resolve_lookup
    current = current[bit]
TypeError: 'URLResolver' object is not subscriptable

During handling of the above exception, another exception occurred:

Traceback (most recent call last):
  File "F:\工具安装\python3.6.3\lib\site-packages\django\template\base.py", line 843, in _resolve_lookup
    current = getattr(current, bit)
AttributeError: 'URLResolver' object has no attribute 'name'

During handling of the above exception, another exception occurred:

Traceback (most recent call last):
  File "F:\工具安装\python3.6.3\lib\site-packages\django\template\base.py", line 849, in _resolve_lookup
    current = current[int(bit)]
ValueError: invalid literal for int() with base 10: 'name'

During handling of the above exception, another exception occurred:

Traceback (most recent call last):
  File "F:\工具安装\python3.6.3\lib\site-packages\django\template\base.py", line 856, in _resolve_lookup
    (bit, current))  # missing attribute
django.template.base.VariableDoesNotExist: Failed lookup for key [name] in <URLResolver <URLPattern list> (None:None) 'api_test/projectdynamic/'>
DEBUG 2018-01-31 15:51:18,276 F:\工具安装\python3.6.3\lib\site-packages\django\template\base.py base.py base _resolve_lookup 878: Exception while resolving variable 'name' in template 'unknown'.
Traceback (most recent call last):
  File "F:\工具安装\python3.6.3\lib\site-packages\django\core\handlers\exception.py", line 35, in inner
    response = get_response(request)
  File "F:\工具安装\python3.6.3\lib\site-packages\django\core\handlers\base.py", line 113, in _get_response
    resolver_match = resolver.resolve(request.path_info)
  File "F:\工具安装\python3.6.3\lib\site-packages\django\urls\resolvers.py", line 523, in resolve
    raise Resolver404({'tried': tried, 'path': new_path})
django.urls.exceptions.Resolver404: {'tried': [[<URLResolver <URLPattern list> (admin:admin) 'admin/'>, <URLPattern '' [name='index']>], [<URLResolver <URLPattern list> (admin:admin) 'admin/'>, <URLPattern 'login/' [name='login']>], [<URLResolver <URLPattern list> (admin:admin) 'admin/'>, <URLPattern 'logout/' [name='logout']>], [<URLResolver <URLPattern list> (admin:admin) 'admin/'>, <URLPattern 'password_change/' [name='password_change']>], [<URLResolver <URLPattern list> (admin:admin) 'admin/'>, <URLPattern 'password_change/done/' [name='password_change_done']>], [<URLResolver <URLPattern list> (admin:admin) 'admin/'>, <URLPattern 'jsi18n/' [name='jsi18n']>], [<URLResolver <URLPattern list> (admin:admin) 'admin/'>, <URLPattern 'r/<int:content_type_id>/<path:object_id>/' [name='view_on_site']>], [<URLResolver <URLPattern list> (admin:admin) 'admin/'>, <URLResolver <URLPattern list> (None:None) 'auth/group/'>], [<URLResolver <URLPattern list> (admin:admin) 'admin/'>, <URLResolver <URLPattern list> (None:None) 'auth/user/'>], [<URLResolver <URLPattern list> (admin:admin) 'admin/'>, <URLResolver <URLPattern list> (None:None) 'api_test/project/'>], [<URLResolver <URLPattern list> (admin:admin) 'admin/'>, <URLResolver <URLPattern list> (None:None) 'api_test/projectdynamic/'>], [<URLResolver <URLPattern list> (admin:admin) 'admin/'>, <URLResolver <URLPattern list> (None:None) 'api_test/projectmember/'>], [<URLResolver <URLPattern list> (admin:admin) 'admin/'>, <URLResolver <URLPattern list> (None:None) 'api_test/globalhost/'>], [<URLResolver <URLPattern list> (admin:admin) 'admin/'>, <URLResolver <URLPattern list> (None:None) 'api_test/custommethod/'>], [<URLResolver <URLPattern list> (admin:admin) 'admin/'>, <URLResolver <URLPattern list> (None:None) 'api_test/apigrouplevelfirst/'>], [<URLResolver <URLPattern list> (admin:admin) 'admin/'>, <URLResolver <URLPattern list> (None:None) 'api_test/apiinfo/'>], [<URLResolver <URLPattern list> (admin:admin) 'admin/'>, <URLResolver <URLPattern list> (None:None) 'api_test/apirequesthistory/'>], [<URLResolver <URLPattern list> (admin:admin) 'admin/'>, <URLResolver <URLPattern list> (None:None) 'api_test/apioperationhistory/'>], [<URLResolver <URLPattern list> (admin:admin) 'admin/'>, <URLResolver <URLPattern list> (None:None) 'api_test/automationgrouplevelfirst/'>], [<URLResolver <URLPattern list> (admin:admin) 'admin/'>, <URLResolver <URLPattern list> (None:None) 'api_test/automationtestcase/'>], [<URLResolver <URLPattern list> (admin:admin) 'admin/'>, <URLResolver <URLPattern list> (None:None) 'api_test/automationcaseapi/'>], [<URLResolver <URLPattern list> (admin:admin) 'admin/'>, <URLResolver <URLPattern list> (None:None) 'api_test/automationtestresult/'>], [<URLResolver <URLPattern list> (admin:admin) 'admin/'>, <URLResolver <URLPattern list> (None:None) 'api_test/automationtesttask/'>], [<URLResolver <URLPattern list> (admin:admin) 'admin/'>, <URLPattern '^(?P<app_label>auth|api_test)/$' [name='app_list']>], [<URLResolver <module 'api_test.urls' from 'H:\\project\\api_automation_test\\api_test\\urls.py'> (None:None) '^api/'>]], 'path': 'admin/api_test/apihead/'}

During handling of the above exception, another exception occurred:

Traceback (most recent call last):
  File "F:\工具安装\python3.6.3\lib\site-packages\django\template\base.py", line 835, in _resolve_lookup
    current = current[bit]
TypeError: 'URLResolver' object is not subscriptable

During handling of the above exception, another exception occurred:

Traceback (most recent call last):
  File "F:\工具安装\python3.6.3\lib\site-packages\django\template\base.py", line 843, in _resolve_lookup
    current = getattr(current, bit)
AttributeError: 'URLResolver' object has no attribute 'name'

During handling of the above exception, another exception occurred:

Traceback (most recent call last):
  File "F:\工具安装\python3.6.3\lib\site-packages\django\template\base.py", line 849, in _resolve_lookup
    current = current[int(bit)]
ValueError: invalid literal for int() with base 10: 'name'

During handling of the above exception, another exception occurred:

Traceback (most recent call last):
  File "F:\工具安装\python3.6.3\lib\site-packages\django\template\base.py", line 856, in _resolve_lookup
    (bit, current))  # missing attribute
django.template.base.VariableDoesNotExist: Failed lookup for key [name] in <URLResolver <URLPattern list> (None:None) 'api_test/projectmember/'>
DEBUG 2018-01-31 15:51:18,276 F:\工具安装\python3.6.3\lib\site-packages\django\template\base.py base.py base _resolve_lookup 878: Exception while resolving variable 'name' in template 'unknown'.
Traceback (most recent call last):
  File "F:\工具安装\python3.6.3\lib\site-packages\django\core\handlers\exception.py", line 35, in inner
    response = get_response(request)
  File "F:\工具安装\python3.6.3\lib\site-packages\django\core\handlers\base.py", line 113, in _get_response
    resolver_match = resolver.resolve(request.path_info)
  File "F:\工具安装\python3.6.3\lib\site-packages\django\urls\resolvers.py", line 523, in resolve
    raise Resolver404({'tried': tried, 'path': new_path})
django.urls.exceptions.Resolver404: {'tried': [[<URLResolver <URLPattern list> (admin:admin) 'admin/'>, <URLPattern '' [name='index']>], [<URLResolver <URLPattern list> (admin:admin) 'admin/'>, <URLPattern 'login/' [name='login']>], [<URLResolver <URLPattern list> (admin:admin) 'admin/'>, <URLPattern 'logout/' [name='logout']>], [<URLResolver <URLPattern list> (admin:admin) 'admin/'>, <URLPattern 'password_change/' [name='password_change']>], [<URLResolver <URLPattern list> (admin:admin) 'admin/'>, <URLPattern 'password_change/done/' [name='password_change_done']>], [<URLResolver <URLPattern list> (admin:admin) 'admin/'>, <URLPattern 'jsi18n/' [name='jsi18n']>], [<URLResolver <URLPattern list> (admin:admin) 'admin/'>, <URLPattern 'r/<int:content_type_id>/<path:object_id>/' [name='view_on_site']>], [<URLResolver <URLPattern list> (admin:admin) 'admin/'>, <URLResolver <URLPattern list> (None:None) 'auth/group/'>], [<URLResolver <URLPattern list> (admin:admin) 'admin/'>, <URLResolver <URLPattern list> (None:None) 'auth/user/'>], [<URLResolver <URLPattern list> (admin:admin) 'admin/'>, <URLResolver <URLPattern list> (None:None) 'api_test/project/'>], [<URLResolver <URLPattern list> (admin:admin) 'admin/'>, <URLResolver <URLPattern list> (None:None) 'api_test/projectdynamic/'>], [<URLResolver <URLPattern list> (admin:admin) 'admin/'>, <URLResolver <URLPattern list> (None:None) 'api_test/projectmember/'>], [<URLResolver <URLPattern list> (admin:admin) 'admin/'>, <URLResolver <URLPattern list> (None:None) 'api_test/globalhost/'>], [<URLResolver <URLPattern list> (admin:admin) 'admin/'>, <URLResolver <URLPattern list> (None:None) 'api_test/custommethod/'>], [<URLResolver <URLPattern list> (admin:admin) 'admin/'>, <URLResolver <URLPattern list> (None:None) 'api_test/apigrouplevelfirst/'>], [<URLResolver <URLPattern list> (admin:admin) 'admin/'>, <URLResolver <URLPattern list> (None:None) 'api_test/apiinfo/'>], [<URLResolver <URLPattern list> (admin:admin) 'admin/'>, <URLResolver <URLPattern list> (None:None) 'api_test/apirequesthistory/'>], [<URLResolver <URLPattern list> (admin:admin) 'admin/'>, <URLResolver <URLPattern list> (None:None) 'api_test/apioperationhistory/'>], [<URLResolver <URLPattern list> (admin:admin) 'admin/'>, <URLResolver <URLPattern list> (None:None) 'api_test/automationgrouplevelfirst/'>], [<URLResolver <URLPattern list> (admin:admin) 'admin/'>, <URLResolver <URLPattern list> (None:None) 'api_test/automationtestcase/'>], [<URLResolver <URLPattern list> (admin:admin) 'admin/'>, <URLResolver <URLPattern list> (None:None) 'api_test/automationcaseapi/'>], [<URLResolver <URLPattern list> (admin:admin) 'admin/'>, <URLResolver <URLPattern list> (None:None) 'api_test/automationtestresult/'>], [<URLResolver <URLPattern list> (admin:admin) 'admin/'>, <URLResolver <URLPattern list> (None:None) 'api_test/automationtesttask/'>], [<URLResolver <URLPattern list> (admin:admin) 'admin/'>, <URLPattern '^(?P<app_label>auth|api_test)/$' [name='app_list']>], [<URLResolver <module 'api_test.urls' from 'H:\\project\\api_automation_test\\api_test\\urls.py'> (None:None) '^api/'>]], 'path': 'admin/api_test/apihead/'}

During handling of the above exception, another exception occurred:

Traceback (most recent call last):
  File "F:\工具安装\python3.6.3\lib\site-packages\django\template\base.py", line 835, in _resolve_lookup
    current = current[bit]
TypeError: 'URLResolver' object is not subscriptable

During handling of the above exception, another exception occurred:

Traceback (most recent call last):
  File "F:\工具安装\python3.6.3\lib\site-packages\django\template\base.py", line 843, in _resolve_lookup
    current = getattr(current, bit)
AttributeError: 'URLResolver' object has no attribute 'name'

During handling of the above exception, another exception occurred:

Traceback (most recent call last):
  File "F:\工具安装\python3.6.3\lib\site-packages\django\template\base.py", line 849, in _resolve_lookup
    current = current[int(bit)]
ValueError: invalid literal for int() with base 10: 'name'

During handling of the above exception, another exception occurred:

Traceback (most recent call last):
  File "F:\工具安装\python3.6.3\lib\site-packages\django\template\base.py", line 856, in _resolve_lookup
    (bit, current))  # missing attribute
django.template.base.VariableDoesNotExist: Failed lookup for key [name] in <URLResolver <URLPattern list> (None:None) 'api_test/globalhost/'>
DEBUG 2018-01-31 15:51:18,277 F:\工具安装\python3.6.3\lib\site-packages\django\template\base.py base.py base _resolve_lookup 878: Exception while resolving variable 'name' in template 'unknown'.
Traceback (most recent call last):
  File "F:\工具安装\python3.6.3\lib\site-packages\django\core\handlers\exception.py", line 35, in inner
    response = get_response(request)
  File "F:\工具安装\python3.6.3\lib\site-packages\django\core\handlers\base.py", line 113, in _get_response
    resolver_match = resolver.resolve(request.path_info)
  File "F:\工具安装\python3.6.3\lib\site-packages\django\urls\resolvers.py", line 523, in resolve
    raise Resolver404({'tried': tried, 'path': new_path})
django.urls.exceptions.Resolver404: {'tried': [[<URLResolver <URLPattern list> (admin:admin) 'admin/'>, <URLPattern '' [name='index']>], [<URLResolver <URLPattern list> (admin:admin) 'admin/'>, <URLPattern 'login/' [name='login']>], [<URLResolver <URLPattern list> (admin:admin) 'admin/'>, <URLPattern 'logout/' [name='logout']>], [<URLResolver <URLPattern list> (admin:admin) 'admin/'>, <URLPattern 'password_change/' [name='password_change']>], [<URLResolver <URLPattern list> (admin:admin) 'admin/'>, <URLPattern 'password_change/done/' [name='password_change_done']>], [<URLResolver <URLPattern list> (admin:admin) 'admin/'>, <URLPattern 'jsi18n/' [name='jsi18n']>], [<URLResolver <URLPattern list> (admin:admin) 'admin/'>, <URLPattern 'r/<int:content_type_id>/<path:object_id>/' [name='view_on_site']>], [<URLResolver <URLPattern list> (admin:admin) 'admin/'>, <URLResolver <URLPattern list> (None:None) 'auth/group/'>], [<URLResolver <URLPattern list> (admin:admin) 'admin/'>, <URLResolver <URLPattern list> (None:None) 'auth/user/'>], [<URLResolver <URLPattern list> (admin:admin) 'admin/'>, <URLResolver <URLPattern list> (None:None) 'api_test/project/'>], [<URLResolver <URLPattern list> (admin:admin) 'admin/'>, <URLResolver <URLPattern list> (None:None) 'api_test/projectdynamic/'>], [<URLResolver <URLPattern list> (admin:admin) 'admin/'>, <URLResolver <URLPattern list> (None:None) 'api_test/projectmember/'>], [<URLResolver <URLPattern list> (admin:admin) 'admin/'>, <URLResolver <URLPattern list> (None:None) 'api_test/globalhost/'>], [<URLResolver <URLPattern list> (admin:admin) 'admin/'>, <URLResolver <URLPattern list> (None:None) 'api_test/custommethod/'>], [<URLResolver <URLPattern list> (admin:admin) 'admin/'>, <URLResolver <URLPattern list> (None:None) 'api_test/apigrouplevelfirst/'>], [<URLResolver <URLPattern list> (admin:admin) 'admin/'>, <URLResolver <URLPattern list> (None:None) 'api_test/apiinfo/'>], [<URLResolver <URLPattern list> (admin:admin) 'admin/'>, <URLResolver <URLPattern list> (None:None) 'api_test/apirequesthistory/'>], [<URLResolver <URLPattern list> (admin:admin) 'admin/'>, <URLResolver <URLPattern list> (None:None) 'api_test/apioperationhistory/'>], [<URLResolver <URLPattern list> (admin:admin) 'admin/'>, <URLResolver <URLPattern list> (None:None) 'api_test/automationgrouplevelfirst/'>], [<URLResolver <URLPattern list> (admin:admin) 'admin/'>, <URLResolver <URLPattern list> (None:None) 'api_test/automationtestcase/'>], [<URLResolver <URLPattern list> (admin:admin) 'admin/'>, <URLResolver <URLPattern list> (None:None) 'api_test/automationcaseapi/'>], [<URLResolver <URLPattern list> (admin:admin) 'admin/'>, <URLResolver <URLPattern list> (None:None) 'api_test/automationtestresult/'>], [<URLResolver <URLPattern list> (admin:admin) 'admin/'>, <URLResolver <URLPattern list> (None:None) 'api_test/automationtesttask/'>], [<URLResolver <URLPattern list> (admin:admin) 'admin/'>, <URLPattern '^(?P<app_label>auth|api_test)/$' [name='app_list']>], [<URLResolver <module 'api_test.urls' from 'H:\\project\\api_automation_test\\api_test\\urls.py'> (None:None) '^api/'>]], 'path': 'admin/api_test/apihead/'}

During handling of the above exception, another exception occurred:

Traceback (most recent call last):
  File "F:\工具安装\python3.6.3\lib\site-packages\django\template\base.py", line 835, in _resolve_lookup
    current = current[bit]
TypeError: 'URLResolver' object is not subscriptable

During handling of the above exception, another exception occurred:

Traceback (most recent call last):
  File "F:\工具安装\python3.6.3\lib\site-packages\django\template\base.py", line 843, in _resolve_lookup
    current = getattr(current, bit)
AttributeError: 'URLResolver' object has no attribute 'name'

During handling of the above exception, another exception occurred:

Traceback (most recent call last):
  File "F:\工具安装\python3.6.3\lib\site-packages\django\template\base.py", line 849, in _resolve_lookup
    current = current[int(bit)]
ValueError: invalid literal for int() with base 10: 'name'

During handling of the above exception, another exception occurred:

Traceback (most recent call last):
  File "F:\工具安装\python3.6.3\lib\site-packages\django\template\base.py", line 856, in _resolve_lookup
    (bit, current))  # missing attribute
django.template.base.VariableDoesNotExist: Failed lookup for key [name] in <URLResolver <URLPattern list> (None:None) 'api_test/custommethod/'>
DEBUG 2018-01-31 15:51:18,278 F:\工具安装\python3.6.3\lib\site-packages\django\template\base.py base.py base _resolve_lookup 878: Exception while resolving variable 'name' in template 'unknown'.
Traceback (most recent call last):
  File "F:\工具安装\python3.6.3\lib\site-packages\django\core\handlers\exception.py", line 35, in inner
    response = get_response(request)
  File "F:\工具安装\python3.6.3\lib\site-packages\django\core\handlers\base.py", line 113, in _get_response
    resolver_match = resolver.resolve(request.path_info)
  File "F:\工具安装\python3.6.3\lib\site-packages\django\urls\resolvers.py", line 523, in resolve
    raise Resolver404({'tried': tried, 'path': new_path})
django.urls.exceptions.Resolver404: {'tried': [[<URLResolver <URLPattern list> (admin:admin) 'admin/'>, <URLPattern '' [name='index']>], [<URLResolver <URLPattern list> (admin:admin) 'admin/'>, <URLPattern 'login/' [name='login']>], [<URLResolver <URLPattern list> (admin:admin) 'admin/'>, <URLPattern 'logout/' [name='logout']>], [<URLResolver <URLPattern list> (admin:admin) 'admin/'>, <URLPattern 'password_change/' [name='password_change']>], [<URLResolver <URLPattern list> (admin:admin) 'admin/'>, <URLPattern 'password_change/done/' [name='password_change_done']>], [<URLResolver <URLPattern list> (admin:admin) 'admin/'>, <URLPattern 'jsi18n/' [name='jsi18n']>], [<URLResolver <URLPattern list> (admin:admin) 'admin/'>, <URLPattern 'r/<int:content_type_id>/<path:object_id>/' [name='view_on_site']>], [<URLResolver <URLPattern list> (admin:admin) 'admin/'>, <URLResolver <URLPattern list> (None:None) 'auth/group/'>], [<URLResolver <URLPattern list> (admin:admin) 'admin/'>, <URLResolver <URLPattern list> (None:None) 'auth/user/'>], [<URLResolver <URLPattern list> (admin:admin) 'admin/'>, <URLResolver <URLPattern list> (None:None) 'api_test/project/'>], [<URLResolver <URLPattern list> (admin:admin) 'admin/'>, <URLResolver <URLPattern list> (None:None) 'api_test/projectdynamic/'>], [<URLResolver <URLPattern list> (admin:admin) 'admin/'>, <URLResolver <URLPattern list> (None:None) 'api_test/projectmember/'>], [<URLResolver <URLPattern list> (admin:admin) 'admin/'>, <URLResolver <URLPattern list> (None:None) 'api_test/globalhost/'>], [<URLResolver <URLPattern list> (admin:admin) 'admin/'>, <URLResolver <URLPattern list> (None:None) 'api_test/custommethod/'>], [<URLResolver <URLPattern list> (admin:admin) 'admin/'>, <URLResolver <URLPattern list> (None:None) 'api_test/apigrouplevelfirst/'>], [<URLResolver <URLPattern list> (admin:admin) 'admin/'>, <URLResolver <URLPattern list> (None:None) 'api_test/apiinfo/'>], [<URLResolver <URLPattern list> (admin:admin) 'admin/'>, <URLResolver <URLPattern list> (None:None) 'api_test/apirequesthistory/'>], [<URLResolver <URLPattern list> (admin:admin) 'admin/'>, <URLResolver <URLPattern list> (None:None) 'api_test/apioperationhistory/'>], [<URLResolver <URLPattern list> (admin:admin) 'admin/'>, <URLResolver <URLPattern list> (None:None) 'api_test/automationgrouplevelfirst/'>], [<URLResolver <URLPattern list> (admin:admin) 'admin/'>, <URLResolver <URLPattern list> (None:None) 'api_test/automationtestcase/'>], [<URLResolver <URLPattern list> (admin:admin) 'admin/'>, <URLResolver <URLPattern list> (None:None) 'api_test/automationcaseapi/'>], [<URLResolver <URLPattern list> (admin:admin) 'admin/'>, <URLResolver <URLPattern list> (None:None) 'api_test/automationtestresult/'>], [<URLResolver <URLPattern list> (admin:admin) 'admin/'>, <URLResolver <URLPattern list> (None:None) 'api_test/automationtesttask/'>], [<URLResolver <URLPattern list> (admin:admin) 'admin/'>, <URLPattern '^(?P<app_label>auth|api_test)/$' [name='app_list']>], [<URLResolver <module 'api_test.urls' from 'H:\\project\\api_automation_test\\api_test\\urls.py'> (None:None) '^api/'>]], 'path': 'admin/api_test/apihead/'}

During handling of the above exception, another exception occurred:

Traceback (most recent call last):
  File "F:\工具安装\python3.6.3\lib\site-packages\django\template\base.py", line 835, in _resolve_lookup
    current = current[bit]
TypeError: 'URLResolver' object is not subscriptable

During handling of the above exception, another exception occurred:

Traceback (most recent call last):
  File "F:\工具安装\python3.6.3\lib\site-packages\django\template\base.py", line 843, in _resolve_lookup
    current = getattr(current, bit)
AttributeError: 'URLResolver' object has no attribute 'name'

During handling of the above exception, another exception occurred:

Traceback (most recent call last):
  File "F:\工具安装\python3.6.3\lib\site-packages\django\template\base.py", line 849, in _resolve_lookup
    current = current[int(bit)]
ValueError: invalid literal for int() with base 10: 'name'

During handling of the above exception, another exception occurred:

Traceback (most recent call last):
  File "F:\工具安装\python3.6.3\lib\site-packages\django\template\base.py", line 856, in _resolve_lookup
    (bit, current))  # missing attribute
django.template.base.VariableDoesNotExist: Failed lookup for key [name] in <URLResolver <URLPattern list> (None:None) 'api_test/apigrouplevelfirst/'>
DEBUG 2018-01-31 15:51:18,279 F:\工具安装\python3.6.3\lib\site-packages\django\template\base.py base.py base _resolve_lookup 878: Exception while resolving variable 'name' in template 'unknown'.
Traceback (most recent call last):
  File "F:\工具安装\python3.6.3\lib\site-packages\django\core\handlers\exception.py", line 35, in inner
    response = get_response(request)
  File "F:\工具安装\python3.6.3\lib\site-packages\django\core\handlers\base.py", line 113, in _get_response
    resolver_match = resolver.resolve(request.path_info)
  File "F:\工具安装\python3.6.3\lib\site-packages\django\urls\resolvers.py", line 523, in resolve
    raise Resolver404({'tried': tried, 'path': new_path})
django.urls.exceptions.Resolver404: {'tried': [[<URLResolver <URLPattern list> (admin:admin) 'admin/'>, <URLPattern '' [name='index']>], [<URLResolver <URLPattern list> (admin:admin) 'admin/'>, <URLPattern 'login/' [name='login']>], [<URLResolver <URLPattern list> (admin:admin) 'admin/'>, <URLPattern 'logout/' [name='logout']>], [<URLResolver <URLPattern list> (admin:admin) 'admin/'>, <URLPattern 'password_change/' [name='password_change']>], [<URLResolver <URLPattern list> (admin:admin) 'admin/'>, <URLPattern 'password_change/done/' [name='password_change_done']>], [<URLResolver <URLPattern list> (admin:admin) 'admin/'>, <URLPattern 'jsi18n/' [name='jsi18n']>], [<URLResolver <URLPattern list> (admin:admin) 'admin/'>, <URLPattern 'r/<int:content_type_id>/<path:object_id>/' [name='view_on_site']>], [<URLResolver <URLPattern list> (admin:admin) 'admin/'>, <URLResolver <URLPattern list> (None:None) 'auth/group/'>], [<URLResolver <URLPattern list> (admin:admin) 'admin/'>, <URLResolver <URLPattern list> (None:None) 'auth/user/'>], [<URLResolver <URLPattern list> (admin:admin) 'admin/'>, <URLResolver <URLPattern list> (None:None) 'api_test/project/'>], [<URLResolver <URLPattern list> (admin:admin) 'admin/'>, <URLResolver <URLPattern list> (None:None) 'api_test/projectdynamic/'>], [<URLResolver <URLPattern list> (admin:admin) 'admin/'>, <URLResolver <URLPattern list> (None:None) 'api_test/projectmember/'>], [<URLResolver <URLPattern list> (admin:admin) 'admin/'>, <URLResolver <URLPattern list> (None:None) 'api_test/globalhost/'>], [<URLResolver <URLPattern list> (admin:admin) 'admin/'>, <URLResolver <URLPattern list> (None:None) 'api_test/custommethod/'>], [<URLResolver <URLPattern list> (admin:admin) 'admin/'>, <URLResolver <URLPattern list> (None:None) 'api_test/apigrouplevelfirst/'>], [<URLResolver <URLPattern list> (admin:admin) 'admin/'>, <URLResolver <URLPattern list> (None:None) 'api_test/apiinfo/'>], [<URLResolver <URLPattern list> (admin:admin) 'admin/'>, <URLResolver <URLPattern list> (None:None) 'api_test/apirequesthistory/'>], [<URLResolver <URLPattern list> (admin:admin) 'admin/'>, <URLResolver <URLPattern list> (None:None) 'api_test/apioperationhistory/'>], [<URLResolver <URLPattern list> (admin:admin) 'admin/'>, <URLResolver <URLPattern list> (None:None) 'api_test/automationgrouplevelfirst/'>], [<URLResolver <URLPattern list> (admin:admin) 'admin/'>, <URLResolver <URLPattern list> (None:None) 'api_test/automationtestcase/'>], [<URLResolver <URLPattern list> (admin:admin) 'admin/'>, <URLResolver <URLPattern list> (None:None) 'api_test/automationcaseapi/'>], [<URLResolver <URLPattern list> (admin:admin) 'admin/'>, <URLResolver <URLPattern list> (None:None) 'api_test/automationtestresult/'>], [<URLResolver <URLPattern list> (admin:admin) 'admin/'>, <URLResolver <URLPattern list> (None:None) 'api_test/automationtesttask/'>], [<URLResolver <URLPattern list> (admin:admin) 'admin/'>, <URLPattern '^(?P<app_label>auth|api_test)/$' [name='app_list']>], [<URLResolver <module 'api_test.urls' from 'H:\\project\\api_automation_test\\api_test\\urls.py'> (None:None) '^api/'>]], 'path': 'admin/api_test/apihead/'}

During handling of the above exception, another exception occurred:

Traceback (most recent call last):
  File "F:\工具安装\python3.6.3\lib\site-packages\django\template\base.py", line 835, in _resolve_lookup
    current = current[bit]
TypeError: 'URLResolver' object is not subscriptable

During handling of the above exception, another exception occurred:

Traceback (most recent call last):
  File "F:\工具安装\python3.6.3\lib\site-packages\django\template\base.py", line 843, in _resolve_lookup
    current = getattr(current, bit)
AttributeError: 'URLResolver' object has no attribute 'name'

During handling of the above exception, another exception occurred:

Traceback (most recent call last):
  File "F:\工具安装\python3.6.3\lib\site-packages\django\template\base.py", line 849, in _resolve_lookup
    current = current[int(bit)]
ValueError: invalid literal for int() with base 10: 'name'

During handling of the above exception, another exception occurred:

Traceback (most recent call last):
  File "F:\工具安装\python3.6.3\lib\site-packages\django\template\base.py", line 856, in _resolve_lookup
    (bit, current))  # missing attribute
django.template.base.VariableDoesNotExist: Failed lookup for key [name] in <URLResolver <URLPattern list> (None:None) 'api_test/apiinfo/'>
DEBUG 2018-01-31 15:51:18,280 F:\工具安装\python3.6.3\lib\site-packages\django\template\base.py base.py base _resolve_lookup 878: Exception while resolving variable 'name' in template 'unknown'.
Traceback (most recent call last):
  File "F:\工具安装\python3.6.3\lib\site-packages\django\core\handlers\exception.py", line 35, in inner
    response = get_response(request)
  File "F:\工具安装\python3.6.3\lib\site-packages\django\core\handlers\base.py", line 113, in _get_response
    resolver_match = resolver.resolve(request.path_info)
  File "F:\工具安装\python3.6.3\lib\site-packages\django\urls\resolvers.py", line 523, in resolve
    raise Resolver404({'tried': tried, 'path': new_path})
django.urls.exceptions.Resolver404: {'tried': [[<URLResolver <URLPattern list> (admin:admin) 'admin/'>, <URLPattern '' [name='index']>], [<URLResolver <URLPattern list> (admin:admin) 'admin/'>, <URLPattern 'login/' [name='login']>], [<URLResolver <URLPattern list> (admin:admin) 'admin/'>, <URLPattern 'logout/' [name='logout']>], [<URLResolver <URLPattern list> (admin:admin) 'admin/'>, <URLPattern 'password_change/' [name='password_change']>], [<URLResolver <URLPattern list> (admin:admin) 'admin/'>, <URLPattern 'password_change/done/' [name='password_change_done']>], [<URLResolver <URLPattern list> (admin:admin) 'admin/'>, <URLPattern 'jsi18n/' [name='jsi18n']>], [<URLResolver <URLPattern list> (admin:admin) 'admin/'>, <URLPattern 'r/<int:content_type_id>/<path:object_id>/' [name='view_on_site']>], [<URLResolver <URLPattern list> (admin:admin) 'admin/'>, <URLResolver <URLPattern list> (None:None) 'auth/group/'>], [<URLResolver <URLPattern list> (admin:admin) 'admin/'>, <URLResolver <URLPattern list> (None:None) 'auth/user/'>], [<URLResolver <URLPattern list> (admin:admin) 'admin/'>, <URLResolver <URLPattern list> (None:None) 'api_test/project/'>], [<URLResolver <URLPattern list> (admin:admin) 'admin/'>, <URLResolver <URLPattern list> (None:None) 'api_test/projectdynamic/'>], [<URLResolver <URLPattern list> (admin:admin) 'admin/'>, <URLResolver <URLPattern list> (None:None) 'api_test/projectmember/'>], [<URLResolver <URLPattern list> (admin:admin) 'admin/'>, <URLResolver <URLPattern list> (None:None) 'api_test/globalhost/'>], [<URLResolver <URLPattern list> (admin:admin) 'admin/'>, <URLResolver <URLPattern list> (None:None) 'api_test/custommethod/'>], [<URLResolver <URLPattern list> (admin:admin) 'admin/'>, <URLResolver <URLPattern list> (None:None) 'api_test/apigrouplevelfirst/'>], [<URLResolver <URLPattern list> (admin:admin) 'admin/'>, <URLResolver <URLPattern list> (None:None) 'api_test/apiinfo/'>], [<URLResolver <URLPattern list> (admin:admin) 'admin/'>, <URLResolver <URLPattern list> (None:None) 'api_test/apirequesthistory/'>], [<URLResolver <URLPattern list> (admin:admin) 'admin/'>, <URLResolver <URLPattern list> (None:None) 'api_test/apioperationhistory/'>], [<URLResolver <URLPattern list> (admin:admin) 'admin/'>, <URLResolver <URLPattern list> (None:None) 'api_test/automationgrouplevelfirst/'>], [<URLResolver <URLPattern list> (admin:admin) 'admin/'>, <URLResolver <URLPattern list> (None:None) 'api_test/automationtestcase/'>], [<URLResolver <URLPattern list> (admin:admin) 'admin/'>, <URLResolver <URLPattern list> (None:None) 'api_test/automationcaseapi/'>], [<URLResolver <URLPattern list> (admin:admin) 'admin/'>, <URLResolver <URLPattern list> (None:None) 'api_test/automationtestresult/'>], [<URLResolver <URLPattern list> (admin:admin) 'admin/'>, <URLResolver <URLPattern list> (None:None) 'api_test/automationtesttask/'>], [<URLResolver <URLPattern list> (admin:admin) 'admin/'>, <URLPattern '^(?P<app_label>auth|api_test)/$' [name='app_list']>], [<URLResolver <module 'api_test.urls' from 'H:\\project\\api_automation_test\\api_test\\urls.py'> (None:None) '^api/'>]], 'path': 'admin/api_test/apihead/'}

During handling of the above exception, another exception occurred:

Traceback (most recent call last):
  File "F:\工具安装\python3.6.3\lib\site-packages\django\template\base.py", line 835, in _resolve_lookup
    current = current[bit]
TypeError: 'URLResolver' object is not subscriptable

During handling of the above exception, another exception occurred:

Traceback (most recent call last):
  File "F:\工具安装\python3.6.3\lib\site-packages\django\template\base.py", line 843, in _resolve_lookup
    current = getattr(current, bit)
AttributeError: 'URLResolver' object has no attribute 'name'

During handling of the above exception, another exception occurred:

Traceback (most recent call last):
  File "F:\工具安装\python3.6.3\lib\site-packages\django\template\base.py", line 849, in _resolve_lookup
    current = current[int(bit)]
ValueError: invalid literal for int() with base 10: 'name'

During handling of the above exception, another exception occurred:

Traceback (most recent call last):
  File "F:\工具安装\python3.6.3\lib\site-packages\django\template\base.py", line 856, in _resolve_lookup
    (bit, current))  # missing attribute
django.template.base.VariableDoesNotExist: Failed lookup for key [name] in <URLResolver <URLPattern list> (None:None) 'api_test/apirequesthistory/'>
DEBUG 2018-01-31 15:51:18,280 F:\工具安装\python3.6.3\lib\site-packages\django\template\base.py base.py base _resolve_lookup 878: Exception while resolving variable 'name' in template 'unknown'.
Traceback (most recent call last):
  File "F:\工具安装\python3.6.3\lib\site-packages\django\core\handlers\exception.py", line 35, in inner
    response = get_response(request)
  File "F:\工具安装\python3.6.3\lib\site-packages\django\core\handlers\base.py", line 113, in _get_response
    resolver_match = resolver.resolve(request.path_info)
  File "F:\工具安装\python3.6.3\lib\site-packages\django\urls\resolvers.py", line 523, in resolve
    raise Resolver404({'tried': tried, 'path': new_path})
django.urls.exceptions.Resolver404: {'tried': [[<URLResolver <URLPattern list> (admin:admin) 'admin/'>, <URLPattern '' [name='index']>], [<URLResolver <URLPattern list> (admin:admin) 'admin/'>, <URLPattern 'login/' [name='login']>], [<URLResolver <URLPattern list> (admin:admin) 'admin/'>, <URLPattern 'logout/' [name='logout']>], [<URLResolver <URLPattern list> (admin:admin) 'admin/'>, <URLPattern 'password_change/' [name='password_change']>], [<URLResolver <URLPattern list> (admin:admin) 'admin/'>, <URLPattern 'password_change/done/' [name='password_change_done']>], [<URLResolver <URLPattern list> (admin:admin) 'admin/'>, <URLPattern 'jsi18n/' [name='jsi18n']>], [<URLResolver <URLPattern list> (admin:admin) 'admin/'>, <URLPattern 'r/<int:content_type_id>/<path:object_id>/' [name='view_on_site']>], [<URLResolver <URLPattern list> (admin:admin) 'admin/'>, <URLResolver <URLPattern list> (None:None) 'auth/group/'>], [<URLResolver <URLPattern list> (admin:admin) 'admin/'>, <URLResolver <URLPattern list> (None:None) 'auth/user/'>], [<URLResolver <URLPattern list> (admin:admin) 'admin/'>, <URLResolver <URLPattern list> (None:None) 'api_test/project/'>], [<URLResolver <URLPattern list> (admin:admin) 'admin/'>, <URLResolver <URLPattern list> (None:None) 'api_test/projectdynamic/'>], [<URLResolver <URLPattern list> (admin:admin) 'admin/'>, <URLResolver <URLPattern list> (None:None) 'api_test/projectmember/'>], [<URLResolver <URLPattern list> (admin:admin) 'admin/'>, <URLResolver <URLPattern list> (None:None) 'api_test/globalhost/'>], [<URLResolver <URLPattern list> (admin:admin) 'admin/'>, <URLResolver <URLPattern list> (None:None) 'api_test/custommethod/'>], [<URLResolver <URLPattern list> (admin:admin) 'admin/'>, <URLResolver <URLPattern list> (None:None) 'api_test/apigrouplevelfirst/'>], [<URLResolver <URLPattern list> (admin:admin) 'admin/'>, <URLResolver <URLPattern list> (None:None) 'api_test/apiinfo/'>], [<URLResolver <URLPattern list> (admin:admin) 'admin/'>, <URLResolver <URLPattern list> (None:None) 'api_test/apirequesthistory/'>], [<URLResolver <URLPattern list> (admin:admin) 'admin/'>, <URLResolver <URLPattern list> (None:None) 'api_test/apioperationhistory/'>], [<URLResolver <URLPattern list> (admin:admin) 'admin/'>, <URLResolver <URLPattern list> (None:None) 'api_test/automationgrouplevelfirst/'>], [<URLResolver <URLPattern list> (admin:admin) 'admin/'>, <URLResolver <URLPattern list> (None:None) 'api_test/automationtestcase/'>], [<URLResolver <URLPattern list> (admin:admin) 'admin/'>, <URLResolver <URLPattern list> (None:None) 'api_test/automationcaseapi/'>], [<URLResolver <URLPattern list> (admin:admin) 'admin/'>, <URLResolver <URLPattern list> (None:None) 'api_test/automationtestresult/'>], [<URLResolver <URLPattern list> (admin:admin) 'admin/'>, <URLResolver <URLPattern list> (None:None) 'api_test/automationtesttask/'>], [<URLResolver <URLPattern list> (admin:admin) 'admin/'>, <URLPattern '^(?P<app_label>auth|api_test)/$' [name='app_list']>], [<URLResolver <module 'api_test.urls' from 'H:\\project\\api_automation_test\\api_test\\urls.py'> (None:None) '^api/'>]], 'path': 'admin/api_test/apihead/'}

During handling of the above exception, another exception occurred:

Traceback (most recent call last):
  File "F:\工具安装\python3.6.3\lib\site-packages\django\template\base.py", line 835, in _resolve_lookup
    current = current[bit]
TypeError: 'URLResolver' object is not subscriptable

During handling of the above exception, another exception occurred:

Traceback (most recent call last):
  File "F:\工具安装\python3.6.3\lib\site-packages\django\template\base.py", line 843, in _resolve_lookup
    current = getattr(current, bit)
AttributeError: 'URLResolver' object has no attribute 'name'

During handling of the above exception, another exception occurred:

Traceback (most recent call last):
  File "F:\工具安装\python3.6.3\lib\site-packages\django\template\base.py", line 849, in _resolve_lookup
    current = current[int(bit)]
ValueError: invalid literal for int() with base 10: 'name'

During handling of the above exception, another exception occurred:

Traceback (most recent call last):
  File "F:\工具安装\python3.6.3\lib\site-packages\django\template\base.py", line 856, in _resolve_lookup
    (bit, current))  # missing attribute
django.template.base.VariableDoesNotExist: Failed lookup for key [name] in <URLResolver <URLPattern list> (None:None) 'api_test/apioperationhistory/'>
DEBUG 2018-01-31 15:51:18,281 F:\工具安装\python3.6.3\lib\site-packages\django\template\base.py base.py base _resolve_lookup 878: Exception while resolving variable 'name' in template 'unknown'.
Traceback (most recent call last):
  File "F:\工具安装\python3.6.3\lib\site-packages\django\core\handlers\exception.py", line 35, in inner
    response = get_response(request)
  File "F:\工具安装\python3.6.3\lib\site-packages\django\core\handlers\base.py", line 113, in _get_response
    resolver_match = resolver.resolve(request.path_info)
  File "F:\工具安装\python3.6.3\lib\site-packages\django\urls\resolvers.py", line 523, in resolve
    raise Resolver404({'tried': tried, 'path': new_path})
django.urls.exceptions.Resolver404: {'tried': [[<URLResolver <URLPattern list> (admin:admin) 'admin/'>, <URLPattern '' [name='index']>], [<URLResolver <URLPattern list> (admin:admin) 'admin/'>, <URLPattern 'login/' [name='login']>], [<URLResolver <URLPattern list> (admin:admin) 'admin/'>, <URLPattern 'logout/' [name='logout']>], [<URLResolver <URLPattern list> (admin:admin) 'admin/'>, <URLPattern 'password_change/' [name='password_change']>], [<URLResolver <URLPattern list> (admin:admin) 'admin/'>, <URLPattern 'password_change/done/' [name='password_change_done']>], [<URLResolver <URLPattern list> (admin:admin) 'admin/'>, <URLPattern 'jsi18n/' [name='jsi18n']>], [<URLResolver <URLPattern list> (admin:admin) 'admin/'>, <URLPattern 'r/<int:content_type_id>/<path:object_id>/' [name='view_on_site']>], [<URLResolver <URLPattern list> (admin:admin) 'admin/'>, <URLResolver <URLPattern list> (None:None) 'auth/group/'>], [<URLResolver <URLPattern list> (admin:admin) 'admin/'>, <URLResolver <URLPattern list> (None:None) 'auth/user/'>], [<URLResolver <URLPattern list> (admin:admin) 'admin/'>, <URLResolver <URLPattern list> (None:None) 'api_test/project/'>], [<URLResolver <URLPattern list> (admin:admin) 'admin/'>, <URLResolver <URLPattern list> (None:None) 'api_test/projectdynamic/'>], [<URLResolver <URLPattern list> (admin:admin) 'admin/'>, <URLResolver <URLPattern list> (None:None) 'api_test/projectmember/'>], [<URLResolver <URLPattern list> (admin:admin) 'admin/'>, <URLResolver <URLPattern list> (None:None) 'api_test/globalhost/'>], [<URLResolver <URLPattern list> (admin:admin) 'admin/'>, <URLResolver <URLPattern list> (None:None) 'api_test/custommethod/'>], [<URLResolver <URLPattern list> (admin:admin) 'admin/'>, <URLResolver <URLPattern list> (None:None) 'api_test/apigrouplevelfirst/'>], [<URLResolver <URLPattern list> (admin:admin) 'admin/'>, <URLResolver <URLPattern list> (None:None) 'api_test/apiinfo/'>], [<URLResolver <URLPattern list> (admin:admin) 'admin/'>, <URLResolver <URLPattern list> (None:None) 'api_test/apirequesthistory/'>], [<URLResolver <URLPattern list> (admin:admin) 'admin/'>, <URLResolver <URLPattern list> (None:None) 'api_test/apioperationhistory/'>], [<URLResolver <URLPattern list> (admin:admin) 'admin/'>, <URLResolver <URLPattern list> (None:None) 'api_test/automationgrouplevelfirst/'>], [<URLResolver <URLPattern list> (admin:admin) 'admin/'>, <URLResolver <URLPattern list> (None:None) 'api_test/automationtestcase/'>], [<URLResolver <URLPattern list> (admin:admin) 'admin/'>, <URLResolver <URLPattern list> (None:None) 'api_test/automationcaseapi/'>], [<URLResolver <URLPattern list> (admin:admin) 'admin/'>, <URLResolver <URLPattern list> (None:None) 'api_test/automationtestresult/'>], [<URLResolver <URLPattern list> (admin:admin) 'admin/'>, <URLResolver <URLPattern list> (None:None) 'api_test/automationtesttask/'>], [<URLResolver <URLPattern list> (admin:admin) 'admin/'>, <URLPattern '^(?P<app_label>auth|api_test)/$' [name='app_list']>], [<URLResolver <module 'api_test.urls' from 'H:\\project\\api_automation_test\\api_test\\urls.py'> (None:None) '^api/'>]], 'path': 'admin/api_test/apihead/'}

During handling of the above exception, another exception occurred:

Traceback (most recent call last):
  File "F:\工具安装\python3.6.3\lib\site-packages\django\template\base.py", line 835, in _resolve_lookup
    current = current[bit]
TypeError: 'URLResolver' object is not subscriptable

During handling of the above exception, another exception occurred:

Traceback (most recent call last):
  File "F:\工具安装\python3.6.3\lib\site-packages\django\template\base.py", line 843, in _resolve_lookup
    current = getattr(current, bit)
AttributeError: 'URLResolver' object has no attribute 'name'

During handling of the above exception, another exception occurred:

Traceback (most recent call last):
  File "F:\工具安装\python3.6.3\lib\site-packages\django\template\base.py", line 849, in _resolve_lookup
    current = current[int(bit)]
ValueError: invalid literal for int() with base 10: 'name'

During handling of the above exception, another exception occurred:

Traceback (most recent call last):
  File "F:\工具安装\python3.6.3\lib\site-packages\django\template\base.py", line 856, in _resolve_lookup
    (bit, current))  # missing attribute
django.template.base.VariableDoesNotExist: Failed lookup for key [name] in <URLResolver <URLPattern list> (None:None) 'api_test/automationgrouplevelfirst/'>
DEBUG 2018-01-31 15:51:18,282 F:\工具安装\python3.6.3\lib\site-packages\django\template\base.py base.py base _resolve_lookup 878: Exception while resolving variable 'name' in template 'unknown'.
Traceback (most recent call last):
  File "F:\工具安装\python3.6.3\lib\site-packages\django\core\handlers\exception.py", line 35, in inner
    response = get_response(request)
  File "F:\工具安装\python3.6.3\lib\site-packages\django\core\handlers\base.py", line 113, in _get_response
    resolver_match = resolver.resolve(request.path_info)
  File "F:\工具安装\python3.6.3\lib\site-packages\django\urls\resolvers.py", line 523, in resolve
    raise Resolver404({'tried': tried, 'path': new_path})
django.urls.exceptions.Resolver404: {'tried': [[<URLResolver <URLPattern list> (admin:admin) 'admin/'>, <URLPattern '' [name='index']>], [<URLResolver <URLPattern list> (admin:admin) 'admin/'>, <URLPattern 'login/' [name='login']>], [<URLResolver <URLPattern list> (admin:admin) 'admin/'>, <URLPattern 'logout/' [name='logout']>], [<URLResolver <URLPattern list> (admin:admin) 'admin/'>, <URLPattern 'password_change/' [name='password_change']>], [<URLResolver <URLPattern list> (admin:admin) 'admin/'>, <URLPattern 'password_change/done/' [name='password_change_done']>], [<URLResolver <URLPattern list> (admin:admin) 'admin/'>, <URLPattern 'jsi18n/' [name='jsi18n']>], [<URLResolver <URLPattern list> (admin:admin) 'admin/'>, <URLPattern 'r/<int:content_type_id>/<path:object_id>/' [name='view_on_site']>], [<URLResolver <URLPattern list> (admin:admin) 'admin/'>, <URLResolver <URLPattern list> (None:None) 'auth/group/'>], [<URLResolver <URLPattern list> (admin:admin) 'admin/'>, <URLResolver <URLPattern list> (None:None) 'auth/user/'>], [<URLResolver <URLPattern list> (admin:admin) 'admin/'>, <URLResolver <URLPattern list> (None:None) 'api_test/project/'>], [<URLResolver <URLPattern list> (admin:admin) 'admin/'>, <URLResolver <URLPattern list> (None:None) 'api_test/projectdynamic/'>], [<URLResolver <URLPattern list> (admin:admin) 'admin/'>, <URLResolver <URLPattern list> (None:None) 'api_test/projectmember/'>], [<URLResolver <URLPattern list> (admin:admin) 'admin/'>, <URLResolver <URLPattern list> (None:None) 'api_test/globalhost/'>], [<URLResolver <URLPattern list> (admin:admin) 'admin/'>, <URLResolver <URLPattern list> (None:None) 'api_test/custommethod/'>], [<URLResolver <URLPattern list> (admin:admin) 'admin/'>, <URLResolver <URLPattern list> (None:None) 'api_test/apigrouplevelfirst/'>], [<URLResolver <URLPattern list> (admin:admin) 'admin/'>, <URLResolver <URLPattern list> (None:None) 'api_test/apiinfo/'>], [<URLResolver <URLPattern list> (admin:admin) 'admin/'>, <URLResolver <URLPattern list> (None:None) 'api_test/apirequesthistory/'>], [<URLResolver <URLPattern list> (admin:admin) 'admin/'>, <URLResolver <URLPattern list> (None:None) 'api_test/apioperationhistory/'>], [<URLResolver <URLPattern list> (admin:admin) 'admin/'>, <URLResolver <URLPattern list> (None:None) 'api_test/automationgrouplevelfirst/'>], [<URLResolver <URLPattern list> (admin:admin) 'admin/'>, <URLResolver <URLPattern list> (None:None) 'api_test/automationtestcase/'>], [<URLResolver <URLPattern list> (admin:admin) 'admin/'>, <URLResolver <URLPattern list> (None:None) 'api_test/automationcaseapi/'>], [<URLResolver <URLPattern list> (admin:admin) 'admin/'>, <URLResolver <URLPattern list> (None:None) 'api_test/automationtestresult/'>], [<URLResolver <URLPattern list> (admin:admin) 'admin/'>, <URLResolver <URLPattern list> (None:None) 'api_test/automationtesttask/'>], [<URLResolver <URLPattern list> (admin:admin) 'admin/'>, <URLPattern '^(?P<app_label>auth|api_test)/$' [name='app_list']>], [<URLResolver <module 'api_test.urls' from 'H:\\project\\api_automation_test\\api_test\\urls.py'> (None:None) '^api/'>]], 'path': 'admin/api_test/apihead/'}

During handling of the above exception, another exception occurred:

Traceback (most recent call last):
  File "F:\工具安装\python3.6.3\lib\site-packages\django\template\base.py", line 835, in _resolve_lookup
    current = current[bit]
TypeError: 'URLResolver' object is not subscriptable

During handling of the above exception, another exception occurred:

Traceback (most recent call last):
  File "F:\工具安装\python3.6.3\lib\site-packages\django\template\base.py", line 843, in _resolve_lookup
    current = getattr(current, bit)
AttributeError: 'URLResolver' object has no attribute 'name'

During handling of the above exception, another exception occurred:

Traceback (most recent call last):
  File "F:\工具安装\python3.6.3\lib\site-packages\django\template\base.py", line 849, in _resolve_lookup
    current = current[int(bit)]
ValueError: invalid literal for int() with base 10: 'name'

During handling of the above exception, another exception occurred:

Traceback (most recent call last):
  File "F:\工具安装\python3.6.3\lib\site-packages\django\template\base.py", line 856, in _resolve_lookup
    (bit, current))  # missing attribute
django.template.base.VariableDoesNotExist: Failed lookup for key [name] in <URLResolver <URLPattern list> (None:None) 'api_test/automationtestcase/'>
DEBUG 2018-01-31 15:51:18,282 F:\工具安装\python3.6.3\lib\site-packages\django\template\base.py base.py base _resolve_lookup 878: Exception while resolving variable 'name' in template 'unknown'.
Traceback (most recent call last):
  File "F:\工具安装\python3.6.3\lib\site-packages\django\core\handlers\exception.py", line 35, in inner
    response = get_response(request)
  File "F:\工具安装\python3.6.3\lib\site-packages\django\core\handlers\base.py", line 113, in _get_response
    resolver_match = resolver.resolve(request.path_info)
  File "F:\工具安装\python3.6.3\lib\site-packages\django\urls\resolvers.py", line 523, in resolve
    raise Resolver404({'tried': tried, 'path': new_path})
django.urls.exceptions.Resolver404: {'tried': [[<URLResolver <URLPattern list> (admin:admin) 'admin/'>, <URLPattern '' [name='index']>], [<URLResolver <URLPattern list> (admin:admin) 'admin/'>, <URLPattern 'login/' [name='login']>], [<URLResolver <URLPattern list> (admin:admin) 'admin/'>, <URLPattern 'logout/' [name='logout']>], [<URLResolver <URLPattern list> (admin:admin) 'admin/'>, <URLPattern 'password_change/' [name='password_change']>], [<URLResolver <URLPattern list> (admin:admin) 'admin/'>, <URLPattern 'password_change/done/' [name='password_change_done']>], [<URLResolver <URLPattern list> (admin:admin) 'admin/'>, <URLPattern 'jsi18n/' [name='jsi18n']>], [<URLResolver <URLPattern list> (admin:admin) 'admin/'>, <URLPattern 'r/<int:content_type_id>/<path:object_id>/' [name='view_on_site']>], [<URLResolver <URLPattern list> (admin:admin) 'admin/'>, <URLResolver <URLPattern list> (None:None) 'auth/group/'>], [<URLResolver <URLPattern list> (admin:admin) 'admin/'>, <URLResolver <URLPattern list> (None:None) 'auth/user/'>], [<URLResolver <URLPattern list> (admin:admin) 'admin/'>, <URLResolver <URLPattern list> (None:None) 'api_test/project/'>], [<URLResolver <URLPattern list> (admin:admin) 'admin/'>, <URLResolver <URLPattern list> (None:None) 'api_test/projectdynamic/'>], [<URLResolver <URLPattern list> (admin:admin) 'admin/'>, <URLResolver <URLPattern list> (None:None) 'api_test/projectmember/'>], [<URLResolver <URLPattern list> (admin:admin) 'admin/'>, <URLResolver <URLPattern list> (None:None) 'api_test/globalhost/'>], [<URLResolver <URLPattern list> (admin:admin) 'admin/'>, <URLResolver <URLPattern list> (None:None) 'api_test/custommethod/'>], [<URLResolver <URLPattern list> (admin:admin) 'admin/'>, <URLResolver <URLPattern list> (None:None) 'api_test/apigrouplevelfirst/'>], [<URLResolver <URLPattern list> (admin:admin) 'admin/'>, <URLResolver <URLPattern list> (None:None) 'api_test/apiinfo/'>], [<URLResolver <URLPattern list> (admin:admin) 'admin/'>, <URLResolver <URLPattern list> (None:None) 'api_test/apirequesthistory/'>], [<URLResolver <URLPattern list> (admin:admin) 'admin/'>, <URLResolver <URLPattern list> (None:None) 'api_test/apioperationhistory/'>], [<URLResolver <URLPattern list> (admin:admin) 'admin/'>, <URLResolver <URLPattern list> (None:None) 'api_test/automationgrouplevelfirst/'>], [<URLResolver <URLPattern list> (admin:admin) 'admin/'>, <URLResolver <URLPattern list> (None:None) 'api_test/automationtestcase/'>], [<URLResolver <URLPattern list> (admin:admin) 'admin/'>, <URLResolver <URLPattern list> (None:None) 'api_test/automationcaseapi/'>], [<URLResolver <URLPattern list> (admin:admin) 'admin/'>, <URLResolver <URLPattern list> (None:None) 'api_test/automationtestresult/'>], [<URLResolver <URLPattern list> (admin:admin) 'admin/'>, <URLResolver <URLPattern list> (None:None) 'api_test/automationtesttask/'>], [<URLResolver <URLPattern list> (admin:admin) 'admin/'>, <URLPattern '^(?P<app_label>auth|api_test)/$' [name='app_list']>], [<URLResolver <module 'api_test.urls' from 'H:\\project\\api_automation_test\\api_test\\urls.py'> (None:None) '^api/'>]], 'path': 'admin/api_test/apihead/'}

During handling of the above exception, another exception occurred:

Traceback (most recent call last):
  File "F:\工具安装\python3.6.3\lib\site-packages\django\template\base.py", line 835, in _resolve_lookup
    current = current[bit]
TypeError: 'URLResolver' object is not subscriptable

During handling of the above exception, another exception occurred:

Traceback (most recent call last):
  File "F:\工具安装\python3.6.3\lib\site-packages\django\template\base.py", line 843, in _resolve_lookup
    current = getattr(current, bit)
AttributeError: 'URLResolver' object has no attribute 'name'

During handling of the above exception, another exception occurred:

Traceback (most recent call last):
  File "F:\工具安装\python3.6.3\lib\site-packages\django\template\base.py", line 849, in _resolve_lookup
    current = current[int(bit)]
ValueError: invalid literal for int() with base 10: 'name'

During handling of the above exception, another exception occurred:

Traceback (most recent call last):
  File "F:\工具安装\python3.6.3\lib\site-packages\django\template\base.py", line 856, in _resolve_lookup
    (bit, current))  # missing attribute
django.template.base.VariableDoesNotExist: Failed lookup for key [name] in <URLResolver <URLPattern list> (None:None) 'api_test/automationcaseapi/'>
DEBUG 2018-01-31 15:51:18,283 F:\工具安装\python3.6.3\lib\site-packages\django\template\base.py base.py base _resolve_lookup 878: Exception while resolving variable 'name' in template 'unknown'.
Traceback (most recent call last):
  File "F:\工具安装\python3.6.3\lib\site-packages\django\core\handlers\exception.py", line 35, in inner
    response = get_response(request)
  File "F:\工具安装\python3.6.3\lib\site-packages\django\core\handlers\base.py", line 113, in _get_response
    resolver_match = resolver.resolve(request.path_info)
  File "F:\工具安装\python3.6.3\lib\site-packages\django\urls\resolvers.py", line 523, in resolve
    raise Resolver404({'tried': tried, 'path': new_path})
django.urls.exceptions.Resolver404: {'tried': [[<URLResolver <URLPattern list> (admin:admin) 'admin/'>, <URLPattern '' [name='index']>], [<URLResolver <URLPattern list> (admin:admin) 'admin/'>, <URLPattern 'login/' [name='login']>], [<URLResolver <URLPattern list> (admin:admin) 'admin/'>, <URLPattern 'logout/' [name='logout']>], [<URLResolver <URLPattern list> (admin:admin) 'admin/'>, <URLPattern 'password_change/' [name='password_change']>], [<URLResolver <URLPattern list> (admin:admin) 'admin/'>, <URLPattern 'password_change/done/' [name='password_change_done']>], [<URLResolver <URLPattern list> (admin:admin) 'admin/'>, <URLPattern 'jsi18n/' [name='jsi18n']>], [<URLResolver <URLPattern list> (admin:admin) 'admin/'>, <URLPattern 'r/<int:content_type_id>/<path:object_id>/' [name='view_on_site']>], [<URLResolver <URLPattern list> (admin:admin) 'admin/'>, <URLResolver <URLPattern list> (None:None) 'auth/group/'>], [<URLResolver <URLPattern list> (admin:admin) 'admin/'>, <URLResolver <URLPattern list> (None:None) 'auth/user/'>], [<URLResolver <URLPattern list> (admin:admin) 'admin/'>, <URLResolver <URLPattern list> (None:None) 'api_test/project/'>], [<URLResolver <URLPattern list> (admin:admin) 'admin/'>, <URLResolver <URLPattern list> (None:None) 'api_test/projectdynamic/'>], [<URLResolver <URLPattern list> (admin:admin) 'admin/'>, <URLResolver <URLPattern list> (None:None) 'api_test/projectmember/'>], [<URLResolver <URLPattern list> (admin:admin) 'admin/'>, <URLResolver <URLPattern list> (None:None) 'api_test/globalhost/'>], [<URLResolver <URLPattern list> (admin:admin) 'admin/'>, <URLResolver <URLPattern list> (None:None) 'api_test/custommethod/'>], [<URLResolver <URLPattern list> (admin:admin) 'admin/'>, <URLResolver <URLPattern list> (None:None) 'api_test/apigrouplevelfirst/'>], [<URLResolver <URLPattern list> (admin:admin) 'admin/'>, <URLResolver <URLPattern list> (None:None) 'api_test/apiinfo/'>], [<URLResolver <URLPattern list> (admin:admin) 'admin/'>, <URLResolver <URLPattern list> (None:None) 'api_test/apirequesthistory/'>], [<URLResolver <URLPattern list> (admin:admin) 'admin/'>, <URLResolver <URLPattern list> (None:None) 'api_test/apioperationhistory/'>], [<URLResolver <URLPattern list> (admin:admin) 'admin/'>, <URLResolver <URLPattern list> (None:None) 'api_test/automationgrouplevelfirst/'>], [<URLResolver <URLPattern list> (admin:admin) 'admin/'>, <URLResolver <URLPattern list> (None:None) 'api_test/automationtestcase/'>], [<URLResolver <URLPattern list> (admin:admin) 'admin/'>, <URLResolver <URLPattern list> (None:None) 'api_test/automationcaseapi/'>], [<URLResolver <URLPattern list> (admin:admin) 'admin/'>, <URLResolver <URLPattern list> (None:None) 'api_test/automationtestresult/'>], [<URLResolver <URLPattern list> (admin:admin) 'admin/'>, <URLResolver <URLPattern list> (None:None) 'api_test/automationtesttask/'>], [<URLResolver <URLPattern list> (admin:admin) 'admin/'>, <URLPattern '^(?P<app_label>auth|api_test)/$' [name='app_list']>], [<URLResolver <module 'api_test.urls' from 'H:\\project\\api_automation_test\\api_test\\urls.py'> (None:None) '^api/'>]], 'path': 'admin/api_test/apihead/'}

During handling of the above exception, another exception occurred:

Traceback (most recent call last):
  File "F:\工具安装\python3.6.3\lib\site-packages\django\template\base.py", line 835, in _resolve_lookup
    current = current[bit]
TypeError: 'URLResolver' object is not subscriptable

During handling of the above exception, another exception occurred:

Traceback (most recent call last):
  File "F:\工具安装\python3.6.3\lib\site-packages\django\template\base.py", line 843, in _resolve_lookup
    current = getattr(current, bit)
AttributeError: 'URLResolver' object has no attribute 'name'

During handling of the above exception, another exception occurred:

Traceback (most recent call last):
  File "F:\工具安装\python3.6.3\lib\site-packages\django\template\base.py", line 849, in _resolve_lookup
    current = current[int(bit)]
ValueError: invalid literal for int() with base 10: 'name'

During handling of the above exception, another exception occurred:

Traceback (most recent call last):
  File "F:\工具安装\python3.6.3\lib\site-packages\django\template\base.py", line 856, in _resolve_lookup
    (bit, current))  # missing attribute
django.template.base.VariableDoesNotExist: Failed lookup for key [name] in <URLResolver <URLPattern list> (None:None) 'api_test/automationtestresult/'>
DEBUG 2018-01-31 15:51:18,284 F:\工具安装\python3.6.3\lib\site-packages\django\template\base.py base.py base _resolve_lookup 878: Exception while resolving variable 'name' in template 'unknown'.
Traceback (most recent call last):
  File "F:\工具安装\python3.6.3\lib\site-packages\django\core\handlers\exception.py", line 35, in inner
    response = get_response(request)
  File "F:\工具安装\python3.6.3\lib\site-packages\django\core\handlers\base.py", line 113, in _get_response
    resolver_match = resolver.resolve(request.path_info)
  File "F:\工具安装\python3.6.3\lib\site-packages\django\urls\resolvers.py", line 523, in resolve
    raise Resolver404({'tried': tried, 'path': new_path})
django.urls.exceptions.Resolver404: {'tried': [[<URLResolver <URLPattern list> (admin:admin) 'admin/'>, <URLPattern '' [name='index']>], [<URLResolver <URLPattern list> (admin:admin) 'admin/'>, <URLPattern 'login/' [name='login']>], [<URLResolver <URLPattern list> (admin:admin) 'admin/'>, <URLPattern 'logout/' [name='logout']>], [<URLResolver <URLPattern list> (admin:admin) 'admin/'>, <URLPattern 'password_change/' [name='password_change']>], [<URLResolver <URLPattern list> (admin:admin) 'admin/'>, <URLPattern 'password_change/done/' [name='password_change_done']>], [<URLResolver <URLPattern list> (admin:admin) 'admin/'>, <URLPattern 'jsi18n/' [name='jsi18n']>], [<URLResolver <URLPattern list> (admin:admin) 'admin/'>, <URLPattern 'r/<int:content_type_id>/<path:object_id>/' [name='view_on_site']>], [<URLResolver <URLPattern list> (admin:admin) 'admin/'>, <URLResolver <URLPattern list> (None:None) 'auth/group/'>], [<URLResolver <URLPattern list> (admin:admin) 'admin/'>, <URLResolver <URLPattern list> (None:None) 'auth/user/'>], [<URLResolver <URLPattern list> (admin:admin) 'admin/'>, <URLResolver <URLPattern list> (None:None) 'api_test/project/'>], [<URLResolver <URLPattern list> (admin:admin) 'admin/'>, <URLResolver <URLPattern list> (None:None) 'api_test/projectdynamic/'>], [<URLResolver <URLPattern list> (admin:admin) 'admin/'>, <URLResolver <URLPattern list> (None:None) 'api_test/projectmember/'>], [<URLResolver <URLPattern list> (admin:admin) 'admin/'>, <URLResolver <URLPattern list> (None:None) 'api_test/globalhost/'>], [<URLResolver <URLPattern list> (admin:admin) 'admin/'>, <URLResolver <URLPattern list> (None:None) 'api_test/custommethod/'>], [<URLResolver <URLPattern list> (admin:admin) 'admin/'>, <URLResolver <URLPattern list> (None:None) 'api_test/apigrouplevelfirst/'>], [<URLResolver <URLPattern list> (admin:admin) 'admin/'>, <URLResolver <URLPattern list> (None:None) 'api_test/apiinfo/'>], [<URLResolver <URLPattern list> (admin:admin) 'admin/'>, <URLResolver <URLPattern list> (None:None) 'api_test/apirequesthistory/'>], [<URLResolver <URLPattern list> (admin:admin) 'admin/'>, <URLResolver <URLPattern list> (None:None) 'api_test/apioperationhistory/'>], [<URLResolver <URLPattern list> (admin:admin) 'admin/'>, <URLResolver <URLPattern list> (None:None) 'api_test/automationgrouplevelfirst/'>], [<URLResolver <URLPattern list> (admin:admin) 'admin/'>, <URLResolver <URLPattern list> (None:None) 'api_test/automationtestcase/'>], [<URLResolver <URLPattern list> (admin:admin) 'admin/'>, <URLResolver <URLPattern list> (None:None) 'api_test/automationcaseapi/'>], [<URLResolver <URLPattern list> (admin:admin) 'admin/'>, <URLResolver <URLPattern list> (None:None) 'api_test/automationtestresult/'>], [<URLResolver <URLPattern list> (admin:admin) 'admin/'>, <URLResolver <URLPattern list> (None:None) 'api_test/automationtesttask/'>], [<URLResolver <URLPattern list> (admin:admin) 'admin/'>, <URLPattern '^(?P<app_label>auth|api_test)/$' [name='app_list']>], [<URLResolver <module 'api_test.urls' from 'H:\\project\\api_automation_test\\api_test\\urls.py'> (None:None) '^api/'>]], 'path': 'admin/api_test/apihead/'}

During handling of the above exception, another exception occurred:

Traceback (most recent call last):
  File "F:\工具安装\python3.6.3\lib\site-packages\django\template\base.py", line 835, in _resolve_lookup
    current = current[bit]
TypeError: 'URLResolver' object is not subscriptable

During handling of the above exception, another exception occurred:

Traceback (most recent call last):
  File "F:\工具安装\python3.6.3\lib\site-packages\django\template\base.py", line 843, in _resolve_lookup
    current = getattr(current, bit)
AttributeError: 'URLResolver' object has no attribute 'name'

During handling of the above exception, another exception occurred:

Traceback (most recent call last):
  File "F:\工具安装\python3.6.3\lib\site-packages\django\template\base.py", line 849, in _resolve_lookup
    current = current[int(bit)]
ValueError: invalid literal for int() with base 10: 'name'

During handling of the above exception, another exception occurred:

Traceback (most recent call last):
  File "F:\工具安装\python3.6.3\lib\site-packages\django\template\base.py", line 856, in _resolve_lookup
    (bit, current))  # missing attribute
django.template.base.VariableDoesNotExist: Failed lookup for key [name] in <URLResolver <URLPattern list> (None:None) 'api_test/automationtesttask/'>
DEBUG 2018-01-31 15:51:18,285 F:\工具安装\python3.6.3\lib\site-packages\django\template\base.py base.py base _resolve_lookup 878: Exception while resolving variable 'name' in template 'unknown'.
Traceback (most recent call last):
  File "F:\工具安装\python3.6.3\lib\site-packages\django\core\handlers\exception.py", line 35, in inner
    response = get_response(request)
  File "F:\工具安装\python3.6.3\lib\site-packages\django\core\handlers\base.py", line 113, in _get_response
    resolver_match = resolver.resolve(request.path_info)
  File "F:\工具安装\python3.6.3\lib\site-packages\django\urls\resolvers.py", line 523, in resolve
    raise Resolver404({'tried': tried, 'path': new_path})
django.urls.exceptions.Resolver404: {'tried': [[<URLResolver <URLPattern list> (admin:admin) 'admin/'>, <URLPattern '' [name='index']>], [<URLResolver <URLPattern list> (admin:admin) 'admin/'>, <URLPattern 'login/' [name='login']>], [<URLResolver <URLPattern list> (admin:admin) 'admin/'>, <URLPattern 'logout/' [name='logout']>], [<URLResolver <URLPattern list> (admin:admin) 'admin/'>, <URLPattern 'password_change/' [name='password_change']>], [<URLResolver <URLPattern list> (admin:admin) 'admin/'>, <URLPattern 'password_change/done/' [name='password_change_done']>], [<URLResolver <URLPattern list> (admin:admin) 'admin/'>, <URLPattern 'jsi18n/' [name='jsi18n']>], [<URLResolver <URLPattern list> (admin:admin) 'admin/'>, <URLPattern 'r/<int:content_type_id>/<path:object_id>/' [name='view_on_site']>], [<URLResolver <URLPattern list> (admin:admin) 'admin/'>, <URLResolver <URLPattern list> (None:None) 'auth/group/'>], [<URLResolver <URLPattern list> (admin:admin) 'admin/'>, <URLResolver <URLPattern list> (None:None) 'auth/user/'>], [<URLResolver <URLPattern list> (admin:admin) 'admin/'>, <URLResolver <URLPattern list> (None:None) 'api_test/project/'>], [<URLResolver <URLPattern list> (admin:admin) 'admin/'>, <URLResolver <URLPattern list> (None:None) 'api_test/projectdynamic/'>], [<URLResolver <URLPattern list> (admin:admin) 'admin/'>, <URLResolver <URLPattern list> (None:None) 'api_test/projectmember/'>], [<URLResolver <URLPattern list> (admin:admin) 'admin/'>, <URLResolver <URLPattern list> (None:None) 'api_test/globalhost/'>], [<URLResolver <URLPattern list> (admin:admin) 'admin/'>, <URLResolver <URLPattern list> (None:None) 'api_test/custommethod/'>], [<URLResolver <URLPattern list> (admin:admin) 'admin/'>, <URLResolver <URLPattern list> (None:None) 'api_test/apigrouplevelfirst/'>], [<URLResolver <URLPattern list> (admin:admin) 'admin/'>, <URLResolver <URLPattern list> (None:None) 'api_test/apiinfo/'>], [<URLResolver <URLPattern list> (admin:admin) 'admin/'>, <URLResolver <URLPattern list> (None:None) 'api_test/apirequesthistory/'>], [<URLResolver <URLPattern list> (admin:admin) 'admin/'>, <URLResolver <URLPattern list> (None:None) 'api_test/apioperationhistory/'>], [<URLResolver <URLPattern list> (admin:admin) 'admin/'>, <URLResolver <URLPattern list> (None:None) 'api_test/automationgrouplevelfirst/'>], [<URLResolver <URLPattern list> (admin:admin) 'admin/'>, <URLResolver <URLPattern list> (None:None) 'api_test/automationtestcase/'>], [<URLResolver <URLPattern list> (admin:admin) 'admin/'>, <URLResolver <URLPattern list> (None:None) 'api_test/automationcaseapi/'>], [<URLResolver <URLPattern list> (admin:admin) 'admin/'>, <URLResolver <URLPattern list> (None:None) 'api_test/automationtestresult/'>], [<URLResolver <URLPattern list> (admin:admin) 'admin/'>, <URLResolver <URLPattern list> (None:None) 'api_test/automationtesttask/'>], [<URLResolver <URLPattern list> (admin:admin) 'admin/'>, <URLPattern '^(?P<app_label>auth|api_test)/$' [name='app_list']>], [<URLResolver <module 'api_test.urls' from 'H:\\project\\api_automation_test\\api_test\\urls.py'> (None:None) '^api/'>]], 'path': 'admin/api_test/apihead/'}

During handling of the above exception, another exception occurred:

Traceback (most recent call last):
  File "F:\工具安装\python3.6.3\lib\site-packages\django\template\base.py", line 835, in _resolve_lookup
    current = current[bit]
TypeError: 'URLResolver' object is not subscriptable

During handling of the above exception, another exception occurred:

Traceback (most recent call last):
  File "F:\工具安装\python3.6.3\lib\site-packages\django\template\base.py", line 843, in _resolve_lookup
    current = getattr(current, bit)
AttributeError: 'URLResolver' object has no attribute 'name'

During handling of the above exception, another exception occurred:

Traceback (most recent call last):
  File "F:\工具安装\python3.6.3\lib\site-packages\django\template\base.py", line 849, in _resolve_lookup
    current = current[int(bit)]
ValueError: invalid literal for int() with base 10: 'name'

During handling of the above exception, another exception occurred:

Traceback (most recent call last):
  File "F:\工具安装\python3.6.3\lib\site-packages\django\template\base.py", line 856, in _resolve_lookup
    (bit, current))  # missing attribute
django.template.base.VariableDoesNotExist: Failed lookup for key [name] in <URLResolver <module 'api_test.urls' from 'H:\\project\\api_automation_test\\api_test\\urls.py'> (None:None) '^api/'>
WARNING 2018-01-31 15:51:18,286 F:\工具安装\python3.6.3\lib\site-packages\django\core\servers\basehttp.py basehttp.py basehttp log_message 124: "GET /admin/api_test/apihead/ HTTP/1.1" 404 6364
DEBUG 2018-01-31 15:51:22,936 F:\工具安装\python3.6.3\lib\site-packages\django\template\base.py base.py base _resolve_lookup 878: Exception while resolving variable 'name' in template 'unknown'.
Traceback (most recent call last):
  File "F:\工具安装\python3.6.3\lib\site-packages\django\core\handlers\exception.py", line 35, in inner
    response = get_response(request)
  File "F:\工具安装\python3.6.3\lib\site-packages\django\core\handlers\base.py", line 113, in _get_response
    resolver_match = resolver.resolve(request.path_info)
  File "F:\工具安装\python3.6.3\lib\site-packages\django\urls\resolvers.py", line 523, in resolve
    raise Resolver404({'tried': tried, 'path': new_path})
django.urls.exceptions.Resolver404: {'tried': [[<URLResolver <URLPattern list> (admin:admin) 'admin/'>], [<URLResolver <module 'api_test.urls' from 'H:\\project\\api_automation_test\\api_test\\urls.py'> (None:None) '^api/'>]], 'path': 'admi'}

During handling of the above exception, another exception occurred:

Traceback (most recent call last):
  File "F:\工具安装\python3.6.3\lib\site-packages\django\template\base.py", line 835, in _resolve_lookup
    current = current[bit]
TypeError: 'URLResolver' object is not subscriptable

During handling of the above exception, another exception occurred:

Traceback (most recent call last):
  File "F:\工具安装\python3.6.3\lib\site-packages\django\template\base.py", line 843, in _resolve_lookup
    current = getattr(current, bit)
AttributeError: 'URLResolver' object has no attribute 'name'

During handling of the above exception, another exception occurred:

Traceback (most recent call last):
  File "F:\工具安装\python3.6.3\lib\site-packages\django\template\base.py", line 849, in _resolve_lookup
    current = current[int(bit)]
ValueError: invalid literal for int() with base 10: 'name'

During handling of the above exception, another exception occurred:

Traceback (most recent call last):
  File "F:\工具安装\python3.6.3\lib\site-packages\django\template\base.py", line 856, in _resolve_lookup
    (bit, current))  # missing attribute
django.template.base.VariableDoesNotExist: Failed lookup for key [name] in <URLResolver <URLPattern list> (admin:admin) 'admin/'>
DEBUG 2018-01-31 15:51:22,937 F:\工具安装\python3.6.3\lib\site-packages\django\template\base.py base.py base _resolve_lookup 878: Exception while resolving variable 'name' in template 'unknown'.
Traceback (most recent call last):
  File "F:\工具安装\python3.6.3\lib\site-packages\django\core\handlers\exception.py", line 35, in inner
    response = get_response(request)
  File "F:\工具安装\python3.6.3\lib\site-packages\django\core\handlers\base.py", line 113, in _get_response
    resolver_match = resolver.resolve(request.path_info)
  File "F:\工具安装\python3.6.3\lib\site-packages\django\urls\resolvers.py", line 523, in resolve
    raise Resolver404({'tried': tried, 'path': new_path})
django.urls.exceptions.Resolver404: {'tried': [[<URLResolver <URLPattern list> (admin:admin) 'admin/'>], [<URLResolver <module 'api_test.urls' from 'H:\\project\\api_automation_test\\api_test\\urls.py'> (None:None) '^api/'>]], 'path': 'admi'}

During handling of the above exception, another exception occurred:

Traceback (most recent call last):
  File "F:\工具安装\python3.6.3\lib\site-packages\django\template\base.py", line 835, in _resolve_lookup
    current = current[bit]
TypeError: 'URLResolver' object is not subscriptable

During handling of the above exception, another exception occurred:

Traceback (most recent call last):
  File "F:\工具安装\python3.6.3\lib\site-packages\django\template\base.py", line 843, in _resolve_lookup
    current = getattr(current, bit)
AttributeError: 'URLResolver' object has no attribute 'name'

During handling of the above exception, another exception occurred:

Traceback (most recent call last):
  File "F:\工具安装\python3.6.3\lib\site-packages\django\template\base.py", line 849, in _resolve_lookup
    current = current[int(bit)]
ValueError: invalid literal for int() with base 10: 'name'

During handling of the above exception, another exception occurred:

Traceback (most recent call last):
  File "F:\工具安装\python3.6.3\lib\site-packages\django\template\base.py", line 856, in _resolve_lookup
    (bit, current))  # missing attribute
django.template.base.VariableDoesNotExist: Failed lookup for key [name] in <URLResolver <module 'api_test.urls' from 'H:\\project\\api_automation_test\\api_test\\urls.py'> (None:None) '^api/'>
WARNING 2018-01-31 15:51:22,938 F:\工具安装\python3.6.3\lib\site-packages\django\core\servers\basehttp.py basehttp.py basehttp log_message 124: "GET /admi HTTP/1.1" 404 2069
DEBUG 2018-01-31 15:51:26,999 F:\工具安装\python3.6.3\lib\site-packages\django\db\backends\utils.py utils.py utils execute 111: (0.001) SELECT @@SQL_AUTO_IS_NULL; args=None
DEBUG 2018-01-31 15:51:26,999 F:\工具安装\python3.6.3\lib\site-packages\django\db\backends\utils.py utils.py utils execute 111: (0.000) SET SESSION TRANSACTION ISOLATION LEVEL READ COMMITTED; args=None
DEBUG 2018-01-31 15:51:27,000 F:\工具安装\python3.6.3\lib\site-packages\django\db\backends\utils.py utils.py utils execute 111: (0.000) SELECT VERSION(); args=None
DEBUG 2018-01-31 15:51:27,017 F:\工具安装\python3.6.3\lib\site-packages\django\db\backends\utils.py utils.py utils execute 111: (0.000) SET SESSION TRANSACTION ISOLATION LEVEL READ COMMITTED; args=None
DEBUG 2018-01-31 15:51:27,018 F:\工具安装\python3.6.3\lib\site-packages\django\db\backends\utils.py utils.py utils execute 111: (0.000) SELECT `django_session`.`session_key`, `django_session`.`session_data`, `django_session`.`expire_date` FROM `django_session` WHERE (`django_session`.`session_key` = '9pf05lmgr4gh5vzyfxkk76qfhagrj9xc' AND `django_session`.`expire_date` > '2018-01-31 07:51:26.981779'); args=('9pf05lmgr4gh5vzyfxkk76qfhagrj9xc', '2018-01-31 07:51:26.981779')
DEBUG 2018-01-31 15:51:27,020 F:\工具安装\python3.6.3\lib\site-packages\django\db\backends\utils.py utils.py utils execute 111: (0.001) SELECT `auth_user`.`id`, `auth_user`.`password`, `auth_user`.`last_login`, `auth_user`.`is_superuser`, `auth_user`.`username`, `auth_user`.`first_name`, `auth_user`.`last_name`, `auth_user`.`email`, `auth_user`.`is_staff`, `auth_user`.`is_active`, `auth_user`.`date_joined` FROM `auth_user` WHERE `auth_user`.`id` = 1; args=(1,)
DEBUG 2018-01-31 15:51:27,070 F:\工具安装\python3.6.3\lib\site-packages\django\template\base.py base.py base _resolve_lookup 878: Exception while resolving variable 'is_popup' in template 'admin/index.html'.
Traceback (most recent call last):
  File "F:\工具安装\python3.6.3\lib\site-packages\django\template\base.py", line 835, in _resolve_lookup
    current = current[bit]
  File "F:\工具安装\python3.6.3\lib\site-packages\django\template\context.py", line 83, in __getitem__
    raise KeyError(key)
KeyError: 'is_popup'

During handling of the above exception, another exception occurred:

Traceback (most recent call last):
  File "F:\工具安装\python3.6.3\lib\site-packages\django\template\base.py", line 841, in _resolve_lookup
    if isinstance(current, BaseContext) and getattr(type(current), bit):
AttributeError: type object 'RequestContext' has no attribute 'is_popup'

During handling of the above exception, another exception occurred:

Traceback (most recent call last):
  File "F:\工具安装\python3.6.3\lib\site-packages\django\template\base.py", line 849, in _resolve_lookup
    current = current[int(bit)]
ValueError: invalid literal for int() with base 10: 'is_popup'

During handling of the above exception, another exception occurred:

Traceback (most recent call last):
  File "F:\工具安装\python3.6.3\lib\site-packages\django\template\base.py", line 856, in _resolve_lookup
    (bit, current))  # missing attribute
django.template.base.VariableDoesNotExist: Failed lookup for key [is_popup] in [{'True': True, 'False': False, 'None': None}, {'csrf_token': <SimpleLazyObject: <function csrf.<locals>._get_val at 0x000001EB3337DAE8>>, 'request': <WSGIRequest: GET '/admin/'>, 'user': <SimpleLazyObject: <User: litao>>, 'perms': <django.contrib.auth.context_processors.PermWrapper object at 0x000001EB334E2FD0>, 'messages': <django.contrib.messages.storage.fallback.FallbackStorage object at 0x000001EB33347470>, 'DEFAULT_MESSAGE_LEVELS': {'DEBUG': 10, 'INFO': 20, 'SUCCESS': 25, 'WARNING': 30, 'ERROR': 40}}, {}, {'site_title': 'Django 站点管理员', 'site_header': '测试平台后台管理', 'site_url': '/', 'has_permission': True, 'available_apps': [{'name': '接口测试平台', 'app_label': 'api_test', 'app_url': '/admin/api_test/', 'has_module_perms': True, 'models': [{'name': 'HOST管理', 'object_name': 'GlobalHost', 'perms': {'add': True, 'change': True, 'delete': True}, 'admin_url': '/admin/api_test/globalhost/', 'add_url': '/admin/api_test/globalhost/add/'}, {'name': '接口分组', 'object_name': 'ApiGroupLevelFirst', 'perms': {'add': True, 'change': True, 'delete': True}, 'admin_url': '/admin/api_test/apigrouplevelfirst/', 'add_url': '/admin/api_test/apigrouplevelfirst/add/'}, {'name': '接口操作历史', 'object_name': 'ApiOperationHistory', 'perms': {'add': False, 'change': True, 'delete': False}, 'admin_url': '/admin/api_test/apioperationhistory/'}, {'name': '接口管理', 'object_name': 'ApiInfo', 'perms': {'add': True, 'change': True, 'delete': True}, 'admin_url': '/admin/api_test/apiinfo/', 'add_url': '/admin/api_test/apiinfo/add/'}, {'name': '接口请求历史', 'object_name': 'APIRequestHistory', 'perms': {'add': False, 'change': True, 'delete': False}, 'admin_url': '/admin/api_test/apirequesthistory/'}, {'name': '测试结果管理', 'object_name': 'AutomationTestResult', 'perms': {'add': False, 'change': True, 'delete': False}, 'admin_url': '/admin/api_test/automationtestresult/'}, {'name': '用例分组管理', 'object_name': 'AutomationGroupLevelFirst', 'perms': {'add': True, 'change': True, 'delete': True}, 'admin_url': '/admin/api_test/automationgrouplevelfirst/', 'add_url': '/admin/api_test/automationgrouplevelfirst/add/'}, {'name': '用例定时任务管理', 'object_name': 'AutomationTestTask', 'perms': {'add': True, 'change': True, 'delete': True}, 'admin_url': '/admin/api_test/automationtesttask/', 'add_url': '/admin/api_test/automationtesttask/add/'}, {'name': '用例接口管理', 'object_name': 'AutomationCaseApi', 'perms': {'add': True, 'change': True, 'delete': True}, 'admin_url': '/admin/api_test/automationcaseapi/', 'add_url': '/admin/api_test/automationcaseapi/add/'}, {'name': '自动化测试用例', 'object_name': 'AutomationTestCase', 'perms': {'add': True, 'change': True, 'delete': True}, 'admin_url': '/admin/api_test/automationtestcase/', 'add_url': '/admin/api_test/automationtestcase/add/'}, {'name': '自定义方法', 'object_name': 'CustomMethod', 'perms': {'add': True, 'change': True, 'delete': True}, 'admin_url': '/admin/api_test/custommethod/', 'add_url': '/admin/api_test/custommethod/add/'}, {'name': '项目', 'object_name': 'Project', 'perms': {'add': True, 'change': True, 'delete': True}, 'admin_url': '/admin/api_test/project/', 'add_url': '/admin/api_test/project/add/'}, {'name': '项目动态', 'object_name': 'ProjectDynamic', 'perms': {'add': False, 'change': True, 'delete': False}, 'admin_url': '/admin/api_test/projectdynamic/'}, {'name': '项目成员', 'object_name': 'ProjectMember', 'perms': {'add': True, 'change': True, 'delete': True}, 'admin_url': '/admin/api_test/projectmember/', 'add_url': '/admin/api_test/projectmember/add/'}]}, {'name': '认证和授权', 'app_label': 'auth', 'app_url': '/admin/auth/', 'has_module_perms': True, 'models': [{'name': '用户', 'object_name': 'User', 'perms': {'add': True, 'change': True, 'delete': True}, 'admin_url': '/admin/auth/user/', 'add_url': '/admin/auth/user/add/'}, {'name': '组', 'object_name': 'Group', 'perms': {'add': True, 'change': True, 'delete': True}, 'admin_url': '/admin/auth/group/', 'add_url': '/admin/auth/group/add/'}]}], 'title': '站点管理', 'app_list': [{'name': '接口测试平台', 'app_label': 'api_test', 'app_url': '/admin/api_test/', 'has_module_perms': True, 'models': [{'name': 'HOST管理', 'object_name': 'GlobalHost', 'perms': {'add': True, 'change': True, 'delete': True}, 'admin_url': '/admin/api_test/globalhost/', 'add_url': '/admin/api_test/globalhost/add/'}, {'name': '接口分组', 'object_name': 'ApiGroupLevelFirst', 'perms': {'add': True, 'change': True, 'delete': True}, 'admin_url': '/admin/api_test/apigrouplevelfirst/', 'add_url': '/admin/api_test/apigrouplevelfirst/add/'}, {'name': '接口操作历史', 'object_name': 'ApiOperationHistory', 'perms': {'add': False, 'change': True, 'delete': False}, 'admin_url': '/admin/api_test/apioperationhistory/'}, {'name': '接口管理', 'object_name': 'ApiInfo', 'perms': {'add': True, 'change': True, 'delete': True}, 'admin_url': '/admin/api_test/apiinfo/', 'add_url': '/admin/api_test/apiinfo/add/'}, {'name': '接口请求历史', 'object_name': 'APIRequestHistory', 'perms': {'add': False, 'change': True, 'delete': False}, 'admin_url': '/admin/api_test/apirequesthistory/'}, {'name': '测试结果管理', 'object_name': 'AutomationTestResult', 'perms': {'add': False, 'change': True, 'delete': False}, 'admin_url': '/admin/api_test/automationtestresult/'}, {'name': '用例分组管理', 'object_name': 'AutomationGroupLevelFirst', 'perms': {'add': True, 'change': True, 'delete': True}, 'admin_url': '/admin/api_test/automationgrouplevelfirst/', 'add_url': '/admin/api_test/automationgrouplevelfirst/add/'}, {'name': '用例定时任务管理', 'object_name': 'AutomationTestTask', 'perms': {'add': True, 'change': True, 'delete': True}, 'admin_url': '/admin/api_test/automationtesttask/', 'add_url': '/admin/api_test/automationtesttask/add/'}, {'name': '用例接口管理', 'object_name': 'AutomationCaseApi', 'perms': {'add': True, 'change': True, 'delete': True}, 'admin_url': '/admin/api_test/automationcaseapi/', 'add_url': '/admin/api_test/automationcaseapi/add/'}, {'name': '自动化测试用例', 'object_name': 'AutomationTestCase', 'perms': {'add': True, 'change': True, 'delete': True}, 'admin_url': '/admin/api_test/automationtestcase/', 'add_url': '/admin/api_test/automationtestcase/add/'}, {'name': '自定义方法', 'object_name': 'CustomMethod', 'perms': {'add': True, 'change': True, 'delete': True}, 'admin_url': '/admin/api_test/custommethod/', 'add_url': '/admin/api_test/custommethod/add/'}, {'name': '项目', 'object_name': 'Project', 'perms': {'add': True, 'change': True, 'delete': True}, 'admin_url': '/admin/api_test/project/', 'add_url': '/admin/api_test/project/add/'}, {'name': '项目动态', 'object_name': 'ProjectDynamic', 'perms': {'add': False, 'change': True, 'delete': False}, 'admin_url': '/admin/api_test/projectdynamic/'}, {'name': '项目成员', 'object_name': 'ProjectMember', 'perms': {'add': True, 'change': True, 'delete': True}, 'admin_url': '/admin/api_test/projectmember/', 'add_url': '/admin/api_test/projectmember/add/'}]}, {'name': '认证和授权', 'app_label': 'auth', 'app_url': '/admin/auth/', 'has_module_perms': True, 'models': [{'name': '用户', 'object_name': 'User', 'perms': {'add': True, 'change': True, 'delete': True}, 'admin_url': '/admin/auth/user/', 'add_url': '/admin/auth/user/add/'}, {'name': '组', 'object_name': 'Group', 'perms': {'add': True, 'change': True, 'delete': True}, 'admin_url': '/admin/auth/group/', 'add_url': '/admin/auth/group/add/'}]}], 'LANGUAGE_CODE': 'zh-Hans', 'LANGUAGE_BIDI': False}]
DEBUG 2018-01-31 15:51:27,073 F:\工具安装\python3.6.3\lib\site-packages\django\template\base.py base.py base _resolve_lookup 878: Exception while resolving variable 'is_popup' in template 'admin/index.html'.
Traceback (most recent call last):
  File "F:\工具安装\python3.6.3\lib\site-packages\django\template\base.py", line 835, in _resolve_lookup
    current = current[bit]
  File "F:\工具安装\python3.6.3\lib\site-packages\django\template\context.py", line 83, in __getitem__
    raise KeyError(key)
KeyError: 'is_popup'

During handling of the above exception, another exception occurred:

Traceback (most recent call last):
  File "F:\工具安装\python3.6.3\lib\site-packages\django\template\base.py", line 841, in _resolve_lookup
    if isinstance(current, BaseContext) and getattr(type(current), bit):
AttributeError: type object 'RequestContext' has no attribute 'is_popup'

During handling of the above exception, another exception occurred:

Traceback (most recent call last):
  File "F:\工具安装\python3.6.3\lib\site-packages\django\template\base.py", line 849, in _resolve_lookup
    current = current[int(bit)]
ValueError: invalid literal for int() with base 10: 'is_popup'

During handling of the above exception, another exception occurred:

Traceback (most recent call last):
  File "F:\工具安装\python3.6.3\lib\site-packages\django\template\base.py", line 856, in _resolve_lookup
    (bit, current))  # missing attribute
django.template.base.VariableDoesNotExist: Failed lookup for key [is_popup] in [{'True': True, 'False': False, 'None': None}, {'csrf_token': <SimpleLazyObject: <function csrf.<locals>._get_val at 0x000001EB3337DAE8>>, 'request': <WSGIRequest: GET '/admin/'>, 'user': <SimpleLazyObject: <User: litao>>, 'perms': <django.contrib.auth.context_processors.PermWrapper object at 0x000001EB334E2FD0>, 'messages': <django.contrib.messages.storage.fallback.FallbackStorage object at 0x000001EB33347470>, 'DEFAULT_MESSAGE_LEVELS': {'DEBUG': 10, 'INFO': 20, 'SUCCESS': 25, 'WARNING': 30, 'ERROR': 40}}, {}, {'site_title': 'Django 站点管理员', 'site_header': '测试平台后台管理', 'site_url': '/', 'has_permission': True, 'available_apps': [{'name': '接口测试平台', 'app_label': 'api_test', 'app_url': '/admin/api_test/', 'has_module_perms': True, 'models': [{'name': 'HOST管理', 'object_name': 'GlobalHost', 'perms': {'add': True, 'change': True, 'delete': True}, 'admin_url': '/admin/api_test/globalhost/', 'add_url': '/admin/api_test/globalhost/add/'}, {'name': '接口分组', 'object_name': 'ApiGroupLevelFirst', 'perms': {'add': True, 'change': True, 'delete': True}, 'admin_url': '/admin/api_test/apigrouplevelfirst/', 'add_url': '/admin/api_test/apigrouplevelfirst/add/'}, {'name': '接口操作历史', 'object_name': 'ApiOperationHistory', 'perms': {'add': False, 'change': True, 'delete': False}, 'admin_url': '/admin/api_test/apioperationhistory/'}, {'name': '接口管理', 'object_name': 'ApiInfo', 'perms': {'add': True, 'change': True, 'delete': True}, 'admin_url': '/admin/api_test/apiinfo/', 'add_url': '/admin/api_test/apiinfo/add/'}, {'name': '接口请求历史', 'object_name': 'APIRequestHistory', 'perms': {'add': False, 'change': True, 'delete': False}, 'admin_url': '/admin/api_test/apirequesthistory/'}, {'name': '测试结果管理', 'object_name': 'AutomationTestResult', 'perms': {'add': False, 'change': True, 'delete': False}, 'admin_url': '/admin/api_test/automationtestresult/'}, {'name': '用例分组管理', 'object_name': 'AutomationGroupLevelFirst', 'perms': {'add': True, 'change': True, 'delete': True}, 'admin_url': '/admin/api_test/automationgrouplevelfirst/', 'add_url': '/admin/api_test/automationgrouplevelfirst/add/'}, {'name': '用例定时任务管理', 'object_name': 'AutomationTestTask', 'perms': {'add': True, 'change': True, 'delete': True}, 'admin_url': '/admin/api_test/automationtesttask/', 'add_url': '/admin/api_test/automationtesttask/add/'}, {'name': '用例接口管理', 'object_name': 'AutomationCaseApi', 'perms': {'add': True, 'change': True, 'delete': True}, 'admin_url': '/admin/api_test/automationcaseapi/', 'add_url': '/admin/api_test/automationcaseapi/add/'}, {'name': '自动化测试用例', 'object_name': 'AutomationTestCase', 'perms': {'add': True, 'change': True, 'delete': True}, 'admin_url': '/admin/api_test/automationtestcase/', 'add_url': '/admin/api_test/automationtestcase/add/'}, {'name': '自定义方法', 'object_name': 'CustomMethod', 'perms': {'add': True, 'change': True, 'delete': True}, 'admin_url': '/admin/api_test/custommethod/', 'add_url': '/admin/api_test/custommethod/add/'}, {'name': '项目', 'object_name': 'Project', 'perms': {'add': True, 'change': True, 'delete': True}, 'admin_url': '/admin/api_test/project/', 'add_url': '/admin/api_test/project/add/'}, {'name': '项目动态', 'object_name': 'ProjectDynamic', 'perms': {'add': False, 'change': True, 'delete': False}, 'admin_url': '/admin/api_test/projectdynamic/'}, {'name': '项目成员', 'object_name': 'ProjectMember', 'perms': {'add': True, 'change': True, 'delete': True}, 'admin_url': '/admin/api_test/projectmember/', 'add_url': '/admin/api_test/projectmember/add/'}]}, {'name': '认证和授权', 'app_label': 'auth', 'app_url': '/admin/auth/', 'has_module_perms': True, 'models': [{'name': '用户', 'object_name': 'User', 'perms': {'add': True, 'change': True, 'delete': True}, 'admin_url': '/admin/auth/user/', 'add_url': '/admin/auth/user/add/'}, {'name': '组', 'object_name': 'Group', 'perms': {'add': True, 'change': True, 'delete': True}, 'admin_url': '/admin/auth/group/', 'add_url': '/admin/auth/group/add/'}]}], 'title': '站点管理', 'app_list': [{'name': '接口测试平台', 'app_label': 'api_test', 'app_url': '/admin/api_test/', 'has_module_perms': True, 'models': [{'name': 'HOST管理', 'object_name': 'GlobalHost', 'perms': {'add': True, 'change': True, 'delete': True}, 'admin_url': '/admin/api_test/globalhost/', 'add_url': '/admin/api_test/globalhost/add/'}, {'name': '接口分组', 'object_name': 'ApiGroupLevelFirst', 'perms': {'add': True, 'change': True, 'delete': True}, 'admin_url': '/admin/api_test/apigrouplevelfirst/', 'add_url': '/admin/api_test/apigrouplevelfirst/add/'}, {'name': '接口操作历史', 'object_name': 'ApiOperationHistory', 'perms': {'add': False, 'change': True, 'delete': False}, 'admin_url': '/admin/api_test/apioperationhistory/'}, {'name': '接口管理', 'object_name': 'ApiInfo', 'perms': {'add': True, 'change': True, 'delete': True}, 'admin_url': '/admin/api_test/apiinfo/', 'add_url': '/admin/api_test/apiinfo/add/'}, {'name': '接口请求历史', 'object_name': 'APIRequestHistory', 'perms': {'add': False, 'change': True, 'delete': False}, 'admin_url': '/admin/api_test/apirequesthistory/'}, {'name': '测试结果管理', 'object_name': 'AutomationTestResult', 'perms': {'add': False, 'change': True, 'delete': False}, 'admin_url': '/admin/api_test/automationtestresult/'}, {'name': '用例分组管理', 'object_name': 'AutomationGroupLevelFirst', 'perms': {'add': True, 'change': True, 'delete': True}, 'admin_url': '/admin/api_test/automationgrouplevelfirst/', 'add_url': '/admin/api_test/automationgrouplevelfirst/add/'}, {'name': '用例定时任务管理', 'object_name': 'AutomationTestTask', 'perms': {'add': True, 'change': True, 'delete': True}, 'admin_url': '/admin/api_test/automationtesttask/', 'add_url': '/admin/api_test/automationtesttask/add/'}, {'name': '用例接口管理', 'object_name': 'AutomationCaseApi', 'perms': {'add': True, 'change': True, 'delete': True}, 'admin_url': '/admin/api_test/automationcaseapi/', 'add_url': '/admin/api_test/automationcaseapi/add/'}, {'name': '自动化测试用例', 'object_name': 'AutomationTestCase', 'perms': {'add': True, 'change': True, 'delete': True}, 'admin_url': '/admin/api_test/automationtestcase/', 'add_url': '/admin/api_test/automationtestcase/add/'}, {'name': '自定义方法', 'object_name': 'CustomMethod', 'perms': {'add': True, 'change': True, 'delete': True}, 'admin_url': '/admin/api_test/custommethod/', 'add_url': '/admin/api_test/custommethod/add/'}, {'name': '项目', 'object_name': 'Project', 'perms': {'add': True, 'change': True, 'delete': True}, 'admin_url': '/admin/api_test/project/', 'add_url': '/admin/api_test/project/add/'}, {'name': '项目动态', 'object_name': 'ProjectDynamic', 'perms': {'add': False, 'change': True, 'delete': False}, 'admin_url': '/admin/api_test/projectdynamic/'}, {'name': '项目成员', 'object_name': 'ProjectMember', 'perms': {'add': True, 'change': True, 'delete': True}, 'admin_url': '/admin/api_test/projectmember/', 'add_url': '/admin/api_test/projectmember/add/'}]}, {'name': '认证和授权', 'app_label': 'auth', 'app_url': '/admin/auth/', 'has_module_perms': True, 'models': [{'name': '用户', 'object_name': 'User', 'perms': {'add': True, 'change': True, 'delete': True}, 'admin_url': '/admin/auth/user/', 'add_url': '/admin/auth/user/add/'}, {'name': '组', 'object_name': 'Group', 'perms': {'add': True, 'change': True, 'delete': True}, 'admin_url': '/admin/auth/group/', 'add_url': '/admin/auth/group/add/'}]}], 'LANGUAGE_CODE': 'zh-Hans', 'LANGUAGE_BIDI': False}]
DEBUG 2018-01-31 15:51:27,076 F:\工具安装\python3.6.3\lib\site-packages\django\template\base.py base.py base _resolve_lookup 878: Exception while resolving variable 'add_url' in template 'admin/index.html'.
Traceback (most recent call last):
  File "F:\工具安装\python3.6.3\lib\site-packages\django\template\base.py", line 835, in _resolve_lookup
    current = current[bit]
KeyError: 'add_url'

During handling of the above exception, another exception occurred:

Traceback (most recent call last):
  File "F:\工具安装\python3.6.3\lib\site-packages\django\template\base.py", line 843, in _resolve_lookup
    current = getattr(current, bit)
AttributeError: 'dict' object has no attribute 'add_url'

During handling of the above exception, another exception occurred:

Traceback (most recent call last):
  File "F:\工具安装\python3.6.3\lib\site-packages\django\template\base.py", line 849, in _resolve_lookup
    current = current[int(bit)]
ValueError: invalid literal for int() with base 10: 'add_url'

During handling of the above exception, another exception occurred:

Traceback (most recent call last):
  File "F:\工具安装\python3.6.3\lib\site-packages\django\template\base.py", line 856, in _resolve_lookup
    (bit, current))  # missing attribute
django.template.base.VariableDoesNotExist: Failed lookup for key [add_url] in {'name': '接口操作历史', 'object_name': 'ApiOperationHistory', 'perms': {'add': False, 'change': True, 'delete': False}, 'admin_url': '/admin/api_test/apioperationhistory/'}
DEBUG 2018-01-31 15:51:27,077 F:\工具安装\python3.6.3\lib\site-packages\django\template\base.py base.py base _resolve_lookup 878: Exception while resolving variable 'add_url' in template 'admin/index.html'.
Traceback (most recent call last):
  File "F:\工具安装\python3.6.3\lib\site-packages\django\template\base.py", line 835, in _resolve_lookup
    current = current[bit]
KeyError: 'add_url'

During handling of the above exception, another exception occurred:

Traceback (most recent call last):
  File "F:\工具安装\python3.6.3\lib\site-packages\django\template\base.py", line 843, in _resolve_lookup
    current = getattr(current, bit)
AttributeError: 'dict' object has no attribute 'add_url'

During handling of the above exception, another exception occurred:

Traceback (most recent call last):
  File "F:\工具安装\python3.6.3\lib\site-packages\django\template\base.py", line 849, in _resolve_lookup
    current = current[int(bit)]
ValueError: invalid literal for int() with base 10: 'add_url'

During handling of the above exception, another exception occurred:

Traceback (most recent call last):
  File "F:\工具安装\python3.6.3\lib\site-packages\django\template\base.py", line 856, in _resolve_lookup
    (bit, current))  # missing attribute
django.template.base.VariableDoesNotExist: Failed lookup for key [add_url] in {'name': '接口请求历史', 'object_name': 'APIRequestHistory', 'perms': {'add': False, 'change': True, 'delete': False}, 'admin_url': '/admin/api_test/apirequesthistory/'}
DEBUG 2018-01-31 15:51:27,078 F:\工具安装\python3.6.3\lib\site-packages\django\template\base.py base.py base _resolve_lookup 878: Exception while resolving variable 'add_url' in template 'admin/index.html'.
Traceback (most recent call last):
  File "F:\工具安装\python3.6.3\lib\site-packages\django\template\base.py", line 835, in _resolve_lookup
    current = current[bit]
KeyError: 'add_url'

During handling of the above exception, another exception occurred:

Traceback (most recent call last):
  File "F:\工具安装\python3.6.3\lib\site-packages\django\template\base.py", line 843, in _resolve_lookup
    current = getattr(current, bit)
AttributeError: 'dict' object has no attribute 'add_url'

During handling of the above exception, another exception occurred:

Traceback (most recent call last):
  File "F:\工具安装\python3.6.3\lib\site-packages\django\template\base.py", line 849, in _resolve_lookup
    current = current[int(bit)]
ValueError: invalid literal for int() with base 10: 'add_url'

During handling of the above exception, another exception occurred:

Traceback (most recent call last):
  File "F:\工具安装\python3.6.3\lib\site-packages\django\template\base.py", line 856, in _resolve_lookup
    (bit, current))  # missing attribute
django.template.base.VariableDoesNotExist: Failed lookup for key [add_url] in {'name': '测试结果管理', 'object_name': 'AutomationTestResult', 'perms': {'add': False, 'change': True, 'delete': False}, 'admin_url': '/admin/api_test/automationtestresult/'}
DEBUG 2018-01-31 15:51:27,079 F:\工具安装\python3.6.3\lib\site-packages\django\template\base.py base.py base _resolve_lookup 878: Exception while resolving variable 'add_url' in template 'admin/index.html'.
Traceback (most recent call last):
  File "F:\工具安装\python3.6.3\lib\site-packages\django\template\base.py", line 835, in _resolve_lookup
    current = current[bit]
KeyError: 'add_url'

During handling of the above exception, another exception occurred:

Traceback (most recent call last):
  File "F:\工具安装\python3.6.3\lib\site-packages\django\template\base.py", line 843, in _resolve_lookup
    current = getattr(current, bit)
AttributeError: 'dict' object has no attribute 'add_url'

During handling of the above exception, another exception occurred:

Traceback (most recent call last):
  File "F:\工具安装\python3.6.3\lib\site-packages\django\template\base.py", line 849, in _resolve_lookup
    current = current[int(bit)]
ValueError: invalid literal for int() with base 10: 'add_url'

During handling of the above exception, another exception occurred:

Traceback (most recent call last):
  File "F:\工具安装\python3.6.3\lib\site-packages\django\template\base.py", line 856, in _resolve_lookup
    (bit, current))  # missing attribute
django.template.base.VariableDoesNotExist: Failed lookup for key [add_url] in {'name': '项目动态', 'object_name': 'ProjectDynamic', 'perms': {'add': False, 'change': True, 'delete': False}, 'admin_url': '/admin/api_test/projectdynamic/'}
DEBUG 2018-01-31 15:51:27,082 F:\工具安装\python3.6.3\lib\site-packages\django\db\backends\utils.py utils.py utils execute 111: (0.001) SELECT `django_admin_log`.`id`, `django_admin_log`.`action_time`, `django_admin_log`.`user_id`, `django_admin_log`.`content_type_id`, `django_admin_log`.`object_id`, `django_admin_log`.`object_repr`, `django_admin_log`.`action_flag`, `django_admin_log`.`change_message`, `auth_user`.`id`, `auth_user`.`password`, `auth_user`.`last_login`, `auth_user`.`is_superuser`, `auth_user`.`username`, `auth_user`.`first_name`, `auth_user`.`last_name`, `auth_user`.`email`, `auth_user`.`is_staff`, `auth_user`.`is_active`, `auth_user`.`date_joined`, `django_content_type`.`id`, `django_content_type`.`app_label`, `django_content_type`.`model` FROM `django_admin_log` INNER JOIN `auth_user` ON (`django_admin_log`.`user_id` = `auth_user`.`id`) LEFT OUTER JOIN `django_content_type` ON (`django_admin_log`.`content_type_id` = `django_content_type`.`id`) WHERE `django_admin_log`.`user_id` = 1 ORDER BY `django_admin_log`.`action_time` DESC LIMIT 10; args=(1,)
INFO 2018-01-31 15:51:27,085 F:\工具安装\python3.6.3\lib\site-packages\django\core\servers\basehttp.py basehttp.py basehttp log_message 124: "GET /admin/ HTTP/1.1" 200 9915
DEBUG 2018-01-31 16:00:54,182 F:\工具安装\python3.6.3\lib\site-packages\django\db\backends\utils.py utils.py utils execute 111: (0.000) SELECT @@SQL_AUTO_IS_NULL; args=None
DEBUG 2018-01-31 16:00:54,182 F:\工具安装\python3.6.3\lib\site-packages\django\db\backends\utils.py utils.py utils execute 111: (0.000) SET SESSION TRANSACTION ISOLATION LEVEL READ COMMITTED; args=None
DEBUG 2018-01-31 16:00:54,182 F:\工具安装\python3.6.3\lib\site-packages\django\db\backends\utils.py utils.py utils execute 111: (0.000) SELECT VERSION(); args=None
DEBUG 2018-01-31 16:00:54,312 F:\工具安装\python3.6.3\lib\site-packages\django\db\backends\utils.py utils.py utils execute 111: (0.000) SET SESSION TRANSACTION ISOLATION LEVEL READ COMMITTED; args=None
DEBUG 2018-01-31 16:00:54,312 F:\工具安装\python3.6.3\lib\site-packages\django\db\backends\utils.py utils.py utils execute 111: (0.000) SHOW FULL TABLES; args=None
DEBUG 2018-01-31 16:00:54,312 F:\工具安装\python3.6.3\lib\site-packages\django\db\backends\utils.py utils.py utils execute 111: (0.000) SELECT `django_migrations`.`app`, `django_migrations`.`name` FROM `django_migrations`; args=()
